/*
*** MADE BY MITHION'S .SCHEMATIC TO JAVA CONVERTING TOOL v1.6 ***
*/

package net.minecraft.src;
import java.util.Random;

public class Cytoid extends WorldGenerator
{
	protected int[] GetValidSpawnBlocks() {
		return new int[] {
		};
	}

	public boolean LocationIsValidSpawn(World world, int i, int j, int k){
		int distanceToAir = 0;
		int checkID = world.getBlockId(i, j, k);

		while (checkID != 0){
			distanceToAir++;
			checkID = world.getBlockId(i, j + distanceToAir, k);
		}

		if (distanceToAir > 3){
			return false;
		}
		j += distanceToAir - 1;

		int blockID = world.getBlockId(i, j, k);
		int blockIDAbove = world.getBlockId(i, j+1, k);
		int blockIDBelow = world.getBlockId(i, j-1, k);
		for (int x : GetValidSpawnBlocks()){
			if (blockIDAbove != 0){
				return false;
			}
			if (blockID == x){
				return true;
			}else if (blockID == Block.snow.blockID && blockIDBelow == x){
				return true;
			}
		}
		return false;
	}

	public Cytoid() { }

	public boolean generate(World world, Random rand, int i, int j, int k) {
		//check that each corner is one of the valid spawn blocks
		if(!LocationIsValidSpawn(world, i, j, k) || !LocationIsValidSpawn(world, i + 26, j, k) || !LocationIsValidSpawn(world, i + 26, j, k + 27) || !LocationIsValidSpawn(world, i, j, k + 27))
		{
			return false;
		}

		world.setBlock(i + 0, j + 0, k + 0, 0);
		world.setBlock(i + 0, j + 0, k + 1, 0);
		world.setBlock(i + 0, j + 0, k + 2, 0);
		world.setBlock(i + 0, j + 0, k + 3, 0);
		world.setBlock(i + 0, j + 0, k + 4, 0);
		world.setBlock(i + 0, j + 0, k + 5, 0);
		world.setBlock(i + 0, j + 0, k + 6, 0);
		world.setBlock(i + 0, j + 0, k + 7, 0);
		world.setBlock(i + 0, j + 0, k + 8, 0);
		world.setBlock(i + 0, j + 0, k + 9, 0);
		world.setBlock(i + 0, j + 0, k + 10, Block.blockSteel.blockID);
		world.setBlock(i + 0, j + 0, k + 11, Block.blockSteel.blockID);
		world.setBlock(i + 0, j + 0, k + 12, Block.blockSteel.blockID);
		world.setBlock(i + 0, j + 0, k + 13, Block.blockSteel.blockID);
		world.setBlock(i + 0, j + 0, k + 14, Block.blockSteel.blockID);
		world.setBlock(i + 0, j + 0, k + 15, Block.blockSteel.blockID);
		world.setBlock(i + 0, j + 0, k + 16, Block.blockSteel.blockID);
		world.setBlock(i + 0, j + 0, k + 17, Block.blockSteel.blockID);
		world.setBlock(i + 0, j + 0, k + 18, Block.blockSteel.blockID);
		world.setBlock(i + 0, j + 0, k + 19, Block.blockSteel.blockID);
		world.setBlock(i + 0, j + 0, k + 20, Block.blockSteel.blockID);
		world.setBlock(i + 0, j + 0, k + 21, Block.blockSteel.blockID);
		world.setBlock(i + 0, j + 0, k + 22, Block.blockSteel.blockID);
		world.setBlock(i + 0, j + 0, k + 23, Block.blockSteel.blockID);
		world.setBlock(i + 0, j + 0, k + 24, Block.blockSteel.blockID);
		world.setBlock(i + 0, j + 0, k + 25, 0);
		world.setBlock(i + 0, j + 0, k + 26, 0);
		world.setBlock(i + 0, j + 0, k + 27, 0);
		world.setBlock(i + 0, j + 1, k + 0, 0);
		world.setBlock(i + 0, j + 1, k + 1, 0);
		world.setBlock(i + 0, j + 1, k + 2, 0);
		world.setBlock(i + 0, j + 1, k + 3, 0);
		world.setBlock(i + 0, j + 1, k + 4, 0);
		world.setBlock(i + 0, j + 1, k + 5, 0);
		world.setBlock(i + 0, j + 1, k + 6, 0);
		world.setBlock(i + 0, j + 1, k + 7, 0);
		world.setBlock(i + 0, j + 1, k + 8, 0);
		world.setBlock(i + 0, j + 1, k + 9, 0);
		world.setBlock(i + 0, j + 1, k + 10, Block.blockSteel.blockID);
		world.setBlock(i + 0, j + 1, k + 11, Block.blockSteel.blockID);
		world.setBlock(i + 0, j + 1, k + 12, Block.blockSteel.blockID);
		world.setBlock(i + 0, j + 1, k + 13, Block.blockSteel.blockID);
		world.setBlock(i + 0, j + 1, k + 14, Block.blockSteel.blockID);
		world.setBlock(i + 0, j + 1, k + 15, Block.blockSteel.blockID);
		world.setBlock(i + 0, j + 1, k + 16, Block.blockSteel.blockID);
		world.setBlock(i + 0, j + 1, k + 17, Block.blockSteel.blockID);
		world.setBlock(i + 0, j + 1, k + 18, Block.blockSteel.blockID);
		world.setBlock(i + 0, j + 1, k + 19, Block.blockSteel.blockID);
		world.setBlock(i + 0, j + 1, k + 20, Block.blockSteel.blockID);
		world.setBlock(i + 0, j + 1, k + 21, Block.blockSteel.blockID);
		world.setBlock(i + 0, j + 1, k + 22, Block.blockSteel.blockID);
		world.setBlock(i + 0, j + 1, k + 23, Block.blockSteel.blockID);
		world.setBlock(i + 0, j + 1, k + 24, Block.blockSteel.blockID);
		world.setBlock(i + 0, j + 1, k + 25, 0);
		world.setBlock(i + 0, j + 1, k + 26, 0);
		world.setBlock(i + 0, j + 1, k + 27, 0);
		world.setBlock(i + 0, j + 2, k + 0, 0);
		world.setBlock(i + 0, j + 2, k + 1, 0);
		world.setBlock(i + 0, j + 2, k + 2, 0);
		world.setBlock(i + 0, j + 2, k + 3, 0);
		world.setBlock(i + 0, j + 2, k + 4, 0);
		world.setBlock(i + 0, j + 2, k + 5, 0);
		world.setBlock(i + 0, j + 2, k + 6, 0);
		world.setBlock(i + 0, j + 2, k + 7, 0);
		world.setBlock(i + 0, j + 2, k + 8, 0);
		world.setBlock(i + 0, j + 2, k + 9, 0);
		world.setBlock(i + 0, j + 2, k + 10, Block.blockSteel.blockID);
		world.setBlock(i + 0, j + 2, k + 11, Block.blockSteel.blockID);
		world.setBlock(i + 0, j + 2, k + 12, Block.blockSteel.blockID);
		world.setBlock(i + 0, j + 2, k + 13, Block.blockSteel.blockID);
		world.setBlock(i + 0, j + 2, k + 14, Block.blockSteel.blockID);
		world.setBlock(i + 0, j + 2, k + 15, Block.blockSteel.blockID);
		world.setBlock(i + 0, j + 2, k + 16, Block.blockSteel.blockID);
		world.setBlock(i + 0, j + 2, k + 17, Block.blockSteel.blockID);
		world.setBlock(i + 0, j + 2, k + 18, Block.blockSteel.blockID);
		world.setBlock(i + 0, j + 2, k + 19, Block.blockSteel.blockID);
		world.setBlock(i + 0, j + 2, k + 20, Block.blockSteel.blockID);
		world.setBlock(i + 0, j + 2, k + 21, Block.blockSteel.blockID);
		world.setBlock(i + 0, j + 2, k + 22, Block.blockSteel.blockID);
		world.setBlock(i + 0, j + 2, k + 23, Block.blockSteel.blockID);
		world.setBlock(i + 0, j + 2, k + 24, Block.blockSteel.blockID);
		world.setBlock(i + 0, j + 2, k + 25, 0);
		world.setBlock(i + 0, j + 2, k + 26, 0);
		world.setBlock(i + 0, j + 2, k + 27, 0);
		world.setBlock(i + 0, j + 3, k + 0, 0);
		world.setBlock(i + 0, j + 3, k + 1, 0);
		world.setBlock(i + 0, j + 3, k + 2, 0);
		world.setBlock(i + 0, j + 3, k + 3, 0);
		world.setBlock(i + 0, j + 3, k + 4, 0);
		world.setBlock(i + 0, j + 3, k + 5, 0);
		world.setBlock(i + 0, j + 3, k + 6, 0);
		world.setBlock(i + 0, j + 3, k + 7, 0);
		world.setBlock(i + 0, j + 3, k + 8, 0);
		world.setBlock(i + 0, j + 3, k + 9, 0);
		world.setBlock(i + 0, j + 3, k + 10, Block.blockSteel.blockID);
		world.setBlock(i + 0, j + 3, k + 11, Block.blockSteel.blockID);
		world.setBlock(i + 0, j + 3, k + 12, Block.blockSteel.blockID);
		world.setBlock(i + 0, j + 3, k + 13, Block.blockSteel.blockID);
		world.setBlock(i + 0, j + 3, k + 14, Block.blockSteel.blockID);
		world.setBlock(i + 0, j + 3, k + 15, Block.blockSteel.blockID);
		world.setBlock(i + 0, j + 3, k + 16, Block.blockSteel.blockID);
		world.setBlock(i + 0, j + 3, k + 17, Block.blockSteel.blockID);
		world.setBlock(i + 0, j + 3, k + 18, Block.blockSteel.blockID);
		world.setBlock(i + 0, j + 3, k + 19, Block.blockSteel.blockID);
		world.setBlock(i + 0, j + 3, k + 20, Block.blockSteel.blockID);
		world.setBlock(i + 0, j + 3, k + 21, Block.blockSteel.blockID);
		world.setBlock(i + 0, j + 3, k + 22, Block.blockSteel.blockID);
		world.setBlock(i + 0, j + 3, k + 23, Block.blockSteel.blockID);
		world.setBlock(i + 0, j + 3, k + 24, Block.blockSteel.blockID);
		world.setBlock(i + 0, j + 3, k + 25, 0);
		world.setBlock(i + 0, j + 3, k + 26, 0);
		world.setBlock(i + 0, j + 3, k + 27, 0);
		world.setBlock(i + 0, j + 4, k + 0, 0);
		world.setBlock(i + 0, j + 4, k + 1, 0);
		world.setBlock(i + 0, j + 4, k + 2, 0);
		world.setBlock(i + 0, j + 4, k + 3, 0);
		world.setBlock(i + 0, j + 4, k + 4, 0);
		world.setBlock(i + 0, j + 4, k + 5, 0);
		world.setBlock(i + 0, j + 4, k + 6, 0);
		world.setBlock(i + 0, j + 4, k + 7, 0);
		world.setBlock(i + 0, j + 4, k + 8, 0);
		world.setBlock(i + 0, j + 4, k + 9, 0);
		world.setBlock(i + 0, j + 4, k + 10, Block.blockSteel.blockID);
		world.setBlock(i + 0, j + 4, k + 11, Block.blockSteel.blockID);
		world.setBlock(i + 0, j + 4, k + 12, Block.blockSteel.blockID);
		world.setBlock(i + 0, j + 4, k + 13, Block.blockSteel.blockID);
		world.setBlock(i + 0, j + 4, k + 14, Block.blockSteel.blockID);
		world.setBlock(i + 0, j + 4, k + 15, Block.blockSteel.blockID);
		world.setBlock(i + 0, j + 4, k + 16, Block.blockSteel.blockID);
		world.setBlock(i + 0, j + 4, k + 17, Block.blockSteel.blockID);
		world.setBlock(i + 0, j + 4, k + 18, Block.blockSteel.blockID);
		world.setBlock(i + 0, j + 4, k + 19, Block.blockSteel.blockID);
		world.setBlock(i + 0, j + 4, k + 20, Block.blockSteel.blockID);
		world.setBlock(i + 0, j + 4, k + 21, Block.blockSteel.blockID);
		world.setBlock(i + 0, j + 4, k + 22, Block.blockSteel.blockID);
		world.setBlock(i + 0, j + 4, k + 23, Block.blockSteel.blockID);
		world.setBlock(i + 0, j + 4, k + 24, Block.blockSteel.blockID);
		world.setBlock(i + 0, j + 4, k + 25, 0);
		world.setBlock(i + 0, j + 4, k + 26, 0);
		world.setBlock(i + 0, j + 4, k + 27, 0);
		world.setBlock(i + 0, j + 5, k + 0, 0);
		world.setBlock(i + 0, j + 5, k + 1, 0);
		world.setBlock(i + 0, j + 5, k + 2, 0);
		world.setBlock(i + 0, j + 5, k + 3, 0);
		world.setBlock(i + 0, j + 5, k + 4, 0);
		world.setBlock(i + 0, j + 5, k + 5, 0);
		world.setBlock(i + 0, j + 5, k + 6, 0);
		world.setBlock(i + 0, j + 5, k + 7, 0);
		world.setBlock(i + 0, j + 5, k + 8, 0);
		world.setBlock(i + 0, j + 5, k + 9, 0);
		world.setBlock(i + 0, j + 5, k + 10, Block.blockSteel.blockID);
		world.setBlock(i + 0, j + 5, k + 11, Block.blockSteel.blockID);
		world.setBlock(i + 0, j + 5, k + 12, Block.blockSteel.blockID);
		world.setBlock(i + 0, j + 5, k + 13, Block.blockSteel.blockID);
		world.setBlock(i + 0, j + 5, k + 14, Block.blockSteel.blockID);
		world.setBlock(i + 0, j + 5, k + 15, Block.blockSteel.blockID);
		world.setBlock(i + 0, j + 5, k + 16, Block.blockSteel.blockID);
		world.setBlock(i + 0, j + 5, k + 17, Block.blockSteel.blockID);
		world.setBlock(i + 0, j + 5, k + 18, Block.blockSteel.blockID);
		world.setBlock(i + 0, j + 5, k + 19, Block.blockSteel.blockID);
		world.setBlock(i + 0, j + 5, k + 20, Block.blockSteel.blockID);
		world.setBlock(i + 0, j + 5, k + 21, Block.blockSteel.blockID);
		world.setBlock(i + 0, j + 5, k + 22, Block.blockSteel.blockID);
		world.setBlock(i + 0, j + 5, k + 23, Block.blockSteel.blockID);
		world.setBlock(i + 0, j + 5, k + 24, Block.blockSteel.blockID);
		world.setBlock(i + 0, j + 5, k + 25, 0);
		world.setBlock(i + 0, j + 5, k + 26, 0);
		world.setBlock(i + 0, j + 5, k + 27, 0);
		world.setBlock(i + 0, j + 6, k + 0, 0);
		world.setBlock(i + 0, j + 6, k + 1, 0);
		world.setBlock(i + 0, j + 6, k + 2, 0);
		world.setBlock(i + 0, j + 6, k + 3, 0);
		world.setBlock(i + 0, j + 6, k + 4, 0);
		world.setBlock(i + 0, j + 6, k + 5, 0);
		world.setBlock(i + 0, j + 6, k + 6, 0);
		world.setBlock(i + 0, j + 6, k + 7, 0);
		world.setBlock(i + 0, j + 6, k + 8, 0);
		world.setBlock(i + 0, j + 6, k + 9, 0);
		world.setBlock(i + 0, j + 6, k + 10, Block.blockSteel.blockID);
		world.setBlock(i + 0, j + 6, k + 11, Block.blockSteel.blockID);
		world.setBlock(i + 0, j + 6, k + 12, Block.blockSteel.blockID);
		world.setBlock(i + 0, j + 6, k + 13, Block.blockSteel.blockID);
		world.setBlock(i + 0, j + 6, k + 14, Block.blockSteel.blockID);
		world.setBlock(i + 0, j + 6, k + 15, Block.blockSteel.blockID);
		world.setBlock(i + 0, j + 6, k + 16, Block.blockSteel.blockID);
		world.setBlock(i + 0, j + 6, k + 17, Block.blockSteel.blockID);
		world.setBlock(i + 0, j + 6, k + 18, Block.blockSteel.blockID);
		world.setBlock(i + 0, j + 6, k + 19, Block.blockSteel.blockID);
		world.setBlock(i + 0, j + 6, k + 20, Block.blockSteel.blockID);
		world.setBlock(i + 0, j + 6, k + 21, Block.blockSteel.blockID);
		world.setBlock(i + 0, j + 6, k + 22, Block.blockSteel.blockID);
		world.setBlock(i + 0, j + 6, k + 23, Block.blockSteel.blockID);
		world.setBlock(i + 0, j + 6, k + 24, Block.blockSteel.blockID);
		world.setBlock(i + 0, j + 6, k + 25, 0);
		world.setBlock(i + 0, j + 6, k + 26, 0);
		world.setBlock(i + 0, j + 6, k + 27, 0);
		world.setBlock(i + 0, j + 7, k + 0, 0);
		world.setBlock(i + 0, j + 7, k + 1, 0);
		world.setBlock(i + 0, j + 7, k + 2, 0);
		world.setBlock(i + 0, j + 7, k + 3, 0);
		world.setBlock(i + 0, j + 7, k + 4, 0);
		world.setBlock(i + 0, j + 7, k + 5, 0);
		world.setBlock(i + 0, j + 7, k + 6, 0);
		world.setBlock(i + 0, j + 7, k + 7, 0);
		world.setBlock(i + 0, j + 7, k + 8, 0);
		world.setBlock(i + 0, j + 7, k + 9, 0);
		world.setBlock(i + 0, j + 7, k + 10, Block.blockSteel.blockID);
		world.setBlock(i + 0, j + 7, k + 11, Block.blockSteel.blockID);
		world.setBlock(i + 0, j + 7, k + 12, Block.blockSteel.blockID);
		world.setBlock(i + 0, j + 7, k + 13, Block.blockSteel.blockID);
		world.setBlock(i + 0, j + 7, k + 14, Block.blockSteel.blockID);
		world.setBlock(i + 0, j + 7, k + 15, Block.blockSteel.blockID);
		world.setBlock(i + 0, j + 7, k + 16, Block.blockSteel.blockID);
		world.setBlock(i + 0, j + 7, k + 17, Block.blockSteel.blockID);
		world.setBlock(i + 0, j + 7, k + 18, Block.blockSteel.blockID);
		world.setBlock(i + 0, j + 7, k + 19, Block.blockSteel.blockID);
		world.setBlock(i + 0, j + 7, k + 20, Block.blockSteel.blockID);
		world.setBlock(i + 0, j + 7, k + 21, Block.blockSteel.blockID);
		world.setBlock(i + 0, j + 7, k + 22, Block.blockSteel.blockID);
		world.setBlock(i + 0, j + 7, k + 23, Block.blockSteel.blockID);
		world.setBlock(i + 0, j + 7, k + 24, Block.blockSteel.blockID);
		world.setBlock(i + 0, j + 7, k + 25, 0);
		world.setBlock(i + 0, j + 7, k + 26, 0);
		world.setBlock(i + 0, j + 7, k + 27, 0);
		world.setBlock(i + 0, j + 8, k + 0, 0);
		world.setBlock(i + 0, j + 8, k + 1, 0);
		world.setBlock(i + 0, j + 8, k + 2, 0);
		world.setBlock(i + 0, j + 8, k + 3, 0);
		world.setBlock(i + 0, j + 8, k + 4, 0);
		world.setBlock(i + 0, j + 8, k + 5, 0);
		world.setBlock(i + 0, j + 8, k + 6, 0);
		world.setBlock(i + 0, j + 8, k + 7, 0);
		world.setBlock(i + 0, j + 8, k + 8, 0);
		world.setBlock(i + 0, j + 8, k + 9, 0);
		world.setBlock(i + 0, j + 8, k + 10, Block.blockSteel.blockID);
		world.setBlock(i + 0, j + 8, k + 11, Block.blockSteel.blockID);
		world.setBlock(i + 0, j + 8, k + 12, Block.blockSteel.blockID);
		world.setBlock(i + 0, j + 8, k + 13, Block.blockSteel.blockID);
		world.setBlock(i + 0, j + 8, k + 14, Block.blockSteel.blockID);
		world.setBlock(i + 0, j + 8, k + 15, Block.blockSteel.blockID);
		world.setBlock(i + 0, j + 8, k + 16, Block.blockSteel.blockID);
		world.setBlock(i + 0, j + 8, k + 17, Block.blockSteel.blockID);
		world.setBlock(i + 0, j + 8, k + 18, Block.blockSteel.blockID);
		world.setBlock(i + 0, j + 8, k + 19, Block.blockSteel.blockID);
		world.setBlock(i + 0, j + 8, k + 20, Block.blockSteel.blockID);
		world.setBlock(i + 0, j + 8, k + 21, Block.blockSteel.blockID);
		world.setBlock(i + 0, j + 8, k + 22, Block.blockSteel.blockID);
		world.setBlock(i + 0, j + 8, k + 23, Block.blockSteel.blockID);
		world.setBlock(i + 0, j + 8, k + 24, Block.blockSteel.blockID);
		world.setBlock(i + 0, j + 8, k + 25, 0);
		world.setBlock(i + 0, j + 8, k + 26, 0);
		world.setBlock(i + 0, j + 8, k + 27, 0);
		world.setBlock(i + 0, j + 9, k + 0, 0);
		world.setBlock(i + 0, j + 9, k + 1, 0);
		world.setBlock(i + 0, j + 9, k + 2, 0);
		world.setBlock(i + 0, j + 9, k + 3, 0);
		world.setBlock(i + 0, j + 9, k + 4, 0);
		world.setBlock(i + 0, j + 9, k + 5, 0);
		world.setBlock(i + 0, j + 9, k + 6, 0);
		world.setBlock(i + 0, j + 9, k + 7, 0);
		world.setBlock(i + 0, j + 9, k + 8, 0);
		world.setBlock(i + 0, j + 9, k + 9, 0);
		world.setBlock(i + 0, j + 9, k + 10, Block.blockSteel.blockID);
		world.setBlock(i + 0, j + 9, k + 11, Block.blockSteel.blockID);
		world.setBlock(i + 0, j + 9, k + 12, Block.blockSteel.blockID);
		world.setBlock(i + 0, j + 9, k + 13, Block.blockSteel.blockID);
		world.setBlock(i + 0, j + 9, k + 14, Block.blockSteel.blockID);
		world.setBlock(i + 0, j + 9, k + 15, Block.blockSteel.blockID);
		world.setBlock(i + 0, j + 9, k + 16, Block.blockSteel.blockID);
		world.setBlock(i + 0, j + 9, k + 17, Block.blockSteel.blockID);
		world.setBlock(i + 0, j + 9, k + 18, Block.blockSteel.blockID);
		world.setBlock(i + 0, j + 9, k + 19, Block.blockSteel.blockID);
		world.setBlock(i + 0, j + 9, k + 20, Block.blockSteel.blockID);
		world.setBlock(i + 0, j + 9, k + 21, Block.blockSteel.blockID);
		world.setBlock(i + 0, j + 9, k + 22, Block.blockSteel.blockID);
		world.setBlock(i + 0, j + 9, k + 23, Block.blockSteel.blockID);
		world.setBlock(i + 0, j + 9, k + 24, Block.blockSteel.blockID);
		world.setBlock(i + 0, j + 9, k + 25, 0);
		world.setBlock(i + 0, j + 9, k + 26, 0);
		world.setBlock(i + 0, j + 9, k + 27, 0);
		world.setBlock(i + 0, j + 10, k + 0, 0);
		world.setBlock(i + 0, j + 10, k + 1, 0);
		world.setBlock(i + 0, j + 10, k + 2, 0);
		world.setBlock(i + 0, j + 10, k + 3, 0);
		world.setBlock(i + 0, j + 10, k + 4, 0);
		world.setBlock(i + 0, j + 10, k + 5, 0);
		world.setBlock(i + 0, j + 10, k + 6, 0);
		world.setBlock(i + 0, j + 10, k + 7, 0);
		world.setBlock(i + 0, j + 10, k + 8, 0);
		world.setBlock(i + 0, j + 10, k + 9, 0);
		world.setBlock(i + 0, j + 10, k + 10, Block.blockSteel.blockID);
		world.setBlock(i + 0, j + 10, k + 11, Block.blockSteel.blockID);
		world.setBlock(i + 0, j + 10, k + 12, Block.blockSteel.blockID);
		world.setBlock(i + 0, j + 10, k + 13, Block.blockSteel.blockID);
		world.setBlock(i + 0, j + 10, k + 14, Block.blockSteel.blockID);
		world.setBlock(i + 0, j + 10, k + 15, Block.blockSteel.blockID);
		world.setBlock(i + 0, j + 10, k + 16, Block.blockSteel.blockID);
		world.setBlock(i + 0, j + 10, k + 17, Block.blockSteel.blockID);
		world.setBlock(i + 0, j + 10, k + 18, Block.blockSteel.blockID);
		world.setBlock(i + 0, j + 10, k + 19, Block.blockSteel.blockID);
		world.setBlock(i + 0, j + 10, k + 20, Block.blockSteel.blockID);
		world.setBlock(i + 0, j + 10, k + 21, Block.blockSteel.blockID);
		world.setBlock(i + 0, j + 10, k + 22, Block.blockSteel.blockID);
		world.setBlock(i + 0, j + 10, k + 23, Block.blockSteel.blockID);
		world.setBlock(i + 0, j + 10, k + 24, Block.blockSteel.blockID);
		world.setBlock(i + 0, j + 10, k + 25, 0);
		world.setBlock(i + 0, j + 10, k + 26, 0);
		world.setBlock(i + 0, j + 10, k + 27, 0);
		world.setBlock(i + 1, j + 0, k + 0, 0);
		world.setBlock(i + 1, j + 0, k + 1, 0);
		world.setBlock(i + 1, j + 0, k + 2, 0);
		world.setBlock(i + 1, j + 0, k + 3, 0);
		world.setBlock(i + 1, j + 0, k + 4, 0);
		world.setBlock(i + 1, j + 0, k + 5, 0);
		world.setBlock(i + 1, j + 0, k + 6, 0);
		world.setBlock(i + 1, j + 0, k + 7, 0);
		world.setBlock(i + 1, j + 0, k + 8, 0);
		world.setBlock(i + 1, j + 0, k + 9, 0);
		world.setBlock(i + 1, j + 0, k + 10, Block.blockSteel.blockID);
		world.setBlock(i + 1, j + 0, k + 11, Block.blockSteel.blockID);
		world.setBlock(i + 1, j + 0, k + 12, Block.blockSteel.blockID);
		world.setBlock(i + 1, j + 0, k + 13, Block.blockSteel.blockID);
		world.setBlock(i + 1, j + 0, k + 14, Block.blockSteel.blockID);
		world.setBlock(i + 1, j + 0, k + 15, Block.blockSteel.blockID);
		world.setBlock(i + 1, j + 0, k + 16, Block.blockSteel.blockID);
		world.setBlock(i + 1, j + 0, k + 17, Block.blockSteel.blockID);
		world.setBlock(i + 1, j + 0, k + 18, Block.blockSteel.blockID);
		world.setBlock(i + 1, j + 0, k + 19, Block.blockSteel.blockID);
		world.setBlock(i + 1, j + 0, k + 20, Block.blockSteel.blockID);
		world.setBlock(i + 1, j + 0, k + 21, Block.blockSteel.blockID);
		world.setBlock(i + 1, j + 0, k + 22, Block.blockSteel.blockID);
		world.setBlock(i + 1, j + 0, k + 23, Block.blockSteel.blockID);
		world.setBlock(i + 1, j + 0, k + 24, Block.blockSteel.blockID);
		world.setBlock(i + 1, j + 0, k + 25, 0);
		world.setBlock(i + 1, j + 0, k + 26, 0);
		world.setBlock(i + 1, j + 0, k + 27, 0);
		world.setBlock(i + 1, j + 1, k + 0, 0);
		world.setBlock(i + 1, j + 1, k + 1, 0);
		world.setBlock(i + 1, j + 1, k + 2, 0);
		world.setBlock(i + 1, j + 1, k + 3, 0);
		world.setBlock(i + 1, j + 1, k + 4, 0);
		world.setBlock(i + 1, j + 1, k + 5, 0);
		world.setBlock(i + 1, j + 1, k + 6, 0);
		world.setBlock(i + 1, j + 1, k + 7, 0);
		world.setBlock(i + 1, j + 1, k + 8, 0);
		world.setBlock(i + 1, j + 1, k + 9, 0);
		world.setBlock(i + 1, j + 1, k + 10, Block.blockSteel.blockID);
		world.setBlock(i + 1, j + 1, k + 11, 0);
		world.setBlock(i + 1, j + 1, k + 12, 0);
		world.setBlock(i + 1, j + 1, k + 13, 0);
		world.setBlock(i + 1, j + 1, k + 14, 0);
		world.setBlock(i + 1, j + 1, k + 15, 0);
		world.setBlock(i + 1, j + 1, k + 16, 0);
		world.setBlock(i + 1, j + 1, k + 17, 0);
		world.setBlock(i + 1, j + 1, k + 18, 0);
		world.setBlock(i + 1, j + 1, k + 19, 0);
		world.setBlock(i + 1, j + 1, k + 20, 0);
		world.setBlock(i + 1, j + 1, k + 21, 0);
		world.setBlock(i + 1, j + 1, k + 22, 0);
		world.setBlock(i + 1, j + 1, k + 23, 0);
		world.setBlock(i + 1, j + 1, k + 24, Block.blockSteel.blockID);
		world.setBlock(i + 1, j + 1, k + 25, 0);
		world.setBlock(i + 1, j + 1, k + 26, 0);
		world.setBlock(i + 1, j + 1, k + 27, 0);
		world.setBlock(i + 1, j + 2, k + 0, 0);
		world.setBlock(i + 1, j + 2, k + 1, 0);
		world.setBlock(i + 1, j + 2, k + 2, 0);
		world.setBlock(i + 1, j + 2, k + 3, 0);
		world.setBlock(i + 1, j + 2, k + 4, 0);
		world.setBlock(i + 1, j + 2, k + 5, 0);
		world.setBlock(i + 1, j + 2, k + 6, 0);
		world.setBlock(i + 1, j + 2, k + 7, 0);
		world.setBlock(i + 1, j + 2, k + 8, 0);
		world.setBlock(i + 1, j + 2, k + 9, 0);
		world.setBlock(i + 1, j + 2, k + 10, Block.blockSteel.blockID);
		world.setBlock(i + 1, j + 2, k + 11, 0);
		world.setBlock(i + 1, j + 2, k + 12, 0);
		world.setBlock(i + 1, j + 2, k + 13, 0);
		world.setBlock(i + 1, j + 2, k + 14, 0);
		world.setBlock(i + 1, j + 2, k + 15, 0);
		world.setBlock(i + 1, j + 2, k + 16, 0);
		world.setBlock(i + 1, j + 2, k + 17, 0);
		world.setBlock(i + 1, j + 2, k + 18, 0);
		world.setBlock(i + 1, j + 2, k + 19, 0);
		world.setBlock(i + 1, j + 2, k + 20, 0);
		world.setBlock(i + 1, j + 2, k + 21, 0);
		world.setBlock(i + 1, j + 2, k + 22, 0);
		world.setBlock(i + 1, j + 2, k + 23, 0);
		world.setBlock(i + 1, j + 2, k + 24, Block.blockSteel.blockID);
		world.setBlock(i + 1, j + 2, k + 25, 0);
		world.setBlock(i + 1, j + 2, k + 26, 0);
		world.setBlock(i + 1, j + 2, k + 27, 0);
		world.setBlock(i + 1, j + 3, k + 0, 0);
		world.setBlock(i + 1, j + 3, k + 1, 0);
		world.setBlock(i + 1, j + 3, k + 2, 0);
		world.setBlock(i + 1, j + 3, k + 3, 0);
		world.setBlock(i + 1, j + 3, k + 4, 0);
		world.setBlock(i + 1, j + 3, k + 5, 0);
		world.setBlock(i + 1, j + 3, k + 6, 0);
		world.setBlock(i + 1, j + 3, k + 7, 0);
		world.setBlock(i + 1, j + 3, k + 8, 0);
		world.setBlock(i + 1, j + 3, k + 9, 0);
		world.setBlock(i + 1, j + 3, k + 10, Block.blockSteel.blockID);
		world.setBlock(i + 1, j + 3, k + 11, 0);
		world.setBlock(i + 1, j + 3, k + 12, Block.stoneBrick.blockID);
		world.setBlock(i + 1, j + 3, k + 13, Block.stoneBrick.blockID);
		world.setBlock(i + 1, j + 3, k + 14, Block.stoneBrick.blockID);
		world.setBlock(i + 1, j + 3, k + 15, Block.stoneBrick.blockID);
		world.setBlock(i + 1, j + 3, k + 16, 0);
		world.setBlock(i + 1, j + 3, k + 17, 0);
		world.setBlock(i + 1, j + 3, k + 18, 0);
		world.setBlock(i + 1, j + 3, k + 19, 0);
		world.setBlock(i + 1, j + 3, k + 20, 0);
		world.setBlock(i + 1, j + 3, k + 21, 0);
		world.setBlock(i + 1, j + 3, k + 22, 0);
		world.setBlock(i + 1, j + 3, k + 23, 0);
		world.setBlock(i + 1, j + 3, k + 24, Block.blockSteel.blockID);
		world.setBlock(i + 1, j + 3, k + 25, 0);
		world.setBlock(i + 1, j + 3, k + 26, 0);
		world.setBlock(i + 1, j + 3, k + 27, 0);
		world.setBlock(i + 1, j + 4, k + 0, 0);
		world.setBlock(i + 1, j + 4, k + 1, 0);
		world.setBlock(i + 1, j + 4, k + 2, 0);
		world.setBlock(i + 1, j + 4, k + 3, 0);
		world.setBlock(i + 1, j + 4, k + 4, 0);
		world.setBlock(i + 1, j + 4, k + 5, 0);
		world.setBlock(i + 1, j + 4, k + 6, 0);
		world.setBlock(i + 1, j + 4, k + 7, 0);
		world.setBlock(i + 1, j + 4, k + 8, 0);
		world.setBlock(i + 1, j + 4, k + 9, 0);
		world.setBlock(i + 1, j + 4, k + 10, Block.blockSteel.blockID);
		world.setBlock(i + 1, j + 4, k + 11, 0);
		world.setBlock(i + 1, j + 4, k + 12, Block.cobblestone.blockID);
		world.setBlock(i + 1, j + 4, k + 13, Block.cobblestone.blockID);
		world.setBlock(i + 1, j + 4, k + 14, Block.cobblestone.blockID);
		world.setBlock(i + 1, j + 4, k + 15, Block.cobblestone.blockID);
		world.setBlock(i + 1, j + 4, k + 16, Block.cobblestone.blockID);
		world.setBlock(i + 1, j + 4, k + 17, Block.cobblestone.blockID);
		world.setBlock(i + 1, j + 4, k + 18, 0);
		world.setBlock(i + 1, j + 4, k + 19, 0);
		world.setBlock(i + 1, j + 4, k + 20, 0);
		world.setBlock(i + 1, j + 4, k + 21, 0);
		world.setBlock(i + 1, j + 4, k + 22, 0);
		world.setBlock(i + 1, j + 4, k + 23, 0);
		world.setBlock(i + 1, j + 4, k + 24, Block.blockSteel.blockID);
		world.setBlock(i + 1, j + 4, k + 25, 0);
		world.setBlock(i + 1, j + 4, k + 26, 0);
		world.setBlock(i + 1, j + 4, k + 27, 0);
		world.setBlock(i + 1, j + 5, k + 0, 0);
		world.setBlock(i + 1, j + 5, k + 1, 0);
		world.setBlock(i + 1, j + 5, k + 2, 0);
		world.setBlock(i + 1, j + 5, k + 3, 0);
		world.setBlock(i + 1, j + 5, k + 4, 0);
		world.setBlock(i + 1, j + 5, k + 5, 0);
		world.setBlock(i + 1, j + 5, k + 6, 0);
		world.setBlock(i + 1, j + 5, k + 7, 0);
		world.setBlock(i + 1, j + 5, k + 8, 0);
		world.setBlock(i + 1, j + 5, k + 9, 0);
		world.setBlock(i + 1, j + 5, k + 10, Block.blockSteel.blockID);
		world.setBlock(i + 1, j + 5, k + 11, 0);
		world.setBlock(i + 1, j + 5, k + 12, Block.glowStone.blockID);
		world.setBlock(i + 1, j + 5, k + 13, Block.glowStone.blockID);
		world.setBlock(i + 1, j + 5, k + 14, Block.glowStone.blockID);
		world.setBlock(i + 1, j + 5, k + 15, Block.glowStone.blockID);
		world.setBlock(i + 1, j + 5, k + 16, Block.glowStone.blockID);
		world.setBlock(i + 1, j + 5, k + 17, Block.glowStone.blockID);
		world.setBlock(i + 1, j + 5, k + 18, Block.glowStone.blockID);
		world.setBlock(i + 1, j + 5, k + 19, 0);
		world.setBlock(i + 1, j + 5, k + 20, 0);
		world.setBlock(i + 1, j + 5, k + 21, 0);
		world.setBlock(i + 1, j + 5, k + 22, 0);
		world.setBlock(i + 1, j + 5, k + 23, 0);
		world.setBlock(i + 1, j + 5, k + 24, Block.blockSteel.blockID);
		world.setBlock(i + 1, j + 5, k + 25, 0);
		world.setBlock(i + 1, j + 5, k + 26, 0);
		world.setBlock(i + 1, j + 5, k + 27, 0);
		world.setBlock(i + 1, j + 6, k + 0, 0);
		world.setBlock(i + 1, j + 6, k + 1, 0);
		world.setBlock(i + 1, j + 6, k + 2, 0);
		world.setBlock(i + 1, j + 6, k + 3, 0);
		world.setBlock(i + 1, j + 6, k + 4, 0);
		world.setBlock(i + 1, j + 6, k + 5, 0);
		world.setBlock(i + 1, j + 6, k + 6, 0);
		world.setBlock(i + 1, j + 6, k + 7, 0);
		world.setBlock(i + 1, j + 6, k + 8, 0);
		world.setBlock(i + 1, j + 6, k + 9, 0);
		world.setBlock(i + 1, j + 6, k + 10, Block.blockSteel.blockID);
		world.setBlock(i + 1, j + 6, k + 11, 0);
		world.setBlock(i + 1, j + 6, k + 12, Block.stoneBrick.blockID);
		world.setBlock(i + 1, j + 6, k + 13, Block.stoneBrick.blockID);
		world.setBlock(i + 1, j + 6, k + 14, Block.stoneBrick.blockID);
		world.setBlock(i + 1, j + 6, k + 15, Block.stoneBrick.blockID);
		world.setBlock(i + 1, j + 6, k + 16, Block.stoneBrick.blockID);
		world.setBlock(i + 1, j + 6, k + 17, Block.stoneBrick.blockID);
		world.setBlock(i + 1, j + 6, k + 18, Block.stoneBrick.blockID);
		world.setBlock(i + 1, j + 6, k + 19, Block.stoneBrick.blockID);
		world.setBlock(i + 1, j + 6, k + 20, Block.stoneBrick.blockID);
		world.setBlock(i + 1, j + 6, k + 21, Block.stoneBrick.blockID);
		world.setBlock(i + 1, j + 6, k + 22, 0);
		world.setBlock(i + 1, j + 6, k + 23, 0);
		world.setBlock(i + 1, j + 6, k + 24, Block.blockSteel.blockID);
		world.setBlock(i + 1, j + 6, k + 25, 0);
		world.setBlock(i + 1, j + 6, k + 26, 0);
		world.setBlock(i + 1, j + 6, k + 27, 0);
		world.setBlock(i + 1, j + 7, k + 0, 0);
		world.setBlock(i + 1, j + 7, k + 1, 0);
		world.setBlock(i + 1, j + 7, k + 2, 0);
		world.setBlock(i + 1, j + 7, k + 3, 0);
		world.setBlock(i + 1, j + 7, k + 4, 0);
		world.setBlock(i + 1, j + 7, k + 5, 0);
		world.setBlock(i + 1, j + 7, k + 6, 0);
		world.setBlock(i + 1, j + 7, k + 7, 0);
		world.setBlock(i + 1, j + 7, k + 8, 0);
		world.setBlock(i + 1, j + 7, k + 9, 0);
		world.setBlock(i + 1, j + 7, k + 10, Block.blockSteel.blockID);
		world.setBlock(i + 1, j + 7, k + 11, 0);
		world.setBlock(i + 1, j + 7, k + 12, Block.cobblestone.blockID);
		world.setBlock(i + 1, j + 7, k + 13, Block.cobblestone.blockID);
		world.setBlock(i + 1, j + 7, k + 14, Block.cobblestone.blockID);
		world.setBlock(i + 1, j + 7, k + 15, Block.cobblestone.blockID);
		world.setBlock(i + 1, j + 7, k + 16, Block.cobblestone.blockID);
		world.setBlock(i + 1, j + 7, k + 17, Block.cobblestone.blockID);
		world.setBlock(i + 1, j + 7, k + 18, Block.cobblestone.blockID);
		world.setBlock(i + 1, j + 7, k + 19, Block.cobblestone.blockID);
		world.setBlock(i + 1, j + 7, k + 20, Block.cobblestone.blockID);
		world.setBlock(i + 1, j + 7, k + 21, Block.cobblestone.blockID);
		world.setBlock(i + 1, j + 7, k + 22, 0);
		world.setBlock(i + 1, j + 7, k + 23, 0);
		world.setBlock(i + 1, j + 7, k + 24, Block.blockSteel.blockID);
		world.setBlock(i + 1, j + 7, k + 25, 0);
		world.setBlock(i + 1, j + 7, k + 26, 0);
		world.setBlock(i + 1, j + 7, k + 27, 0);
		world.setBlock(i + 1, j + 8, k + 0, 0);
		world.setBlock(i + 1, j + 8, k + 1, 0);
		world.setBlock(i + 1, j + 8, k + 2, 0);
		world.setBlock(i + 1, j + 8, k + 3, 0);
		world.setBlock(i + 1, j + 8, k + 4, 0);
		world.setBlock(i + 1, j + 8, k + 5, 0);
		world.setBlock(i + 1, j + 8, k + 6, 0);
		world.setBlock(i + 1, j + 8, k + 7, 0);
		world.setBlock(i + 1, j + 8, k + 8, 0);
		world.setBlock(i + 1, j + 8, k + 9, 0);
		world.setBlock(i + 1, j + 8, k + 10, Block.blockSteel.blockID);
		world.setBlock(i + 1, j + 8, k + 11, 0);
		world.setBlock(i + 1, j + 8, k + 12, 0);
		world.setBlock(i + 1, j + 8, k + 13, 0);
		world.setBlock(i + 1, j + 8, k + 14, 0);
		world.setBlock(i + 1, j + 8, k + 15, 0);
		world.setBlock(i + 1, j + 8, k + 16, 0);
		world.setBlock(i + 1, j + 8, k + 17, 0);
		world.setBlock(i + 1, j + 8, k + 18, 0);
		world.setBlock(i + 1, j + 8, k + 19, 0);
		world.setBlock(i + 1, j + 8, k + 20, 0);
		world.setBlock(i + 1, j + 8, k + 21, 0);
		world.setBlock(i + 1, j + 8, k + 22, 0);
		world.setBlock(i + 1, j + 8, k + 23, 0);
		world.setBlock(i + 1, j + 8, k + 24, Block.blockSteel.blockID);
		world.setBlock(i + 1, j + 8, k + 25, 0);
		world.setBlock(i + 1, j + 8, k + 26, 0);
		world.setBlock(i + 1, j + 8, k + 27, 0);
		world.setBlock(i + 1, j + 9, k + 0, 0);
		world.setBlock(i + 1, j + 9, k + 1, 0);
		world.setBlock(i + 1, j + 9, k + 2, 0);
		world.setBlock(i + 1, j + 9, k + 3, 0);
		world.setBlock(i + 1, j + 9, k + 4, 0);
		world.setBlock(i + 1, j + 9, k + 5, 0);
		world.setBlock(i + 1, j + 9, k + 6, 0);
		world.setBlock(i + 1, j + 9, k + 7, 0);
		world.setBlock(i + 1, j + 9, k + 8, 0);
		world.setBlock(i + 1, j + 9, k + 9, 0);
		world.setBlock(i + 1, j + 9, k + 10, Block.blockSteel.blockID);
		world.setBlock(i + 1, j + 9, k + 11, 0);
		world.setBlock(i + 1, j + 9, k + 12, 0);
		world.setBlock(i + 1, j + 9, k + 13, 0);
		world.setBlock(i + 1, j + 9, k + 14, 0);
		world.setBlock(i + 1, j + 9, k + 15, 0);
		world.setBlock(i + 1, j + 9, k + 16, 0);
		world.setBlock(i + 1, j + 9, k + 17, 0);
		world.setBlock(i + 1, j + 9, k + 18, 0);
		world.setBlock(i + 1, j + 9, k + 19, 0);
		world.setBlock(i + 1, j + 9, k + 20, 0);
		world.setBlock(i + 1, j + 9, k + 21, 0);
		world.setBlock(i + 1, j + 9, k + 22, 0);
		world.setBlock(i + 1, j + 9, k + 23, 0);
		world.setBlock(i + 1, j + 9, k + 24, Block.blockSteel.blockID);
		world.setBlock(i + 1, j + 9, k + 25, 0);
		world.setBlock(i + 1, j + 9, k + 26, 0);
		world.setBlock(i + 1, j + 9, k + 27, 0);
		world.setBlock(i + 1, j + 10, k + 0, 0);
		world.setBlock(i + 1, j + 10, k + 1, 0);
		world.setBlock(i + 1, j + 10, k + 2, 0);
		world.setBlock(i + 1, j + 10, k + 3, 0);
		world.setBlock(i + 1, j + 10, k + 4, 0);
		world.setBlock(i + 1, j + 10, k + 5, 0);
		world.setBlock(i + 1, j + 10, k + 6, 0);
		world.setBlock(i + 1, j + 10, k + 7, 0);
		world.setBlock(i + 1, j + 10, k + 8, 0);
		world.setBlock(i + 1, j + 10, k + 9, 0);
		world.setBlock(i + 1, j + 10, k + 10, Block.blockSteel.blockID);
		world.setBlock(i + 1, j + 10, k + 11, Block.blockSteel.blockID);
		world.setBlock(i + 1, j + 10, k + 12, Block.blockSteel.blockID);
		world.setBlock(i + 1, j + 10, k + 13, Block.blockSteel.blockID);
		world.setBlock(i + 1, j + 10, k + 14, Block.blockSteel.blockID);
		world.setBlock(i + 1, j + 10, k + 15, Block.blockSteel.blockID);
		world.setBlock(i + 1, j + 10, k + 16, Block.blockSteel.blockID);
		world.setBlock(i + 1, j + 10, k + 17, Block.blockSteel.blockID);
		world.setBlock(i + 1, j + 10, k + 18, Block.blockSteel.blockID);
		world.setBlock(i + 1, j + 10, k + 19, Block.blockSteel.blockID);
		world.setBlock(i + 1, j + 10, k + 20, Block.blockSteel.blockID);
		world.setBlock(i + 1, j + 10, k + 21, Block.blockSteel.blockID);
		world.setBlock(i + 1, j + 10, k + 22, Block.blockSteel.blockID);
		world.setBlock(i + 1, j + 10, k + 23, Block.blockSteel.blockID);
		world.setBlock(i + 1, j + 10, k + 24, Block.blockSteel.blockID);
		world.setBlock(i + 1, j + 10, k + 25, 0);
		world.setBlock(i + 1, j + 10, k + 26, 0);
		world.setBlock(i + 1, j + 10, k + 27, 0);
		world.setBlock(i + 2, j + 0, k + 0, 0);
		world.setBlock(i + 2, j + 0, k + 1, 0);
		world.setBlock(i + 2, j + 0, k + 2, 0);
		world.setBlock(i + 2, j + 0, k + 3, 0);
		world.setBlock(i + 2, j + 0, k + 4, 0);
		world.setBlock(i + 2, j + 0, k + 5, 0);
		world.setBlock(i + 2, j + 0, k + 6, 0);
		world.setBlock(i + 2, j + 0, k + 7, 0);
		world.setBlock(i + 2, j + 0, k + 8, 0);
		world.setBlock(i + 2, j + 0, k + 9, 0);
		world.setBlock(i + 2, j + 0, k + 10, Block.blockSteel.blockID);
		world.setBlock(i + 2, j + 0, k + 11, Block.blockSteel.blockID);
		world.setBlock(i + 2, j + 0, k + 12, Block.blockSteel.blockID);
		world.setBlock(i + 2, j + 0, k + 13, Block.blockSteel.blockID);
		world.setBlock(i + 2, j + 0, k + 14, Block.blockSteel.blockID);
		world.setBlock(i + 2, j + 0, k + 15, Block.blockSteel.blockID);
		world.setBlock(i + 2, j + 0, k + 16, Block.blockSteel.blockID);
		world.setBlock(i + 2, j + 0, k + 17, Block.blockSteel.blockID);
		world.setBlock(i + 2, j + 0, k + 18, Block.blockSteel.blockID);
		world.setBlock(i + 2, j + 0, k + 19, Block.blockSteel.blockID);
		world.setBlock(i + 2, j + 0, k + 20, Block.blockSteel.blockID);
		world.setBlock(i + 2, j + 0, k + 21, Block.blockSteel.blockID);
		world.setBlock(i + 2, j + 0, k + 22, Block.blockSteel.blockID);
		world.setBlock(i + 2, j + 0, k + 23, Block.blockSteel.blockID);
		world.setBlock(i + 2, j + 0, k + 24, Block.blockSteel.blockID);
		world.setBlock(i + 2, j + 0, k + 25, 0);
		world.setBlock(i + 2, j + 0, k + 26, 0);
		world.setBlock(i + 2, j + 0, k + 27, 0);
		world.setBlock(i + 2, j + 1, k + 0, 0);
		world.setBlock(i + 2, j + 1, k + 1, 0);
		world.setBlock(i + 2, j + 1, k + 2, 0);
		world.setBlock(i + 2, j + 1, k + 3, 0);
		world.setBlock(i + 2, j + 1, k + 4, 0);
		world.setBlock(i + 2, j + 1, k + 5, 0);
		world.setBlock(i + 2, j + 1, k + 6, 0);
		world.setBlock(i + 2, j + 1, k + 7, 0);
		world.setBlock(i + 2, j + 1, k + 8, 0);
		world.setBlock(i + 2, j + 1, k + 9, 0);
		world.setBlock(i + 2, j + 1, k + 10, Block.blockSteel.blockID);
		world.setBlock(i + 2, j + 1, k + 11, 0);
		world.setBlock(i + 2, j + 1, k + 12, 0);
		world.setBlock(i + 2, j + 1, k + 13, 0);
		world.setBlock(i + 2, j + 1, k + 14, 0);
		world.setBlock(i + 2, j + 1, k + 15, 0);
		world.setBlock(i + 2, j + 1, k + 16, 0);
		world.setBlock(i + 2, j + 1, k + 17, 0);
		world.setBlock(i + 2, j + 1, k + 18, 0);
		world.setBlock(i + 2, j + 1, k + 19, 0);
		world.setBlock(i + 2, j + 1, k + 20, 0);
		world.setBlock(i + 2, j + 1, k + 21, 0);
		world.setBlock(i + 2, j + 1, k + 22, 0);
		world.setBlock(i + 2, j + 1, k + 23, 0);
		world.setBlock(i + 2, j + 1, k + 24, Block.blockSteel.blockID);
		world.setBlock(i + 2, j + 1, k + 25, 0);
		world.setBlock(i + 2, j + 1, k + 26, 0);
		world.setBlock(i + 2, j + 1, k + 27, 0);
		world.setBlock(i + 2, j + 2, k + 0, 0);
		world.setBlock(i + 2, j + 2, k + 1, 0);
		world.setBlock(i + 2, j + 2, k + 2, 0);
		world.setBlock(i + 2, j + 2, k + 3, 0);
		world.setBlock(i + 2, j + 2, k + 4, 0);
		world.setBlock(i + 2, j + 2, k + 5, 0);
		world.setBlock(i + 2, j + 2, k + 6, 0);
		world.setBlock(i + 2, j + 2, k + 7, 0);
		world.setBlock(i + 2, j + 2, k + 8, 0);
		world.setBlock(i + 2, j + 2, k + 9, 0);
		world.setBlock(i + 2, j + 2, k + 10, Block.blockSteel.blockID);
		world.setBlock(i + 2, j + 2, k + 11, 0);
		world.setBlock(i + 2, j + 2, k + 12, Block.stoneDoubleSlab.blockID);
		world.setBlock(i + 2, j + 2, k + 13, Block.stoneDoubleSlab.blockID);
		world.setBlock(i + 2, j + 2, k + 14, 0);
		world.setBlock(i + 2, j + 2, k + 15, 0);
		world.setBlock(i + 2, j + 2, k + 16, 0);
		world.setBlock(i + 2, j + 2, k + 17, 0);
		world.setBlock(i + 2, j + 2, k + 18, 0);
		world.setBlock(i + 2, j + 2, k + 19, 0);
		world.setBlock(i + 2, j + 2, k + 20, 0);
		world.setBlock(i + 2, j + 2, k + 21, 0);
		world.setBlock(i + 2, j + 2, k + 22, 0);
		world.setBlock(i + 2, j + 2, k + 23, 0);
		world.setBlock(i + 2, j + 2, k + 24, Block.blockSteel.blockID);
		world.setBlock(i + 2, j + 2, k + 25, 0);
		world.setBlock(i + 2, j + 2, k + 26, 0);
		world.setBlock(i + 2, j + 2, k + 27, 0);
		world.setBlock(i + 2, j + 3, k + 0, 0);
		world.setBlock(i + 2, j + 3, k + 1, 0);
		world.setBlock(i + 2, j + 3, k + 2, 0);
		world.setBlock(i + 2, j + 3, k + 3, 0);
		world.setBlock(i + 2, j + 3, k + 4, 0);
		world.setBlock(i + 2, j + 3, k + 5, 0);
		world.setBlock(i + 2, j + 3, k + 6, 0);
		world.setBlock(i + 2, j + 3, k + 7, 0);
		world.setBlock(i + 2, j + 3, k + 8, 0);
		world.setBlock(i + 2, j + 3, k + 9, 0);
		world.setBlock(i + 2, j + 3, k + 10, Block.blockSteel.blockID);
		world.setBlock(i + 2, j + 3, k + 11, Block.stoneBrick.blockID);
		world.setBlock(i + 2, j + 3, k + 12, 0);
		world.setBlock(i + 2, j + 3, k + 13, 0);
		world.setBlock(i + 2, j + 3, k + 14, Block.stoneSingleSlab.blockID);
		world.setBlock(i + 2, j + 3, k + 15, Block.stoneDoubleSlab.blockID);
		world.setBlock(i + 2, j + 3, k + 16, 0);
		world.setBlock(i + 2, j + 3, k + 17, 0);
		world.setBlock(i + 2, j + 3, k + 18, 0);
		world.setBlock(i + 2, j + 3, k + 19, 0);
		world.setBlock(i + 2, j + 3, k + 20, 0);
		world.setBlock(i + 2, j + 3, k + 21, 0);
		world.setBlock(i + 2, j + 3, k + 22, 0);
		world.setBlock(i + 2, j + 3, k + 23, 0);
		world.setBlock(i + 2, j + 3, k + 24, Block.blockSteel.blockID);
		world.setBlock(i + 2, j + 3, k + 25, 0);
		world.setBlock(i + 2, j + 3, k + 26, 0);
		world.setBlock(i + 2, j + 3, k + 27, 0);
		world.setBlock(i + 2, j + 4, k + 0, 0);
		world.setBlock(i + 2, j + 4, k + 1, 0);
		world.setBlock(i + 2, j + 4, k + 2, 0);
		world.setBlock(i + 2, j + 4, k + 3, 0);
		world.setBlock(i + 2, j + 4, k + 4, 0);
		world.setBlock(i + 2, j + 4, k + 5, 0);
		world.setBlock(i + 2, j + 4, k + 6, 0);
		world.setBlock(i + 2, j + 4, k + 7, 0);
		world.setBlock(i + 2, j + 4, k + 8, 0);
		world.setBlock(i + 2, j + 4, k + 9, 0);
		world.setBlock(i + 2, j + 4, k + 10, Block.blockSteel.blockID);
		world.setBlock(i + 2, j + 4, k + 11, Block.cobblestone.blockID);
		world.setBlock(i + 2, j + 4, k + 12, 0);
		world.setBlock(i + 2, j + 4, k + 13, 0);
		world.setBlock(i + 2, j + 4, k + 14, 0);
		world.setBlock(i + 2, j + 4, k + 15, 0);
		world.setBlock(i + 2, j + 4, k + 16, Block.stoneSingleSlab.blockID);
		world.setBlock(i + 2, j + 4, k + 17, Block.stoneDoubleSlab.blockID);
		world.setBlock(i + 2, j + 4, k + 18, 0);
		world.setBlock(i + 2, j + 4, k + 19, 0);
		world.setBlock(i + 2, j + 4, k + 20, 0);
		world.setBlock(i + 2, j + 4, k + 21, 0);
		world.setBlock(i + 2, j + 4, k + 22, 0);
		world.setBlock(i + 2, j + 4, k + 23, 0);
		world.setBlock(i + 2, j + 4, k + 24, Block.blockSteel.blockID);
		world.setBlock(i + 2, j + 4, k + 25, 0);
		world.setBlock(i + 2, j + 4, k + 26, 0);
		world.setBlock(i + 2, j + 4, k + 27, 0);
		world.setBlock(i + 2, j + 5, k + 0, 0);
		world.setBlock(i + 2, j + 5, k + 1, 0);
		world.setBlock(i + 2, j + 5, k + 2, 0);
		world.setBlock(i + 2, j + 5, k + 3, 0);
		world.setBlock(i + 2, j + 5, k + 4, 0);
		world.setBlock(i + 2, j + 5, k + 5, 0);
		world.setBlock(i + 2, j + 5, k + 6, 0);
		world.setBlock(i + 2, j + 5, k + 7, 0);
		world.setBlock(i + 2, j + 5, k + 8, 0);
		world.setBlock(i + 2, j + 5, k + 9, 0);
		world.setBlock(i + 2, j + 5, k + 10, Block.blockSteel.blockID);
		world.setBlock(i + 2, j + 5, k + 11, Block.glowStone.blockID);
		world.setBlock(i + 2, j + 5, k + 12, 0);
		world.setBlock(i + 2, j + 5, k + 13, 0);
		world.setBlock(i + 2, j + 5, k + 14, 0);
		world.setBlock(i + 2, j + 5, k + 15, 0);
		world.setBlock(i + 2, j + 5, k + 16, 0);
		world.setBlock(i + 2, j + 5, k + 17, 0);
		world.setBlock(i + 2, j + 5, k + 18, Block.stoneSingleSlab.blockID);
		world.setBlock(i + 2, j + 5, k + 19, Block.stoneDoubleSlab.blockID);
		world.setBlock(i + 2, j + 5, k + 20, Block.stoneDoubleSlab.blockID);
		world.setBlock(i + 2, j + 5, k + 21, Block.stoneDoubleSlab.blockID);
		world.setBlock(i + 2, j + 5, k + 22, 0);
		world.setBlock(i + 2, j + 5, k + 23, 0);
		world.setBlock(i + 2, j + 5, k + 24, Block.blockSteel.blockID);
		world.setBlock(i + 2, j + 5, k + 25, 0);
		world.setBlock(i + 2, j + 5, k + 26, 0);
		world.setBlock(i + 2, j + 5, k + 27, 0);
		world.setBlock(i + 2, j + 6, k + 0, 0);
		world.setBlock(i + 2, j + 6, k + 1, 0);
		world.setBlock(i + 2, j + 6, k + 2, 0);
		world.setBlock(i + 2, j + 6, k + 3, 0);
		world.setBlock(i + 2, j + 6, k + 4, 0);
		world.setBlock(i + 2, j + 6, k + 5, 0);
		world.setBlock(i + 2, j + 6, k + 6, 0);
		world.setBlock(i + 2, j + 6, k + 7, 0);
		world.setBlock(i + 2, j + 6, k + 8, 0);
		world.setBlock(i + 2, j + 6, k + 9, 0);
		world.setBlock(i + 2, j + 6, k + 10, Block.blockSteel.blockID);
		world.setBlock(i + 2, j + 6, k + 11, Block.stoneBrick.blockID);
		world.setBlock(i + 2, j + 6, k + 12, 0);
		world.setBlock(i + 2, j + 6, k + 13, 0);
		world.setBlock(i + 2, j + 6, k + 14, 0);
		world.setBlock(i + 2, j + 6, k + 15, 0);
		world.setBlock(i + 2, j + 6, k + 16, 0);
		world.setBlock(i + 2, j + 6, k + 17, 0);
		world.setBlock(i + 2, j + 6, k + 18, 0);
		world.setBlock(i + 2, j + 6, k + 19, 0);
		world.setBlock(i + 2, j + 6, k + 20, 0);
		world.setBlock(i + 2, j + 6, k + 21, 0);
		world.setBlock(i + 2, j + 6, k + 22, Block.stoneBrick.blockID);
		world.setBlock(i + 2, j + 6, k + 23, 0);
		world.setBlock(i + 2, j + 6, k + 24, Block.blockSteel.blockID);
		world.setBlock(i + 2, j + 6, k + 25, 0);
		world.setBlock(i + 2, j + 6, k + 26, 0);
		world.setBlock(i + 2, j + 6, k + 27, 0);
		world.setBlock(i + 2, j + 7, k + 0, 0);
		world.setBlock(i + 2, j + 7, k + 1, 0);
		world.setBlock(i + 2, j + 7, k + 2, 0);
		world.setBlock(i + 2, j + 7, k + 3, 0);
		world.setBlock(i + 2, j + 7, k + 4, 0);
		world.setBlock(i + 2, j + 7, k + 5, 0);
		world.setBlock(i + 2, j + 7, k + 6, 0);
		world.setBlock(i + 2, j + 7, k + 7, 0);
		world.setBlock(i + 2, j + 7, k + 8, 0);
		world.setBlock(i + 2, j + 7, k + 9, 0);
		world.setBlock(i + 2, j + 7, k + 10, Block.blockSteel.blockID);
		world.setBlock(i + 2, j + 7, k + 11, Block.cobblestone.blockID);
		world.setBlock(i + 2, j + 7, k + 12, 0);
		world.setBlock(i + 2, j + 7, k + 13, 0);
		world.setBlock(i + 2, j + 7, k + 14, 0);
		world.setBlock(i + 2, j + 7, k + 15, 0);
		world.setBlock(i + 2, j + 7, k + 16, 0);
		world.setBlock(i + 2, j + 7, k + 17, 0);
		world.setBlock(i + 2, j + 7, k + 18, 0);
		world.setBlock(i + 2, j + 7, k + 19, 0);
		world.setBlock(i + 2, j + 7, k + 20, 0);
		world.setBlock(i + 2, j + 7, k + 21, 0);
		world.setBlock(i + 2, j + 7, k + 22, Block.cobblestone.blockID);
		world.setBlock(i + 2, j + 7, k + 23, 0);
		world.setBlock(i + 2, j + 7, k + 24, Block.blockSteel.blockID);
		world.setBlock(i + 2, j + 7, k + 25, 0);
		world.setBlock(i + 2, j + 7, k + 26, 0);
		world.setBlock(i + 2, j + 7, k + 27, 0);
		world.setBlock(i + 2, j + 8, k + 0, 0);
		world.setBlock(i + 2, j + 8, k + 1, 0);
		world.setBlock(i + 2, j + 8, k + 2, 0);
		world.setBlock(i + 2, j + 8, k + 3, 0);
		world.setBlock(i + 2, j + 8, k + 4, 0);
		world.setBlock(i + 2, j + 8, k + 5, 0);
		world.setBlock(i + 2, j + 8, k + 6, 0);
		world.setBlock(i + 2, j + 8, k + 7, 0);
		world.setBlock(i + 2, j + 8, k + 8, 0);
		world.setBlock(i + 2, j + 8, k + 9, 0);
		world.setBlock(i + 2, j + 8, k + 10, Block.blockSteel.blockID);
		world.setBlock(i + 2, j + 8, k + 11, 0);
		world.setBlock(i + 2, j + 8, k + 12, Block.stoneDoubleSlab.blockID);
		world.setBlock(i + 2, j + 8, k + 13, Block.stoneDoubleSlab.blockID);
		world.setBlock(i + 2, j + 8, k + 14, Block.stoneDoubleSlab.blockID);
		world.setBlock(i + 2, j + 8, k + 15, Block.stoneDoubleSlab.blockID);
		world.setBlock(i + 2, j + 8, k + 16, Block.stoneDoubleSlab.blockID);
		world.setBlock(i + 2, j + 8, k + 17, Block.stoneDoubleSlab.blockID);
		world.setBlock(i + 2, j + 8, k + 18, Block.stoneDoubleSlab.blockID);
		world.setBlock(i + 2, j + 8, k + 19, Block.stoneDoubleSlab.blockID);
		world.setBlock(i + 2, j + 8, k + 20, Block.stoneDoubleSlab.blockID);
		world.setBlock(i + 2, j + 8, k + 21, Block.stoneDoubleSlab.blockID);
		world.setBlock(i + 2, j + 8, k + 22, 0);
		world.setBlock(i + 2, j + 8, k + 23, 0);
		world.setBlock(i + 2, j + 8, k + 24, Block.blockSteel.blockID);
		world.setBlock(i + 2, j + 8, k + 25, 0);
		world.setBlock(i + 2, j + 8, k + 26, 0);
		world.setBlock(i + 2, j + 8, k + 27, 0);
		world.setBlock(i + 2, j + 9, k + 0, 0);
		world.setBlock(i + 2, j + 9, k + 1, 0);
		world.setBlock(i + 2, j + 9, k + 2, 0);
		world.setBlock(i + 2, j + 9, k + 3, 0);
		world.setBlock(i + 2, j + 9, k + 4, 0);
		world.setBlock(i + 2, j + 9, k + 5, 0);
		world.setBlock(i + 2, j + 9, k + 6, 0);
		world.setBlock(i + 2, j + 9, k + 7, 0);
		world.setBlock(i + 2, j + 9, k + 8, 0);
		world.setBlock(i + 2, j + 9, k + 9, 0);
		world.setBlock(i + 2, j + 9, k + 10, Block.blockSteel.blockID);
		world.setBlock(i + 2, j + 9, k + 11, 0);
		world.setBlock(i + 2, j + 9, k + 12, 0);
		world.setBlock(i + 2, j + 9, k + 13, 0);
		world.setBlock(i + 2, j + 9, k + 14, 0);
		world.setBlock(i + 2, j + 9, k + 15, 0);
		world.setBlock(i + 2, j + 9, k + 16, 0);
		world.setBlock(i + 2, j + 9, k + 17, 0);
		world.setBlock(i + 2, j + 9, k + 18, 0);
		world.setBlock(i + 2, j + 9, k + 19, 0);
		world.setBlock(i + 2, j + 9, k + 20, 0);
		world.setBlock(i + 2, j + 9, k + 21, 0);
		world.setBlock(i + 2, j + 9, k + 22, 0);
		world.setBlock(i + 2, j + 9, k + 23, 0);
		world.setBlock(i + 2, j + 9, k + 24, Block.blockSteel.blockID);
		world.setBlock(i + 2, j + 9, k + 25, 0);
		world.setBlock(i + 2, j + 9, k + 26, 0);
		world.setBlock(i + 2, j + 9, k + 27, 0);
		world.setBlock(i + 2, j + 10, k + 0, 0);
		world.setBlock(i + 2, j + 10, k + 1, 0);
		world.setBlock(i + 2, j + 10, k + 2, 0);
		world.setBlock(i + 2, j + 10, k + 3, 0);
		world.setBlock(i + 2, j + 10, k + 4, 0);
		world.setBlock(i + 2, j + 10, k + 5, 0);
		world.setBlock(i + 2, j + 10, k + 6, 0);
		world.setBlock(i + 2, j + 10, k + 7, 0);
		world.setBlock(i + 2, j + 10, k + 8, 0);
		world.setBlock(i + 2, j + 10, k + 9, 0);
		world.setBlock(i + 2, j + 10, k + 10, Block.blockSteel.blockID);
		world.setBlock(i + 2, j + 10, k + 11, Block.blockSteel.blockID);
		world.setBlock(i + 2, j + 10, k + 12, Block.blockSteel.blockID);
		world.setBlock(i + 2, j + 10, k + 13, Block.blockSteel.blockID);
		world.setBlock(i + 2, j + 10, k + 14, Block.blockSteel.blockID);
		world.setBlock(i + 2, j + 10, k + 15, Block.blockSteel.blockID);
		world.setBlock(i + 2, j + 10, k + 16, Block.blockSteel.blockID);
		world.setBlock(i + 2, j + 10, k + 17, Block.blockSteel.blockID);
		world.setBlock(i + 2, j + 10, k + 18, Block.blockSteel.blockID);
		world.setBlock(i + 2, j + 10, k + 19, Block.blockSteel.blockID);
		world.setBlock(i + 2, j + 10, k + 20, Block.blockSteel.blockID);
		world.setBlock(i + 2, j + 10, k + 21, Block.blockSteel.blockID);
		world.setBlock(i + 2, j + 10, k + 22, Block.blockSteel.blockID);
		world.setBlock(i + 2, j + 10, k + 23, Block.blockSteel.blockID);
		world.setBlock(i + 2, j + 10, k + 24, Block.blockSteel.blockID);
		world.setBlock(i + 2, j + 10, k + 25, 0);
		world.setBlock(i + 2, j + 10, k + 26, 0);
		world.setBlock(i + 2, j + 10, k + 27, 0);
		world.setBlock(i + 3, j + 0, k + 0, 0);
		world.setBlock(i + 3, j + 0, k + 1, 0);
		world.setBlock(i + 3, j + 0, k + 2, 0);
		world.setBlock(i + 3, j + 0, k + 3, 0);
		world.setBlock(i + 3, j + 0, k + 4, 0);
		world.setBlock(i + 3, j + 0, k + 5, 0);
		world.setBlock(i + 3, j + 0, k + 6, 0);
		world.setBlock(i + 3, j + 0, k + 7, 0);
		world.setBlock(i + 3, j + 0, k + 8, 0);
		world.setBlock(i + 3, j + 0, k + 9, 0);
		world.setBlock(i + 3, j + 0, k + 10, Block.blockSteel.blockID);
		world.setBlock(i + 3, j + 0, k + 11, Block.blockSteel.blockID);
		world.setBlock(i + 3, j + 0, k + 12, Block.blockSteel.blockID);
		world.setBlock(i + 3, j + 0, k + 13, Block.blockSteel.blockID);
		world.setBlock(i + 3, j + 0, k + 14, Block.blockSteel.blockID);
		world.setBlock(i + 3, j + 0, k + 15, Block.blockSteel.blockID);
		world.setBlock(i + 3, j + 0, k + 16, Block.blockSteel.blockID);
		world.setBlock(i + 3, j + 0, k + 17, Block.blockSteel.blockID);
		world.setBlock(i + 3, j + 0, k + 18, Block.blockSteel.blockID);
		world.setBlock(i + 3, j + 0, k + 19, Block.blockSteel.blockID);
		world.setBlock(i + 3, j + 0, k + 20, Block.blockSteel.blockID);
		world.setBlock(i + 3, j + 0, k + 21, Block.blockSteel.blockID);
		world.setBlock(i + 3, j + 0, k + 22, Block.blockSteel.blockID);
		world.setBlock(i + 3, j + 0, k + 23, Block.blockSteel.blockID);
		world.setBlock(i + 3, j + 0, k + 24, Block.blockSteel.blockID);
		world.setBlock(i + 3, j + 0, k + 25, 0);
		world.setBlock(i + 3, j + 0, k + 26, 0);
		world.setBlock(i + 3, j + 0, k + 27, 0);
		world.setBlock(i + 3, j + 1, k + 0, 0);
		world.setBlock(i + 3, j + 1, k + 1, 0);
		world.setBlock(i + 3, j + 1, k + 2, 0);
		world.setBlock(i + 3, j + 1, k + 3, 0);
		world.setBlock(i + 3, j + 1, k + 4, 0);
		world.setBlock(i + 3, j + 1, k + 5, 0);
		world.setBlock(i + 3, j + 1, k + 6, 0);
		world.setBlock(i + 3, j + 1, k + 7, 0);
		world.setBlock(i + 3, j + 1, k + 8, 0);
		world.setBlock(i + 3, j + 1, k + 9, 0);
		world.setBlock(i + 3, j + 1, k + 10, Block.blockSteel.blockID);
		world.setBlock(i + 3, j + 1, k + 11, 0);
		world.setBlock(i + 3, j + 1, k + 12, 0);
		world.setBlock(i + 3, j + 1, k + 13, 0);
		world.setBlock(i + 3, j + 1, k + 14, 0);
		world.setBlock(i + 3, j + 1, k + 15, 0);
		world.setBlock(i + 3, j + 1, k + 16, 0);
		world.setBlock(i + 3, j + 1, k + 17, 0);
		world.setBlock(i + 3, j + 1, k + 18, 0);
		world.setBlock(i + 3, j + 1, k + 19, 0);
		world.setBlock(i + 3, j + 1, k + 20, 0);
		world.setBlock(i + 3, j + 1, k + 21, 0);
		world.setBlock(i + 3, j + 1, k + 22, 0);
		world.setBlock(i + 3, j + 1, k + 23, 0);
		world.setBlock(i + 3, j + 1, k + 24, Block.blockSteel.blockID);
		world.setBlock(i + 3, j + 1, k + 25, 0);
		world.setBlock(i + 3, j + 1, k + 26, 0);
		world.setBlock(i + 3, j + 1, k + 27, 0);
		world.setBlock(i + 3, j + 2, k + 0, 0);
		world.setBlock(i + 3, j + 2, k + 1, 0);
		world.setBlock(i + 3, j + 2, k + 2, 0);
		world.setBlock(i + 3, j + 2, k + 3, 0);
		world.setBlock(i + 3, j + 2, k + 4, 0);
		world.setBlock(i + 3, j + 2, k + 5, 0);
		world.setBlock(i + 3, j + 2, k + 6, 0);
		world.setBlock(i + 3, j + 2, k + 7, 0);
		world.setBlock(i + 3, j + 2, k + 8, 0);
		world.setBlock(i + 3, j + 2, k + 9, 0);
		world.setBlock(i + 3, j + 2, k + 10, Block.blockSteel.blockID);
		world.setBlock(i + 3, j + 2, k + 11, 0);
		world.setBlock(i + 3, j + 2, k + 12, Block.stoneDoubleSlab.blockID);
		world.setBlock(i + 3, j + 2, k + 13, Block.stoneDoubleSlab.blockID);
		world.setBlock(i + 3, j + 2, k + 14, 0);
		world.setBlock(i + 3, j + 2, k + 15, 0);
		world.setBlock(i + 3, j + 2, k + 16, 0);
		world.setBlock(i + 3, j + 2, k + 17, 0);
		world.setBlock(i + 3, j + 2, k + 18, 0);
		world.setBlock(i + 3, j + 2, k + 19, 0);
		world.setBlock(i + 3, j + 2, k + 20, 0);
		world.setBlock(i + 3, j + 2, k + 21, 0);
		world.setBlock(i + 3, j + 2, k + 22, 0);
		world.setBlock(i + 3, j + 2, k + 23, 0);
		world.setBlock(i + 3, j + 2, k + 24, Block.blockSteel.blockID);
		world.setBlock(i + 3, j + 2, k + 25, 0);
		world.setBlock(i + 3, j + 2, k + 26, 0);
		world.setBlock(i + 3, j + 2, k + 27, 0);
		world.setBlock(i + 3, j + 3, k + 0, 0);
		world.setBlock(i + 3, j + 3, k + 1, 0);
		world.setBlock(i + 3, j + 3, k + 2, 0);
		world.setBlock(i + 3, j + 3, k + 3, 0);
		world.setBlock(i + 3, j + 3, k + 4, 0);
		world.setBlock(i + 3, j + 3, k + 5, 0);
		world.setBlock(i + 3, j + 3, k + 6, 0);
		world.setBlock(i + 3, j + 3, k + 7, 0);
		world.setBlock(i + 3, j + 3, k + 8, 0);
		world.setBlock(i + 3, j + 3, k + 9, 0);
		world.setBlock(i + 3, j + 3, k + 10, Block.blockSteel.blockID);
		world.setBlock(i + 3, j + 3, k + 11, Block.stoneBrick.blockID);
		world.setBlock(i + 3, j + 3, k + 12, 0);
		world.setBlock(i + 3, j + 3, k + 13, 0);
		world.setBlock(i + 3, j + 3, k + 14, Block.stoneSingleSlab.blockID);
		world.setBlock(i + 3, j + 3, k + 15, Block.stoneDoubleSlab.blockID);
		world.setBlock(i + 3, j + 3, k + 16, 0);
		world.setBlock(i + 3, j + 3, k + 17, 0);
		world.setBlock(i + 3, j + 3, k + 18, 0);
		world.setBlock(i + 3, j + 3, k + 19, 0);
		world.setBlock(i + 3, j + 3, k + 20, 0);
		world.setBlock(i + 3, j + 3, k + 21, 0);
		world.setBlock(i + 3, j + 3, k + 22, 0);
		world.setBlock(i + 3, j + 3, k + 23, 0);
		world.setBlock(i + 3, j + 3, k + 24, Block.blockSteel.blockID);
		world.setBlock(i + 3, j + 3, k + 25, 0);
		world.setBlock(i + 3, j + 3, k + 26, 0);
		world.setBlock(i + 3, j + 3, k + 27, 0);
		world.setBlock(i + 3, j + 4, k + 0, 0);
		world.setBlock(i + 3, j + 4, k + 1, 0);
		world.setBlock(i + 3, j + 4, k + 2, 0);
		world.setBlock(i + 3, j + 4, k + 3, 0);
		world.setBlock(i + 3, j + 4, k + 4, 0);
		world.setBlock(i + 3, j + 4, k + 5, 0);
		world.setBlock(i + 3, j + 4, k + 6, 0);
		world.setBlock(i + 3, j + 4, k + 7, 0);
		world.setBlock(i + 3, j + 4, k + 8, 0);
		world.setBlock(i + 3, j + 4, k + 9, 0);
		world.setBlock(i + 3, j + 4, k + 10, Block.blockSteel.blockID);
		world.setBlock(i + 3, j + 4, k + 11, Block.cobblestone.blockID);
		world.setBlock(i + 3, j + 4, k + 12, 0);
		world.setBlock(i + 3, j + 4, k + 13, 0);
		world.setBlock(i + 3, j + 4, k + 14, 0);
		world.setBlock(i + 3, j + 4, k + 15, 0);
		world.setBlock(i + 3, j + 4, k + 16, Block.stoneSingleSlab.blockID);
		world.setBlock(i + 3, j + 4, k + 17, Block.stoneDoubleSlab.blockID);
		world.setBlock(i + 3, j + 4, k + 18, 0);
		world.setBlock(i + 3, j + 4, k + 19, 0);
		world.setBlock(i + 3, j + 4, k + 20, 0);
		world.setBlock(i + 3, j + 4, k + 21, 0);
		world.setBlock(i + 3, j + 4, k + 22, 0);
		world.setBlock(i + 3, j + 4, k + 23, 0);
		world.setBlock(i + 3, j + 4, k + 24, Block.blockSteel.blockID);
		world.setBlock(i + 3, j + 4, k + 25, 0);
		world.setBlock(i + 3, j + 4, k + 26, 0);
		world.setBlock(i + 3, j + 4, k + 27, 0);
		world.setBlock(i + 3, j + 5, k + 0, 0);
		world.setBlock(i + 3, j + 5, k + 1, 0);
		world.setBlock(i + 3, j + 5, k + 2, 0);
		world.setBlock(i + 3, j + 5, k + 3, 0);
		world.setBlock(i + 3, j + 5, k + 4, 0);
		world.setBlock(i + 3, j + 5, k + 5, 0);
		world.setBlock(i + 3, j + 5, k + 6, 0);
		world.setBlock(i + 3, j + 5, k + 7, 0);
		world.setBlock(i + 3, j + 5, k + 8, 0);
		world.setBlock(i + 3, j + 5, k + 9, 0);
		world.setBlock(i + 3, j + 5, k + 10, Block.blockSteel.blockID);
		world.setBlock(i + 3, j + 5, k + 11, Block.glowStone.blockID);
		world.setBlock(i + 3, j + 5, k + 12, 0);
		world.setBlock(i + 3, j + 5, k + 13, 0);
		world.setBlock(i + 3, j + 5, k + 14, 0);
		world.setBlock(i + 3, j + 5, k + 15, 0);
		world.setBlock(i + 3, j + 5, k + 16, 0);
		world.setBlock(i + 3, j + 5, k + 17, 0);
		world.setBlock(i + 3, j + 5, k + 18, Block.stoneSingleSlab.blockID);
		world.setBlock(i + 3, j + 5, k + 19, Block.stoneDoubleSlab.blockID);
		world.setBlock(i + 3, j + 5, k + 20, Block.stoneDoubleSlab.blockID);
		world.setBlock(i + 3, j + 5, k + 21, Block.stoneDoubleSlab.blockID);
		world.setBlock(i + 3, j + 5, k + 22, 0);
		world.setBlock(i + 3, j + 5, k + 23, 0);
		world.setBlock(i + 3, j + 5, k + 24, Block.blockSteel.blockID);
		world.setBlock(i + 3, j + 5, k + 25, 0);
		world.setBlock(i + 3, j + 5, k + 26, 0);
		world.setBlock(i + 3, j + 5, k + 27, 0);
		world.setBlock(i + 3, j + 6, k + 0, 0);
		world.setBlock(i + 3, j + 6, k + 1, 0);
		world.setBlock(i + 3, j + 6, k + 2, 0);
		world.setBlock(i + 3, j + 6, k + 3, 0);
		world.setBlock(i + 3, j + 6, k + 4, 0);
		world.setBlock(i + 3, j + 6, k + 5, 0);
		world.setBlock(i + 3, j + 6, k + 6, 0);
		world.setBlock(i + 3, j + 6, k + 7, 0);
		world.setBlock(i + 3, j + 6, k + 8, 0);
		world.setBlock(i + 3, j + 6, k + 9, 0);
		world.setBlock(i + 3, j + 6, k + 10, Block.blockSteel.blockID);
		world.setBlock(i + 3, j + 6, k + 11, Block.stoneBrick.blockID);
		world.setBlock(i + 3, j + 6, k + 12, 0);
		world.setBlock(i + 3, j + 6, k + 13, 0);
		world.setBlock(i + 3, j + 6, k + 14, 0);
		world.setBlock(i + 3, j + 6, k + 15, 0);
		world.setBlock(i + 3, j + 6, k + 16, 0);
		world.setBlock(i + 3, j + 6, k + 17, 0);
		world.setBlock(i + 3, j + 6, k + 18, 0);
		world.setBlock(i + 3, j + 6, k + 19, 0);
		world.setBlock(i + 3, j + 6, k + 20, Block.mobSpawner.blockID);
		world.setBlock(i + 3, j + 6, k + 21, 0);
		world.setBlock(i + 3, j + 6, k + 22, Block.stoneBrick.blockID);
		world.setBlock(i + 3, j + 6, k + 23, 0);
		world.setBlock(i + 3, j + 6, k + 24, Block.blockSteel.blockID);
		world.setBlock(i + 3, j + 6, k + 25, 0);
		world.setBlock(i + 3, j + 6, k + 26, 0);
		world.setBlock(i + 3, j + 6, k + 27, 0);
		world.setBlock(i + 3, j + 7, k + 0, 0);
		world.setBlock(i + 3, j + 7, k + 1, 0);
		world.setBlock(i + 3, j + 7, k + 2, 0);
		world.setBlock(i + 3, j + 7, k + 3, 0);
		world.setBlock(i + 3, j + 7, k + 4, 0);
		world.setBlock(i + 3, j + 7, k + 5, 0);
		world.setBlock(i + 3, j + 7, k + 6, 0);
		world.setBlock(i + 3, j + 7, k + 7, 0);
		world.setBlock(i + 3, j + 7, k + 8, 0);
		world.setBlock(i + 3, j + 7, k + 9, 0);
		world.setBlock(i + 3, j + 7, k + 10, Block.blockSteel.blockID);
		world.setBlock(i + 3, j + 7, k + 11, Block.cobblestone.blockID);
		world.setBlock(i + 3, j + 7, k + 12, 0);
		world.setBlock(i + 3, j + 7, k + 13, 0);
		world.setBlock(i + 3, j + 7, k + 14, 0);
		world.setBlock(i + 3, j + 7, k + 15, 0);
		world.setBlock(i + 3, j + 7, k + 16, 0);
		world.setBlock(i + 3, j + 7, k + 17, 0);
		world.setBlock(i + 3, j + 7, k + 18, 0);
		world.setBlock(i + 3, j + 7, k + 19, 0);
		world.setBlockAndMetadata(i + 3, j + 7, k + 20, Block.chest.blockID, 2);
		world.setBlock(i + 3, j + 7, k + 21, 0);
		world.setBlock(i + 3, j + 7, k + 22, Block.cobblestone.blockID);
		world.setBlock(i + 3, j + 7, k + 23, 0);
		world.setBlock(i + 3, j + 7, k + 24, Block.blockSteel.blockID);
		world.setBlock(i + 3, j + 7, k + 25, 0);
		world.setBlock(i + 3, j + 7, k + 26, 0);
		world.setBlock(i + 3, j + 7, k + 27, 0);
		world.setBlock(i + 3, j + 8, k + 0, 0);
		world.setBlock(i + 3, j + 8, k + 1, 0);
		world.setBlock(i + 3, j + 8, k + 2, 0);
		world.setBlock(i + 3, j + 8, k + 3, 0);
		world.setBlock(i + 3, j + 8, k + 4, 0);
		world.setBlock(i + 3, j + 8, k + 5, 0);
		world.setBlock(i + 3, j + 8, k + 6, 0);
		world.setBlock(i + 3, j + 8, k + 7, 0);
		world.setBlock(i + 3, j + 8, k + 8, 0);
		world.setBlock(i + 3, j + 8, k + 9, 0);
		world.setBlock(i + 3, j + 8, k + 10, Block.blockSteel.blockID);
		world.setBlock(i + 3, j + 8, k + 11, 0);
		world.setBlock(i + 3, j + 8, k + 12, Block.stoneDoubleSlab.blockID);
		world.setBlock(i + 3, j + 8, k + 13, Block.stoneDoubleSlab.blockID);
		world.setBlock(i + 3, j + 8, k + 14, Block.stoneDoubleSlab.blockID);
		world.setBlock(i + 3, j + 8, k + 15, Block.stoneDoubleSlab.blockID);
		world.setBlock(i + 3, j + 8, k + 16, Block.stoneDoubleSlab.blockID);
		world.setBlock(i + 3, j + 8, k + 17, Block.stoneDoubleSlab.blockID);
		world.setBlock(i + 3, j + 8, k + 18, Block.stoneDoubleSlab.blockID);
		world.setBlock(i + 3, j + 8, k + 19, Block.stoneDoubleSlab.blockID);
		world.setBlock(i + 3, j + 8, k + 20, Block.stoneDoubleSlab.blockID);
		world.setBlock(i + 3, j + 8, k + 21, Block.stoneDoubleSlab.blockID);
		world.setBlock(i + 3, j + 8, k + 22, 0);
		world.setBlock(i + 3, j + 8, k + 23, 0);
		world.setBlock(i + 3, j + 8, k + 24, Block.blockSteel.blockID);
		world.setBlock(i + 3, j + 8, k + 25, 0);
		world.setBlock(i + 3, j + 8, k + 26, 0);
		world.setBlock(i + 3, j + 8, k + 27, 0);
		world.setBlock(i + 3, j + 9, k + 0, 0);
		world.setBlock(i + 3, j + 9, k + 1, 0);
		world.setBlock(i + 3, j + 9, k + 2, 0);
		world.setBlock(i + 3, j + 9, k + 3, 0);
		world.setBlock(i + 3, j + 9, k + 4, 0);
		world.setBlock(i + 3, j + 9, k + 5, 0);
		world.setBlock(i + 3, j + 9, k + 6, 0);
		world.setBlock(i + 3, j + 9, k + 7, 0);
		world.setBlock(i + 3, j + 9, k + 8, 0);
		world.setBlock(i + 3, j + 9, k + 9, 0);
		world.setBlock(i + 3, j + 9, k + 10, Block.blockSteel.blockID);
		world.setBlock(i + 3, j + 9, k + 11, 0);
		world.setBlock(i + 3, j + 9, k + 12, 0);
		world.setBlock(i + 3, j + 9, k + 13, 0);
		world.setBlock(i + 3, j + 9, k + 14, 0);
		world.setBlock(i + 3, j + 9, k + 15, 0);
		world.setBlock(i + 3, j + 9, k + 16, 0);
		world.setBlock(i + 3, j + 9, k + 17, 0);
		world.setBlock(i + 3, j + 9, k + 18, 0);
		world.setBlock(i + 3, j + 9, k + 19, 0);
		world.setBlock(i + 3, j + 9, k + 20, 0);
		world.setBlock(i + 3, j + 9, k + 21, 0);
		world.setBlock(i + 3, j + 9, k + 22, 0);
		world.setBlock(i + 3, j + 9, k + 23, 0);
		world.setBlock(i + 3, j + 9, k + 24, Block.blockSteel.blockID);
		world.setBlock(i + 3, j + 9, k + 25, 0);
		world.setBlock(i + 3, j + 9, k + 26, 0);
		world.setBlock(i + 3, j + 9, k + 27, 0);
		world.setBlock(i + 3, j + 10, k + 0, 0);
		world.setBlock(i + 3, j + 10, k + 1, 0);
		world.setBlock(i + 3, j + 10, k + 2, 0);
		world.setBlock(i + 3, j + 10, k + 3, 0);
		world.setBlock(i + 3, j + 10, k + 4, 0);
		world.setBlock(i + 3, j + 10, k + 5, 0);
		world.setBlock(i + 3, j + 10, k + 6, 0);
		world.setBlock(i + 3, j + 10, k + 7, 0);
		world.setBlock(i + 3, j + 10, k + 8, 0);
		world.setBlock(i + 3, j + 10, k + 9, 0);
		world.setBlock(i + 3, j + 10, k + 10, Block.blockSteel.blockID);
		world.setBlock(i + 3, j + 10, k + 11, Block.blockSteel.blockID);
		world.setBlock(i + 3, j + 10, k + 12, Block.blockSteel.blockID);
		world.setBlock(i + 3, j + 10, k + 13, Block.blockSteel.blockID);
		world.setBlock(i + 3, j + 10, k + 14, Block.blockSteel.blockID);
		world.setBlock(i + 3, j + 10, k + 15, Block.blockSteel.blockID);
		world.setBlock(i + 3, j + 10, k + 16, Block.blockSteel.blockID);
		world.setBlock(i + 3, j + 10, k + 17, Block.blockSteel.blockID);
		world.setBlock(i + 3, j + 10, k + 18, Block.blockSteel.blockID);
		world.setBlock(i + 3, j + 10, k + 19, Block.blockSteel.blockID);
		world.setBlock(i + 3, j + 10, k + 20, Block.blockSteel.blockID);
		world.setBlock(i + 3, j + 10, k + 21, Block.blockSteel.blockID);
		world.setBlock(i + 3, j + 10, k + 22, Block.blockSteel.blockID);
		world.setBlock(i + 3, j + 10, k + 23, Block.blockSteel.blockID);
		world.setBlock(i + 3, j + 10, k + 24, Block.blockSteel.blockID);
		world.setBlock(i + 3, j + 10, k + 25, 0);
		world.setBlock(i + 3, j + 10, k + 26, 0);
		world.setBlock(i + 3, j + 10, k + 27, 0);
		world.setBlock(i + 4, j + 0, k + 0, Block.blockSteel.blockID);
		world.setBlock(i + 4, j + 0, k + 1, Block.blockSteel.blockID);
		world.setBlock(i + 4, j + 0, k + 2, Block.blockSteel.blockID);
		world.setBlock(i + 4, j + 0, k + 3, Block.blockSteel.blockID);
		world.setBlock(i + 4, j + 0, k + 4, Block.blockSteel.blockID);
		world.setBlock(i + 4, j + 0, k + 5, Block.blockSteel.blockID);
		world.setBlock(i + 4, j + 0, k + 6, Block.blockSteel.blockID);
		world.setBlock(i + 4, j + 0, k + 7, Block.blockSteel.blockID);
		world.setBlock(i + 4, j + 0, k + 8, Block.blockSteel.blockID);
		world.setBlock(i + 4, j + 0, k + 9, Block.blockSteel.blockID);
		world.setBlock(i + 4, j + 0, k + 10, Block.blockSteel.blockID);
		world.setBlock(i + 4, j + 0, k + 11, Block.blockSteel.blockID);
		world.setBlock(i + 4, j + 0, k + 12, Block.blockSteel.blockID);
		world.setBlock(i + 4, j + 0, k + 13, Block.blockSteel.blockID);
		world.setBlock(i + 4, j + 0, k + 14, Block.blockSteel.blockID);
		world.setBlock(i + 4, j + 0, k + 15, Block.blockSteel.blockID);
		world.setBlock(i + 4, j + 0, k + 16, Block.blockSteel.blockID);
		world.setBlock(i + 4, j + 0, k + 17, Block.blockSteel.blockID);
		world.setBlock(i + 4, j + 0, k + 18, Block.blockSteel.blockID);
		world.setBlock(i + 4, j + 0, k + 19, Block.blockSteel.blockID);
		world.setBlock(i + 4, j + 0, k + 20, Block.blockSteel.blockID);
		world.setBlock(i + 4, j + 0, k + 21, Block.blockSteel.blockID);
		world.setBlock(i + 4, j + 0, k + 22, Block.blockSteel.blockID);
		world.setBlock(i + 4, j + 0, k + 23, Block.blockSteel.blockID);
		world.setBlock(i + 4, j + 0, k + 24, Block.blockSteel.blockID);
		world.setBlock(i + 4, j + 0, k + 25, 0);
		world.setBlock(i + 4, j + 0, k + 26, 0);
		world.setBlock(i + 4, j + 0, k + 27, 0);
		world.setBlock(i + 4, j + 1, k + 0, Block.blockSteel.blockID);
		world.setBlock(i + 4, j + 1, k + 1, Block.blockSteel.blockID);
		world.setBlock(i + 4, j + 1, k + 2, Block.blockSteel.blockID);
		world.setBlock(i + 4, j + 1, k + 3, Block.blockSteel.blockID);
		world.setBlock(i + 4, j + 1, k + 4, Block.blockSteel.blockID);
		world.setBlock(i + 4, j + 1, k + 5, Block.blockSteel.blockID);
		world.setBlock(i + 4, j + 1, k + 6, Block.blockSteel.blockID);
		world.setBlock(i + 4, j + 1, k + 7, Block.blockSteel.blockID);
		world.setBlock(i + 4, j + 1, k + 8, Block.blockSteel.blockID);
		world.setBlock(i + 4, j + 1, k + 9, Block.blockSteel.blockID);
		world.setBlock(i + 4, j + 1, k + 10, 0);
		world.setBlock(i + 4, j + 1, k + 11, 0);
		world.setBlock(i + 4, j + 1, k + 12, 0);
		world.setBlock(i + 4, j + 1, k + 13, 0);
		world.setBlock(i + 4, j + 1, k + 14, 0);
		world.setBlock(i + 4, j + 1, k + 15, 0);
		world.setBlock(i + 4, j + 1, k + 16, 0);
		world.setBlock(i + 4, j + 1, k + 17, 0);
		world.setBlock(i + 4, j + 1, k + 18, 0);
		world.setBlock(i + 4, j + 1, k + 19, 0);
		world.setBlock(i + 4, j + 1, k + 20, 0);
		world.setBlock(i + 4, j + 1, k + 21, 0);
		world.setBlock(i + 4, j + 1, k + 22, 0);
		world.setBlock(i + 4, j + 1, k + 23, 0);
		world.setBlock(i + 4, j + 1, k + 24, Block.blockSteel.blockID);
		world.setBlock(i + 4, j + 1, k + 25, 0);
		world.setBlock(i + 4, j + 1, k + 26, 0);
		world.setBlock(i + 4, j + 1, k + 27, 0);
		world.setBlock(i + 4, j + 2, k + 0, Block.blockSteel.blockID);
		world.setBlock(i + 4, j + 2, k + 1, Block.blockSteel.blockID);
		world.setBlock(i + 4, j + 2, k + 2, Block.blockSteel.blockID);
		world.setBlock(i + 4, j + 2, k + 3, Block.blockSteel.blockID);
		world.setBlock(i + 4, j + 2, k + 4, Block.blockSteel.blockID);
		world.setBlock(i + 4, j + 2, k + 5, Block.blockSteel.blockID);
		world.setBlock(i + 4, j + 2, k + 6, Block.blockSteel.blockID);
		world.setBlock(i + 4, j + 2, k + 7, Block.blockSteel.blockID);
		world.setBlock(i + 4, j + 2, k + 8, Block.blockSteel.blockID);
		world.setBlock(i + 4, j + 2, k + 9, Block.blockSteel.blockID);
		world.setBlock(i + 4, j + 2, k + 10, 0);
		world.setBlock(i + 4, j + 2, k + 11, 0);
		world.setBlock(i + 4, j + 2, k + 12, Block.stoneDoubleSlab.blockID);
		world.setBlock(i + 4, j + 2, k + 13, Block.stoneDoubleSlab.blockID);
		world.setBlock(i + 4, j + 2, k + 14, 0);
		world.setBlock(i + 4, j + 2, k + 15, 0);
		world.setBlock(i + 4, j + 2, k + 16, 0);
		world.setBlock(i + 4, j + 2, k + 17, 0);
		world.setBlock(i + 4, j + 2, k + 18, 0);
		world.setBlock(i + 4, j + 2, k + 19, 0);
		world.setBlock(i + 4, j + 2, k + 20, 0);
		world.setBlock(i + 4, j + 2, k + 21, 0);
		world.setBlock(i + 4, j + 2, k + 22, 0);
		world.setBlock(i + 4, j + 2, k + 23, 0);
		world.setBlock(i + 4, j + 2, k + 24, Block.blockSteel.blockID);
		world.setBlock(i + 4, j + 2, k + 25, 0);
		world.setBlock(i + 4, j + 2, k + 26, 0);
		world.setBlock(i + 4, j + 2, k + 27, 0);
		world.setBlock(i + 4, j + 3, k + 0, Block.blockSteel.blockID);
		world.setBlock(i + 4, j + 3, k + 1, Block.blockSteel.blockID);
		world.setBlock(i + 4, j + 3, k + 2, Block.blockSteel.blockID);
		world.setBlock(i + 4, j + 3, k + 3, Block.blockSteel.blockID);
		world.setBlock(i + 4, j + 3, k + 4, Block.blockSteel.blockID);
		world.setBlock(i + 4, j + 3, k + 5, Block.blockSteel.blockID);
		world.setBlock(i + 4, j + 3, k + 6, Block.blockSteel.blockID);
		world.setBlock(i + 4, j + 3, k + 7, Block.blockSteel.blockID);
		world.setBlock(i + 4, j + 3, k + 8, Block.blockSteel.blockID);
		world.setBlock(i + 4, j + 3, k + 9, Block.blockSteel.blockID);
		world.setBlock(i + 4, j + 3, k + 10, 0);
		world.setBlock(i + 4, j + 3, k + 11, Block.stoneBrick.blockID);
		world.setBlock(i + 4, j + 3, k + 12, 0);
		world.setBlock(i + 4, j + 3, k + 13, 0);
		world.setBlock(i + 4, j + 3, k + 14, Block.stoneSingleSlab.blockID);
		world.setBlock(i + 4, j + 3, k + 15, Block.stoneDoubleSlab.blockID);
		world.setBlock(i + 4, j + 3, k + 16, 0);
		world.setBlock(i + 4, j + 3, k + 17, 0);
		world.setBlock(i + 4, j + 3, k + 18, 0);
		world.setBlock(i + 4, j + 3, k + 19, 0);
		world.setBlock(i + 4, j + 3, k + 20, 0);
		world.setBlock(i + 4, j + 3, k + 21, 0);
		world.setBlock(i + 4, j + 3, k + 22, 0);
		world.setBlock(i + 4, j + 3, k + 23, 0);
		world.setBlock(i + 4, j + 3, k + 24, Block.blockSteel.blockID);
		world.setBlock(i + 4, j + 3, k + 25, 0);
		world.setBlock(i + 4, j + 3, k + 26, 0);
		world.setBlock(i + 4, j + 3, k + 27, 0);
		world.setBlock(i + 4, j + 4, k + 0, Block.blockSteel.blockID);
		world.setBlock(i + 4, j + 4, k + 1, Block.blockSteel.blockID);
		world.setBlock(i + 4, j + 4, k + 2, Block.blockSteel.blockID);
		world.setBlock(i + 4, j + 4, k + 3, 0);
		world.setBlock(i + 4, j + 4, k + 4, Block.blockSteel.blockID);
		world.setBlock(i + 4, j + 4, k + 5, 0);
		world.setBlock(i + 4, j + 4, k + 6, Block.blockSteel.blockID);
		world.setBlock(i + 4, j + 4, k + 7, 0);
		world.setBlock(i + 4, j + 4, k + 8, Block.blockSteel.blockID);
		world.setBlock(i + 4, j + 4, k + 9, 0);
		world.setBlock(i + 4, j + 4, k + 10, Block.blockSteel.blockID);
		world.setBlock(i + 4, j + 4, k + 11, Block.cobblestone.blockID);
		world.setBlock(i + 4, j + 4, k + 12, 0);
		world.setBlock(i + 4, j + 4, k + 13, 0);
		world.setBlock(i + 4, j + 4, k + 14, 0);
		world.setBlock(i + 4, j + 4, k + 15, 0);
		world.setBlock(i + 4, j + 4, k + 16, Block.stoneSingleSlab.blockID);
		world.setBlock(i + 4, j + 4, k + 17, Block.stoneDoubleSlab.blockID);
		world.setBlock(i + 4, j + 4, k + 18, 0);
		world.setBlock(i + 4, j + 4, k + 19, 0);
		world.setBlock(i + 4, j + 4, k + 20, 0);
		world.setBlock(i + 4, j + 4, k + 21, 0);
		world.setBlock(i + 4, j + 4, k + 22, 0);
		world.setBlock(i + 4, j + 4, k + 23, 0);
		world.setBlock(i + 4, j + 4, k + 24, Block.blockSteel.blockID);
		world.setBlock(i + 4, j + 4, k + 25, 0);
		world.setBlock(i + 4, j + 4, k + 26, 0);
		world.setBlock(i + 4, j + 4, k + 27, 0);
		world.setBlock(i + 4, j + 5, k + 0, Block.blockSteel.blockID);
		world.setBlock(i + 4, j + 5, k + 1, Block.blockSteel.blockID);
		world.setBlock(i + 4, j + 5, k + 2, Block.blockSteel.blockID);
		world.setBlock(i + 4, j + 5, k + 3, Block.blockSteel.blockID);
		world.setBlock(i + 4, j + 5, k + 4, Block.blockSteel.blockID);
		world.setBlock(i + 4, j + 5, k + 5, Block.blockSteel.blockID);
		world.setBlock(i + 4, j + 5, k + 6, Block.blockSteel.blockID);
		world.setBlock(i + 4, j + 5, k + 7, Block.blockSteel.blockID);
		world.setBlock(i + 4, j + 5, k + 8, Block.blockSteel.blockID);
		world.setBlock(i + 4, j + 5, k + 9, Block.blockSteel.blockID);
		world.setBlock(i + 4, j + 5, k + 10, 0);
		world.setBlock(i + 4, j + 5, k + 11, Block.glowStone.blockID);
		world.setBlock(i + 4, j + 5, k + 12, 0);
		world.setBlock(i + 4, j + 5, k + 13, 0);
		world.setBlock(i + 4, j + 5, k + 14, 0);
		world.setBlock(i + 4, j + 5, k + 15, 0);
		world.setBlock(i + 4, j + 5, k + 16, 0);
		world.setBlock(i + 4, j + 5, k + 17, 0);
		world.setBlock(i + 4, j + 5, k + 18, Block.stoneSingleSlab.blockID);
		world.setBlock(i + 4, j + 5, k + 19, Block.stoneDoubleSlab.blockID);
		world.setBlock(i + 4, j + 5, k + 20, Block.stoneDoubleSlab.blockID);
		world.setBlock(i + 4, j + 5, k + 21, Block.stoneDoubleSlab.blockID);
		world.setBlock(i + 4, j + 5, k + 22, 0);
		world.setBlock(i + 4, j + 5, k + 23, 0);
		world.setBlock(i + 4, j + 5, k + 24, Block.blockSteel.blockID);
		world.setBlock(i + 4, j + 5, k + 25, 0);
		world.setBlock(i + 4, j + 5, k + 26, 0);
		world.setBlock(i + 4, j + 5, k + 27, 0);
		world.setBlock(i + 4, j + 6, k + 0, Block.blockSteel.blockID);
		world.setBlock(i + 4, j + 6, k + 1, Block.blockSteel.blockID);
		world.setBlock(i + 4, j + 6, k + 2, Block.blockSteel.blockID);
		world.setBlock(i + 4, j + 6, k + 3, Block.blockSteel.blockID);
		world.setBlock(i + 4, j + 6, k + 4, Block.blockSteel.blockID);
		world.setBlock(i + 4, j + 6, k + 5, Block.blockSteel.blockID);
		world.setBlock(i + 4, j + 6, k + 6, Block.blockSteel.blockID);
		world.setBlock(i + 4, j + 6, k + 7, Block.blockSteel.blockID);
		world.setBlock(i + 4, j + 6, k + 8, Block.blockSteel.blockID);
		world.setBlock(i + 4, j + 6, k + 9, Block.blockSteel.blockID);
		world.setBlock(i + 4, j + 6, k + 10, 0);
		world.setBlock(i + 4, j + 6, k + 11, Block.stoneBrick.blockID);
		world.setBlock(i + 4, j + 6, k + 12, 0);
		world.setBlock(i + 4, j + 6, k + 13, 0);
		world.setBlock(i + 4, j + 6, k + 14, 0);
		world.setBlock(i + 4, j + 6, k + 15, 0);
		world.setBlock(i + 4, j + 6, k + 16, 0);
		world.setBlock(i + 4, j + 6, k + 17, 0);
		world.setBlock(i + 4, j + 6, k + 18, 0);
		world.setBlock(i + 4, j + 6, k + 19, 0);
		world.setBlock(i + 4, j + 6, k + 20, 0);
		world.setBlock(i + 4, j + 6, k + 21, 0);
		world.setBlock(i + 4, j + 6, k + 22, Block.stoneBrick.blockID);
		world.setBlock(i + 4, j + 6, k + 23, 0);
		world.setBlock(i + 4, j + 6, k + 24, Block.blockSteel.blockID);
		world.setBlock(i + 4, j + 6, k + 25, 0);
		world.setBlock(i + 4, j + 6, k + 26, 0);
		world.setBlock(i + 4, j + 6, k + 27, 0);
		world.setBlock(i + 4, j + 7, k + 0, 0);
		world.setBlock(i + 4, j + 7, k + 1, 0);
		world.setBlock(i + 4, j + 7, k + 2, 0);
		world.setBlock(i + 4, j + 7, k + 3, 0);
		world.setBlock(i + 4, j + 7, k + 4, 0);
		world.setBlock(i + 4, j + 7, k + 5, 0);
		world.setBlock(i + 4, j + 7, k + 6, 0);
		world.setBlock(i + 4, j + 7, k + 7, 0);
		world.setBlock(i + 4, j + 7, k + 8, 0);
		world.setBlock(i + 4, j + 7, k + 9, 0);
		world.setBlock(i + 4, j + 7, k + 10, Block.blockSteel.blockID);
		world.setBlock(i + 4, j + 7, k + 11, Block.cobblestone.blockID);
		world.setBlock(i + 4, j + 7, k + 12, 0);
		world.setBlock(i + 4, j + 7, k + 13, 0);
		world.setBlock(i + 4, j + 7, k + 14, 0);
		world.setBlock(i + 4, j + 7, k + 15, 0);
		world.setBlock(i + 4, j + 7, k + 16, 0);
		world.setBlock(i + 4, j + 7, k + 17, 0);
		world.setBlock(i + 4, j + 7, k + 18, 0);
		world.setBlock(i + 4, j + 7, k + 19, 0);
		world.setBlock(i + 4, j + 7, k + 20, 0);
		world.setBlock(i + 4, j + 7, k + 21, 0);
		world.setBlock(i + 4, j + 7, k + 22, Block.cobblestone.blockID);
		world.setBlock(i + 4, j + 7, k + 23, 0);
		world.setBlock(i + 4, j + 7, k + 24, Block.blockSteel.blockID);
		world.setBlock(i + 4, j + 7, k + 25, 0);
		world.setBlock(i + 4, j + 7, k + 26, 0);
		world.setBlock(i + 4, j + 7, k + 27, 0);
		world.setBlock(i + 4, j + 8, k + 0, 0);
		world.setBlock(i + 4, j + 8, k + 1, 0);
		world.setBlock(i + 4, j + 8, k + 2, 0);
		world.setBlock(i + 4, j + 8, k + 3, 0);
		world.setBlock(i + 4, j + 8, k + 4, 0);
		world.setBlock(i + 4, j + 8, k + 5, 0);
		world.setBlock(i + 4, j + 8, k + 6, 0);
		world.setBlock(i + 4, j + 8, k + 7, 0);
		world.setBlock(i + 4, j + 8, k + 8, 0);
		world.setBlock(i + 4, j + 8, k + 9, 0);
		world.setBlock(i + 4, j + 8, k + 10, Block.blockSteel.blockID);
		world.setBlock(i + 4, j + 8, k + 11, 0);
		world.setBlock(i + 4, j + 8, k + 12, Block.stoneDoubleSlab.blockID);
		world.setBlock(i + 4, j + 8, k + 13, Block.stoneDoubleSlab.blockID);
		world.setBlock(i + 4, j + 8, k + 14, Block.stoneDoubleSlab.blockID);
		world.setBlock(i + 4, j + 8, k + 15, Block.stoneDoubleSlab.blockID);
		world.setBlock(i + 4, j + 8, k + 16, Block.stoneDoubleSlab.blockID);
		world.setBlock(i + 4, j + 8, k + 17, Block.stoneDoubleSlab.blockID);
		world.setBlock(i + 4, j + 8, k + 18, Block.stoneDoubleSlab.blockID);
		world.setBlock(i + 4, j + 8, k + 19, Block.stoneDoubleSlab.blockID);
		world.setBlock(i + 4, j + 8, k + 20, Block.stoneDoubleSlab.blockID);
		world.setBlock(i + 4, j + 8, k + 21, Block.stoneDoubleSlab.blockID);
		world.setBlock(i + 4, j + 8, k + 22, 0);
		world.setBlock(i + 4, j + 8, k + 23, 0);
		world.setBlock(i + 4, j + 8, k + 24, Block.blockSteel.blockID);
		world.setBlock(i + 4, j + 8, k + 25, 0);
		world.setBlock(i + 4, j + 8, k + 26, 0);
		world.setBlock(i + 4, j + 8, k + 27, 0);
		world.setBlock(i + 4, j + 9, k + 0, 0);
		world.setBlock(i + 4, j + 9, k + 1, 0);
		world.setBlock(i + 4, j + 9, k + 2, 0);
		world.setBlock(i + 4, j + 9, k + 3, 0);
		world.setBlock(i + 4, j + 9, k + 4, 0);
		world.setBlock(i + 4, j + 9, k + 5, 0);
		world.setBlock(i + 4, j + 9, k + 6, 0);
		world.setBlock(i + 4, j + 9, k + 7, 0);
		world.setBlock(i + 4, j + 9, k + 8, 0);
		world.setBlock(i + 4, j + 9, k + 9, 0);
		world.setBlock(i + 4, j + 9, k + 10, Block.blockSteel.blockID);
		world.setBlock(i + 4, j + 9, k + 11, 0);
		world.setBlock(i + 4, j + 9, k + 12, 0);
		world.setBlock(i + 4, j + 9, k + 13, 0);
		world.setBlock(i + 4, j + 9, k + 14, 0);
		world.setBlock(i + 4, j + 9, k + 15, 0);

		generate2(world, rand, i, j, k);
		return true;
	}

	public boolean generate2(World world, Random rand, int i, int j, int k) {
		world.setBlock(i + 4, j + 9, k + 16, 0);
		world.setBlock(i + 4, j + 9, k + 17, 0);
		world.setBlock(i + 4, j + 9, k + 18, 0);
		world.setBlock(i + 4, j + 9, k + 19, 0);
		world.setBlock(i + 4, j + 9, k + 20, 0);
		world.setBlock(i + 4, j + 9, k + 21, 0);
		world.setBlock(i + 4, j + 9, k + 22, 0);
		world.setBlock(i + 4, j + 9, k + 23, 0);
		world.setBlock(i + 4, j + 9, k + 24, Block.blockSteel.blockID);
		world.setBlock(i + 4, j + 9, k + 25, 0);
		world.setBlock(i + 4, j + 9, k + 26, 0);
		world.setBlock(i + 4, j + 9, k + 27, 0);
		world.setBlock(i + 4, j + 10, k + 0, 0);
		world.setBlock(i + 4, j + 10, k + 1, 0);
		world.setBlock(i + 4, j + 10, k + 2, 0);
		world.setBlock(i + 4, j + 10, k + 3, 0);
		world.setBlock(i + 4, j + 10, k + 4, 0);
		world.setBlock(i + 4, j + 10, k + 5, 0);
		world.setBlock(i + 4, j + 10, k + 6, 0);
		world.setBlock(i + 4, j + 10, k + 7, 0);
		world.setBlock(i + 4, j + 10, k + 8, 0);
		world.setBlock(i + 4, j + 10, k + 9, 0);
		world.setBlock(i + 4, j + 10, k + 10, Block.blockSteel.blockID);
		world.setBlock(i + 4, j + 10, k + 11, Block.blockSteel.blockID);
		world.setBlock(i + 4, j + 10, k + 12, Block.blockSteel.blockID);
		world.setBlock(i + 4, j + 10, k + 13, Block.blockSteel.blockID);
		world.setBlock(i + 4, j + 10, k + 14, Block.blockSteel.blockID);
		world.setBlock(i + 4, j + 10, k + 15, Block.blockSteel.blockID);
		world.setBlock(i + 4, j + 10, k + 16, Block.blockSteel.blockID);
		world.setBlock(i + 4, j + 10, k + 17, Block.blockSteel.blockID);
		world.setBlock(i + 4, j + 10, k + 18, Block.blockSteel.blockID);
		world.setBlock(i + 4, j + 10, k + 19, Block.blockSteel.blockID);
		world.setBlock(i + 4, j + 10, k + 20, Block.blockSteel.blockID);
		world.setBlock(i + 4, j + 10, k + 21, Block.blockSteel.blockID);
		world.setBlock(i + 4, j + 10, k + 22, Block.blockSteel.blockID);
		world.setBlock(i + 4, j + 10, k + 23, Block.blockSteel.blockID);
		world.setBlock(i + 4, j + 10, k + 24, Block.blockSteel.blockID);
		world.setBlock(i + 4, j + 10, k + 25, 0);
		world.setBlock(i + 4, j + 10, k + 26, 0);
		world.setBlock(i + 4, j + 10, k + 27, 0);
		world.setBlock(i + 5, j + 0, k + 0, Block.blockSteel.blockID);
		world.setBlock(i + 5, j + 0, k + 1, Block.blockSteel.blockID);
		world.setBlock(i + 5, j + 0, k + 2, Block.blockSteel.blockID);
		world.setBlock(i + 5, j + 0, k + 3, Block.blockSteel.blockID);
		world.setBlock(i + 5, j + 0, k + 4, Block.blockSteel.blockID);
		world.setBlock(i + 5, j + 0, k + 5, Block.blockSteel.blockID);
		world.setBlock(i + 5, j + 0, k + 6, Block.blockSteel.blockID);
		world.setBlock(i + 5, j + 0, k + 7, Block.blockSteel.blockID);
		world.setBlock(i + 5, j + 0, k + 8, Block.blockSteel.blockID);
		world.setBlock(i + 5, j + 0, k + 9, Block.blockSteel.blockID);
		world.setBlock(i + 5, j + 0, k + 10, Block.blockSteel.blockID);
		world.setBlock(i + 5, j + 0, k + 11, Block.blockSteel.blockID);
		world.setBlock(i + 5, j + 0, k + 12, Block.blockSteel.blockID);
		world.setBlock(i + 5, j + 0, k + 13, Block.blockSteel.blockID);
		world.setBlock(i + 5, j + 0, k + 14, Block.blockSteel.blockID);
		world.setBlock(i + 5, j + 0, k + 15, Block.blockSteel.blockID);
		world.setBlock(i + 5, j + 0, k + 16, Block.blockSteel.blockID);
		world.setBlock(i + 5, j + 0, k + 17, Block.blockSteel.blockID);
		world.setBlock(i + 5, j + 0, k + 18, Block.blockSteel.blockID);
		world.setBlock(i + 5, j + 0, k + 19, Block.blockSteel.blockID);
		world.setBlock(i + 5, j + 0, k + 20, Block.blockSteel.blockID);
		world.setBlock(i + 5, j + 0, k + 21, Block.blockSteel.blockID);
		world.setBlock(i + 5, j + 0, k + 22, Block.blockSteel.blockID);
		world.setBlock(i + 5, j + 0, k + 23, Block.blockSteel.blockID);
		world.setBlock(i + 5, j + 0, k + 24, Block.blockSteel.blockID);
		world.setBlock(i + 5, j + 0, k + 25, 0);
		world.setBlock(i + 5, j + 0, k + 26, 0);
		world.setBlock(i + 5, j + 0, k + 27, 0);
		world.setBlock(i + 5, j + 1, k + 0, Block.blockSteel.blockID);
		world.setBlock(i + 5, j + 1, k + 1, 0);
		world.setBlock(i + 5, j + 1, k + 2, 0);
		world.setBlock(i + 5, j + 1, k + 3, 0);
		world.setBlock(i + 5, j + 1, k + 4, 0);
		world.setBlock(i + 5, j + 1, k + 5, 0);
		world.setBlock(i + 5, j + 1, k + 6, 0);
		world.setBlock(i + 5, j + 1, k + 7, 0);
		world.setBlock(i + 5, j + 1, k + 8, 0);
		world.setBlock(i + 5, j + 1, k + 9, 0);
		world.setBlock(i + 5, j + 1, k + 10, 0);
		world.setBlock(i + 5, j + 1, k + 11, 0);
		world.setBlock(i + 5, j + 1, k + 12, 0);
		world.setBlock(i + 5, j + 1, k + 13, 0);
		world.setBlock(i + 5, j + 1, k + 14, 0);
		world.setBlock(i + 5, j + 1, k + 15, 0);
		world.setBlock(i + 5, j + 1, k + 16, 0);
		world.setBlock(i + 5, j + 1, k + 17, 0);
		world.setBlock(i + 5, j + 1, k + 18, 0);
		world.setBlock(i + 5, j + 1, k + 19, 0);
		world.setBlock(i + 5, j + 1, k + 20, 0);
		world.setBlock(i + 5, j + 1, k + 21, 0);
		world.setBlock(i + 5, j + 1, k + 22, 0);
		world.setBlock(i + 5, j + 1, k + 23, 0);
		world.setBlock(i + 5, j + 1, k + 24, Block.blockSteel.blockID);
		world.setBlock(i + 5, j + 1, k + 25, 0);
		world.setBlock(i + 5, j + 1, k + 26, 0);
		world.setBlock(i + 5, j + 1, k + 27, 0);
		world.setBlock(i + 5, j + 2, k + 0, Block.blockSteel.blockID);
		world.setBlock(i + 5, j + 2, k + 1, 0);
		world.setBlock(i + 5, j + 2, k + 2, 0);
		world.setBlock(i + 5, j + 2, k + 3, 0);
		world.setBlock(i + 5, j + 2, k + 4, 0);
		world.setBlock(i + 5, j + 2, k + 5, 0);
		world.setBlock(i + 5, j + 2, k + 6, 0);
		world.setBlock(i + 5, j + 2, k + 7, 0);
		world.setBlock(i + 5, j + 2, k + 8, 0);
		world.setBlock(i + 5, j + 2, k + 9, 0);
		world.setBlock(i + 5, j + 2, k + 10, 0);
		world.setBlock(i + 5, j + 2, k + 11, 0);
		world.setBlock(i + 5, j + 2, k + 12, Block.stoneDoubleSlab.blockID);
		world.setBlock(i + 5, j + 2, k + 13, Block.stoneDoubleSlab.blockID);
		world.setBlock(i + 5, j + 2, k + 14, 0);
		world.setBlock(i + 5, j + 2, k + 15, 0);
		world.setBlock(i + 5, j + 2, k + 16, 0);
		world.setBlock(i + 5, j + 2, k + 17, 0);
		world.setBlock(i + 5, j + 2, k + 18, 0);
		world.setBlock(i + 5, j + 2, k + 19, 0);
		world.setBlock(i + 5, j + 2, k + 20, 0);
		world.setBlock(i + 5, j + 2, k + 21, 0);
		world.setBlock(i + 5, j + 2, k + 22, 0);
		world.setBlock(i + 5, j + 2, k + 23, 0);
		world.setBlock(i + 5, j + 2, k + 24, Block.blockSteel.blockID);
		world.setBlock(i + 5, j + 2, k + 25, 0);
		world.setBlock(i + 5, j + 2, k + 26, 0);
		world.setBlock(i + 5, j + 2, k + 27, 0);
		world.setBlock(i + 5, j + 3, k + 0, Block.blockSteel.blockID);
		world.setBlock(i + 5, j + 3, k + 1, 0);
		world.setBlock(i + 5, j + 3, k + 2, Block.stoneBrick.blockID);
		world.setBlock(i + 5, j + 3, k + 3, Block.stone.blockID);
		world.setBlock(i + 5, j + 3, k + 4, Block.stoneBrick.blockID);
		world.setBlock(i + 5, j + 3, k + 5, Block.stone.blockID);
		world.setBlock(i + 5, j + 3, k + 6, Block.stoneBrick.blockID);
		world.setBlock(i + 5, j + 3, k + 7, Block.stone.blockID);
		world.setBlock(i + 5, j + 3, k + 8, Block.stoneBrick.blockID);
		world.setBlock(i + 5, j + 3, k + 9, Block.stone.blockID);
		world.setBlock(i + 5, j + 3, k + 10, Block.stoneBrick.blockID);
		world.setBlock(i + 5, j + 3, k + 11, Block.stoneBrick.blockID);
		world.setBlock(i + 5, j + 3, k + 12, 0);
		world.setBlock(i + 5, j + 3, k + 13, 0);
		world.setBlock(i + 5, j + 3, k + 14, Block.stoneBrick.blockID);
		world.setBlock(i + 5, j + 3, k + 15, Block.stoneBrick.blockID);
		world.setBlock(i + 5, j + 3, k + 16, Block.stoneBrick.blockID);
		world.setBlock(i + 5, j + 3, k + 17, Block.stoneBrick.blockID);
		world.setBlock(i + 5, j + 3, k + 18, Block.stoneBrick.blockID);
		world.setBlock(i + 5, j + 3, k + 19, Block.stoneBrick.blockID);
		world.setBlock(i + 5, j + 3, k + 20, Block.stoneBrick.blockID);
		world.setBlock(i + 5, j + 3, k + 21, Block.stoneBrick.blockID);
		world.setBlock(i + 5, j + 3, k + 22, 0);
		world.setBlock(i + 5, j + 3, k + 23, 0);
		world.setBlock(i + 5, j + 3, k + 24, Block.blockSteel.blockID);
		world.setBlock(i + 5, j + 3, k + 25, 0);
		world.setBlock(i + 5, j + 3, k + 26, 0);
		world.setBlock(i + 5, j + 3, k + 27, 0);
		world.setBlock(i + 5, j + 4, k + 0, Block.blockSteel.blockID);
		world.setBlock(i + 5, j + 4, k + 1, 0);
		world.setBlock(i + 5, j + 4, k + 2, Block.cobblestone.blockID);
		world.setBlock(i + 5, j + 4, k + 3, Block.glass.blockID);
		world.setBlock(i + 5, j + 4, k + 4, Block.cobblestone.blockID);
		world.setBlock(i + 5, j + 4, k + 5, Block.glass.blockID);
		world.setBlock(i + 5, j + 4, k + 6, Block.cobblestone.blockID);
		world.setBlock(i + 5, j + 4, k + 7, Block.glass.blockID);
		world.setBlock(i + 5, j + 4, k + 8, Block.cobblestone.blockID);
		world.setBlock(i + 5, j + 4, k + 9, Block.glass.blockID);
		world.setBlock(i + 5, j + 4, k + 10, Block.cobblestone.blockID);
		world.setBlock(i + 5, j + 4, k + 11, Block.cobblestone.blockID);
		world.setBlock(i + 5, j + 4, k + 12, 0);
		world.setBlock(i + 5, j + 4, k + 13, 0);
		world.setBlock(i + 5, j + 4, k + 14, Block.stone.blockID);
		world.setBlock(i + 5, j + 4, k + 15, Block.stone.blockID);
		world.setBlock(i + 5, j + 4, k + 16, Block.stone.blockID);
		world.setBlock(i + 5, j + 4, k + 17, Block.stone.blockID);
		world.setBlock(i + 5, j + 4, k + 18, Block.stone.blockID);
		world.setBlock(i + 5, j + 4, k + 19, Block.stone.blockID);
		world.setBlock(i + 5, j + 4, k + 20, Block.stone.blockID);
		world.setBlock(i + 5, j + 4, k + 21, Block.stone.blockID);
		world.setBlock(i + 5, j + 4, k + 22, 0);
		world.setBlock(i + 5, j + 4, k + 23, 0);
		world.setBlock(i + 5, j + 4, k + 24, Block.blockSteel.blockID);
		world.setBlock(i + 5, j + 4, k + 25, 0);
		world.setBlock(i + 5, j + 4, k + 26, 0);
		world.setBlock(i + 5, j + 4, k + 27, 0);
		world.setBlock(i + 5, j + 5, k + 0, Block.blockSteel.blockID);
		world.setBlock(i + 5, j + 5, k + 1, 0);
		world.setBlock(i + 5, j + 5, k + 2, 0);
		world.setBlock(i + 5, j + 5, k + 3, Block.stone.blockID);
		world.setBlock(i + 5, j + 5, k + 4, 0);
		world.setBlock(i + 5, j + 5, k + 5, Block.stone.blockID);
		world.setBlock(i + 5, j + 5, k + 6, 0);
		world.setBlock(i + 5, j + 5, k + 7, Block.stone.blockID);
		world.setBlock(i + 5, j + 5, k + 8, 0);
		world.setBlock(i + 5, j + 5, k + 9, Block.stone.blockID);
		world.setBlock(i + 5, j + 5, k + 10, 0);
		world.setBlock(i + 5, j + 5, k + 11, Block.glowStone.blockID);
		world.setBlock(i + 5, j + 5, k + 12, 0);
		world.setBlock(i + 5, j + 5, k + 13, 0);
		world.setBlock(i + 5, j + 5, k + 14, Block.glowStone.blockID);
		world.setBlock(i + 5, j + 5, k + 15, Block.glowStone.blockID);
		world.setBlock(i + 5, j + 5, k + 16, Block.glowStone.blockID);
		world.setBlock(i + 5, j + 5, k + 17, Block.glowStone.blockID);
		world.setBlock(i + 5, j + 5, k + 18, Block.glowStone.blockID);
		world.setBlock(i + 5, j + 5, k + 19, Block.glowStone.blockID);
		world.setBlock(i + 5, j + 5, k + 20, Block.glowStone.blockID);
		world.setBlock(i + 5, j + 5, k + 21, Block.glowStone.blockID);
		world.setBlock(i + 5, j + 5, k + 22, 0);
		world.setBlock(i + 5, j + 5, k + 23, 0);
		world.setBlock(i + 5, j + 5, k + 24, Block.blockSteel.blockID);
		world.setBlock(i + 5, j + 5, k + 25, 0);
		world.setBlock(i + 5, j + 5, k + 26, 0);
		world.setBlock(i + 5, j + 5, k + 27, 0);
		world.setBlock(i + 5, j + 6, k + 0, Block.blockSteel.blockID);
		world.setBlock(i + 5, j + 6, k + 1, Block.blockSteel.blockID);
		world.setBlock(i + 5, j + 6, k + 2, Block.blockSteel.blockID);
		world.setBlock(i + 5, j + 6, k + 3, Block.blockSteel.blockID);
		world.setBlock(i + 5, j + 6, k + 4, Block.blockSteel.blockID);
		world.setBlock(i + 5, j + 6, k + 5, Block.blockSteel.blockID);
		world.setBlock(i + 5, j + 6, k + 6, Block.blockSteel.blockID);
		world.setBlock(i + 5, j + 6, k + 7, Block.blockSteel.blockID);
		world.setBlock(i + 5, j + 6, k + 8, Block.blockSteel.blockID);
		world.setBlock(i + 5, j + 6, k + 9, Block.blockSteel.blockID);
		world.setBlock(i + 5, j + 6, k + 10, 0);
		world.setBlock(i + 5, j + 6, k + 11, Block.stoneBrick.blockID);
		world.setBlock(i + 5, j + 6, k + 12, 0);
		world.setBlock(i + 5, j + 6, k + 13, 0);
		world.setBlock(i + 5, j + 6, k + 14, Block.stoneBrick.blockID);
		world.setBlock(i + 5, j + 6, k + 15, Block.stone.blockID);
		world.setBlock(i + 5, j + 6, k + 16, Block.stoneBrick.blockID);
		world.setBlock(i + 5, j + 6, k + 17, Block.stone.blockID);
		world.setBlock(i + 5, j + 6, k + 18, Block.stoneBrick.blockID);
		world.setBlock(i + 5, j + 6, k + 19, 0);
		world.setBlock(i + 5, j + 6, k + 20, 0);
		world.setBlock(i + 5, j + 6, k + 21, 0);
		world.setBlock(i + 5, j + 6, k + 22, Block.stoneBrick.blockID);
		world.setBlock(i + 5, j + 6, k + 23, 0);
		world.setBlock(i + 5, j + 6, k + 24, Block.blockSteel.blockID);
		world.setBlock(i + 5, j + 6, k + 25, 0);
		world.setBlock(i + 5, j + 6, k + 26, 0);
		world.setBlock(i + 5, j + 6, k + 27, 0);
		world.setBlock(i + 5, j + 7, k + 0, 0);
		world.setBlock(i + 5, j + 7, k + 1, 0);
		world.setBlock(i + 5, j + 7, k + 2, 0);
		world.setBlock(i + 5, j + 7, k + 3, 0);
		world.setBlock(i + 5, j + 7, k + 4, 0);
		world.setBlock(i + 5, j + 7, k + 5, 0);
		world.setBlock(i + 5, j + 7, k + 6, 0);
		world.setBlock(i + 5, j + 7, k + 7, 0);
		world.setBlock(i + 5, j + 7, k + 8, 0);
		world.setBlock(i + 5, j + 7, k + 9, 0);
		world.setBlock(i + 5, j + 7, k + 10, Block.blockSteel.blockID);
		world.setBlock(i + 5, j + 7, k + 11, Block.cobblestone.blockID);
		world.setBlock(i + 5, j + 7, k + 12, 0);
		world.setBlock(i + 5, j + 7, k + 13, 0);
		world.setBlock(i + 5, j + 7, k + 14, Block.cobblestone.blockID);
		world.setBlock(i + 5, j + 7, k + 15, Block.glass.blockID);
		world.setBlock(i + 5, j + 7, k + 16, Block.cobblestone.blockID);
		world.setBlock(i + 5, j + 7, k + 17, Block.glass.blockID);
		world.setBlock(i + 5, j + 7, k + 18, Block.cobblestone.blockID);
		world.setBlock(i + 5, j + 7, k + 19, 0);
		world.setBlock(i + 5, j + 7, k + 20, 0);
		world.setBlock(i + 5, j + 7, k + 21, 0);
		world.setBlock(i + 5, j + 7, k + 22, Block.cobblestone.blockID);
		world.setBlock(i + 5, j + 7, k + 23, 0);
		world.setBlock(i + 5, j + 7, k + 24, Block.blockSteel.blockID);
		world.setBlock(i + 5, j + 7, k + 25, 0);
		world.setBlock(i + 5, j + 7, k + 26, 0);
		world.setBlock(i + 5, j + 7, k + 27, 0);
		world.setBlock(i + 5, j + 8, k + 0, 0);
		world.setBlock(i + 5, j + 8, k + 1, 0);
		world.setBlock(i + 5, j + 8, k + 2, 0);
		world.setBlock(i + 5, j + 8, k + 3, 0);
		world.setBlock(i + 5, j + 8, k + 4, 0);
		world.setBlock(i + 5, j + 8, k + 5, 0);
		world.setBlock(i + 5, j + 8, k + 6, 0);
		world.setBlock(i + 5, j + 8, k + 7, 0);
		world.setBlock(i + 5, j + 8, k + 8, 0);
		world.setBlock(i + 5, j + 8, k + 9, 0);
		world.setBlock(i + 5, j + 8, k + 10, Block.blockSteel.blockID);
		world.setBlock(i + 5, j + 8, k + 11, 0);
		world.setBlock(i + 5, j + 8, k + 12, Block.stoneDoubleSlab.blockID);
		world.setBlock(i + 5, j + 8, k + 13, Block.stoneDoubleSlab.blockID);
		world.setBlock(i + 5, j + 8, k + 14, 0);
		world.setBlock(i + 5, j + 8, k + 15, Block.stone.blockID);
		world.setBlock(i + 5, j + 8, k + 16, 0);
		world.setBlock(i + 5, j + 8, k + 17, Block.stone.blockID);
		world.setBlock(i + 5, j + 8, k + 18, 0);
		world.setBlock(i + 5, j + 8, k + 19, Block.stoneDoubleSlab.blockID);
		world.setBlock(i + 5, j + 8, k + 20, Block.stoneDoubleSlab.blockID);
		world.setBlock(i + 5, j + 8, k + 21, Block.stoneDoubleSlab.blockID);
		world.setBlock(i + 5, j + 8, k + 22, 0);
		world.setBlock(i + 5, j + 8, k + 23, 0);
		world.setBlock(i + 5, j + 8, k + 24, Block.blockSteel.blockID);
		world.setBlock(i + 5, j + 8, k + 25, 0);
		world.setBlock(i + 5, j + 8, k + 26, 0);
		world.setBlock(i + 5, j + 8, k + 27, 0);
		world.setBlock(i + 5, j + 9, k + 0, 0);
		world.setBlock(i + 5, j + 9, k + 1, 0);
		world.setBlock(i + 5, j + 9, k + 2, 0);
		world.setBlock(i + 5, j + 9, k + 3, 0);
		world.setBlock(i + 5, j + 9, k + 4, 0);
		world.setBlock(i + 5, j + 9, k + 5, 0);
		world.setBlock(i + 5, j + 9, k + 6, 0);
		world.setBlock(i + 5, j + 9, k + 7, 0);
		world.setBlock(i + 5, j + 9, k + 8, 0);
		world.setBlock(i + 5, j + 9, k + 9, 0);
		world.setBlock(i + 5, j + 9, k + 10, Block.blockSteel.blockID);
		world.setBlock(i + 5, j + 9, k + 11, 0);
		world.setBlock(i + 5, j + 9, k + 12, 0);
		world.setBlock(i + 5, j + 9, k + 13, 0);
		world.setBlock(i + 5, j + 9, k + 14, 0);
		world.setBlock(i + 5, j + 9, k + 15, 0);
		world.setBlock(i + 5, j + 9, k + 16, 0);
		world.setBlock(i + 5, j + 9, k + 17, 0);
		world.setBlock(i + 5, j + 9, k + 18, 0);
		world.setBlock(i + 5, j + 9, k + 19, 0);
		world.setBlock(i + 5, j + 9, k + 20, 0);
		world.setBlock(i + 5, j + 9, k + 21, 0);
		world.setBlock(i + 5, j + 9, k + 22, 0);
		world.setBlock(i + 5, j + 9, k + 23, 0);
		world.setBlock(i + 5, j + 9, k + 24, Block.blockSteel.blockID);
		world.setBlock(i + 5, j + 9, k + 25, 0);
		world.setBlock(i + 5, j + 9, k + 26, 0);
		world.setBlock(i + 5, j + 9, k + 27, 0);
		world.setBlock(i + 5, j + 10, k + 0, 0);
		world.setBlock(i + 5, j + 10, k + 1, 0);
		world.setBlock(i + 5, j + 10, k + 2, 0);
		world.setBlock(i + 5, j + 10, k + 3, 0);
		world.setBlock(i + 5, j + 10, k + 4, 0);
		world.setBlock(i + 5, j + 10, k + 5, 0);
		world.setBlock(i + 5, j + 10, k + 6, 0);
		world.setBlock(i + 5, j + 10, k + 7, 0);
		world.setBlock(i + 5, j + 10, k + 8, 0);
		world.setBlock(i + 5, j + 10, k + 9, 0);
		world.setBlock(i + 5, j + 10, k + 10, Block.blockSteel.blockID);
		world.setBlock(i + 5, j + 10, k + 11, Block.blockSteel.blockID);
		world.setBlock(i + 5, j + 10, k + 12, Block.blockSteel.blockID);
		world.setBlock(i + 5, j + 10, k + 13, Block.blockSteel.blockID);
		world.setBlock(i + 5, j + 10, k + 14, Block.blockSteel.blockID);
		world.setBlock(i + 5, j + 10, k + 15, Block.blockSteel.blockID);
		world.setBlock(i + 5, j + 10, k + 16, Block.blockSteel.blockID);
		world.setBlock(i + 5, j + 10, k + 17, Block.blockSteel.blockID);
		world.setBlock(i + 5, j + 10, k + 18, Block.blockSteel.blockID);
		world.setBlock(i + 5, j + 10, k + 19, Block.blockSteel.blockID);
		world.setBlock(i + 5, j + 10, k + 20, Block.blockSteel.blockID);
		world.setBlock(i + 5, j + 10, k + 21, Block.blockSteel.blockID);
		world.setBlock(i + 5, j + 10, k + 22, Block.blockSteel.blockID);
		world.setBlock(i + 5, j + 10, k + 23, Block.blockSteel.blockID);
		world.setBlock(i + 5, j + 10, k + 24, Block.blockSteel.blockID);
		world.setBlock(i + 5, j + 10, k + 25, 0);
		world.setBlock(i + 5, j + 10, k + 26, 0);
		world.setBlock(i + 5, j + 10, k + 27, 0);
		world.setBlock(i + 6, j + 0, k + 0, Block.blockSteel.blockID);
		world.setBlock(i + 6, j + 0, k + 1, Block.blockSteel.blockID);
		world.setBlock(i + 6, j + 0, k + 2, Block.blockSteel.blockID);
		world.setBlock(i + 6, j + 0, k + 3, Block.blockSteel.blockID);
		world.setBlock(i + 6, j + 0, k + 4, Block.blockSteel.blockID);
		world.setBlock(i + 6, j + 0, k + 5, Block.blockSteel.blockID);
		world.setBlock(i + 6, j + 0, k + 6, Block.blockSteel.blockID);
		world.setBlock(i + 6, j + 0, k + 7, Block.blockSteel.blockID);
		world.setBlock(i + 6, j + 0, k + 8, Block.blockSteel.blockID);
		world.setBlock(i + 6, j + 0, k + 9, Block.blockSteel.blockID);
		world.setBlock(i + 6, j + 0, k + 10, Block.blockSteel.blockID);
		world.setBlock(i + 6, j + 0, k + 11, Block.blockSteel.blockID);
		world.setBlock(i + 6, j + 0, k + 12, Block.blockSteel.blockID);
		world.setBlock(i + 6, j + 0, k + 13, Block.blockSteel.blockID);
		world.setBlock(i + 6, j + 0, k + 14, Block.blockSteel.blockID);
		world.setBlock(i + 6, j + 0, k + 15, Block.blockSteel.blockID);
		world.setBlock(i + 6, j + 0, k + 16, Block.blockSteel.blockID);
		world.setBlock(i + 6, j + 0, k + 17, Block.blockSteel.blockID);
		world.setBlock(i + 6, j + 0, k + 18, Block.blockSteel.blockID);
		world.setBlock(i + 6, j + 0, k + 19, Block.blockSteel.blockID);
		world.setBlock(i + 6, j + 0, k + 20, Block.blockSteel.blockID);
		world.setBlock(i + 6, j + 0, k + 21, Block.blockSteel.blockID);
		world.setBlock(i + 6, j + 0, k + 22, Block.blockSteel.blockID);
		world.setBlock(i + 6, j + 0, k + 23, Block.blockSteel.blockID);
		world.setBlock(i + 6, j + 0, k + 24, Block.blockSteel.blockID);
		world.setBlock(i + 6, j + 0, k + 25, 0);
		world.setBlock(i + 6, j + 0, k + 26, 0);
		world.setBlock(i + 6, j + 0, k + 27, 0);
		world.setBlock(i + 6, j + 1, k + 0, Block.blockSteel.blockID);
		world.setBlock(i + 6, j + 1, k + 1, 0);
		world.setBlock(i + 6, j + 1, k + 2, 0);
		world.setBlock(i + 6, j + 1, k + 3, 0);
		world.setBlock(i + 6, j + 1, k + 4, 0);
		world.setBlock(i + 6, j + 1, k + 5, 0);
		world.setBlock(i + 6, j + 1, k + 6, 0);
		world.setBlock(i + 6, j + 1, k + 7, 0);
		world.setBlock(i + 6, j + 1, k + 8, 0);
		world.setBlock(i + 6, j + 1, k + 9, 0);
		world.setBlock(i + 6, j + 1, k + 10, 0);
		world.setBlock(i + 6, j + 1, k + 11, 0);
		world.setBlock(i + 6, j + 1, k + 12, 0);
		world.setBlock(i + 6, j + 1, k + 13, 0);
		world.setBlock(i + 6, j + 1, k + 14, 0);
		world.setBlock(i + 6, j + 1, k + 15, 0);
		world.setBlock(i + 6, j + 1, k + 16, 0);
		world.setBlock(i + 6, j + 1, k + 17, 0);
		world.setBlock(i + 6, j + 1, k + 18, 0);
		world.setBlock(i + 6, j + 1, k + 19, 0);
		world.setBlock(i + 6, j + 1, k + 20, 0);
		world.setBlock(i + 6, j + 1, k + 21, 0);
		world.setBlock(i + 6, j + 1, k + 22, 0);
		world.setBlock(i + 6, j + 1, k + 23, 0);
		world.setBlock(i + 6, j + 1, k + 24, Block.blockSteel.blockID);
		world.setBlock(i + 6, j + 1, k + 25, 0);
		world.setBlock(i + 6, j + 1, k + 26, 0);
		world.setBlock(i + 6, j + 1, k + 27, 0);
		world.setBlock(i + 6, j + 2, k + 0, Block.blockSteel.blockID);
		world.setBlock(i + 6, j + 2, k + 1, 0);
		world.setBlock(i + 6, j + 2, k + 2, Block.stoneDoubleSlab.blockID);
		world.setBlock(i + 6, j + 2, k + 3, Block.stoneDoubleSlab.blockID);
		world.setBlock(i + 6, j + 2, k + 4, Block.stoneDoubleSlab.blockID);
		world.setBlock(i + 6, j + 2, k + 5, Block.stoneDoubleSlab.blockID);
		world.setBlock(i + 6, j + 2, k + 6, Block.stoneDoubleSlab.blockID);
		world.setBlock(i + 6, j + 2, k + 7, Block.stoneDoubleSlab.blockID);
		world.setBlock(i + 6, j + 2, k + 8, Block.stoneDoubleSlab.blockID);
		world.setBlock(i + 6, j + 2, k + 9, Block.stoneDoubleSlab.blockID);
		world.setBlock(i + 6, j + 2, k + 10, Block.stoneDoubleSlab.blockID);
