package teamm.mods.virtious.world.gen;
import java.util.Random;

import teamm.mods.virtious.lib.VirtiousBlocks;

import net.minecraft.block.Block;
import net.minecraft.world.World;
import net.minecraft.world.gen.feature.WorldGenerator;

public class VirtiousGenTemple extends WorldGenerator
{
	protected int[] GetValidSpawnBlocks() {
		return new int[] {
		};
	}

	public boolean LocationIsValidSpawn(World world, int i, int j, int k){
		int distanceToAir = 0;
		int checkID = world.getBlockId(i, j, k);

		while (checkID != 0){
			distanceToAir++;
			checkID = world.getBlockId(i, j + distanceToAir, k);
		}

		if (distanceToAir > 3){
			return false;
		}
		j += distanceToAir - 1;

		int blockID = world.getBlockId(i, j, k);
		int blockIDAbove = world.getBlockId(i, j+1, k);
		int blockIDBelow = world.getBlockId(i, j-1, k);
		for (int x : GetValidSpawnBlocks()){
			if (blockIDAbove != 0){
				return false;
			}
			if (blockID == x){
				return true;
			}
			else if (blockID == VirtiousBlocks.virtianGrass.blockID && blockIDBelow == x){
				return true;
			}
		}
		return false;
	}

	public VirtiousGenTemple() { }

	public boolean generate(World world, Random rand, int i, int j, int k) {
		//check that each corner is one of the valid spawn blocks
		
		/*
		if(!LocationIsValidSpawn(world, i, j, k) || !LocationIsValidSpawn(world, i + 20, j, k) || !LocationIsValidSpawn(world, i + 20, j, k + 18) || !LocationIsValidSpawn(world, i, j, k + 18))
		{
			return false;
		}
		*/

		while (world.isAirBlock(i, j, k) && j > 2)
        {
            --j;
        }

		world.setBlockMetadataWithNotify(i + 0, j + 11, k + 8, Block.woodSingleSlab.blockID, 10);
		world.setBlockMetadataWithNotify(i + 0, j + 11, k + 9, Block.woodSingleSlab.blockID, 10);
		world.setBlockMetadataWithNotify(i + 0, j + 11, k + 10, Block.woodSingleSlab.blockID, 10);
		world.setBlockMetadataWithNotify(i + 0, j + 11, k + 11, Block.woodSingleSlab.blockID, 10);
		world.setBlockMetadataWithNotify(i + 0, j + 11, k + 12, Block.woodSingleSlab.blockID, 10);
		world.setBlockMetadataWithNotify(i + 0, j + 11, k + 13, Block.woodSingleSlab.blockID, 10);
		world.setBlockMetadataWithNotify(i + 0, j + 11, k + 14, Block.woodSingleSlab.blockID, 10);
		world.setBlockMetadataWithNotify(i + 0, j + 11, k + 15, Block.woodSingleSlab.blockID, 10);
		world.setBlockMetadataWithNotify(i + 0, j + 11, k + 16, Block.woodSingleSlab.blockID, 10);
		world.setBlockMetadataWithNotify(i + 1, j + 8, k + 9, Block.stairsStoneBrick.blockID, 4);
		world.setBlockMetadataWithNotify(i + 1, j + 8, k + 10, Block.stairsStoneBrick.blockID, 4);
		world.setBlockMetadataWithNotify(i + 1, j + 8, k + 11, Block.stairsStoneBrick.blockID, 4);
		world.setBlockMetadataWithNotify(i + 1, j + 8, k + 12, Block.stairsStoneBrick.blockID, 4);
		world.setBlockMetadataWithNotify(i + 1, j + 8, k + 13, Block.stairsStoneBrick.blockID, 4);
		world.setBlockMetadataWithNotify(i + 1, j + 8, k + 14, Block.stairsStoneBrick.blockID, 4);
		world.setBlockMetadataWithNotify(i + 1, j + 8, k + 15, Block.stairsStoneBrick.blockID, 7);
		world.setBlock(i + 1, j + 9, k + 9, Block.stoneBrick.blockID);
		world.setBlock(i + 1, j + 9, k + 10, Block.stoneBrick.blockID);
		world.setBlock(i + 1, j + 9, k + 11, Block.stoneBrick.blockID);
		world.setBlock(i + 1, j + 9, k + 12, Block.stoneBrick.blockID);
		world.setBlock(i + 1, j + 9, k + 13, Block.stoneBrick.blockID);
		world.setBlock(i + 1, j + 9, k + 14, Block.stoneBrick.blockID);
		world.setBlock(i + 1, j + 9, k + 15, Block.stoneBrick.blockID);
		world.setBlock(i + 1, j + 10, k + 9, Block.stoneBrick.blockID);
		world.setBlock(i + 1, j + 10, k + 10, Block.stoneBrick.blockID);
		world.setBlock(i + 1, j + 10, k + 11, Block.stoneBrick.blockID);
		world.setBlock(i + 1, j + 10, k + 12, Block.glass.blockID);
		world.setBlock(i + 1, j + 10, k + 13, Block.stoneBrick.blockID);
		world.setBlock(i + 1, j + 10, k + 14, Block.stoneBrick.blockID);
		world.setBlock(i + 1, j + 10, k + 15, Block.stoneBrick.blockID);
		world.setBlockMetadataWithNotify(i + 1, j + 11, k + 8, Block.woodSingleSlab.blockID, 10);
		world.setBlock(i + 1, j + 11, k + 9, Block.stoneBrick.blockID);
		world.setBlock(i + 1, j + 11, k + 10, Block.stoneBrick.blockID);
		world.setBlock(i + 1, j + 11, k + 11, Block.stoneBrick.blockID);
		world.setBlock(i + 1, j + 11, k + 12, Block.stoneBrick.blockID);
		world.setBlock(i + 1, j + 11, k + 13, Block.stoneBrick.blockID);
		world.setBlock(i + 1, j + 11, k + 14, Block.stoneBrick.blockID);
		world.setBlock(i + 1, j + 11, k + 15, Block.stoneBrick.blockID);
		world.setBlockMetadataWithNotify(i + 1, j + 11, k + 16, Block.woodSingleSlab.blockID, 10);
		world.setBlockMetadataWithNotify(i + 1, j + 12, k + 9, Block.woodSingleSlab.blockID, 2);
		world.setBlockMetadataWithNotify(i + 1, j + 12, k + 10, Block.woodSingleSlab.blockID, 2);
		world.setBlockMetadataWithNotify(i + 1, j + 12, k + 11, Block.woodSingleSlab.blockID, 2);
		world.setBlockMetadataWithNotify(i + 1, j + 12, k + 12, Block.woodSingleSlab.blockID, 2);
		world.setBlockMetadataWithNotify(i + 1, j + 12, k + 13, Block.woodSingleSlab.blockID, 2);
		world.setBlockMetadataWithNotify(i + 1, j + 12, k + 14, Block.woodSingleSlab.blockID, 2);
		world.setBlockMetadataWithNotify(i + 1, j + 12, k + 15, Block.woodSingleSlab.blockID, 2);
		world.setBlock(i + 2, j + 0, k + 3, Block.stoneBrick.blockID);
		world.setBlock(i + 2, j + 0, k + 4, Block.stoneBrick.blockID);
		world.setBlock(i + 2, j + 0, k + 5, Block.stoneBrick.blockID);
		world.setBlock(i + 2, j + 0, k + 6, Block.stoneBrick.blockID);
		world.setBlock(i + 2, j + 0, k + 7, Block.stoneBrick.blockID);
		world.setBlock(i + 2, j + 0, k + 8, Block.stoneBrick.blockID);
		world.setBlock(i + 2, j + 0, k + 9, Block.stoneBrick.blockID);
		world.setBlock(i + 2, j + 0, k + 10, Block.stoneBrick.blockID);
		world.setBlock(i + 2, j + 0, k + 11, Block.stoneBrick.blockID);
		world.setBlock(i + 2, j + 0, k + 12, Block.stoneBrick.blockID);
		world.setBlock(i + 2, j + 0, k + 13, Block.stoneBrick.blockID);
		world.setBlock(i + 2, j + 0, k + 14, Block.stoneBrick.blockID);
		world.setBlock(i + 2, j + 1, k + 3, Block.stoneBrick.blockID);
		world.setBlock(i + 2, j + 1, k + 4, Block.stoneBrick.blockID);
		world.setBlock(i + 2, j + 1, k + 5, Block.stoneBrick.blockID);
		world.setBlock(i + 2, j + 1, k + 6, Block.stoneBrick.blockID);
		world.setBlock(i + 2, j + 1, k + 7, Block.stoneBrick.blockID);
		world.setBlock(i + 2, j + 1, k + 8, Block.stoneBrick.blockID);
		world.setBlock(i + 2, j + 1, k + 9, Block.stoneBrick.blockID);
		world.setBlock(i + 2, j + 1, k + 10, Block.stoneBrick.blockID);
		world.setBlock(i + 2, j + 1, k + 11, Block.stoneBrick.blockID);
		world.setBlock(i + 2, j + 1, k + 12, Block.stoneBrick.blockID);
		world.setBlock(i + 2, j + 1, k + 13, Block.stoneBrick.blockID);
		world.setBlock(i + 2, j + 1, k + 14, Block.stoneBrick.blockID);
		world.setBlock(i + 2, j + 2, k + 3, Block.stoneBrick.blockID);
		world.setBlock(i + 2, j + 2, k + 4, Block.stoneBrick.blockID);
		world.setBlock(i + 2, j + 2, k + 5, Block.stoneBrick.blockID);
		world.setBlock(i + 2, j + 2, k + 6, Block.stoneBrick.blockID);
		world.setBlock(i + 2, j + 2, k + 7, Block.stoneBrick.blockID);
		world.setBlock(i + 2, j + 2, k + 8, Block.stoneBrick.blockID);
		world.setBlock(i + 2, j + 2, k + 9, Block.stoneBrick.blockID);
		world.setBlock(i + 2, j + 2, k + 10, Block.stoneBrick.blockID);
		world.setBlock(i + 2, j + 2, k + 11, Block.stoneBrick.blockID);
		world.setBlock(i + 2, j + 2, k + 12, Block.stoneBrick.blockID);
		world.setBlock(i + 2, j + 2, k + 13, Block.stoneBrick.blockID);
		world.setBlock(i + 2, j + 2, k + 14, Block.stoneBrick.blockID);
		world.setBlock(i + 2, j + 3, k + 3, Block.fenceIron.blockID);
		world.setBlock(i + 2, j + 3, k + 4, Block.fenceIron.blockID);
		world.setBlock(i + 2, j + 3, k + 5, Block.fenceIron.blockID);
		world.setBlock(i + 2, j + 3, k + 6, Block.fenceIron.blockID);
		world.setBlock(i + 2, j + 3, k + 7, Block.fenceIron.blockID);
		world.setBlock(i + 2, j + 3, k + 8, Block.fenceIron.blockID);
		world.setBlock(i + 2, j + 3, k + 9, Block.fenceIron.blockID);
		world.setBlock(i + 2, j + 3, k + 10, Block.stoneBrick.blockID);
		world.setBlock(i + 2, j + 3, k + 11, Block.stoneBrick.blockID);
		world.setBlock(i + 2, j + 3, k + 12, Block.stoneBrick.blockID);
		world.setBlock(i + 2, j + 3, k + 13, Block.stoneBrick.blockID);
		world.setBlock(i + 2, j + 3, k + 14, Block.stoneBrick.blockID);
		world.setBlock(i + 2, j + 4, k + 10, Block.stoneBrick.blockID);
		world.setBlock(i + 2, j + 4, k + 11, Block.stoneBrick.blockID);
		world.setBlock(i + 2, j + 4, k + 12, Block.stoneBrick.blockID);
		world.setBlock(i + 2, j + 4, k + 13, Block.stoneBrick.blockID);
		world.setBlock(i + 2, j + 4, k + 14, Block.stoneBrick.blockID);
		world.setBlock(i + 2, j + 5, k + 10, Block.stoneBrick.blockID);
		world.setBlock(i + 2, j + 5, k + 11, Block.stoneBrick.blockID);
		world.setBlock(i + 2, j + 5, k + 12, Block.stoneBrick.blockID);
		world.setBlock(i + 2, j + 5, k + 13, Block.stoneBrick.blockID);
		world.setBlock(i + 2, j + 5, k + 14, Block.stoneBrick.blockID);
		world.setBlock(i + 2, j + 6, k + 10, Block.stoneBrick.blockID);
		world.setBlock(i + 2, j + 6, k + 11, Block.stoneBrick.blockID);
		world.setBlock(i + 2, j + 6, k + 12, Block.glass.blockID);
		world.setBlock(i + 2, j + 6, k + 13, Block.stoneBrick.blockID);
		world.setBlock(i + 2, j + 6, k + 14, Block.stoneBrick.blockID);
		world.setBlock(i + 2, j + 7, k + 10, Block.stoneBrick.blockID);
		world.setBlock(i + 2, j + 7, k + 11, Block.stoneBrick.blockID);
		world.setBlock(i + 2, j + 7, k + 12, Block.stoneBrick.blockID);
		world.setBlock(i + 2, j + 7, k + 13, Block.stoneBrick.blockID);
		world.setBlock(i + 2, j + 7, k + 14, Block.stoneBrick.blockID);
		world.setBlockMetadataWithNotify(i + 2, j + 8, k + 9, Block.stairsStoneBrick.blockID, 6);
		world.setBlock(i + 2, j + 8, k + 10, Block.stoneBrick.blockID);
		world.setBlock(i + 2, j + 8, k + 11, Block.stoneBrick.blockID);
		world.setBlock(i + 2, j + 8, k + 12, Block.stoneBrick.blockID);
		world.setBlock(i + 2, j + 8, k + 13, Block.stoneBrick.blockID);
		world.setBlock(i + 2, j + 8, k + 14, Block.stoneBrick.blockID);
		world.setBlockMetadataWithNotify(i + 2, j + 8, k + 15, Block.stairsStoneBrick.blockID, 7);
		world.setBlock(i + 2, j + 9, k + 9, Block.stoneBrick.blockID);
		world.setBlock(i + 2, j + 9, k + 15, Block.stoneBrick.blockID);
		world.setBlock(i + 2, j + 10, k + 9, Block.stoneBrick.blockID);
		world.setBlock(i + 2, j + 10, k + 15, Block.stoneBrick.blockID);
		world.setBlockMetadataWithNotify(i + 2, j + 11, k + 8, Block.woodSingleSlab.blockID, 10);
		world.setBlock(i + 2, j + 11, k + 9, Block.stoneBrick.blockID);
		world.setBlock(i + 2, j + 11, k + 15, Block.stoneBrick.blockID);
		world.setBlockMetadataWithNotify(i + 2, j + 11, k + 16, Block.woodSingleSlab.blockID, 10);
		world.setBlockMetadataWithNotify(i + 2, j + 12, k + 9, Block.woodSingleSlab.blockID, 2);
		world.setBlockMetadataWithNotify(i + 2, j + 12, k + 10, Block.woodSingleSlab.blockID, 10);
		world.setBlockMetadataWithNotify(i + 2, j + 12, k + 11, Block.woodSingleSlab.blockID, 10);
		world.setBlockMetadataWithNotify(i + 2, j + 12, k + 12, Block.woodSingleSlab.blockID, 10);
		world.setBlockMetadataWithNotify(i + 2, j + 12, k + 13, Block.woodSingleSlab.blockID, 10);
		world.setBlockMetadataWithNotify(i + 2, j + 12, k + 14, Block.woodSingleSlab.blockID, 10);
		world.setBlockMetadataWithNotify(i + 2, j + 12, k + 15, Block.woodSingleSlab.blockID, 2);
		world.setBlock(i + 3, j + 0, k + 3, Block.stoneBrick.blockID);
		world.setBlock(i + 3, j + 0, k + 14, Block.stoneBrick.blockID);
		world.setBlock(i + 3, j + 1, k + 3, Block.stoneBrick.blockID);
		world.setBlock(i + 3, j + 1, k + 4, Block.stoneBrick.blockID);
		world.setBlock(i + 3, j + 1, k + 5, Block.stoneBrick.blockID);
		world.setBlock(i + 3, j + 1, k + 6, Block.stoneBrick.blockID);
		world.setBlock(i + 3, j + 1, k + 7, Block.stoneBrick.blockID);
		world.setBlock(i + 3, j + 1, k + 8, Block.stoneBrick.blockID);
		world.setBlock(i + 3, j + 1, k + 9, Block.stoneBrick.blockID);
		world.setBlock(i + 3, j + 1, k + 14, Block.stoneBrick.blockID);
		world.setBlock(i + 3, j + 2, k + 3, Block.stoneBrick.blockID);
		world.setBlock(i + 3, j + 2, k + 10, Block.stoneBrick.blockID);
		world.setBlock(i + 3, j + 2, k + 11, Block.stoneBrick.blockID);
		world.setBlock(i + 3, j + 2, k + 12, Block.stoneBrick.blockID);
		world.setBlock(i + 3, j + 2, k + 13, Block.stoneBrick.blockID);
		world.setBlock(i + 3, j + 2, k + 14, Block.stoneBrick.blockID);
		world.setBlock(i + 3, j + 3, k + 3, Block.fenceIron.blockID);
		world.setBlock(i + 3, j + 3, k + 10, Block.stoneBrick.blockID);
		world.setBlock(i + 3, j + 3, k + 14, Block.stoneBrick.blockID);
		world.setBlock(i + 3, j + 4, k + 10, Block.stoneBrick.blockID);
		world.setBlockMetadataWithNotify(i + 3, j + 4, k + 12, Block.stoneSingleSlab.blockID, 11);
		world.setBlockMetadataWithNotify(i + 3, j + 4, k + 13, Block.stoneSingleSlab.blockID, 3);
		world.setBlock(i + 3, j + 4, k + 14, Block.stoneBrick.blockID);
		world.setBlock(i + 3, j + 5, k + 10, Block.stoneBrick.blockID);
		world.setBlockMetadataWithNotify(i + 3, j + 5, k + 11, Block.stoneSingleSlab.blockID, 3);
		world.setBlock(i + 3, j + 5, k + 14, Block.stoneBrick.blockID);
		world.setBlock(i + 3, j + 6, k + 10, Block.stoneBrick.blockID);
		world.setBlock(i + 3, j + 6, k + 14, Block.stoneBrick.blockID);
		world.setBlock(i + 3, j + 7, k + 10, Block.stoneBrick.blockID);
		world.setBlock(i + 3, j + 7, k + 14, Block.stoneBrick.blockID);
		world.setBlockMetadataWithNotify(i + 3, j + 8, k + 9, Block.stairsStoneBrick.blockID, 6);
		world.setBlock(i + 3, j + 8, k + 10, Block.stoneBrick.blockID);
		world.setBlockMetadataWithNotify(i + 3, j + 8, k + 11, Block.stoneSingleSlab.blockID, 11);
		world.setBlockMetadataWithNotify(i + 3, j + 8, k + 12, Block.stoneSingleSlab.blockID, 11);
		world.setBlockMetadataWithNotify(i + 3, j + 8, k + 13, Block.stoneSingleSlab.blockID, 3);
		world.setBlock(i + 3, j + 8, k + 14, Block.stoneBrick.blockID);
		world.setBlockMetadataWithNotify(i + 3, j + 8, k + 15, Block.stairsStoneBrick.blockID, 7);
		world.setBlock(i + 3, j + 9, k + 9, Block.stoneBrick.blockID);
		world.setBlock(i + 3, j + 9, k + 15, Block.stoneBrick.blockID);
		world.setBlock(i + 3, j + 10, k + 9, Block.stoneBrick.blockID);
		world.setBlock(i + 3, j + 10, k + 15, Block.stoneBrick.blockID);
		world.setBlockMetadataWithNotify(i + 3, j + 11, k + 8, Block.woodSingleSlab.blockID, 10);
		world.setBlock(i + 3, j + 11, k + 9, Block.stoneBrick.blockID);
		world.setBlock(i + 3, j + 11, k + 15, Block.stoneBrick.blockID);
		world.setBlockMetadataWithNotify(i + 3, j + 11, k + 16, Block.woodSingleSlab.blockID, 10);
		world.setBlockMetadataWithNotify(i + 3, j + 12, k + 9, Block.woodSingleSlab.blockID, 2);
		world.setBlockMetadataWithNotify(i + 3, j + 12, k + 10, Block.woodSingleSlab.blockID, 10);
		world.setBlockMetadataWithNotify(i + 3, j + 12, k + 14, Block.woodSingleSlab.blockID, 10);
		world.setBlockMetadataWithNotify(i + 3, j + 12, k + 15, Block.woodSingleSlab.blockID, 2);
		world.setBlockMetadataWithNotify(i + 3, j + 13, k + 11, Block.woodSingleSlab.blockID, 2);
		world.setBlockMetadataWithNotify(i + 3, j + 13, k + 12, Block.woodSingleSlab.blockID, 2);
		world.setBlockMetadataWithNotify(i + 3, j + 13, k + 13, Block.woodSingleSlab.blockID, 2);
		world.setBlock(i + 4, j + 0, k + 3, Block.stoneBrick.blockID);
		world.setBlock(i + 4, j + 0, k + 14, Block.stoneBrick.blockID);
		world.setBlock(i + 4, j + 1, k + 3, Block.stoneBrick.blockID);
		world.setBlock(i + 4, j + 1, k + 4, Block.stoneBrick.blockID);
		world.setBlock(i + 4, j + 1, k + 5, Block.stoneBrick.blockID);
		world.setBlock(i + 4, j + 1, k + 6, Block.stoneBrick.blockID);
		world.setBlock(i + 4, j + 1, k + 7, Block.stoneBrick.blockID);
		world.setBlock(i + 4, j + 1, k + 8, Block.stoneBrick.blockID);
		world.setBlock(i + 4, j + 1, k + 9, Block.stoneBrick.blockID);
		world.setBlock(i + 4, j + 1, k + 14, Block.stoneBrick.blockID);
		world.setBlock(i + 4, j + 2, k + 3, Block.stoneBrick.blockID);
		world.setBlock(i + 4, j + 2, k + 10, Block.stoneBrick.blockID);
		world.setBlock(i + 4, j + 2, k + 11, Block.stoneBrick.blockID);
		world.setBlock(i + 4, j + 2, k + 12, Block.stoneBrick.blockID);
		world.setBlock(i + 4, j + 2, k + 13, Block.stoneBrick.blockID);
		world.setBlock(i + 4, j + 2, k + 14, Block.stoneBrick.blockID);
		world.setBlock(i + 4, j + 3, k + 3, Block.fenceIron.blockID);
		world.setBlock(i + 4, j + 3, k + 10, Block.stoneBrick.blockID);
		world.setBlockMetadataWithNotify(i + 4, j + 3, k + 12, Block.blockNetherQuartz.blockID, 2);
		world.setBlockMetadataWithNotify(i + 4, j + 3, k + 13, Block.stoneSingleSlab.blockID, 11);
		world.setBlock(i + 4, j + 3, k + 14, Block.stoneBrick.blockID);
		world.setBlock(i + 4, j + 4, k + 10, Block.stoneBrick.blockID);
		world.setBlockMetadataWithNotify(i + 4, j + 4, k + 12, Block.blockNetherQuartz.blockID, 2);
		world.setBlock(i + 4, j + 4, k + 14, Block.stoneBrick.blockID);
		world.setBlock(i + 4, j + 5, k + 10, Block.stoneBrick.blockID);
		world.setBlockMetadataWithNotify(i + 4, j + 5, k + 11, Block.stoneSingleSlab.blockID, 11);
		world.setBlockMetadataWithNotify(i + 4, j + 5, k + 12, Block.blockNetherQuartz.blockID, 2);
		world.setBlock(i + 4, j + 5, k + 14, Block.glass.blockID);
		world.setBlock(i + 4, j + 6, k + 10, Block.stoneBrick.blockID);
		world.setBlockMetadataWithNotify(i + 4, j + 6, k + 12, Block.blockNetherQuartz.blockID, 2);
		world.setBlock(i + 4, j + 6, k + 14, Block.stoneBrick.blockID);
		world.setBlock(i + 4, j + 7, k + 10, Block.glass.blockID);
		world.setBlockMetadataWithNotify(i + 4, j + 7, k + 12, Block.blockNetherQuartz.blockID, 2);
		world.setBlockMetadataWithNotify(i + 4, j + 7, k + 13, Block.stoneSingleSlab.blockID, 11);
		world.setBlock(i + 4, j + 7, k + 14, Block.stoneBrick.blockID);
		world.setBlockMetadataWithNotify(i + 4, j + 8, k + 4, Block.stairsStoneBrick.blockID, 4);
		world.setBlockMetadataWithNotify(i + 4, j + 8, k + 5, Block.stairsStoneBrick.blockID, 4);
		world.setBlockMetadataWithNotify(i + 4, j + 8, k + 6, Block.stairsStoneBrick.blockID, 4);
		world.setBlockMetadataWithNotify(i + 4, j + 8, k + 7, Block.stairsStoneBrick.blockID, 4);
		world.setBlockMetadataWithNotify(i + 4, j + 8, k + 8, Block.stairsStoneBrick.blockID, 4);
		world.setBlockMetadataWithNotify(i + 4, j + 8, k + 9, Block.stairsStoneBrick.blockID, 4);
		world.setBlock(i + 4, j + 8, k + 10, Block.stoneBrick.blockID);
		world.setBlockMetadataWithNotify(i + 4, j + 8, k + 11, Block.stoneSingleSlab.blockID, 11);
		world.setBlockMetadataWithNotify(i + 4, j + 8, k + 12, Block.blockNetherQuartz.blockID, 2);
		world.setBlock(i + 4, j + 8, k + 14, Block.stoneBrick.blockID);
		world.setBlockMetadataWithNotify(i + 4, j + 8, k + 15, Block.stairsStoneBrick.blockID, 7);
		world.setBlock(i + 4, j + 9, k + 4, Block.fenceIron.blockID);
		world.setBlock(i + 4, j + 9, k + 5, Block.fenceIron.blockID);
		world.setBlock(i + 4, j + 9, k + 6, Block.fenceIron.blockID);
		world.setBlock(i + 4, j + 9, k + 7, Block.fenceIron.blockID);
		world.setBlock(i + 4, j + 9, k + 8, Block.fenceIron.blockID);
		world.setBlock(i + 4, j + 9, k + 9, Block.stoneBrick.blockID);
		world.setBlockMetadataWithNotify(i + 4, j + 9, k + 12, Block.blockNetherQuartz.blockID, 2);
		world.setBlock(i + 4, j + 9, k + 15, Block.stoneBrick.blockID);
		world.setBlock(i + 4, j + 10, k + 9, Block.glass.blockID);
		world.setBlockMetadataWithNotify(i + 4, j + 10, k + 12, Block.blockNetherQuartz.blockID, 2);
		world.setBlock(i + 4, j + 10, k + 15, Block.glass.blockID);
		world.setBlockMetadataWithNotify(i + 4, j + 11, k + 8, Block.woodSingleSlab.blockID, 10);
		world.setBlock(i + 4, j + 11, k + 9, Block.stoneBrick.blockID);
		world.setBlockMetadataWithNotify(i + 4, j + 11, k + 12, Block.blockNetherQuartz.blockID, 2);
		world.setBlock(i + 4, j + 11, k + 15, Block.stoneBrick.blockID);
		world.setBlockMetadataWithNotify(i + 4, j + 11, k + 16, Block.woodSingleSlab.blockID, 10);
		world.setBlockMetadataWithNotify(i + 4, j + 12, k + 9, Block.woodSingleSlab.blockID, 2);
		world.setBlockMetadataWithNotify(i + 4, j + 12, k + 10, Block.woodSingleSlab.blockID, 10);
		world.setBlockMetadataWithNotify(i + 4, j + 12, k + 12, Block.blockNetherQuartz.blockID, 2);
		world.setBlockMetadataWithNotify(i + 4, j + 12, k + 14, Block.woodSingleSlab.blockID, 10);
		world.setBlockMetadataWithNotify(i + 4, j + 12, k + 15, Block.woodSingleSlab.blockID, 2);
		world.setBlockMetadataWithNotify(i + 4, j + 13, k + 11, Block.woodSingleSlab.blockID, 2);
		world.setBlockMetadataWithNotify(i + 4, j + 13, k + 12, Block.woodDoubleSlab.blockID, 2);
		world.setBlockMetadataWithNotify(i + 4, j + 13, k + 13, Block.woodSingleSlab.blockID, 2);
		world.setBlock(i + 5, j + 0, k + 3, Block.stoneBrick.blockID);
		world.setBlock(i + 5, j + 0, k + 14, Block.stoneBrick.blockID);
		world.setBlock(i + 5, j + 1, k + 3, Block.stoneBrick.blockID);
		world.setBlock(i + 5, j + 1, k + 4, Block.stoneBrick.blockID);
		world.setBlock(i + 5, j + 1, k + 5, Block.stoneBrick.blockID);
		world.setBlock(i + 5, j + 1, k + 6, Block.stoneBrick.blockID);
		world.setBlock(i + 5, j + 1, k + 7, Block.stoneBrick.blockID);
		world.setBlock(i + 5, j + 1, k + 8, Block.stoneBrick.blockID);
		world.setBlock(i + 5, j + 1, k + 9, Block.stoneBrick.blockID);
		world.setBlock(i + 5, j + 1, k + 14, Block.stoneBrick.blockID);
		world.setBlock(i + 5, j + 2, k + 3, Block.stoneBrick.blockID);
		world.setBlock(i + 5, j + 2, k + 10, Block.stoneBrick.blockID);
		world.setBlock(i + 5, j + 2, k + 11, Block.stoneBrick.blockID);
		world.setBlock(i + 5, j + 2, k + 12, Block.stoneBrick.blockID);
		world.setBlock(i + 5, j + 2, k + 13, Block.stoneBrick.blockID);
		world.setBlock(i + 5, j + 2, k + 14, Block.stoneBrick.blockID);
		world.setBlock(i + 5, j + 3, k + 3, Block.fenceIron.blockID);
		world.setBlock(i + 5, j + 3, k + 10, Block.stoneBrick.blockID);
		world.setBlockMetadataWithNotify(i + 5, j + 3, k + 13, Block.stoneSingleSlab.blockID, 3);
		world.setBlock(i + 5, j + 3, k + 14, Block.stoneBrick.blockID);
		world.setBlock(i + 5, j + 4, k + 10, Block.stoneBrick.blockID);
		world.setBlock(i + 5, j + 4, k + 14, Block.stoneBrick.blockID);
		world.setBlock(i + 5, j + 5, k + 10, Block.stoneBrick.blockID);
		world.setBlock(i + 5, j + 5, k + 14, Block.stoneBrick.blockID);
		world.setBlock(i + 5, j + 6, k + 10, Block.stoneBrick.blockID);
		world.setBlockMetadataWithNotify(i + 5, j + 6, k + 11, Block.stoneSingleSlab.blockID, 3);
		world.setBlockMetadataWithNotify(i + 5, j + 6, k + 12, Block.stoneSingleSlab.blockID, 11);
		world.setBlock(i + 5, j + 6, k + 14, Block.stoneBrick.blockID);
		world.setBlockMetadataWithNotify(i + 5, j + 7, k + 5, Block.stoneSingleSlab.blockID, 13);
		world.setBlockMetadataWithNotify(i + 5, j + 7, k + 6, Block.stoneSingleSlab.blockID, 13);
		world.setBlockMetadataWithNotify(i + 5, j + 7, k + 7, Block.stoneSingleSlab.blockID, 13);
		world.setBlockMetadataWithNotify(i + 5, j + 7, k + 8, Block.stoneSingleSlab.blockID, 13);
		world.setBlockMetadataWithNotify(i + 5, j + 7, k + 9, Block.stoneSingleSlab.blockID, 13);
		world.setBlock(i + 5, j + 7, k + 10, Block.stoneBrick.blockID);
		world.setBlockMetadataWithNotify(i + 5, j + 7, k + 13, Block.stoneSingleSlab.blockID, 3);
		world.setBlock(i + 5, j + 7, k + 14, Block.stoneBrick.blockID);
		world.setBlockMetadataWithNotify(i + 5, j + 8, k + 4, Block.stairsStoneBrick.blockID, 6);
		world.setBlock(i + 5, j + 8, k + 5, Block.stoneBrick.blockID);
		world.setBlock(i + 5, j + 8, k + 6, Block.stoneBrick.blockID);
		world.setBlock(i + 5, j + 8, k + 7, Block.stoneBrick.blockID);
		world.setBlock(i + 5, j + 8, k + 8, Block.stoneBrick.blockID);
		world.setBlock(i + 5, j + 8, k + 9, Block.stoneBrick.blockID);
		world.setBlock(i + 5, j + 8, k + 10, Block.stoneBrick.blockID);
		world.setBlock(i + 5, j + 8, k + 14, Block.stoneBrick.blockID);
		world.setBlockMetadataWithNotify(i + 5, j + 8, k + 15, Block.stairsStoneBrick.blockID, 7);
		world.setBlock(i + 5, j + 9, k + 4, Block.fenceIron.blockID);
		world.setBlock(i + 5, j + 9, k + 9, Block.stoneBrick.blockID);
		world.setBlock(i + 5, j + 9, k + 15, Block.stoneBrick.blockID);
		world.setBlock(i + 5, j + 10, k + 9, Block.stoneBrick.blockID);
		world.setBlock(i + 5, j + 10, k + 15, Block.stoneBrick.blockID);
		world.setBlockMetadataWithNotify(i + 5, j + 11, k + 8, Block.woodSingleSlab.blockID, 10);
		world.setBlock(i + 5, j + 11, k + 9, Block.stoneBrick.blockID);
		world.setBlock(i + 5, j + 11, k + 15, Block.stoneBrick.blockID);
		world.setBlockMetadataWithNotify(i + 5, j + 11, k + 16, Block.woodSingleSlab.blockID, 10);
		world.setBlockMetadataWithNotify(i + 5, j + 12, k + 9, Block.woodSingleSlab.blockID, 2);
		world.setBlockMetadataWithNotify(i + 5, j + 12, k + 10, Block.woodSingleSlab.blockID, 10);
		world.setBlockMetadataWithNotify(i + 5, j + 12, k + 14, Block.woodSingleSlab.blockID, 10);
		world.setBlockMetadataWithNotify(i + 5, j + 12, k + 15, Block.woodSingleSlab.blockID, 2);
		world.setBlockMetadataWithNotify(i + 5, j + 13, k + 11, Block.woodSingleSlab.blockID, 2);
		world.setBlockMetadataWithNotify(i + 5, j + 13, k + 12, Block.woodSingleSlab.blockID, 2);
		world.setBlockMetadataWithNotify(i + 5, j + 13, k + 13, Block.woodSingleSlab.blockID, 2);
		world.setBlock(i + 6, j + 0, k + 3, Block.stoneBrick.blockID);
		world.setBlock(i + 6, j + 0, k + 14, Block.stoneBrick.blockID);
		world.setBlock(i + 6, j + 1, k + 3, Block.stoneBrick.blockID);
		world.setBlock(i + 6, j + 1, k + 14, Block.stoneBrick.blockID);
		world.setBlock(i + 6, j + 2, k + 3, Block.stoneBrick.blockID);
		world.setBlock(i + 6, j + 2, k + 4, Block.stoneBrick.blockID);
		world.setBlock(i + 6, j + 2, k + 5, Block.stoneBrick.blockID);
		world.setBlock(i + 6, j + 2, k + 6, Block.stoneBrick.blockID);
		world.setBlock(i + 6, j + 2, k + 7, Block.stoneBrick.blockID);
		world.setBlock(i + 6, j + 2, k + 8, Block.stoneBrick.blockID);
		world.setBlock(i + 6, j + 2, k + 9, Block.stoneBrick.blockID);
		world.setBlock(i + 6, j + 2, k + 10, Block.stoneBrick.blockID);
		world.setBlock(i + 6, j + 2, k + 11, Block.stoneBrick.blockID);
		world.setBlock(i + 6, j + 2, k + 12, Block.stoneBrick.blockID);
		world.setBlock(i + 6, j + 2, k + 13, Block.stoneBrick.blockID);
		world.setBlock(i + 6, j + 2, k + 14, Block.stoneBrick.blockID);
		world.setBlock(i + 6, j + 3, k + 3, Block.stoneBrick.blockID);
		world.setBlock(i + 6, j + 3, k + 4, Block.stoneBrick.blockID);
		world.setBlock(i + 6, j + 3, k + 5, Block.stoneBrick.blockID);
		world.setBlock(i + 6, j + 3, k + 7, Block.stoneBrick.blockID);
		world.setBlock(i + 6, j + 3, k + 8, Block.stoneBrick.blockID);
		world.setBlock(i + 6, j + 3, k + 9, Block.stoneBrick.blockID);
		world.setBlock(i + 6, j + 3, k + 10, Block.stoneBrick.blockID);
		world.setBlock(i + 6, j + 3, k + 11, Block.stoneBrick.blockID);
		world.setBlock(i + 6, j + 3, k + 13, Block.stoneBrick.blockID);
		world.setBlock(i + 6, j + 3, k + 14, Block.stoneBrick.blockID);
		world.setBlock(i + 6, j + 4, k + 3, Block.stoneBrick.blockID);
		world.setBlock(i + 6, j + 4, k + 4, Block.stoneBrick.blockID);
		world.setBlock(i + 6, j + 4, k + 5, Block.stoneBrick.blockID);
		world.setBlock(i + 6, j + 4, k + 7, Block.stoneBrick.blockID);
		world.setBlock(i + 6, j + 4, k + 8, Block.glass.blockID);
		world.setBlock(i + 6, j + 4, k + 9, Block.stoneBrick.blockID);
		world.setBlock(i + 6, j + 4, k + 10, Block.stoneBrick.blockID);
		world.setBlock(i + 6, j + 4, k + 11, Block.stoneBrick.blockID);
		world.setBlock(i + 6, j + 4, k + 13, Block.stoneBrick.blockID);
		world.setBlock(i + 6, j + 4, k + 14, Block.stoneBrick.blockID);
		world.setBlock(i + 6, j + 5, k + 3, Block.stoneBrick.blockID);
		world.setBlock(i + 6, j + 5, k + 4, Block.stoneBrick.blockID);
		world.setBlock(i + 6, j + 5, k + 5, Block.stoneBrick.blockID);
		world.setBlock(i + 6, j + 5, k + 6, Block.stoneBrick.blockID);
		world.setBlock(i + 6, j + 5, k + 7, Block.stoneBrick.blockID);
		world.setBlock(i + 6, j + 5, k + 8, Block.stoneBrick.blockID);
		world.setBlock(i + 6, j + 5, k + 9, Block.stoneBrick.blockID);
		world.setBlock(i + 6, j + 5, k + 10, Block.stoneBrick.blockID);
		world.setBlock(i + 6, j + 5, k + 11, Block.stoneBrick.blockID);
		world.setBlock(i + 6, j + 5, k + 12, Block.stoneBrick.blockID);
		world.setBlock(i + 6, j + 5, k + 13, Block.stoneBrick.blockID);
		world.setBlock(i + 6, j + 5, k + 14, Block.stoneBrick.blockID);
		world.setBlock(i + 6, j + 6, k + 3, Block.stoneBrick.blockID);
		world.setBlock(i + 6, j + 6, k + 4, Block.stoneBrick.blockID);
		world.setBlock(i + 6, j + 6, k + 5, Block.stoneBrick.blockID);
		world.setBlock(i + 6, j + 6, k + 6, Block.stoneBrick.blockID);
		world.setBlock(i + 6, j + 6, k + 7, Block.stoneBrick.blockID);
		world.setBlock(i + 6, j + 6, k + 8, Block.stoneBrick.blockID);
		world.setBlock(i + 6, j + 6, k + 9, Block.stoneBrick.blockID);
		world.setBlock(i + 6, j + 6, k + 10, Block.stoneBrick.blockID);
		world.setBlock(i + 6, j + 6, k + 11, Block.stoneBrick.blockID);
		world.setBlock(i + 6, j + 6, k + 12, Block.stoneBrick.blockID);
		world.setBlock(i + 6, j + 6, k + 13, Block.stoneBrick.blockID);
		world.setBlock(i + 6, j + 6, k + 14, Block.stoneBrick.blockID);
		world.setBlock(i + 6, j + 7, k + 3, Block.stoneBrick.blockID);
		world.setBlock(i + 6, j + 7, k + 4, Block.stoneBrick.blockID);
		world.setBlock(i + 6, j + 7, k + 5, Block.stoneBrick.blockID);
		world.setBlock(i + 6, j + 7, k + 6, Block.stoneBrick.blockID);
		world.setBlock(i + 6, j + 7, k + 7, Block.stoneBrick.blockID);
		world.setBlock(i + 6, j + 7, k + 8, Block.stoneBrick.blockID);
		world.setBlock(i + 6, j + 7, k + 9, Block.stoneBrick.blockID);
		world.setBlock(i + 6, j + 7, k + 10, Block.stoneBrick.blockID);
		world.setBlock(i + 6, j + 7, k + 11, Block.stoneBrick.blockID);
		world.setBlock(i + 6, j + 7, k + 12, Block.stoneBrick.blockID);
		world.setBlock(i + 6, j + 7, k + 13, Block.stoneBrick.blockID);
		world.setBlock(i + 6, j + 7, k + 14, Block.stoneBrick.blockID);
		world.setBlock(i + 6, j + 8, k + 3, Block.stoneBrick.blockID);
		world.setBlock(i + 6, j + 8, k + 4, Block.stoneBrick.blockID);
		world.setBlock(i + 6, j + 8, k + 5, Block.stoneBrick.blockID);
		world.setBlock(i + 6, j + 8, k + 6, Block.stoneBrick.blockID);
		world.setBlock(i + 6, j + 8, k + 7, Block.stoneBrick.blockID);
		world.setBlock(i + 6, j + 8, k + 8, Block.stoneBrick.blockID);
		world.setBlock(i + 6, j + 8, k + 9, Block.stoneBrick.blockID);
		world.setBlock(i + 6, j + 8, k + 10, Block.stoneBrick.blockID);
		world.setBlock(i + 6, j + 8, k + 11, Block.stoneBrick.blockID);
		world.setBlock(i + 6, j + 8, k + 12, Block.stoneBrick.blockID);
		world.setBlock(i + 6, j + 8, k + 13, Block.stoneBrick.blockID);
		world.setBlock(i + 6, j + 8, k + 14, Block.stoneBrick.blockID);
		world.setBlockMetadataWithNotify(i + 6, j + 8, k + 15, Block.stairsStoneBrick.blockID, 7);
		world.setBlock(i + 6, j + 9, k + 3, Block.stoneBrick.blockID);
		world.setBlock(i + 6, j + 9, k + 4, Block.stoneBrick.blockID);
		world.setBlock(i + 6, j + 9, k + 5, Block.stoneBrick.blockID);
		world.setBlock(i + 6, j + 9, k + 6, Block.stoneBrick.blockID);
		world.setBlock(i + 6, j + 9, k + 7, Block.stoneBrick.blockID);
		world.setBlock(i + 6, j + 9, k + 8, Block.stoneBrick.blockID);
		world.setBlock(i + 6, j + 9, k + 9, Block.stoneBrick.blockID);
		world.setBlock(i + 6, j + 9, k + 15, Block.stoneBrick.blockID);
		world.setBlock(i + 6, j + 10, k + 3, Block.stoneBrick.blockID);
		world.setBlock(i + 6, j + 10, k + 4, Block.stoneBrick.blockID);
		world.setBlock(i + 6, j + 10, k + 5, Block.glass.blockID);
		world.setBlock(i + 6, j + 10, k + 6, Block.stoneBrick.blockID);
		world.setBlock(i + 6, j + 10, k + 7, Block.glass.blockID);
		world.setBlock(i + 6, j + 10, k + 8, Block.stoneBrick.blockID);
		world.setBlock(i + 6, j + 10, k + 9, Block.stoneBrick.blockID);
		world.setBlock(i + 6, j + 10, k + 15, Block.stoneBrick.blockID);
		world.setBlock(i + 6, j + 11, k + 3, Block.stoneBrick.blockID);
		world.setBlock(i + 6, j + 11, k + 4, Block.stoneBrick.blockID);
		world.setBlock(i + 6, j + 11, k + 5, Block.stoneBrick.blockID);
		world.setBlock(i + 6, j + 11, k + 6, Block.stoneBrick.blockID);
		world.setBlock(i + 6, j + 11, k + 7, Block.stoneBrick.blockID);
		world.setBlock(i + 6, j + 11, k + 8, Block.stoneBrick.blockID);
		world.setBlock(i + 6, j + 11, k + 9, Block.stoneBrick.blockID);
		world.setBlock(i + 6, j + 11, k + 15, Block.stoneBrick.blockID);
		world.setBlockMetadataWithNotify(i + 6, j + 11, k + 16, Block.woodSingleSlab.blockID, 10);
		world.setBlock(i + 6, j + 12, k + 3, Block.stoneBrick.blockID);
		world.setBlock(i + 6, j + 12, k + 4, Block.stoneBrick.blockID);
		world.setBlock(i + 6, j + 12, k + 5, Block.stoneBrick.blockID);
		world.setBlock(i + 6, j + 12, k + 6, Block.stoneBrick.blockID);
		world.setBlock(i + 6, j + 12, k + 7, Block.stoneBrick.blockID);
		world.setBlock(i + 6, j + 12, k + 8, Block.stoneBrick.blockID);
		world.setBlock(i + 6, j + 12, k + 9, Block.stoneBrick.blockID);
		world.setBlockMetadataWithNotify(i + 6, j + 12, k + 10, Block.woodSingleSlab.blockID, 10);
		world.setBlockMetadataWithNotify(i + 6, j + 12, k + 11, Block.woodSingleSlab.blockID, 10);
		world.setBlockMetadataWithNotify(i + 6, j + 12, k + 12, Block.woodSingleSlab.blockID, 10);
		world.setBlockMetadataWithNotify(i + 6, j + 12, k + 13, Block.woodSingleSlab.blockID, 10);
		world.setBlockMetadataWithNotify(i + 6, j + 12, k + 14, Block.woodSingleSlab.blockID, 10);
		world.setBlockMetadataWithNotify(i + 6, j + 12, k + 15, Block.woodDoubleSlab.blockID, 2);
		world.setBlockMetadataWithNotify(i + 6, j + 12, k + 16, Block.woodSingleSlab.blockID, 10);
		world.setBlock(i + 6, j + 13, k + 3, Block.stoneBrick.blockID);
		world.setBlock(i + 6, j + 13, k + 4, Block.stoneBrick.blockID);
		world.setBlock(i + 6, j + 13, k + 5, Block.stoneBrick.blockID);
		world.setBlock(i + 6, j + 13, k + 6, Block.stoneBrick.blockID);
		world.setBlock(i + 6, j + 13, k + 7, Block.stoneBrick.blockID);
		world.setBlock(i + 6, j + 13, k + 8, Block.stoneBrick.blockID);
		world.setBlock(i + 6, j + 13, k + 9, Block.stoneBrick.blockID);
		world.setBlock(i + 6, j + 13, k + 10, Block.stoneBrick.blockID);
		world.setBlock(i + 6, j + 14, k + 3, Block.stoneBrick.blockID);
		world.setBlock(i + 6, j + 14, k + 4, Block.stoneBrick.blockID);
		world.setBlock(i + 6, j + 14, k + 5, Block.stoneBrick.blockID);
		world.setBlock(i + 6, j + 14, k + 6, Block.stoneBrick.blockID);
		world.setBlock(i + 6, j + 14, k + 7, Block.stoneBrick.blockID);
		world.setBlock(i + 6, j + 14, k + 8, Block.stoneBrick.blockID);
		world.setBlock(i + 6, j + 14, k + 9, Block.stoneBrick.blockID);
		world.setBlock(i + 6, j + 14, k + 10, Block.stoneBrick.blockID);
		world.setBlockMetadataWithNotify(i + 6, j + 15, k + 3, Block.stairsStoneBrick.blockID, 2);
		world.setBlock(i + 6, j + 15, k + 4, Block.stoneBrick.blockID);
		world.setBlock(i + 6, j + 15, k + 5, Block.stoneBrick.blockID);
		world.setBlock(i + 6, j + 15, k + 6, Block.stoneBrick.blockID);
		world.setBlock(i + 6, j + 15, k + 7, Block.glass.blockID);
		world.setBlock(i + 6, j + 15, k + 8, Block.stoneBrick.blockID);
		world.setBlock(i + 6, j + 15, k + 9, Block.stoneBrick.blockID);
		world.setBlockMetadataWithNotify(i + 6, j + 15, k + 10, Block.stairsStoneBrick.blockID, 3);
		world.setBlock(i + 6, j + 16, k + 4, Block.stoneBrick.blockID);
		world.setBlock(i + 6, j + 16, k + 5, Block.stoneBrick.blockID);
		world.setBlock(i + 6, j + 16, k + 6, Block.stoneBrick.blockID);
		world.setBlock(i + 6, j + 16, k + 7, Block.stoneBrick.blockID);
		world.setBlock(i + 6, j + 16, k + 8, Block.stoneBrick.blockID);
		world.setBlock(i + 6, j + 16, k + 9, Block.stoneBrick.blockID);
		world.setBlock(i + 6, j + 17, k + 4, Block.stoneBrick.blockID);
		world.setBlock(i + 6, j + 17, k + 5, Block.stoneBrick.blockID);
		world.setBlock(i + 6, j + 17, k + 6, Block.stoneBrick.blockID);
		world.setBlock(i + 6, j + 17, k + 7, Block.stoneBrick.blockID);
		world.setBlock(i + 6, j + 17, k + 8, Block.stoneBrick.blockID);
		world.setBlock(i + 6, j + 17, k + 9, Block.stoneBrick.blockID);
		world.setBlock(i + 6, j + 18, k + 4, Block.stairsStoneBrick.blockID);
		world.setBlock(i + 6, j + 18, k + 5, Block.stairsStoneBrick.blockID);
		world.setBlock(i + 6, j + 18, k + 6, Block.stairsStoneBrick.blockID);
		world.setBlock(i + 6, j + 18, k + 7, Block.stairsStoneBrick.blockID);
		world.setBlock(i + 6, j + 18, k + 8, Block.stairsStoneBrick.blockID);
		world.setBlock(i + 6, j + 18, k + 9, Block.stairsStoneBrick.blockID);
		world.setBlockMetadataWithNotify(i + 6, j + 27, k + 4, Block.woodSingleSlab.blockID, 10);
		world.setBlockMetadataWithNotify(i + 6, j + 27, k + 5, Block.woodSingleSlab.blockID, 10);
		world.setBlockMetadataWithNotify(i + 6, j + 27, k + 6, Block.woodSingleSlab.blockID, 10);
		world.setBlockMetadataWithNotify(i + 6, j + 27, k + 7, Block.woodSingleSlab.blockID, 10);
		world.setBlockMetadataWithNotify(i + 6, j + 27, k + 8, Block.woodSingleSlab.blockID, 10);
		world.setBlockMetadataWithNotify(i + 6, j + 27, k + 9, Block.woodSingleSlab.blockID, 10);
		world.setBlockMetadataWithNotify(i + 6, j + 27, k + 10, Block.woodSingleSlab.blockID, 10);
		world.setBlock(i + 7, j + 0, k + 3, Block.stoneBrick.blockID);
		world.setBlock(i + 7, j + 0, k + 15, Block.stoneBrick.blockID);
		world.setBlock(i + 7, j + 1, k + 3, Block.stoneBrick.blockID);
		world.setBlock(i + 7, j + 1, k + 15, Block.stoneBrick.blockID);
		world.setBlock(i + 7, j + 2, k + 3, Block.stoneBrick.blockID);
		world.setBlock(i + 7, j + 2, k + 4, Block.stoneBrick.blockID);
		world.setBlock(i + 7, j + 2, k + 5, Block.stoneBrick.blockID);
		world.setBlock(i + 7, j + 2, k + 6, Block.stoneBrick.blockID);
		world.setBlock(i + 7, j + 2, k + 7, Block.stoneBrick.blockID);
		world.setBlock(i + 7, j + 2, k + 8, Block.stoneBrick.blockID);
		world.setBlock(i + 7, j + 2, k + 9, Block.stoneBrick.blockID);
		world.setBlock(i + 7, j + 2, k + 10, Block.stoneBrick.blockID);
		world.setBlock(i + 7, j + 2, k + 11, Block.stoneBrick.blockID);
		world.setBlock(i + 7, j + 2, k + 12, Block.stoneBrick.blockID);
		world.setBlock(i + 7, j + 2, k + 13, Block.stoneBrick.blockID);
		world.setBlock(i + 7, j + 2, k + 14, Block.stoneBrick.blockID);
		world.setBlock(i + 7, j + 2, k + 15, Block.stoneBrick.blockID);
		world.setBlock(i + 7, j + 3, k + 3, Block.stoneBrick.blockID);
		world.setBlock(i + 7, j + 3, k + 15, Block.stoneBrick.blockID);
		world.setBlock(i + 7, j + 4, k + 3, Block.stoneBrick.blockID);
		world.setBlock(i + 7, j + 4, k + 15, Block.stoneBrick.blockID);
		world.setBlock(i + 7, j + 5, k + 3, Block.stoneBrick.blockID);
		world.setBlockMetadataWithNotify(i + 7, j + 5, k + 4, Block.stairsStoneBrick.blockID, 5);
		world.setBlockMetadataWithNotify(i + 7, j + 5, k + 5, Block.stairsStoneBrick.blockID, 5);
		world.setBlockMetadataWithNotify(i + 7, j + 5, k + 6, Block.stairsStoneBrick.blockID, 5);
		world.setBlockMetadataWithNotify(i + 7, j + 5, k + 7, Block.stairsStoneBrick.blockID, 5);
		world.setBlockMetadataWithNotify(i + 7, j + 5, k + 8, Block.stairsStoneBrick.blockID, 5);
		world.setBlockMetadataWithNotify(i + 7, j + 5, k + 9, Block.stairsStoneBrick.blockID, 5);
		world.setBlockMetadataWithNotify(i + 7, j + 5, k + 10, Block.stairsStoneBrick.blockID, 5);
		world.setBlockMetadataWithNotify(i + 7, j + 5, k + 11, Block.stairsStoneBrick.blockID, 5);
		world.setBlockMetadataWithNotify(i + 7, j + 5, k + 12, Block.stairsStoneBrick.blockID, 5);
		world.setBlockMetadataWithNotify(i + 7, j + 5, k + 13, Block.stairsStoneBrick.blockID, 5);
		world.setBlockMetadataWithNotify(i + 7, j + 5, k + 14, Block.stairsStoneBrick.blockID, 5);
		world.setBlock(i + 7, j + 5, k + 15, Block.stoneBrick.blockID);
		world.setBlock(i + 7, j + 6, k + 3, Block.stoneBrick.blockID);
		world.setBlock(i + 7, j + 6, k + 4, Block.stoneBrick.blockID);
		world.setBlock(i + 7, j + 6, k + 5, Block.stoneBrick.blockID);
		world.setBlock(i + 7, j + 6, k + 6, Block.stoneBrick.blockID);
		world.setBlock(i + 7, j + 6, k + 7, Block.stoneBrick.blockID);
		world.setBlock(i + 7, j + 6, k + 8, Block.stoneBrick.blockID);
		world.setBlock(i + 7, j + 6, k + 9, Block.stoneBrick.blockID);
		world.setBlock(i + 7, j + 6, k + 10, Block.stoneBrick.blockID);
		world.setBlock(i + 7, j + 6, k + 11, Block.stoneBrick.blockID);
		world.setBlock(i + 7, j + 6, k + 12, Block.stoneBrick.blockID);
		world.setBlock(i + 7, j + 6, k + 13, Block.stoneBrick.blockID);
		world.setBlock(i + 7, j + 6, k + 14, Block.stoneBrick.blockID);
		world.setBlock(i + 7, j + 6, k + 15, Block.stoneBrick.blockID);
		world.setBlock(i + 7, j + 7, k + 3, Block.stoneBrick.blockID);
		world.setBlock(i + 7, j + 7, k + 4, Block.stoneBrick.blockID);
		world.setBlock(i + 7, j + 7, k + 5, Block.stoneBrick.blockID);
		world.setBlock(i + 7, j + 7, k + 6, Block.stoneBrick.blockID);
		world.setBlock(i + 7, j + 7, k + 7, Block.stoneBrick.blockID);
		world.setBlock(i + 7, j + 7, k + 8, Block.stoneBrick.blockID);
		world.setBlock(i + 7, j + 7, k + 9, Block.stoneBrick.blockID);
		world.setBlock(i + 7, j + 7, k + 10, Block.stoneBrick.blockID);
		world.setBlock(i + 7, j + 7, k + 11, Block.stoneBrick.blockID);
		world.setBlock(i + 7, j + 7, k + 12, Block.stoneBrick.blockID);
		world.setBlock(i + 7, j + 7, k + 13, Block.stoneBrick.blockID);
		world.setBlock(i + 7, j + 7, k + 14, Block.stoneBrick.blockID);
		world.setBlock(i + 7, j + 7, k + 15, Block.stoneBrick.blockID);
		world.setBlock(i + 7, j + 8, k + 3, Block.stoneBrick.blockID);
		world.setBlock(i + 7, j + 8, k + 4, Block.stoneBrick.blockID);
		world.setBlock(i + 7, j + 8, k + 5, Block.stoneBrick.blockID);
		world.setBlock(i + 7, j + 8, k + 6, Block.stoneBrick.blockID);
		world.setBlock(i + 7, j + 8, k + 7, Block.stoneBrick.blockID);
		world.setBlock(i + 7, j + 8, k + 8, Block.stoneBrick.blockID);
		world.setBlock(i + 7, j + 8, k + 9, Block.stoneBrick.blockID);
		world.setBlock(i + 7, j + 8, k + 10, Block.stoneBrick.blockID);
		world.setBlock(i + 7, j + 8, k + 11, Block.stoneBrick.blockID);
		world.setBlock(i + 7, j + 8, k + 12, Block.stoneBrick.blockID);
		world.setBlock(i + 7, j + 8, k + 13, Block.stoneBrick.blockID);
		world.setBlock(i + 7, j + 8, k + 14, Block.stoneBrick.blockID);
		world.setBlock(i + 7, j + 8, k + 15, Block.stoneBrick.blockID);
		world.setBlock(i + 7, j + 9, k + 3, Block.stoneBrick.blockID);
		world.setBlockMetadataWithNotify(i + 7, j + 9, k + 7, Block.stoneSingleSlab.blockID, 11);
		world.setBlock(i + 7, j + 9, k + 10, Block.stoneBrick.blockID);
		world.setBlock(i + 7, j + 9, k + 11, Block.stoneBrick.blockID);
		world.setBlock(i + 7, j + 9, k + 13, Block.stoneBrick.blockID);
		world.setBlock(i + 7, j + 9, k + 14, Block.stoneBrick.blockID);
		world.setBlock(i + 7, j + 9, k + 15, Block.stoneBrick.blockID);
		world.setBlock(i + 7, j + 10, k + 3, Block.stoneBrick.blockID);
		world.setBlockMetadataWithNotify(i + 7, j + 10, k + 5, Block.stoneSingleSlab.blockID, 11);
		world.setBlockMetadataWithNotify(i + 7, j + 10, k + 6, Block.stoneSingleSlab.blockID, 3);
		world.setBlock(i + 7, j + 10, k + 10, Block.stoneBrick.blockID);
		world.setBlock(i + 7, j + 10, k + 11, Block.stoneBrick.blockID);
		world.setBlock(i + 7, j + 10, k + 13, Block.stoneBrick.blockID);
		world.setBlock(i + 7, j + 10, k + 14, Block.stoneBrick.blockID);
		world.setBlock(i + 7, j + 10, k + 15, Block.stoneBrick.blockID);
		world.setBlock(i + 7, j + 11, k + 3, Block.stoneBrick.blockID);
		world.setBlock(i + 7, j + 11, k + 10, Block.stoneBrick.blockID);
		world.setBlock(i + 7, j + 11, k + 11, Block.stoneBrick.blockID);
		world.setBlock(i + 7, j + 11, k + 12, Block.stoneBrick.blockID);
		world.setBlock(i + 7, j + 11, k + 13, Block.stoneBrick.blockID);
		world.setBlock(i + 7, j + 11, k + 14, Block.stoneBrick.blockID);
		world.setBlock(i + 7, j + 11, k + 15, Block.stoneBrick.blockID);
		world.setBlockMetadataWithNotify(i + 7, j + 11, k + 16, Block.woodSingleSlab.blockID, 10);
		world.setBlock(i + 7, j + 12, k + 3, Block.stoneBrick.blockID);
		world.setBlock(i + 7, j + 12, k + 10, Block.stoneBrick.blockID);
		world.setBlock(i + 7, j + 12, k + 11, Block.stoneBrick.blockID);
		world.setBlock(i + 7, j + 12, k + 12, Block.stoneBrick.blockID);
		world.setBlock(i + 7, j + 12, k + 13, Block.stoneBrick.blockID);
		world.setBlock(i + 7, j + 12, k + 14, Block.stoneBrick.blockID);
		world.setBlock(i + 7, j + 12, k + 15, Block.stoneBrick.blockID);
		world.setBlockMetadataWithNotify(i + 7, j + 12, k + 16, Block.woodSingleSlab.blockID, 10);
		world.setBlock(i + 7, j + 13, k + 3, Block.stoneBrick.blockID);
		world.setBlockMetadataWithNotify(i + 7, j + 13, k + 7, Block.stoneSingleSlab.blockID, 11);
		world.setBlock(i + 7, j + 13, k + 10, Block.stoneBrick.blockID);
		world.setBlockMetadataWithNotify(i + 7, j + 13, k + 11, Block.woodSingleSlab.blockID, 2);
		world.setBlockMetadataWithNotify(i + 7, j + 13, k + 12, Block.woodSingleSlab.blockID, 2);
		world.setBlockMetadataWithNotify(i + 7, j + 13, k + 13, Block.woodSingleSlab.blockID, 2);
		world.setBlockMetadataWithNotify(i + 7, j + 13, k + 14, Block.woodSingleSlab.blockID, 2);
		world.setBlockMetadataWithNotify(i + 7, j + 13, k + 15, Block.woodSingleSlab.blockID, 2);
		world.setBlock(i + 7, j + 14, k + 3, Block.stoneBrick.blockID);
		world.setBlockMetadataWithNotify(i + 7, j + 14, k + 4, Block.stairsStoneBrick.blockID, 7);
		world.setBlockMetadataWithNotify(i + 7, j + 14, k + 5, Block.stoneSingleSlab.blockID, 11);
		world.setBlockMetadataWithNotify(i + 7, j + 14, k + 6, Block.stoneSingleSlab.blockID, 3);
		world.setBlockMetadataWithNotify(i + 7, j + 14, k + 9, Block.stairsStoneBrick.blockID, 6);
		world.setBlock(i + 7, j + 14, k + 10, Block.stoneBrick.blockID);
		world.setBlockMetadataWithNotify(i + 7, j + 15, k + 3, Block.stairsStoneBrick.blockID, 2);
		world.setBlock(i + 7, j + 15, k + 4, Block.stoneBrick.blockID);
		world.setBlock(i + 7, j + 15, k + 9, Block.stoneBrick.blockID);
		world.setBlockMetadataWithNotify(i + 7, j + 15, k + 10, Block.stairsStoneBrick.blockID, 3);
		world.setBlock(i + 7, j + 16, k + 4, Block.stoneBrick.blockID);
		world.setBlock(i + 7, j + 16, k + 9, Block.stoneBrick.blockID);
		world.setBlock(i + 7, j + 17, k + 4, Block.stoneBrick.blockID);
		world.setBlock(i + 7, j + 17, k + 9, Block.stoneBrick.blockID);
		world.setBlock(i + 7, j + 18, k + 4, Block.stoneBrick.blockID);
		world.setBlock(i + 7, j + 18, k + 5, Block.stoneBrick.blockID);
		world.setBlock(i + 7, j + 18, k + 6, Block.stoneBrick.blockID);
		world.setBlock(i + 7, j + 18, k + 7, Block.stoneBrick.blockID);
		world.setBlock(i + 7, j + 18, k + 8, Block.stoneBrick.blockID);
		world.setBlock(i + 7, j + 18, k + 9, Block.stoneBrick.blockID);
		world.setBlock(i + 7, j + 19, k + 4, Block.stoneBrick.blockID);
		world.setBlock(i + 7, j + 19, k + 5, Block.stoneBrick.blockID);
		world.setBlock(i + 7, j + 19, k + 6, Block.stoneBrick.blockID);
		world.setBlock(i + 7, j + 19, k + 7, Block.stoneBrick.blockID);
		world.setBlock(i + 7, j + 19, k + 8, Block.stoneBrick.blockID);
		world.setBlock(i + 7, j + 19, k + 9, Block.stoneBrick.blockID);
		world.setBlock(i + 7, j + 20, k + 4, Block.stoneBrick.blockID);
		world.setBlock(i + 7, j + 20, k + 5, Block.stoneBrick.blockID);
		world.setBlock(i + 7, j + 20, k + 6, Block.stoneBrick.blockID);
		world.setBlock(i + 7, j + 20, k + 7, Block.stoneBrick.blockID);
		world.setBlock(i + 7, j + 20, k + 8, Block.stoneBrick.blockID);
		world.setBlock(i + 7, j + 20, k + 9, Block.stoneBrick.blockID);
		world.setBlock(i + 7, j + 21, k + 4, Block.stairsStoneBrick.blockID);
		world.setBlock(i + 7, j + 21, k + 5, Block.stairsStoneBrick.blockID);
		world.setBlock(i + 7, j + 21, k + 6, Block.stairsStoneBrick.blockID);
		world.setBlock(i + 7, j + 21, k + 7, Block.stairsStoneBrick.blockID);
		world.setBlock(i + 7, j + 21, k + 8, Block.stairsStoneBrick.blockID);
		world.setBlock(i + 7, j + 21, k + 9, Block.stairsStoneBrick.blockID);
		world.setBlockMetadataWithNotify(i + 7, j + 24, k + 5, Block.stairsStoneBrick.blockID, 6);
		world.setBlockMetadataWithNotify(i + 7, j + 24, k + 6, Block.stairsStoneBrick.blockID, 4);
		world.setBlockMetadataWithNotify(i + 7, j + 24, k + 7, Block.stairsStoneBrick.blockID, 4);
		world.setBlockMetadataWithNotify(i + 7, j + 24, k + 8, Block.stairsStoneBrick.blockID, 4);
		world.setBlockMetadataWithNotify(i + 7, j + 24, k + 9, Block.stairsStoneBrick.blockID, 7);
		world.setBlock(i + 7, j + 25, k + 5, Block.stoneBrick.blockID);
		world.setBlock(i + 7, j + 25, k + 6, Block.stoneBrick.blockID);
		world.setBlock(i + 7, j + 25, k + 7, Block.stoneBrick.blockID);
		world.setBlock(i + 7, j + 25, k + 8, Block.stoneBrick.blockID);
		world.setBlock(i + 7, j + 25, k + 9, Block.stoneBrick.blockID);
		world.setBlock(i + 7, j + 26, k + 5, Block.stoneBrick.blockID);
		world.setBlock(i + 7, j + 26, k + 6, Block.stoneBrick.blockID);
		world.setBlock(i + 7, j + 26, k + 7, Block.glass.blockID);
		world.setBlock(i + 7, j + 26, k + 8, Block.stoneBrick.blockID);
		world.setBlock(i + 7, j + 26, k + 9, Block.stoneBrick.blockID);
		world.setBlockMetadataWithNotify(i + 7, j + 27, k + 3, Block.woodSingleSlab.blockID, 10);
		world.setBlockMetadataWithNotify(i + 7, j + 27, k + 4, Block.woodSingleSlab.blockID, 10);
		world.setBlock(i + 7, j + 27, k + 5, Block.stoneBrick.blockID);
		world.setBlock(i + 7, j + 27, k + 6, Block.stoneBrick.blockID);
		world.setBlock(i + 7, j + 27, k + 7, Block.stoneBrick.blockID);
		world.setBlock(i + 7, j + 27, k + 8, Block.stoneBrick.blockID);
		world.setBlock(i + 7, j + 27, k + 9, Block.stoneBrick.blockID);
		world.setBlockMetadataWithNotify(i + 7, j + 27, k + 10, Block.woodSingleSlab.blockID, 10);
		world.setBlockMetadataWithNotify(i + 7, j + 27, k + 11, Block.woodSingleSlab.blockID, 10);
		world.setBlockMetadataWithNotify(i + 7, j + 28, k + 5, Block.woodSingleSlab.blockID, 2);
		world.setBlockMetadataWithNotify(i + 7, j + 28, k + 6, Block.woodSingleSlab.blockID, 2);
		world.setBlockMetadataWithNotify(i + 7, j + 28, k + 7, Block.woodSingleSlab.blockID, 2);
		world.setBlockMetadataWithNotify(i + 7, j + 28, k + 8, Block.woodSingleSlab.blockID, 2);
		world.setBlockMetadataWithNotify(i + 7, j + 28, k + 9, Block.woodSingleSlab.blockID, 2);
		world.setBlock(i + 8, j + 0, k + 3, Block.stoneBrick.blockID);
		world.setBlock(i + 8, j + 0, k + 15, Block.stoneBrick.blockID);
		world.setBlockMetadataWithNotify(i + 8, j + 0, k + 17, Block.blockNetherQuartz.blockID, 2);
		world.setBlock(i + 8, j + 1, k + 3, Block.stoneBrick.blockID);
		world.setBlock(i + 8, j + 1, k + 15, Block.stoneBrick.blockID);
		world.setBlockMetadataWithNotify(i + 8, j + 1, k + 17, Block.blockNetherQuartz.blockID, 2);
		world.setBlockMetadataWithNotify(i + 8, j + 2, k + 1, Block.stairsStoneBrick.blockID, 6);
		world.setBlockMetadataWithNotify(i + 8, j + 2, k + 2, Block.stairsStoneBrick.blockID, 4);
		world.setBlock(i + 8, j + 2, k + 3, Block.stoneBrick.blockID);
		world.setBlock(i + 8, j + 2, k + 4, Block.stoneBrick.blockID);
		world.setBlock(i + 8, j + 2, k + 5, Block.stoneBrick.blockID);
		world.setBlock(i + 8, j + 2, k + 6, Block.stoneBrick.blockID);
		world.setBlock(i + 8, j + 2, k + 7, Block.stoneBrick.blockID);
		world.setBlock(i + 8, j + 2, k + 8, Block.stoneBrick.blockID);
		world.setBlock(i + 8, j + 2, k + 9, Block.stoneBrick.blockID);
		world.setBlock(i + 8, j + 2, k + 10, Block.stoneBrick.blockID);
		world.setBlock(i + 8, j + 2, k + 11, Block.stoneBrick.blockID);
		world.setBlock(i + 8, j + 2, k + 12, Block.stoneBrick.blockID);
		world.setBlock(i + 8, j + 2, k + 13, Block.stoneBrick.blockID);
		world.setBlock(i + 8, j + 2, k + 14, Block.stoneBrick.blockID);
		world.setBlock(i + 8, j + 2, k + 15, Block.stoneBrick.blockID);
		world.setBlock(i + 8, j + 2, k + 17, Block.glowStone.blockID);
		world.setBlock(i + 8, j + 3, k + 1, Block.fenceIron.blockID);
		world.setBlock(i + 8, j + 3, k + 2, Block.fenceIron.blockID);
		world.setBlock(i + 8, j + 3, k + 3, Block.stoneBrick.blockID);
		world.setBlockMetadataWithNotify(i + 8, j + 3, k + 5, Block.blockNetherQuartz.blockID, 2);
		world.setBlockMetadataWithNotify(i + 8, j + 3, k + 7, Block.blockNetherQuartz.blockID, 2);
		world.setBlockMetadataWithNotify(i + 8, j + 3, k + 9, Block.blockNetherQuartz.blockID, 2);
		world.setBlockMetadataWithNotify(i + 8, j + 3, k + 11, Block.blockNetherQuartz.blockID, 2);
		world.setBlockMetadataWithNotify(i + 8, j + 3, k + 13, Block.blockNetherQuartz.blockID, 2);
		world.setBlock(i + 8, j + 3, k + 15, Block.stoneBrick.blockID);
		world.setBlockMetadataWithNotify(i + 8, j + 3, k + 17, Block.stoneSingleSlab.blockID, 5);
		world.setBlock(i + 8, j + 4, k + 3, Block.stoneBrick.blockID);
		world.setBlockMetadataWithNotify(i + 8, j + 4, k + 5, Block.blockNetherQuartz.blockID, 2);
		world.setBlockMetadataWithNotify(i + 8, j + 4, k + 7, Block.blockNetherQuartz.blockID, 2);
		world.setBlockMetadataWithNotify(i + 8, j + 4, k + 9, Block.blockNetherQuartz.blockID, 2);
		world.setBlockMetadataWithNotify(i + 8, j + 4, k + 11, Block.blockNetherQuartz.blockID, 2);
		world.setBlockMetadataWithNotify(i + 8, j + 4, k + 13, Block.blockNetherQuartz.blockID, 2);
		world.setBlock(i + 8, j + 4, k + 15, Block.stoneBrick.blockID);
		world.setBlock(i + 8, j + 5, k + 3, Block.stoneBrick.blockID);
		world.setBlockMetadataWithNotify(i + 8, j + 5, k + 5, Block.blockNetherQuartz.blockID, 2);
		world.setBlockMetadataWithNotify(i + 8, j + 5, k + 7, Block.blockNetherQuartz.blockID, 2);
		world.setBlockMetadataWithNotify(i + 8, j + 5, k + 9, Block.blockNetherQuartz.blockID, 2);
		world.setBlockMetadataWithNotify(i + 8, j + 5, k + 11, Block.blockNetherQuartz.blockID, 2);
		world.setBlockMetadataWithNotify(i + 8, j + 5, k + 13, Block.blockNetherQuartz.blockID, 2);
		world.setBlock(i + 8, j + 5, k + 15, Block.stoneBrick.blockID);
		world.setBlock(i + 8, j + 6, k + 3, Block.stoneBrick.blockID);
		world.setBlockMetadataWithNotify(i + 8, j + 6, k + 4, Block.stairsStoneBrick.blockID, 5);
		world.setBlockMetadataWithNotify(i + 8, j + 6, k + 5, Block.blockNetherQuartz.blockID, 2);
		world.setBlockMetadataWithNotify(i + 8, j + 6, k + 6, Block.stairsStoneBrick.blockID, 5);
		world.setBlockMetadataWithNotify(i + 8, j + 6, k + 7, Block.blockNetherQuartz.blockID, 2);
		world.setBlockMetadataWithNotify(i + 8, j + 6, k + 8, Block.stairsStoneBrick.blockID, 5);
		world.setBlockMetadataWithNotify(i + 8, j + 6, k + 9, Block.blockNetherQuartz.blockID, 2);
		world.setBlockMetadataWithNotify(i + 8, j + 6, k + 10, Block.stairsStoneBrick.blockID, 5);
		world.setBlockMetadataWithNotify(i + 8, j + 6, k + 11, Block.blockNetherQuartz.blockID, 2);
		world.setBlockMetadataWithNotify(i + 8, j + 6, k + 12, Block.stairsStoneBrick.blockID, 5);
		world.setBlockMetadataWithNotify(i + 8, j + 6, k + 13, Block.blockNetherQuartz.blockID, 2);
		world.setBlockMetadataWithNotify(i + 8, j + 6, k + 14, Block.stairsStoneBrick.blockID, 5);
		world.setBlock(i + 8, j + 6, k + 15, Block.stoneBrick.blockID);
		world.setBlock(i + 8, j + 7, k + 3, Block.stoneBrick.blockID);
		world.setBlock(i + 8, j + 7, k + 4, Block.stoneBrick.blockID);
		world.setBlock(i + 8, j + 7, k + 5, Block.stoneBrick.blockID);
		world.setBlock(i + 8, j + 7, k + 6, Block.stoneBrick.blockID);
		world.setBlock(i + 8, j + 7, k + 7, Block.stoneBrick.blockID);
		world.setBlock(i + 8, j + 7, k + 8, Block.stoneBrick.blockID);
		world.setBlock(i + 8, j + 7, k + 9, Block.stoneBrick.blockID);
		world.setBlock(i + 8, j + 7, k + 10, Block.stoneBrick.blockID);
		world.setBlock(i + 8, j + 7, k + 11, Block.stoneBrick.blockID);
		world.setBlock(i + 8, j + 7, k + 12, Block.stoneBrick.blockID);
		world.setBlock(i + 8, j + 7, k + 13, Block.stoneBrick.blockID);
		world.setBlock(i + 8, j + 7, k + 14, Block.stoneBrick.blockID);
		world.setBlock(i + 8, j + 7, k + 15, Block.stoneBrick.blockID);
		world.setBlockMetadataWithNotify(i + 8, j + 8, k + 0, Block.stairsStoneBrick.blockID, 6);
		world.setBlockMetadataWithNotify(i + 8, j + 8, k + 1, Block.stairsStoneBrick.blockID, 4);
		world.setBlockMetadataWithNotify(i + 8, j + 8, k + 2, Block.stairsStoneBrick.blockID, 4);
		world.setBlock(i + 8, j + 8, k + 3, Block.stoneBrick.blockID);
		world.setBlock(i + 8, j + 8, k + 4, Block.stoneBrick.blockID);
		world.setBlock(i + 8, j + 8, k + 5, Block.stoneBrick.blockID);
		world.setBlock(i + 8, j + 8, k + 6, Block.stoneBrick.blockID);
		world.setBlock(i + 8, j + 8, k + 7, Block.stoneBrick.blockID);
		world.setBlock(i + 8, j + 8, k + 8, Block.stoneBrick.blockID);
		world.setBlock(i + 8, j + 8, k + 9, Block.stoneBrick.blockID);
		world.setBlock(i + 8, j + 8, k + 10, Block.stoneBrick.blockID);
		world.setBlock(i + 8, j + 8, k + 11, Block.stoneBrick.blockID);
		world.setBlock(i + 8, j + 8, k + 12, Block.stoneBrick.blockID);
		world.setBlock(i + 8, j + 8, k + 13, Block.stoneBrick.blockID);
		world.setBlock(i + 8, j + 8, k + 14, Block.stoneBrick.blockID);
		world.setBlock(i + 8, j + 8, k + 15, Block.stoneBrick.blockID);
		world.setBlockMetadataWithNotify(i + 8, j + 8, k + 16, Block.stairsStoneBrick.blockID, 4);
		world.setBlockMetadataWithNotify(i + 8, j + 8, k + 17, Block.stairsStoneBrick.blockID, 7);
		world.setBlock(i + 8, j + 9, k + 0, Block.fenceIron.blockID);
		world.setBlock(i + 8, j + 9, k + 1, Block.fenceIron.blockID);
		world.setBlock(i + 8, j + 9, k + 2, Block.fenceIron.blockID);
		world.setBlock(i + 8, j + 9, k + 3, Block.stoneBrick.blockID);
		world.setBlockMetadataWithNotify(i + 8, j + 9, k + 6, Block.blockNetherQuartz.blockID, 2);
		world.setBlockMetadataWithNotify(i + 8, j + 9, k + 7, Block.stoneSingleSlab.blockID, 3);
		world.setBlock(i + 8, j + 9, k + 15, Block.stoneBrick.blockID);
		//world.setBlock(i + 8, j + 9, k + 16, -117);
		//world.setBlock(i + 8, j + 9, k + 17, -117);
		world.setBlock(i + 8, j + 10, k + 3, Block.stoneBrick.blockID);
		world.setBlockMetadataWithNotify(i + 8, j + 10, k + 6, Block.blockNetherQuartz.blockID, 2);
		world.setBlock(i + 8, j + 10, k + 15, Block.stoneBrick.blockID);
		world.setBlock(i + 8, j + 11, k + 3, Block.stoneBrick.blockID);
		world.setBlockMetadataWithNotify(i + 8, j + 11, k + 5, Block.stoneSingleSlab.blockID, 3);
		world.setBlockMetadataWithNotify(i + 8, j + 11, k + 6, Block.blockNetherQuartz.blockID, 2);
		world.setBlock(i + 8, j + 11, k + 15, Block.stoneBrick.blockID);
		world.setBlock(i + 8, j + 12, k + 3, Block.stoneBrick.blockID);
		world.setBlockMetadataWithNotify(i + 8, j + 12, k + 6, Block.blockNetherQuartz.blockID, 2);
		world.setBlockMetadataWithNotify(i + 8, j + 12, k + 10, Block.stairsStoneBrick.blockID, 5);
		world.setBlock(i + 8, j + 12, k + 15, Block.stoneBrick.blockID);
		world.setBlockMetadataWithNotify(i + 8, j + 12, k + 16, Block.woodSingleSlab.blockID, 10);
		world.setBlock(i + 8, j + 13, k + 3, Block.stoneBrick.blockID);
		world.setBlockMetadataWithNotify(i + 8, j + 13, k + 6, Block.blockNetherQuartz.blockID, 2);
		world.setBlockMetadataWithNotify(i + 8, j + 13, k + 7, Block.stoneSingleSlab.blockID, 3);
		world.setBlock(i + 8, j + 13, k + 10, Block.stoneBrick.blockID);
		world.setBlockMetadataWithNotify(i + 8, j + 13, k + 11, Block.woodDoubleSlab.blockID, 2);
		world.setBlockMetadataWithNotify(i + 8, j + 13, k + 12, Block.woodDoubleSlab.blockID, 2);
		world.setBlockMetadataWithNotify(i + 8, j + 13, k + 13, Block.woodDoubleSlab.blockID, 2);
		world.setBlockMetadataWithNotify(i + 8, j + 13, k + 14, Block.woodDoubleSlab.blockID, 2);
		world.setBlockMetadataWithNotify(i + 8, j + 13, k + 15, Block.woodSingleSlab.blockID, 2);
		world.setBlockMetadataWithNotify(i + 8, j + 13, k + 16, Block.woodSingleSlab.blockID, 2);
		world.setBlock(i + 8, j + 14, k + 3, Block.stoneBrick.blockID);
		world.setBlockMetadataWithNotify(i + 8, j + 14, k + 4, Block.stairsStoneBrick.blockID, 7);
		world.setBlockMetadataWithNotify(i + 8, j + 14, k + 6, Block.blockNetherQuartz.blockID, 2);
		world.setBlockMetadataWithNotify(i + 8, j + 14, k + 9, Block.stairsStoneBrick.blockID, 6);
		world.setBlock(i + 8, j + 14, k + 10, Block.stoneBrick.blockID);
		world.setBlockMetadataWithNotify(i + 8, j + 15, k + 3, Block.stairsStoneBrick.blockID, 2);
		world.setBlock(i + 8, j + 15, k + 4, Block.stoneBrick.blockID);
		world.setBlockMetadataWithNotify(i + 8, j + 15, k + 5, Block.stoneSingleSlab.blockID, 3);
		world.setBlockMetadataWithNotify(i + 8, j + 15, k + 6, Block.blockNetherQuartz.blockID, 2);
		world.setBlock(i + 8, j + 15, k + 9, Block.stoneBrick.blockID);
		world.setBlockMetadataWithNotify(i + 8, j + 15, k + 10, Block.stairsStoneBrick.blockID, 3);
		world.setBlock(i + 8, j + 16, k + 4, Block.stoneBrick.blockID);
		world.setBlockMetadataWithNotify(i + 8, j + 16, k + 6, Block.blockNetherQuartz.blockID, 2);
		world.setBlock(i + 8, j + 16, k + 9, Block.stoneBrick.blockID);
		world.setBlock(i + 8, j + 17, k + 4, Block.stoneBrick.blockID);
		world.setBlockMetadataWithNotify(i + 8, j + 17, k + 6, Block.blockNetherQuartz.blockID, 2);
		world.setBlock(i + 8, j + 17, k + 9, Block.stoneBrick.blockID);
		world.setBlock(i + 8, j + 18, k + 4, Block.stoneBrick.blockID);
		world.setBlockMetadataWithNotify(i + 8, j + 18, k + 6, Block.blockNetherQuartz.blockID, 2);
		world.setBlock(i + 8, j + 18, k + 9, Block.stoneBrick.blockID);
		world.setBlock(i + 8, j + 19, k + 4, Block.stoneBrick.blockID);
		world.setBlockMetadataWithNotify(i + 8, j + 19, k + 6, Block.blockNetherQuartz.blockID, 2);
		world.setBlock(i + 8, j + 19, k + 9, Block.stoneBrick.blockID);
		world.setBlock(i + 8, j + 20, k + 4, Block.stoneBrick.blockID);
		world.setBlockMetadataWithNotify(i + 8, j + 20, k + 6, Block.blockNetherQuartz.blockID, 2);
		world.setBlock(i + 8, j + 20, k + 9, Block.stoneBrick.blockID);
		world.setBlockMetadataWithNotify(i + 8, j + 21, k + 4, Block.stairsStoneBrick.blockID, 2);
		world.setBlock(i + 8, j + 21, k + 5, Block.stoneBrick.blockID);
		world.setBlock(i + 8, j + 21, k + 6, Block.stoneBrick.blockID);
		world.setBlock(i + 8, j + 21, k + 7, Block.stoneBrick.blockID);
		world.setBlock(i + 8, j + 21, k + 8, Block.stoneBrick.blockID);
		world.setBlock(i + 8, j + 21, k + 9, Block.stoneBrick.blockID);
		world.setBlock(i + 8, j + 22, k + 6, Block.stoneBrick.blockID);
		world.setBlock(i + 8, j + 22, k + 7, Block.stoneBrick.blockID);
		world.setBlock(i + 8, j + 22, k + 8, Block.stoneBrick.blockID);
		world.setBlock(i + 8, j + 23, k + 6, Block.stoneBrick.blockID);
		world.setBlock(i + 8, j + 23, k + 7, Block.stoneBrick.blockID);
		world.setBlock(i + 8, j + 23, k + 8, Block.stoneBrick.blockID);
		world.setBlockMetadataWithNotify(i + 8, j + 24, k + 4, Block.stairsStoneBrick.blockID, 4);
		world.setBlockMetadataWithNotify(i + 8, j + 24, k + 5, Block.stairsStoneBrick.blockID, 4);
		world.setBlock(i + 8, j + 24, k + 6, Block.stoneBrick.blockID);
		world.setBlock(i + 8, j + 24, k + 7, Block.stoneBrick.blockID);
		world.setBlock(i + 8, j + 24, k + 8, Block.stoneBrick.blockID);
		world.setBlockMetadataWithNotify(i + 8, j + 24, k + 9, Block.stairsStoneBrick.blockID, 7);
		world.setBlockMetadataWithNotify(i + 8, j + 24, k + 10, Block.stairsStoneBrick.blockID, 4);
		world.setBlock(i + 8, j + 25, k + 4, Block.stoneBrick.blockID);
		world.setBlock(i + 8, j + 25, k + 10, Block.stoneBrick.blockID);
		world.setBlock(i + 8, j + 26, k + 4, Block.stoneBrick.blockID);
		world.setBlock(i + 8, j + 26, k + 10, Block.stoneBrick.blockID);
		world.setBlockMetadataWithNotify(i + 8, j + 27, k + 3, Block.woodSingleSlab.blockID, 10);
		world.setBlock(i + 8, j + 27, k + 4, Block.stoneBrick.blockID);
		world.setBlock(i + 8, j + 27, k + 10, Block.stoneBrick.blockID);
		world.setBlockMetadataWithNotify(i + 8, j + 27, k + 11, Block.woodSingleSlab.blockID, 10);
		world.setBlockMetadataWithNotify(i + 8, j + 28, k + 4, Block.woodSingleSlab.blockID, 2);
		world.setBlockMetadataWithNotify(i + 8, j + 28, k + 5, Block.woodSingleSlab.blockID, 2);
		world.setBlockMetadataWithNotify(i + 8, j + 28, k + 6, Block.woodSingleSlab.blockID, 10);
		world.setBlockMetadataWithNotify(i + 8, j + 28, k + 7, Block.woodSingleSlab.blockID, 10);
		world.setBlockMetadataWithNotify(i + 8, j + 28, k + 8, Block.woodSingleSlab.blockID, 10);
		world.setBlockMetadataWithNotify(i + 8, j + 28, k + 9, Block.woodSingleSlab.blockID, 2);
		world.setBlockMetadataWithNotify(i + 8, j + 28, k + 10, Block.woodSingleSlab.blockID, 2);
		world.setBlock(i + 9, j + 0, k + 3, Block.stoneBrick.blockID);
		world.setBlock(i + 9, j + 0, k + 15, Block.stoneBrick.blockID);
		world.setBlock(i + 9, j + 0, k + 16, Block.stoneBrick.blockID);
		world.setBlock(i + 9, j + 0, k + 17, Block.stoneBrick.blockID);
		world.setBlockMetadataWithNotify(i + 9, j + 0, k + 18, Block.stairsStoneBrick.blockID, 3);
		world.setBlockMetadataWithNotify(i + 9, j + 1, k + 2, Block.stoneSingleSlab.blockID, 13);
		world.setBlock(i + 9, j + 1, k + 3, Block.stoneBrick.blockID);
		world.setBlock(i + 9, j + 1, k + 15, Block.stoneBrick.blockID);
		world.setBlock(i + 9, j + 1, k + 16, Block.stoneBrick.blockID);
		world.setBlockMetadataWithNotify(i + 9, j + 1, k + 17, Block.stairsStoneBrick.blockID, 3);
		world.setBlockMetadataWithNotify(i + 9, j + 2, k + 1, Block.stairsStoneBrick.blockID, 6);
		world.setBlock(i + 9, j + 2, k + 2, Block.stoneBrick.blockID);
		world.setBlock(i + 9, j + 2, k + 3, Block.stoneBrick.blockID);
		world.setBlock(i + 9, j + 2, k + 4, Block.stoneBrick.blockID);
		world.setBlock(i + 9, j + 2, k + 5, Block.stoneBrick.blockID);
		world.setBlock(i + 9, j + 2, k + 6, Block.stoneBrick.blockID);
		world.setBlock(i + 9, j + 2, k + 7, Block.stoneBrick.blockID);
		world.setBlock(i + 9, j + 2, k + 8, Block.stoneBrick.blockID);
		world.setBlock(i + 9, j + 2, k + 9, Block.stoneBrick.blockID);
		world.setBlock(i + 9, j + 2, k + 10, Block.stoneBrick.blockID);
		world.setBlock(i + 9, j + 2, k + 11, Block.stoneBrick.blockID);
		world.setBlock(i + 9, j + 2, k + 12, Block.stoneBrick.blockID);
		world.setBlock(i + 9, j + 2, k + 13, Block.stoneBrick.blockID);
		world.setBlock(i + 9, j + 2, k + 14, Block.stoneBrick.blockID);
		world.setBlock(i + 9, j + 2, k + 15, Block.stoneBrick.blockID);
		world.setBlockMetadataWithNotify(i + 9, j + 2, k + 16, Block.stairsStoneBrick.blockID, 3);
		world.setBlock(i + 9, j + 3, k + 1, Block.fenceIron.blockID);
		world.setBlock(i + 9, j + 3, k + 3, Block.glass.blockID);
		world.setBlock(i + 9, j + 4, k + 3, Block.glass.blockID);
		world.setBlock(i + 9, j + 5, k + 3, Block.glass.blockID);
		world.setBlockMetadataWithNotify(i + 9, j + 5, k + 15, Block.stairsStoneBrick.blockID, 5);
		world.setBlock(i + 9, j + 6, k + 3, Block.stoneBrick.blockID);
		world.setBlock(i + 9, j + 6, k + 15, Block.stoneBrick.blockID);
		world.setBlockMetadataWithNotify(i + 9, j + 7, k + 1, Block.stoneSingleSlab.blockID, 13);
		world.setBlockMetadataWithNotify(i + 9, j + 7, k + 2, Block.stoneSingleSlab.blockID, 13);
		world.setBlock(i + 9, j + 7, k + 3, Block.stoneBrick.blockID);
		world.setBlockMetadataWithNotify(i + 9, j + 7, k + 4, Block.stairsStoneBrick.blockID, 5);
		world.setBlockMetadataWithNotify(i + 9, j + 7, k + 5, Block.stairsStoneBrick.blockID, 5);
		world.setBlockMetadataWithNotify(i + 9, j + 7, k + 6, Block.stairsStoneBrick.blockID, 5);
		world.setBlockMetadataWithNotify(i + 9, j + 7, k + 7, Block.stairsStoneBrick.blockID, 5);
		world.setBlockMetadataWithNotify(i + 9, j + 7, k + 8, Block.stairsStoneBrick.blockID, 5);
		world.setBlockMetadataWithNotify(i + 9, j + 7, k + 9, Block.stairsStoneBrick.blockID, 5);
		world.setBlockMetadataWithNotify(i + 9, j + 7, k + 10, Block.stairsStoneBrick.blockID, 5);
		world.setBlockMetadataWithNotify(i + 9, j + 7, k + 11, Block.stairsStoneBrick.blockID, 5);
		world.setBlockMetadataWithNotify(i + 9, j + 7, k + 12, Block.stairsStoneBrick.blockID, 5);
		world.setBlockMetadataWithNotify(i + 9, j + 7, k + 13, Block.stairsStoneBrick.blockID, 5);
		world.setBlockMetadataWithNotify(i + 9, j + 7, k + 14, Block.stairsStoneBrick.blockID, 5);
		world.setBlock(i + 9, j + 7, k + 15, Block.stoneBrick.blockID);
		world.setBlockMetadataWithNotify(i + 9, j + 7, k + 16, Block.stoneSingleSlab.blockID, 13);
		world.setBlockMetadataWithNotify(i + 9, j + 8, k + 0, Block.stairsStoneBrick.blockID, 6);
		world.setBlock(i + 9, j + 8, k + 1, Block.stoneBrick.blockID);
		world.setBlock(i + 9, j + 8, k + 2, Block.stoneBrick.blockID);
		world.setBlock(i + 9, j + 8, k + 3, Block.stoneBrick.blockID);
		world.setBlock(i + 9, j + 8, k + 4, Block.stoneBrick.blockID);
		world.setBlock(i + 9, j + 8, k + 5, Block.stoneBrick.blockID);
		world.setBlock(i + 9, j + 8, k + 6, Block.stoneBrick.blockID);
		world.setBlock(i + 9, j + 8, k + 7, Block.stoneBrick.blockID);
		world.setBlock(i + 9, j + 8, k + 8, Block.stoneBrick.blockID);
		world.setBlock(i + 9, j + 8, k + 9, Block.stoneBrick.blockID);
		world.setBlock(i + 9, j + 8, k + 10, Block.stoneBrick.blockID);
		world.setBlock(i + 9, j + 8, k + 11, Block.stoneBrick.blockID);
		world.setBlock(i + 9, j + 8, k + 12, Block.stoneBrick.blockID);
		world.setBlock(i + 9, j + 8, k + 13, Block.stoneBrick.blockID);
		world.setBlock(i + 9, j + 8, k + 14, Block.stoneBrick.blockID);
		world.setBlock(i + 9, j + 8, k + 15, Block.stoneBrick.blockID);
		world.setBlock(i + 9, j + 8, k + 16, Block.stoneBrick.blockID);
		world.setBlockMetadataWithNotify(i + 9, j + 8, k + 17, Block.stairsStoneBrick.blockID, 7);
		world.setBlock(i + 9, j + 9, k + 0, Block.fenceIron.blockID);
		world.setBlock(i + 9, j + 9, k + 15, Block.glass.blockID);
		//world.setBlock(i + 9, j + 9, k + 17, -117);
		world.setBlock(i + 9, j + 10, k + 15, Block.glass.blockID);
		world.setBlockMetadataWithNotify(i + 9, j + 11, k + 3, Block.stairsStoneBrick.blockID, 5);
		world.setBlockMetadataWithNotify(i + 9, j + 11, k + 5, Block.stoneSingleSlab.blockID, 11);
		world.setBlock(i + 9, j + 11, k + 15, Block.glass.blockID);
		world.setBlock(i + 9, j + 12, k + 3, Block.stoneBrick.blockID);
		world.setBlockMetadataWithNotify(i + 9, j + 12, k + 6, Block.stoneSingleSlab.blockID, 3);
		world.setBlockMetadataWithNotify(i + 9, j + 12, k + 7, Block.stoneSingleSlab.blockID, 11);
		world.setBlock(i + 9, j + 12, k + 15, Block.stoneBrick.blockID);
		world.setBlock(i + 9, j + 13, k + 3, Block.stoneBrick.blockID);
		world.setBlock(i + 9, j + 13, k + 10, Block.stoneBrick.blockID);
		world.setBlockMetadataWithNotify(i + 9, j + 13, k + 11, Block.woodSingleSlab.blockID, 10);
		world.setBlockMetadataWithNotify(i + 9, j + 13, k + 12, Block.woodSingleSlab.blockID, 10);
		world.setBlockMetadataWithNotify(i + 9, j + 13, k + 13, Block.woodSingleSlab.blockID, 10);
		world.setBlockMetadataWithNotify(i + 9, j + 13, k + 14, Block.woodDoubleSlab.blockID, 2);
		world.setBlockMetadataWithNotify(i + 9, j + 13, k + 15, Block.woodDoubleSlab.blockID, 2);
		world.setBlockMetadataWithNotify(i + 9, j + 13, k + 16, Block.woodDoubleSlab.blockID, 2);
		world.setBlock(i + 9, j + 14, k + 3, Block.stoneBrick.blockID);
		world.setBlockMetadataWithNotify(i + 9, j + 14, k + 4, Block.stairsStoneBrick.blockID, 7);
		world.setBlockMetadataWithNotify(i + 9, j + 14, k + 9, Block.stairsStoneBrick.blockID, 6);
		world.setBlock(i + 9, j + 14, k + 10, Block.stoneBrick.blockID);
		world.setBlockMetadataWithNotify(i + 9, j + 14, k + 11, Block.woodSingleSlab.blockID, 2);
		world.setBlockMetadataWithNotify(i + 9, j + 14, k + 12, Block.woodSingleSlab.blockID, 2);
		world.setBlockMetadataWithNotify(i + 9, j + 14, k + 13, Block.woodSingleSlab.blockID, 2);
		world.setBlockMetadataWithNotify(i + 9, j + 15, k + 3, Block.stairsStoneBrick.blockID, 2);
		world.setBlock(i + 9, j + 15, k + 4, Block.stoneBrick.blockID);
		world.setBlockMetadataWithNotify(i + 9, j + 15, k + 5, Block.stoneSingleSlab.blockID, 11);
		world.setBlock(i + 9, j + 15, k + 9, Block.stoneBrick.blockID);
		world.setBlockMetadataWithNotify(i + 9, j + 15, k + 10, Block.stairsStoneBrick.blockID, 3);
		world.setBlock(i + 9, j + 16, k + 4, Block.stoneBrick.blockID);
		world.setBlock(i + 9, j + 16, k + 9, Block.stoneBrick.blockID);
		world.setBlock(i + 9, j + 17, k + 4, Block.glass.blockID);
		world.setBlockMetadataWithNotify(i + 9, j + 17, k + 6, Block.stoneSingleSlab.blockID, 3);
		world.setBlockMetadataWithNotify(i + 9, j + 17, k + 7, Block.stoneSingleSlab.blockID, 11);
		world.setBlock(i + 9, j + 17, k + 9, Block.stoneBrick.blockID);
		world.setBlock(i + 9, j + 18, k + 4, Block.stoneBrick.blockID);
		world.setBlockMetadataWithNotify(i + 9, j + 18, k + 8, Block.stoneSingleSlab.blockID, 3);
		world.setBlock(i + 9, j + 18, k + 9, Block.stoneBrick.blockID);
		world.setBlock(i + 9, j + 19, k + 4, Block.stoneBrick.blockID);
		world.setBlock(i + 9, j + 19, k + 9, Block.stoneBrick.blockID);
		world.setBlock(i + 9, j + 20, k + 4, Block.stoneBrick.blockID);
		world.setBlock(i + 9, j + 20, k + 9, Block.stoneBrick.blockID);
		world.setBlockMetadataWithNotify(i + 9, j + 21, k + 4, Block.stairsStoneBrick.blockID, 2);
		world.setBlock(i + 9, j + 21, k + 5, Block.stoneBrick.blockID);
		world.setBlockMetadataWithNotify(i + 9, j + 21, k + 6, Block.stoneSingleSlab.blockID, 3);
		world.setBlockMetadataWithNotify(i + 9, j + 21, k + 7, Block.stoneSingleSlab.blockID, 11);
		world.setBlock(i + 9, j + 21, k + 9, Block.stoneBrick.blockID);
		world.setBlock(i + 9, j + 22, k + 5, Block.stoneBrick.blockID);
		world.setBlockMetadataWithNotify(i + 9, j + 22, k + 8, Block.stoneSingleSlab.blockID, 3);
		world.setBlock(i + 9, j + 22, k + 9, Block.stoneBrick.blockID);
		world.setBlock(i + 9, j + 23, k + 5, Block.stoneBrick.blockID);
		world.setBlock(i + 9, j + 23, k + 9, Block.stoneBrick.blockID);
		world.setBlockMetadataWithNotify(i + 9, j + 24, k + 4, Block.stairsStoneBrick.blockID, 6);
		world.setBlock(i + 9, j + 24, k + 5, Block.stoneBrick.blockID);
		world.setBlockMetadataWithNotify(i + 9, j + 24, k + 6, Block.stoneSingleSlab.blockID, 11);
		world.setBlock(i + 9, j + 24, k + 9, Block.stoneBrick.blockID);
		world.setBlockMetadataWithNotify(i + 9, j + 24, k + 10, Block.stairsStoneBrick.blockID, 7);
		world.setBlock(i + 9, j + 25, k + 4, Block.stoneBrick.blockID);
		world.setBlock(i + 9, j + 25, k + 10, Block.stoneBrick.blockID);
		world.setBlock(i + 9, j + 26, k + 4, Block.stoneBrick.blockID);
		world.setBlock(i + 9, j + 26, k + 10, Block.stoneBrick.blockID);
		world.setBlockMetadataWithNotify(i + 9, j + 27, k + 3, Block.woodSingleSlab.blockID, 10);
		world.setBlock(i + 9, j + 27, k + 4, Block.stoneBrick.blockID);
		world.setBlock(i + 9, j + 27, k + 10, Block.stoneBrick.blockID);
		world.setBlockMetadataWithNotify(i + 9, j + 27, k + 11, Block.woodSingleSlab.blockID, 10);
		world.setBlockMetadataWithNotify(i + 9, j + 28, k + 4, Block.woodSingleSlab.blockID, 2);
		world.setBlockMetadataWithNotify(i + 9, j + 28, k + 5, Block.woodSingleSlab.blockID, 10);
		world.setBlockMetadataWithNotify(i + 9, j + 28, k + 6, Block.woodSingleSlab.blockID, 10);
		world.setBlockMetadataWithNotify(i + 9, j + 28, k + 8, Block.woodSingleSlab.blockID, 10);
		world.setBlockMetadataWithNotify(i + 9, j + 28, k + 9, Block.woodSingleSlab.blockID, 10);
		world.setBlockMetadataWithNotify(i + 9, j + 28, k + 10, Block.woodSingleSlab.blockID, 2);
		world.setBlockMetadataWithNotify(i + 9, j + 29, k + 7, Block.woodSingleSlab.blockID, 2);
		world.setBlock(i + 10, j + 0, k + 3, Block.stoneBrick.blockID);
		world.setBlock(i + 10, j + 0, k + 15, Block.stoneBrick.blockID);
		world.setBlock(i + 10, j + 0, k + 16, Block.stoneBrick.blockID);
		world.setBlock(i + 10, j + 0, k + 17, Block.stoneBrick.blockID);
		world.setBlockMetadataWithNotify(i + 10, j + 0, k + 18, Block.stairsStoneBrick.blockID, 3);
		world.setBlockMetadataWithNotify(i + 10, j + 1, k + 2, Block.stoneSingleSlab.blockID, 13);
		world.setBlock(i + 10, j + 1, k + 3, Block.stoneBrick.blockID);
		world.setBlock(i + 10, j + 1, k + 15, Block.stoneBrick.blockID);
		world.setBlock(i + 10, j + 1, k + 16, Block.stoneBrick.blockID);
		world.setBlockMetadataWithNotify(i + 10, j + 1, k + 17, Block.stairsStoneBrick.blockID, 3);
		world.setBlockMetadataWithNotify(i + 10, j + 2, k + 1, Block.stairsStoneBrick.blockID, 6);
		world.setBlock(i + 10, j + 2, k + 2, Block.stoneBrick.blockID);
		world.setBlock(i + 10, j + 2, k + 3, Block.stoneBrick.blockID);
		world.setBlock(i + 10, j + 2, k + 4, Block.stoneBrick.blockID);
		world.setBlock(i + 10, j + 2, k + 5, Block.stoneBrick.blockID);
		world.setBlock(i + 10, j + 2, k + 6, Block.stoneBrick.blockID);
		world.setBlock(i + 10, j + 2, k + 7, Block.stoneBrick.blockID);
		world.setBlock(i + 10, j + 2, k + 8, Block.stoneBrick.blockID);
		world.setBlock(i + 10, j + 2, k + 9, Block.stoneBrick.blockID);
		world.setBlock(i + 10, j + 2, k + 10, Block.stoneBrick.blockID);
		world.setBlock(i + 10, j + 2, k + 11, Block.stoneBrick.blockID);
		world.setBlock(i + 10, j + 2, k + 12, Block.stoneBrick.blockID);
		world.setBlock(i + 10, j + 2, k + 13, Block.stoneBrick.blockID);
		world.setBlock(i + 10, j + 2, k + 14, Block.stoneBrick.blockID);
		world.setBlock(i + 10, j + 2, k + 15, Block.stoneBrick.blockID);
		world.setBlockMetadataWithNotify(i + 10, j + 2, k + 16, Block.stairsStoneBrick.blockID, 3);
		world.setBlock(i + 10, j + 3, k + 1, Block.fenceIron.blockID);
		world.setBlock(i + 10, j + 3, k + 3, Block.glass.blockID);
		world.setBlock(i + 10, j + 4, k + 3, Block.glass.blockID);
		world.setBlock(i + 10, j + 5, k + 3, Block.glass.blockID);
		world.setBlock(i + 10, j + 6, k + 3, Block.glass.blockID);
		world.setBlock(i + 10, j + 6, k + 15, Block.stoneBrick.blockID);
		world.setBlockMetadataWithNotify(i + 10, j + 7, k + 1, Block.stoneSingleSlab.blockID, 13);
		world.setBlockMetadataWithNotify(i + 10, j + 7, k + 2, Block.stoneSingleSlab.blockID, 13);
		world.setBlock(i + 10, j + 7, k + 3, Block.stoneBrick.blockID);
		world.setBlock(i + 10, j + 7, k + 15, Block.stoneBrick.blockID);
		world.setBlockMetadataWithNotify(i + 10, j + 7, k + 16, Block.stoneSingleSlab.blockID, 13);
		world.setBlockMetadataWithNotify(i + 10, j + 8, k + 0, Block.stairsStoneBrick.blockID, 6);
		world.setBlock(i + 10, j + 8, k + 1, Block.stoneBrick.blockID);
		world.setBlock(i + 10, j + 8, k + 2, Block.stoneBrick.blockID);
		world.setBlock(i + 10, j + 8, k + 3, Block.stoneBrick.blockID);
		world.setBlock(i + 10, j + 8, k + 4, Block.stoneBrick.blockID);
		world.setBlock(i + 10, j + 8, k + 5, Block.stoneBrick.blockID);
		world.setBlock(i + 10, j + 8, k + 6, Block.stoneBrick.blockID);
		world.setBlock(i + 10, j + 8, k + 7, Block.stoneBrick.blockID);
		world.setBlock(i + 10, j + 8, k + 8, Block.stoneBrick.blockID);
		world.setBlock(i + 10, j + 8, k + 9, Block.stoneBrick.blockID);
		world.setBlock(i + 10, j + 8, k + 10, Block.stoneBrick.blockID);
		world.setBlock(i + 10, j + 8, k + 11, Block.stoneBrick.blockID);
		world.setBlock(i + 10, j + 8, k + 12, Block.stoneBrick.blockID);
		world.setBlock(i + 10, j + 8, k + 13, Block.stoneBrick.blockID);
		world.setBlock(i + 10, j + 8, k + 14, Block.stoneBrick.blockID);
		world.setBlock(i + 10, j + 8, k + 15, Block.stoneBrick.blockID);
		world.setBlock(i + 10, j + 8, k + 16, Block.stoneBrick.blockID);
		world.setBlockMetadataWithNotify(i + 10, j + 8, k + 17, Block.stairsStoneBrick.blockID, 7);
		world.setBlock(i + 10, j + 9, k + 0, Block.fenceIron.blockID);
		world.setBlockMetadataWithNotify(i + 10, j + 9, k + 7, Block.blockNetherQuartz.blockID, 2);
		world.setBlock(i + 10, j + 9, k + 15, Block.glass.blockID);
		//world.setBlock(i + 10, j + 9, k + 17, -117);
		world.setBlockMetadataWithNotify(i + 10, j + 10, k + 7, Block.blockNetherQuartz.blockID, 2);
		world.setBlock(i + 10, j + 10, k + 15, Block.glass.blockID);
		world.setBlockMetadataWithNotify(i + 10, j + 11, k + 7, Block.blockNetherQuartz.blockID, 2);
		world.setBlock(i + 10, j + 11, k + 15, Block.glass.blockID);
		world.setBlock(i + 10, j + 12, k + 3, Block.stoneBrick.blockID);
		world.setBlockMetadataWithNotify(i + 10, j + 12, k + 7, Block.blockNetherQuartz.blockID, 2);
		world.setBlock(i + 10, j + 12, k + 15, Block.glass.blockID);
		world.setBlock(i + 10, j + 13, k + 3, Block.stoneBrick.blockID);
		world.setBlockMetadataWithNotify(i + 10, j + 13, k + 7, Block.blockNetherQuartz.blockID, 2);
		world.setBlock(i + 10, j + 13, k + 10, Block.stoneBrick.blockID);
		world.setBlockMetadataWithNotify(i + 10, j + 13, k + 13, Block.woodSingleSlab.blockID, 10);
		world.setBlockMetadataWithNotify(i + 10, j + 13, k + 14, Block.woodDoubleSlab.blockID, 2);
		world.setBlock(i + 10, j + 13, k + 15, Block.stoneBrick.blockID);
		world.setBlockMetadataWithNotify(i + 10, j + 13, k + 16, Block.woodSingleSlab.blockID, 10);
		world.setBlock(i + 10, j + 14, k + 3, Block.stoneBrick.blockID);
		world.setBlockMetadataWithNotify(i + 10, j + 14, k + 4, Block.stairsStoneBrick.blockID, 7);
		world.setBlockMetadataWithNotify(i + 10, j + 14, k + 7, Block.blockNetherQuartz.blockID, 2);
		world.setBlockMetadataWithNotify(i + 10, j + 14, k + 9, Block.stairsStoneBrick.blockID, 6);
		world.setBlock(i + 10, j + 14, k + 10, Block.stoneBrick.blockID);
		world.setBlockMetadataWithNotify(i + 10, j + 14, k + 11, Block.woodDoubleSlab.blockID, 2);
		world.setBlockMetadataWithNotify(i + 10, j + 14, k + 12, Block.woodDoubleSlab.blockID, 2);
		world.setBlockMetadataWithNotify(i + 10, j + 14, k + 13, Block.woodSingleSlab.blockID, 2);
		world.setBlockMetadataWithNotify(i + 10, j + 14, k + 14, Block.woodSingleSlab.blockID, 2);
		world.setBlockMetadataWithNotify(i + 10, j + 14, k + 15, Block.woodSingleSlab.blockID, 2);
		world.setBlockMetadataWithNotify(i + 10, j + 14, k + 16, Block.woodSingleSlab.blockID, 2);
		world.setBlockMetadataWithNotify(i + 10, j + 15, k + 3, Block.stairsStoneBrick.blockID, 2);
		world.setBlock(i + 10, j + 15, k + 4, Block.stoneBrick.blockID);
		world.setBlockMetadataWithNotify(i + 10, j + 15, k + 7, Block.blockNetherQuartz.blockID, 2);
		world.setBlock(i + 10, j + 15, k + 9, Block.stoneBrick.blockID);
		world.setBlockMetadataWithNotify(i + 10, j + 15, k + 10, Block.stairsStoneBrick.blockID, 3);
		world.setBlock(i + 10, j + 16, k + 4, Block.stoneBrick.blockID);
		world.setBlockMetadataWithNotify(i + 10, j + 16, k + 5, Block.stoneSingleSlab.blockID, 3);
		world.setBlockMetadataWithNotify(i + 10, j + 16, k + 6, Block.stoneSingleSlab.blockID, 11);
		world.setBlockMetadataWithNotify(i + 10, j + 16, k + 7, Block.blockNetherQuartz.blockID, 2);
		world.setBlock(i + 10, j + 16, k + 9, Block.stoneBrick.blockID);
		world.setBlock(i + 10, j + 17, k + 4, Block.stoneBrick.blockID);
		world.setBlockMetadataWithNotify(i + 10, j + 17, k + 7, Block.blockNetherQuartz.blockID, 2);
		world.setBlock(i + 10, j + 17, k + 9, Block.stoneBrick.blockID);
		world.setBlock(i + 10, j + 18, k + 4, Block.stoneBrick.blockID);
		world.setBlockMetadataWithNotify(i + 10, j + 18, k + 7, Block.blockNetherQuartz.blockID, 2);
		world.setBlockMetadataWithNotify(i + 10, j + 18, k + 8, Block.stoneSingleSlab.blockID, 11);
		world.setBlock(i + 10, j + 18, k + 9, Block.stoneBrick.blockID);
		world.setBlock(i + 10, j + 19, k + 4, Block.stoneBrick.blockID);
		world.setBlockMetadataWithNotify(i + 10, j + 19, k + 7, Block.blockNetherQuartz.blockID, 2);
		world.setBlock(i + 10, j + 19, k + 9, Block.stoneBrick.blockID);
		world.setBlock(i + 10, j + 20, k + 4, Block.stoneBrick.blockID);
		world.setBlockMetadataWithNotify(i + 10, j + 20, k + 6, Block.stoneSingleSlab.blockID, 11);
		world.setBlockMetadataWithNotify(i + 10, j + 20, k + 7, Block.blockNetherQuartz.blockID, 2);
		world.setBlock(i + 10, j + 20, k + 9, Block.glass.blockID);
		world.setBlockMetadataWithNotify(i + 10, j + 21, k + 4, Block.stairsStoneBrick.blockID, 2);
		world.setBlock(i + 10, j + 21, k + 5, Block.stoneBrick.blockID);
		world.setBlockMetadataWithNotify(i + 10, j + 21, k + 7, Block.blockNetherQuartz.blockID, 2);
		world.setBlock(i + 10, j + 21, k + 9, Block.stoneBrick.blockID);
		world.setBlock(i + 10, j + 22, k + 5, Block.glass.blockID);
		world.setBlockMetadataWithNotify(i + 10, j + 22, k + 7, Block.blockNetherQuartz.blockID, 2);
		world.setBlockMetadataWithNotify(i + 10, j + 22, k + 8, Block.stoneSingleSlab.blockID, 11);
		world.setBlock(i + 10, j + 22, k + 9, Block.stoneBrick.blockID);
		world.setBlock(i + 10, j + 23, k + 5, Block.stoneBrick.blockID);
		world.setBlockMetadataWithNotify(i + 10, j + 23, k + 7, Block.blockNetherQuartz.blockID, 2);
		world.setBlock(i + 10, j + 23, k + 9, Block.stoneBrick.blockID);
		world.setBlockMetadataWithNotify(i + 10, j + 24, k + 4, Block.stairsStoneBrick.blockID, 6);
		world.setBlock(i + 10, j + 24, k + 5, Block.stoneBrick.blockID);
		world.setBlockMetadataWithNotify(i + 10, j + 24, k + 6, Block.stoneSingleSlab.blockID, 11);
		world.setBlockMetadataWithNotify(i + 10, j + 24, k + 7, Block.blockNetherQuartz.blockID, 2);
		world.setBlock(i + 10, j + 24, k + 9, Block.stoneBrick.blockID);
		world.setBlockMetadataWithNotify(i + 10, j + 24, k + 10, Block.stairsStoneBrick.blockID, 7);
		world.setBlock(i + 10, j + 25, k + 4, Block.stoneBrick.blockID);
		world.setBlockMetadataWithNotify(i + 10, j + 25, k + 7, Block.blockNetherQuartz.blockID, 2);
		world.setBlock(i + 10, j + 25, k + 10, Block.stoneBrick.blockID);
		world.setBlock(i + 10, j + 26, k + 4, Block.glass.blockID);
		world.setBlock(i + 10, j + 26, k + 7, Block.glowStone.blockID);
		world.setBlock(i + 10, j + 26, k + 10, Block.glass.blockID);
		world.setBlockMetadataWithNotify(i + 10, j + 27, k + 3, Block.woodSingleSlab.blockID, 10);
		world.setBlock(i + 10, j + 27, k + 4, Block.stoneBrick.blockID);
		world.setBlockMetadataWithNotify(i + 10, j + 27, k + 7, Block.chest.blockID, 3);
		world.setBlock(i + 10, j + 27, k + 10, Block.stoneBrick.blockID);
		world.setBlockMetadataWithNotify(i + 10, j + 27, k + 11, Block.woodSingleSlab.blockID, 10);
		world.setBlockMetadataWithNotify(i + 10, j + 28, k + 4, Block.woodSingleSlab.blockID, 2);
		world.setBlockMetadataWithNotify(i + 10, j + 28, k + 5, Block.woodSingleSlab.blockID, 10);
		world.setBlockMetadataWithNotify(i + 10, j + 28, k + 9, Block.woodSingleSlab.blockID, 10);
		world.setBlockMetadataWithNotify(i + 10, j + 28, k + 10, Block.woodSingleSlab.blockID, 2);
		world.setBlockMetadataWithNotify(i + 10, j + 29, k + 6, Block.woodSingleSlab.blockID, 2);
		world.setBlockMetadataWithNotify(i + 10, j + 29, k + 7, Block.woodSingleSlab.blockID, 2);
		world.setBlockMetadataWithNotify(i + 10, j + 29, k + 8, Block.woodSingleSlab.blockID, 2);
		world.setBlock(i + 11, j + 0, k + 3, Block.stoneBrick.blockID);
		world.setBlock(i + 11, j + 0, k + 15, Block.stoneBrick.blockID);
		world.setBlock(i + 11, j + 0, k + 16, Block.stoneBrick.blockID);
		world.setBlock(i + 11, j + 0, k + 17, Block.stoneBrick.blockID);
		world.setBlockMetadataWithNotify(i + 11, j + 0, k + 18, Block.stairsStoneBrick.blockID, 3);
		world.setBlockMetadataWithNotify(i + 11, j + 1, k + 2, Block.stoneSingleSlab.blockID, 13);
		world.setBlock(i + 11, j + 1, k + 3, Block.stoneBrick.blockID);
		world.setBlock(i + 11, j + 1, k + 15, Block.stoneBrick.blockID);
		world.setBlock(i + 11, j + 1, k + 16, Block.stoneBrick.blockID);
		world.setBlockMetadataWithNotify(i + 11, j + 1, k + 17, Block.stairsStoneBrick.blockID, 3);
		world.setBlockMetadataWithNotify(i + 11, j + 2, k + 1, Block.stairsStoneBrick.blockID, 6);
		world.setBlock(i + 11, j + 2, k + 2, Block.stoneBrick.blockID);
		world.setBlock(i + 11, j + 2, k + 3, Block.stoneBrick.blockID);
		world.setBlock(i + 11, j + 2, k + 4, Block.stoneBrick.blockID);
		world.setBlock(i + 11, j + 2, k + 5, Block.stoneBrick.blockID);
		world.setBlock(i + 11, j + 2, k + 6, Block.stoneBrick.blockID);
		world.setBlock(i + 11, j + 2, k + 7, Block.stoneBrick.blockID);
		world.setBlock(i + 11, j + 2, k + 8, Block.stoneBrick.blockID);
		world.setBlock(i + 11, j + 2, k + 9, Block.stoneBrick.blockID);
		world.setBlock(i + 11, j + 2, k + 10, Block.stoneBrick.blockID);
		world.setBlock(i + 11, j + 2, k + 11, Block.stoneBrick.blockID);
		world.setBlock(i + 11, j + 2, k + 12, Block.stoneBrick.blockID);
		world.setBlock(i + 11, j + 2, k + 13, Block.stoneBrick.blockID);
		world.setBlock(i + 11, j + 2, k + 14, Block.stoneBrick.blockID);
		world.setBlock(i + 11, j + 2, k + 15, Block.stoneBrick.blockID);
		world.setBlockMetadataWithNotify(i + 11, j + 2, k + 16, Block.stairsStoneBrick.blockID, 3);
		world.setBlock(i + 11, j + 3, k + 1, Block.fenceIron.blockID);
		world.setBlock(i + 11, j + 3, k + 3, Block.glass.blockID);
		world.setBlock(i + 11, j + 4, k + 3, Block.glass.blockID);
		world.setBlock(i + 11, j + 5, k + 3, Block.glass.blockID);
		world.setBlockMetadataWithNotify(i + 11, j + 5, k + 15, Block.stairsStoneBrick.blockID, 4);
		world.setBlock(i + 11, j + 6, k + 3, Block.stoneBrick.blockID);
		world.setBlock(i + 11, j + 6, k + 15, Block.stoneBrick.blockID);
		world.setBlockMetadataWithNotify(i + 11, j + 7, k + 1, Block.stoneSingleSlab.blockID, 13);
		world.setBlockMetadataWithNotify(i + 11, j + 7, k + 2, Block.stoneSingleSlab.blockID, 13);
		world.setBlock(i + 11, j + 7, k + 3, Block.stoneBrick.blockID);
		world.setBlockMetadataWithNotify(i + 11, j + 7, k + 4, Block.stairsStoneBrick.blockID, 4);
		world.setBlockMetadataWithNotify(i + 11, j + 7, k + 5, Block.stairsStoneBrick.blockID, 4);
		world.setBlockMetadataWithNotify(i + 11, j + 7, k + 6, Block.stairsStoneBrick.blockID, 4);
		world.setBlockMetadataWithNotify(i + 11, j + 7, k + 7, Block.stairsStoneBrick.blockID, 4);
		world.setBlockMetadataWithNotify(i + 11, j + 7, k + 8, Block.stairsStoneBrick.blockID, 4);
		world.setBlockMetadataWithNotify(i + 11, j + 7, k + 9, Block.stairsStoneBrick.blockID, 4);
		world.setBlockMetadataWithNotify(i + 11, j + 7, k + 10, Block.stairsStoneBrick.blockID, 4);
		world.setBlockMetadataWithNotify(i + 11, j + 7, k + 11, Block.stairsStoneBrick.blockID, 4);
		world.setBlockMetadataWithNotify(i + 11, j + 7, k + 12, Block.stairsStoneBrick.blockID, 4);
		world.setBlockMetadataWithNotify(i + 11, j + 7, k + 13, Block.stairsStoneBrick.blockID, 4);
		world.setBlockMetadataWithNotify(i + 11, j + 7, k + 14, Block.stairsStoneBrick.blockID, 4);
		world.setBlock(i + 11, j + 7, k + 15, Block.stoneBrick.blockID);
		world.setBlockMetadataWithNotify(i + 11, j + 7, k + 16, Block.stoneSingleSlab.blockID, 13);
		world.setBlockMetadataWithNotify(i + 11, j + 8, k + 0, Block.stairsStoneBrick.blockID, 6);
		world.setBlock(i + 11, j + 8, k + 1, Block.stoneBrick.blockID);
		world.setBlock(i + 11, j + 8, k + 2, Block.stoneBrick.blockID);
		world.setBlock(i + 11, j + 8, k + 3, Block.stoneBrick.blockID);
		world.setBlock(i + 11, j + 8, k + 4, Block.stoneBrick.blockID);
		world.setBlock(i + 11, j + 8, k + 5, Block.stoneBrick.blockID);
		world.setBlock(i + 11, j + 8, k + 6, Block.stoneBrick.blockID);
		world.setBlock(i + 11, j + 8, k + 7, Block.stoneBrick.blockID);
		world.setBlock(i + 11, j + 8, k + 8, Block.stoneBrick.blockID);
		world.setBlock(i + 11, j + 8, k + 9, Block.stoneBrick.blockID);
		world.setBlock(i + 11, j + 8, k + 10, Block.stoneBrick.blockID);
		world.setBlock(i + 11, j + 8, k + 11, Block.stoneBrick.blockID);
		world.setBlock(i + 11, j + 8, k + 12, Block.stoneBrick.blockID);
		world.setBlock(i + 11, j + 8, k + 13, Block.stoneBrick.blockID);
		world.setBlock(i + 11, j + 8, k + 14, Block.stoneBrick.blockID);
		world.setBlock(i + 11, j + 8, k + 15, Block.stoneBrick.blockID);
		world.setBlock(i + 11, j + 8, k + 16, Block.stoneBrick.blockID);
		world.setBlockMetadataWithNotify(i + 11, j + 8, k + 17, Block.stairsStoneBrick.blockID, 7);
		world.setBlock(i + 11, j + 9, k + 0, Block.fenceIron.blockID);
		world.setBlock(i + 11, j + 9, k + 15, Block.glass.blockID);
		//world.setBlock(i + 11, j + 9, k + 17, -117);
		world.setBlock(i + 11, j + 10, k + 15, Block.glass.blockID);
		world.setBlockMetadataWithNotify(i + 11, j + 11, k + 3, Block.stairsStoneBrick.blockID, 4);
		world.setBlockMetadataWithNotify(i + 11, j + 11, k + 5, Block.stoneSingleSlab.blockID, 11);
		world.setBlock(i + 11, j + 11, k + 15, Block.glass.blockID);
		world.setBlock(i + 11, j + 12, k + 3, Block.stoneBrick.blockID);
		world.setBlockMetadataWithNotify(i + 11, j + 12, k + 6, Block.stoneSingleSlab.blockID, 3);
		world.setBlockMetadataWithNotify(i + 11, j + 12, k + 7, Block.stoneSingleSlab.blockID, 11);
		world.setBlock(i + 11, j + 12, k + 15, Block.stoneBrick.blockID);
		world.setBlock(i + 11, j + 13, k + 3, Block.stoneBrick.blockID);
		world.setBlock(i + 11, j + 13, k + 10, Block.stoneBrick.blockID);
		world.setBlockMetadataWithNotify(i + 11, j + 13, k + 11, Block.woodSingleSlab.blockID, 10);
		world.setBlockMetadataWithNotify(i + 11, j + 13, k + 12, Block.woodSingleSlab.blockID, 10);
		world.setBlockMetadataWithNotify(i + 11, j + 13, k + 13, Block.woodSingleSlab.blockID, 10);
		world.setBlockMetadataWithNotify(i + 11, j + 13, k + 14, Block.woodDoubleSlab.blockID, 2);
		world.setBlockMetadataWithNotify(i + 11, j + 13, k + 15, Block.woodDoubleSlab.blockID, 2);
		world.setBlockMetadataWithNotify(i + 11, j + 13, k + 16, Block.woodDoubleSlab.blockID, 2);
		world.setBlock(i + 11, j + 14, k + 3, Block.stoneBrick.blockID);
		world.setBlockMetadataWithNotify(i + 11, j + 14, k + 4, Block.stairsStoneBrick.blockID, 7);
		world.setBlockMetadataWithNotify(i + 11, j + 14, k + 9, Block.stairsStoneBrick.blockID, 6);
		world.setBlock(i + 11, j + 14, k + 10, Block.stoneBrick.blockID);
		world.setBlockMetadataWithNotify(i + 11, j + 14, k + 11, Block.woodSingleSlab.blockID, 2);
		world.setBlockMetadataWithNotify(i + 11, j + 14, k + 12, Block.woodSingleSlab.blockID, 2);
		world.setBlockMetadataWithNotify(i + 11, j + 14, k + 13, Block.woodSingleSlab.blockID, 2);
		world.setBlockMetadataWithNotify(i + 11, j + 15, k + 3, Block.stairsStoneBrick.blockID, 2);
		world.setBlock(i + 11, j + 15, k + 4, Block.stoneBrick.blockID);
		world.setBlockMetadataWithNotify(i + 11, j + 15, k + 5, Block.stoneSingleSlab.blockID, 11);
		world.setBlock(i + 11, j + 15, k + 9, Block.stoneBrick.blockID);
		world.setBlockMetadataWithNotify(i + 11, j + 15, k + 10, Block.stairsStoneBrick.blockID, 3);
		world.setBlock(i + 11, j + 16, k + 4, Block.stoneBrick.blockID);
		world.setBlock(i + 11, j + 16, k + 9, Block.stoneBrick.blockID);
		world.setBlock(i + 11, j + 17, k + 4, Block.glass.blockID);
		world.setBlock(i + 11, j + 17, k + 9, Block.stoneBrick.blockID);
		world.setBlock(i + 11, j + 18, k + 4, Block.stoneBrick.blockID);
		world.setBlock(i + 11, j + 18, k + 9, Block.stoneBrick.blockID);
		world.setBlock(i + 11, j + 19, k + 4, Block.stoneBrick.blockID);
		world.setBlockMetadataWithNotify(i + 11, j + 19, k + 7, Block.stoneSingleSlab.blockID, 11);
		world.setBlockMetadataWithNotify(i + 11, j + 19, k + 8, Block.stoneSingleSlab.blockID, 3);
		world.setBlock(i + 11, j + 19, k + 9, Block.stoneBrick.blockID);
		world.setBlock(i + 11, j + 20, k + 4, Block.stoneBrick.blockID);
		world.setBlockMetadataWithNotify(i + 11, j + 20, k + 6, Block.stoneSingleSlab.blockID, 3);
		world.setBlock(i + 11, j + 20, k + 9, Block.stoneBrick.blockID);
		world.setBlockMetadataWithNotify(i + 11, j + 21, k + 4, Block.stairsStoneBrick.blockID, 2);
		world.setBlock(i + 11, j + 21, k + 5, Block.stoneBrick.blockID);
		world.setBlock(i + 11, j + 21, k + 9, Block.stoneBrick.blockID);
		world.setBlock(i + 11, j + 22, k + 5, Block.stoneBrick.blockID);
		world.setBlock(i + 11, j + 22, k + 9, Block.stoneBrick.blockID);
		world.setBlock(i + 11, j + 23, k + 5, Block.stoneBrick.blockID);
		world.setBlockMetadataWithNotify(i + 11, j + 23, k + 7, Block.stoneSingleSlab.blockID, 11);
		world.setBlockMetadataWithNotify(i + 11, j + 23, k + 8, Block.stoneSingleSlab.blockID, 3);
		world.setBlock(i + 11, j + 23, k + 9, Block.stoneBrick.blockID);
		world.setBlockMetadataWithNotify(i + 11, j + 24, k + 4, Block.stairsStoneBrick.blockID, 6);
		world.setBlock(i + 11, j + 24, k + 5, Block.stoneBrick.blockID);
		world.setBlockMetadataWithNotify(i + 11, j + 24, k + 6, Block.stoneSingleSlab.blockID, 3);
		world.setBlock(i + 11, j + 24, k + 9, Block.stoneBrick.blockID);
		world.setBlockMetadataWithNotify(i + 11, j + 24, k + 10, Block.stairsStoneBrick.blockID, 7);
		world.setBlock(i + 11, j + 25, k + 4, Block.stoneBrick.blockID);
		world.setBlock(i + 11, j + 25, k + 10, Block.stoneBrick.blockID);
		world.setBlock(i + 11, j + 26, k + 4, Block.stoneBrick.blockID);
		world.setBlock(i + 11, j + 26, k + 10, Block.stoneBrick.blockID);
		world.setBlockMetadataWithNotify(i + 11, j + 27, k + 3, Block.woodSingleSlab.blockID, 10);
		world.setBlock(i + 11, j + 27, k + 4, Block.stoneBrick.blockID);
		world.setBlock(i + 11, j + 27, k + 10, Block.stoneBrick.blockID);
		world.setBlockMetadataWithNotify(i + 11, j + 27, k + 11, Block.woodSingleSlab.blockID, 10);
		world.setBlockMetadataWithNotify(i + 11, j + 28, k + 4, Block.woodSingleSlab.blockID, 2);
		world.setBlockMetadataWithNotify(i + 11, j + 28, k + 5, Block.woodSingleSlab.blockID, 10);
		world.setBlockMetadataWithNotify(i + 11, j + 28, k + 6, Block.woodSingleSlab.blockID, 10);
		world.setBlockMetadataWithNotify(i + 11, j + 28, k + 8, Block.woodSingleSlab.blockID, 10);
		world.setBlockMetadataWithNotify(i + 11, j + 28, k + 9, Block.woodSingleSlab.blockID, 10);
		world.setBlockMetadataWithNotify(i + 11, j + 28, k + 10, Block.woodSingleSlab.blockID, 2);
		world.setBlockMetadataWithNotify(i + 11, j + 29, k + 7, Block.woodSingleSlab.blockID, 2);
		world.setBlock(i + 12, j + 0, k + 3, Block.stoneBrick.blockID);
		world.setBlock(i + 12, j + 0, k + 15, Block.stoneBrick.blockID);
		world.setBlockMetadataWithNotify(i + 12, j + 0, k + 17, Block.blockNetherQuartz.blockID, 2);
		world.setBlock(i + 12, j + 1, k + 3, Block.stoneBrick.blockID);
		world.setBlock(i + 12, j + 1, k + 15, Block.stoneBrick.blockID);
		world.setBlockMetadataWithNotify(i + 12, j + 1, k + 17, Block.blockNetherQuartz.blockID, 2);
		world.setBlockMetadataWithNotify(i + 12, j + 2, k + 1, Block.stairsStoneBrick.blockID, 6);
		world.setBlockMetadataWithNotify(i + 12, j + 2, k + 2, Block.stairsStoneBrick.blockID, 5);
		world.setBlock(i + 12, j + 2, k + 3, Block.stoneBrick.blockID);
		world.setBlock(i + 12, j + 2, k + 4, Block.stoneBrick.blockID);
		world.setBlock(i + 12, j + 2, k + 5, Block.stoneBrick.blockID);
		world.setBlock(i + 12, j + 2, k + 6, Block.stoneBrick.blockID);
		world.setBlock(i + 12, j + 2, k + 7, Block.stoneBrick.blockID);
		world.setBlock(i + 12, j + 2, k + 8, Block.stoneBrick.blockID);
		world.setBlock(i + 12, j + 2, k + 9, Block.stoneBrick.blockID);
		world.setBlock(i + 12, j + 2, k + 10, Block.stoneBrick.blockID);
		world.setBlock(i + 12, j + 2, k + 11, Block.stoneBrick.blockID);
		world.setBlock(i + 12, j + 2, k + 12, Block.stoneBrick.blockID);
		world.setBlock(i + 12, j + 2, k + 13, Block.stoneBrick.blockID);
		world.setBlock(i + 12, j + 2, k + 14, Block.stoneBrick.blockID);
		world.setBlock(i + 12, j + 2, k + 15, Block.stoneBrick.blockID);
		world.setBlock(i + 12, j + 2, k + 17, Block.glowStone.blockID);
		world.setBlock(i + 12, j + 3, k + 1, Block.fenceIron.blockID);
		world.setBlock(i + 12, j + 3, k + 2, Block.fenceIron.blockID);
		world.setBlock(i + 12, j + 3, k + 3, Block.stoneBrick.blockID);
		world.setBlockMetadataWithNotify(i + 12, j + 3, k + 5, Block.blockNetherQuartz.blockID, 2);
		world.setBlockMetadataWithNotify(i + 12, j + 3, k + 7, Block.blockNetherQuartz.blockID, 2);
		world.setBlockMetadataWithNotify(i + 12, j + 3, k + 9, Block.blockNetherQuartz.blockID, 2);
		world.setBlockMetadataWithNotify(i + 12, j + 3, k + 11, Block.blockNetherQuartz.blockID, 2);
		world.setBlockMetadataWithNotify(i + 12, j + 3, k + 13, Block.blockNetherQuartz.blockID, 2);
		world.setBlock(i + 12, j + 3, k + 15, Block.stoneBrick.blockID);
		world.setBlockMetadataWithNotify(i + 12, j + 3, k + 17, Block.stoneSingleSlab.blockID, 5);
		world.setBlock(i + 12, j + 4, k + 3, Block.stoneBrick.blockID);
		world.setBlockMetadataWithNotify(i + 12, j + 4, k + 5, Block.blockNetherQuartz.blockID, 2);
		world.setBlockMetadataWithNotify(i + 12, j + 4, k + 7, Block.blockNetherQuartz.blockID, 2);
		world.setBlockMetadataWithNotify(i + 12, j + 4, k + 9, Block.blockNetherQuartz.blockID, 2);
		world.setBlockMetadataWithNotify(i + 12, j + 4, k + 11, Block.blockNetherQuartz.blockID, 2);
		world.setBlockMetadataWithNotify(i + 12, j + 4, k + 13, Block.blockNetherQuartz.blockID, 2);
		world.setBlock(i + 12, j + 4, k + 15, Block.stoneBrick.blockID);
		world.setBlock(i + 12, j + 5, k + 3, Block.stoneBrick.blockID);
		world.setBlockMetadataWithNotify(i + 12, j + 5, k + 5, Block.blockNetherQuartz.blockID, 2);
		world.setBlockMetadataWithNotify(i + 12, j + 5, k + 7, Block.blockNetherQuartz.blockID, 2);
