package minestrapteam.virtious.world.gen;
import java.util.Random;

import minestrapteam.virtious.block.VirtiousFlower;
import minestrapteam.virtious.lib.VirtiousBlocks;

import net.minecraft.block.Block;
import net.minecraft.tileentity.TileEntityMobSpawner;
import net.minecraft.util.MathHelper;
import net.minecraft.world.World;
import net.minecraft.world.gen.feature.WorldGenerator;

public class VirtiousGenCytoidCommandCenter extends WorldGenerator
{
	protected int[] GetValidSpawnBlocks() {
		return new int[] {
		};
	}

	public boolean LocationIsValidSpawn(World world, int i, int j, int k)
	{
		int distanceToAir = 0;
		int checkID = world.getBlockId(i, j, k);

		while (checkID != 0){
			distanceToAir++;
			checkID = world.getBlockId(i, j + distanceToAir, k);
		}

		if (distanceToAir > 3){
			return false;
		}
		j += distanceToAir - 1;

		int blockID = world.getBlockId(i, j, k);
		int blockIDAbove = world.getBlockId(i, j+1, k);
		int blockIDBelow = world.getBlockId(i, j-1, k);
		for (int id : GetValidSpawnBlocks()){
			if (blockIDAbove != 0){
				return false;
			}
			if (blockID == id){
				return true;
			}
			else if (blockID == VirtiousBlocks.virtianGrass.blockID && blockIDBelow == id){
				return true;
			}
		}
		return true;
	}
	public VirtiousGenCytoidCommandCenter() { }

	public boolean generate(World world, Random rand, int i, int j, int k) {
		//check that each corner is one of the valid spawn blocks
		if(!LocationIsValidSpawn(world, i, j, k) || !LocationIsValidSpawn(world, i + 26, j, k) || !LocationIsValidSpawn(world, i + 26, j, k + 27) || !LocationIsValidSpawn(world, i, j, k + 27))
		{
			return false;
		}
		
		int center = getTopSolidBlock(world, i, k);
		int corner1 = getTopSolidBlock(world, i + 20, k);
		int corner2 = getTopSolidBlock(world, i + 20, k + 18);
		int corner3 = getTopSolidBlock(world, i, k + 20);
		
		j =  (int) MathHelper.average(new long[]{center, corner1, corner2, corner3});
		
		for(int y = 0; y < 28; y++)
		{
			for(int x = (int) (2 - y * 0.3); x <= 18 + y * 0.3F ; x++)
			{
				for(int z = (int) (2 - y * 0.3); z <= 17 + y * 0.5F ; z++)
				{
				
					world.setBlockToAir(i + x, j + y, k + z);
				}
			}
		}
		TileEntityMobSpawner tileentitymobspawner;
		
		world.setBlock(i + 0, j + 0, k + 0, 0);
		world.setBlock(i + 0, j + 0, k + 1, 0);
		world.setBlock(i + 0, j + 0, k + 2, 0);
		world.setBlock(i + 0, j + 0, k + 3, 0);
		world.setBlock(i + 0, j + 0, k + 4, 0);
		world.setBlock(i + 0, j + 0, k + 5, 0);
		world.setBlock(i + 0, j + 0, k + 6, 0);
		world.setBlock(i + 0, j + 0, k + 7, 0);
		world.setBlock(i + 0, j + 0, k + 8, 0);
		world.setBlock(i + 0, j + 0, k + 9, 0);
		world.setBlock(i + 0, j + 0, k + 10, getDarkWallId());
		world.setBlock(i + 0, j + 0, k + 11, getDarkWallId());
		world.setBlock(i + 0, j + 0, k + 12, getDarkWallId());
		world.setBlock(i + 0, j + 0, k + 13, getDarkWallId());
		world.setBlock(i + 0, j + 0, k + 14, getDarkWallId());
		world.setBlock(i + 0, j + 0, k + 15, getDarkWallId());
		world.setBlock(i + 0, j + 0, k + 16, getDarkWallId());
		world.setBlock(i + 0, j + 0, k + 17, getDarkWallId());
		world.setBlock(i + 0, j + 0, k + 18, getDarkWallId());
		world.setBlock(i + 0, j + 0, k + 19, getDarkWallId());
		world.setBlock(i + 0, j + 0, k + 20, getDarkWallId());
		world.setBlock(i + 0, j + 0, k + 21, getDarkWallId());
		world.setBlock(i + 0, j + 0, k + 22, getDarkWallId());
		world.setBlock(i + 0, j + 0, k + 23, getDarkWallId());
		world.setBlock(i + 0, j + 0, k + 24, getDarkWallId());
		world.setBlock(i + 0, j + 0, k + 25, 0);
		world.setBlock(i + 0, j + 0, k + 26, 0);
		world.setBlock(i + 0, j + 0, k + 27, 0);
		world.setBlock(i + 0, j + 1, k + 0, 0);
		world.setBlock(i + 0, j + 1, k + 1, 0);
		world.setBlock(i + 0, j + 1, k + 2, 0);
		world.setBlock(i + 0, j + 1, k + 3, 0);
		world.setBlock(i + 0, j + 1, k + 4, 0);
		world.setBlock(i + 0, j + 1, k + 5, 0);
		world.setBlock(i + 0, j + 1, k + 6, 0);
		world.setBlock(i + 0, j + 1, k + 7, 0);
		world.setBlock(i + 0, j + 1, k + 8, 0);
		world.setBlock(i + 0, j + 1, k + 9, 0);
		world.setBlock(i + 0, j + 1, k + 10, getDarkWallId());
		world.setBlock(i + 0, j + 1, k + 11, getDarkWallId());
		world.setBlock(i + 0, j + 1, k + 12, getDarkWallId());
		world.setBlock(i + 0, j + 1, k + 13, getDarkWallId());
		world.setBlock(i + 0, j + 1, k + 14, getDarkWallId());
		world.setBlock(i + 0, j + 1, k + 15, getDarkWallId());
		world.setBlock(i + 0, j + 1, k + 16, getDarkWallId());
		world.setBlock(i + 0, j + 1, k + 17, getDarkWallId());
		world.setBlock(i + 0, j + 1, k + 18, getDarkWallId());
		world.setBlock(i + 0, j + 1, k + 19, getDarkWallId());
		world.setBlock(i + 0, j + 1, k + 20, getDarkWallId());
		world.setBlock(i + 0, j + 1, k + 21, getDarkWallId());
		world.setBlock(i + 0, j + 1, k + 22, getDarkWallId());
		world.setBlock(i + 0, j + 1, k + 23, getDarkWallId());
		world.setBlock(i + 0, j + 1, k + 24, getDarkWallId());
		world.setBlock(i + 0, j + 1, k + 25, 0);
		world.setBlock(i + 0, j + 1, k + 26, 0);
		world.setBlock(i + 0, j + 1, k + 27, 0);
		world.setBlock(i + 0, j + 2, k + 0, 0);
		world.setBlock(i + 0, j + 2, k + 1, 0);
		world.setBlock(i + 0, j + 2, k + 2, 0);
		world.setBlock(i + 0, j + 2, k + 3, 0);
		world.setBlock(i + 0, j + 2, k + 4, 0);
		world.setBlock(i + 0, j + 2, k + 5, 0);
		world.setBlock(i + 0, j + 2, k + 6, 0);
		world.setBlock(i + 0, j + 2, k + 7, 0);
		world.setBlock(i + 0, j + 2, k + 8, 0);
		world.setBlock(i + 0, j + 2, k + 9, 0);
		world.setBlock(i + 0, j + 2, k + 10, getDarkWallId());
		world.setBlock(i + 0, j + 2, k + 11, getDarkWallId());
		world.setBlock(i + 0, j + 2, k + 12, getDarkWallId());
		world.setBlock(i + 0, j + 2, k + 13, getDarkWallId());
		world.setBlock(i + 0, j + 2, k + 14, getDarkWallId());
		world.setBlock(i + 0, j + 2, k + 15, getDarkWallId());
		world.setBlock(i + 0, j + 2, k + 16, getDarkWallId());
		world.setBlock(i + 0, j + 2, k + 17, getDarkWallId());
		world.setBlock(i + 0, j + 2, k + 18, getDarkWallId());
		world.setBlock(i + 0, j + 2, k + 19, getDarkWallId());
		world.setBlock(i + 0, j + 2, k + 20, getDarkWallId());
		world.setBlock(i + 0, j + 2, k + 21, getDarkWallId());
		world.setBlock(i + 0, j + 2, k + 22, getDarkWallId());
		world.setBlock(i + 0, j + 2, k + 23, getDarkWallId());
		world.setBlock(i + 0, j + 2, k + 24, getDarkWallId());
		world.setBlock(i + 0, j + 2, k + 25, 0);
		world.setBlock(i + 0, j + 2, k + 26, 0);
		world.setBlock(i + 0, j + 2, k + 27, 0);
		world.setBlock(i + 0, j + 3, k + 0, 0);
		world.setBlock(i + 0, j + 3, k + 1, 0);
		world.setBlock(i + 0, j + 3, k + 2, 0);
		world.setBlock(i + 0, j + 3, k + 3, 0);
		world.setBlock(i + 0, j + 3, k + 4, 0);
		world.setBlock(i + 0, j + 3, k + 5, 0);
		world.setBlock(i + 0, j + 3, k + 6, 0);
		world.setBlock(i + 0, j + 3, k + 7, 0);
		world.setBlock(i + 0, j + 3, k + 8, 0);
		world.setBlock(i + 0, j + 3, k + 9, 0);
		world.setBlock(i + 0, j + 3, k + 10, getDarkWallId());
		world.setBlock(i + 0, j + 3, k + 11, getDarkWallId());
		world.setBlock(i + 0, j + 3, k + 12, getDarkWallId());
		world.setBlock(i + 0, j + 3, k + 13, getDarkWallId());
		world.setBlock(i + 0, j + 3, k + 14, getDarkWallId());
		world.setBlock(i + 0, j + 3, k + 15, getDarkWallId());
		world.setBlock(i + 0, j + 3, k + 16, getDarkWallId());
		world.setBlock(i + 0, j + 3, k + 17, getDarkWallId());
		world.setBlock(i + 0, j + 3, k + 18, getDarkWallId());
		world.setBlock(i + 0, j + 3, k + 19, getDarkWallId());
		world.setBlock(i + 0, j + 3, k + 20, getDarkWallId());
		world.setBlock(i + 0, j + 3, k + 21, getDarkWallId());
		world.setBlock(i + 0, j + 3, k + 22, getDarkWallId());
		world.setBlock(i + 0, j + 3, k + 23, getDarkWallId());
		world.setBlock(i + 0, j + 3, k + 24, getDarkWallId());
		world.setBlock(i + 0, j + 3, k + 25, 0);
		world.setBlock(i + 0, j + 3, k + 26, 0);
		world.setBlock(i + 0, j + 3, k + 27, 0);
		world.setBlock(i + 0, j + 4, k + 0, 0);
		world.setBlock(i + 0, j + 4, k + 1, 0);
		world.setBlock(i + 0, j + 4, k + 2, 0);
		world.setBlock(i + 0, j + 4, k + 3, 0);
		world.setBlock(i + 0, j + 4, k + 4, 0);
		world.setBlock(i + 0, j + 4, k + 5, 0);
		world.setBlock(i + 0, j + 4, k + 6, 0);
		world.setBlock(i + 0, j + 4, k + 7, 0);
		world.setBlock(i + 0, j + 4, k + 8, 0);
		world.setBlock(i + 0, j + 4, k + 9, 0);
		world.setBlock(i + 0, j + 4, k + 10, getDarkWallId());
		world.setBlock(i + 0, j + 4, k + 11, getDarkWallId());
		world.setBlock(i + 0, j + 4, k + 12, getDarkWallId());
		world.setBlock(i + 0, j + 4, k + 13, getDarkWallId());
		world.setBlock(i + 0, j + 4, k + 14, getDarkWallId());
		world.setBlock(i + 0, j + 4, k + 15, getDarkWallId());
		world.setBlock(i + 0, j + 4, k + 16, getDarkWallId());
		world.setBlock(i + 0, j + 4, k + 17, getDarkWallId());
		world.setBlock(i + 0, j + 4, k + 18, getDarkWallId());
		world.setBlock(i + 0, j + 4, k + 19, getDarkWallId());
		world.setBlock(i + 0, j + 4, k + 20, getDarkWallId());
		world.setBlock(i + 0, j + 4, k + 21, getDarkWallId());
		world.setBlock(i + 0, j + 4, k + 22, getDarkWallId());
		world.setBlock(i + 0, j + 4, k + 23, getDarkWallId());
		world.setBlock(i + 0, j + 4, k + 24, getDarkWallId());
		world.setBlock(i + 0, j + 4, k + 25, 0);
		world.setBlock(i + 0, j + 4, k + 26, 0);
		world.setBlock(i + 0, j + 4, k + 27, 0);
		world.setBlock(i + 0, j + 5, k + 0, 0);
		world.setBlock(i + 0, j + 5, k + 1, 0);
		world.setBlock(i + 0, j + 5, k + 2, 0);
		world.setBlock(i + 0, j + 5, k + 3, 0);
		world.setBlock(i + 0, j + 5, k + 4, 0);
		world.setBlock(i + 0, j + 5, k + 5, 0);
		world.setBlock(i + 0, j + 5, k + 6, 0);
		world.setBlock(i + 0, j + 5, k + 7, 0);
		world.setBlock(i + 0, j + 5, k + 8, 0);
		world.setBlock(i + 0, j + 5, k + 9, 0);
		world.setBlock(i + 0, j + 5, k + 10, getDarkWallId());
		world.setBlock(i + 0, j + 5, k + 11, getDarkWallId());
		world.setBlock(i + 0, j + 5, k + 12, getDarkWallId());
		world.setBlock(i + 0, j + 5, k + 13, getDarkWallId());
		world.setBlock(i + 0, j + 5, k + 14, getDarkWallId());
		world.setBlock(i + 0, j + 5, k + 15, getDarkWallId());
		world.setBlock(i + 0, j + 5, k + 16, getDarkWallId());
		world.setBlock(i + 0, j + 5, k + 17, getDarkWallId());
		world.setBlock(i + 0, j + 5, k + 18, getDarkWallId());
		world.setBlock(i + 0, j + 5, k + 19, getDarkWallId());
		world.setBlock(i + 0, j + 5, k + 20, getDarkWallId());
		world.setBlock(i + 0, j + 5, k + 21, getDarkWallId());
		world.setBlock(i + 0, j + 5, k + 22, getDarkWallId());
		world.setBlock(i + 0, j + 5, k + 23, getDarkWallId());
		world.setBlock(i + 0, j + 5, k + 24, getDarkWallId());
		world.setBlock(i + 0, j + 5, k + 25, 0);
		world.setBlock(i + 0, j + 5, k + 26, 0);
		world.setBlock(i + 0, j + 5, k + 27, 0);
		world.setBlock(i + 0, j + 6, k + 0, 0);
		world.setBlock(i + 0, j + 6, k + 1, 0);
		world.setBlock(i + 0, j + 6, k + 2, 0);
		world.setBlock(i + 0, j + 6, k + 3, 0);
		world.setBlock(i + 0, j + 6, k + 4, 0);
		world.setBlock(i + 0, j + 6, k + 5, 0);
		world.setBlock(i + 0, j + 6, k + 6, 0);
		world.setBlock(i + 0, j + 6, k + 7, 0);
		world.setBlock(i + 0, j + 6, k + 8, 0);
		world.setBlock(i + 0, j + 6, k + 9, 0);
		world.setBlock(i + 0, j + 6, k + 10, getDarkWallId());
		world.setBlock(i + 0, j + 6, k + 11, getDarkWallId());
		world.setBlock(i + 0, j + 6, k + 12, getDarkWallId());
		world.setBlock(i + 0, j + 6, k + 13, getDarkWallId());
		world.setBlock(i + 0, j + 6, k + 14, getDarkWallId());
		world.setBlock(i + 0, j + 6, k + 15, getDarkWallId());
		world.setBlock(i + 0, j + 6, k + 16, getDarkWallId());
		world.setBlock(i + 0, j + 6, k + 17, getDarkWallId());
		world.setBlock(i + 0, j + 6, k + 18, getDarkWallId());
		world.setBlock(i + 0, j + 6, k + 19, getDarkWallId());
		world.setBlock(i + 0, j + 6, k + 20, getDarkWallId());
		world.setBlock(i + 0, j + 6, k + 21, getDarkWallId());
		world.setBlock(i + 0, j + 6, k + 22, getDarkWallId());
		world.setBlock(i + 0, j + 6, k + 23, getDarkWallId());
		world.setBlock(i + 0, j + 6, k + 24, getDarkWallId());
		world.setBlock(i + 0, j + 6, k + 25, 0);
		world.setBlock(i + 0, j + 6, k + 26, 0);
		world.setBlock(i + 0, j + 6, k + 27, 0);
		world.setBlock(i + 0, j + 7, k + 0, 0);
		world.setBlock(i + 0, j + 7, k + 1, 0);
		world.setBlock(i + 0, j + 7, k + 2, 0);
		world.setBlock(i + 0, j + 7, k + 3, 0);
		world.setBlock(i + 0, j + 7, k + 4, 0);
		world.setBlock(i + 0, j + 7, k + 5, 0);
		world.setBlock(i + 0, j + 7, k + 6, 0);
		world.setBlock(i + 0, j + 7, k + 7, 0);
		world.setBlock(i + 0, j + 7, k + 8, 0);
		world.setBlock(i + 0, j + 7, k + 9, 0);
		world.setBlock(i + 0, j + 7, k + 10, getDarkWallId());
		world.setBlock(i + 0, j + 7, k + 11, getDarkWallId());
		world.setBlock(i + 0, j + 7, k + 12, getDarkWallId());
		world.setBlock(i + 0, j + 7, k + 13, getDarkWallId());
		world.setBlock(i + 0, j + 7, k + 14, getDarkWallId());
		world.setBlock(i + 0, j + 7, k + 15, getDarkWallId());
		world.setBlock(i + 0, j + 7, k + 16, getDarkWallId());
		world.setBlock(i + 0, j + 7, k + 17, getDarkWallId());
		world.setBlock(i + 0, j + 7, k + 18, getDarkWallId());
		world.setBlock(i + 0, j + 7, k + 19, getDarkWallId());
		world.setBlock(i + 0, j + 7, k + 20, getDarkWallId());
		world.setBlock(i + 0, j + 7, k + 21, getDarkWallId());
		world.setBlock(i + 0, j + 7, k + 22, getDarkWallId());
		world.setBlock(i + 0, j + 7, k + 23, getDarkWallId());
		world.setBlock(i + 0, j + 7, k + 24, getDarkWallId());
		world.setBlock(i + 0, j + 7, k + 25, 0);
		world.setBlock(i + 0, j + 7, k + 26, 0);
		world.setBlock(i + 0, j + 7, k + 27, 0);
		world.setBlock(i + 0, j + 8, k + 0, 0);
		world.setBlock(i + 0, j + 8, k + 1, 0);
		world.setBlock(i + 0, j + 8, k + 2, 0);
		world.setBlock(i + 0, j + 8, k + 3, 0);
		world.setBlock(i + 0, j + 8, k + 4, 0);
		world.setBlock(i + 0, j + 8, k + 5, 0);
		world.setBlock(i + 0, j + 8, k + 6, 0);
		world.setBlock(i + 0, j + 8, k + 7, 0);
		world.setBlock(i + 0, j + 8, k + 8, 0);
		world.setBlock(i + 0, j + 8, k + 9, 0);
		world.setBlock(i + 0, j + 8, k + 10, getDarkWallId());
		world.setBlock(i + 0, j + 8, k + 11, getDarkWallId());
		world.setBlock(i + 0, j + 8, k + 12, getDarkWallId());
		world.setBlock(i + 0, j + 8, k + 13, getDarkWallId());
		world.setBlock(i + 0, j + 8, k + 14, getDarkWallId());
		world.setBlock(i + 0, j + 8, k + 15, getDarkWallId());
		world.setBlock(i + 0, j + 8, k + 16, getDarkWallId());
		world.setBlock(i + 0, j + 8, k + 17, getDarkWallId());
		world.setBlock(i + 0, j + 8, k + 18, getDarkWallId());
		world.setBlock(i + 0, j + 8, k + 19, getDarkWallId());
		world.setBlock(i + 0, j + 8, k + 20, getDarkWallId());
		world.setBlock(i + 0, j + 8, k + 21, getDarkWallId());
		world.setBlock(i + 0, j + 8, k + 22, getDarkWallId());
		world.setBlock(i + 0, j + 8, k + 23, getDarkWallId());
		world.setBlock(i + 0, j + 8, k + 24, getDarkWallId());
		world.setBlock(i + 0, j + 8, k + 25, 0);
		world.setBlock(i + 0, j + 8, k + 26, 0);
		world.setBlock(i + 0, j + 8, k + 27, 0);
		world.setBlock(i + 0, j + 9, k + 0, 0);
		world.setBlock(i + 0, j + 9, k + 1, 0);
		world.setBlock(i + 0, j + 9, k + 2, 0);
		world.setBlock(i + 0, j + 9, k + 3, 0);
		world.setBlock(i + 0, j + 9, k + 4, 0);
		world.setBlock(i + 0, j + 9, k + 5, 0);
		world.setBlock(i + 0, j + 9, k + 6, 0);
		world.setBlock(i + 0, j + 9, k + 7, 0);
		world.setBlock(i + 0, j + 9, k + 8, 0);
		world.setBlock(i + 0, j + 9, k + 9, 0);
		world.setBlock(i + 0, j + 9, k + 10, getDarkWallId());
		world.setBlock(i + 0, j + 9, k + 11, getDarkWallId());
		world.setBlock(i + 0, j + 9, k + 12, getDarkWallId());
		world.setBlock(i + 0, j + 9, k + 13, getDarkWallId());
		world.setBlock(i + 0, j + 9, k + 14, getDarkWallId());
		world.setBlock(i + 0, j + 9, k + 15, getDarkWallId());
		world.setBlock(i + 0, j + 9, k + 16, getDarkWallId());
		world.setBlock(i + 0, j + 9, k + 17, getDarkWallId());
		world.setBlock(i + 0, j + 9, k + 18, getDarkWallId());
		world.setBlock(i + 0, j + 9, k + 19, getDarkWallId());
		world.setBlock(i + 0, j + 9, k + 20, getDarkWallId());
		world.setBlock(i + 0, j + 9, k + 21, getDarkWallId());
		world.setBlock(i + 0, j + 9, k + 22, getDarkWallId());
		world.setBlock(i + 0, j + 9, k + 23, getDarkWallId());
		world.setBlock(i + 0, j + 9, k + 24, getDarkWallId());
		world.setBlock(i + 0, j + 9, k + 25, 0);
		world.setBlock(i + 0, j + 9, k + 26, 0);
		world.setBlock(i + 0, j + 9, k + 27, 0);
		world.setBlock(i + 0, j + 10, k + 0, 0);
		world.setBlock(i + 0, j + 10, k + 1, 0);
		world.setBlock(i + 0, j + 10, k + 2, 0);
		world.setBlock(i + 0, j + 10, k + 3, 0);
		world.setBlock(i + 0, j + 10, k + 4, 0);
		world.setBlock(i + 0, j + 10, k + 5, 0);
		world.setBlock(i + 0, j + 10, k + 6, 0);
		world.setBlock(i + 0, j + 10, k + 7, 0);
		world.setBlock(i + 0, j + 10, k + 8, 0);
		world.setBlock(i + 0, j + 10, k + 9, 0);
		world.setBlock(i + 0, j + 10, k + 10, getDarkWallId());
		world.setBlock(i + 0, j + 10, k + 11, getDarkWallId());
		world.setBlock(i + 0, j + 10, k + 12, getDarkWallId());
		world.setBlock(i + 0, j + 10, k + 13, getDarkWallId());
		world.setBlock(i + 0, j + 10, k + 14, getDarkWallId());
		world.setBlock(i + 0, j + 10, k + 15, getDarkWallId());
		world.setBlock(i + 0, j + 10, k + 16, getDarkWallId());
		world.setBlock(i + 0, j + 10, k + 17, getDarkWallId());
		world.setBlock(i + 0, j + 10, k + 18, getDarkWallId());
		world.setBlock(i + 0, j + 10, k + 19, getDarkWallId());
		world.setBlock(i + 0, j + 10, k + 20, getDarkWallId());
		world.setBlock(i + 0, j + 10, k + 21, getDarkWallId());
		world.setBlock(i + 0, j + 10, k + 22, getDarkWallId());
		world.setBlock(i + 0, j + 10, k + 23, getDarkWallId());
		world.setBlock(i + 0, j + 10, k + 24, getDarkWallId());
		world.setBlock(i + 0, j + 10, k + 25, 0);
		world.setBlock(i + 0, j + 10, k + 26, 0);
		world.setBlock(i + 0, j + 10, k + 27, 0);
		world.setBlock(i + 1, j + 0, k + 0, 0);
		world.setBlock(i + 1, j + 0, k + 1, 0);
		world.setBlock(i + 1, j + 0, k + 2, 0);
		world.setBlock(i + 1, j + 0, k + 3, 0);
		world.setBlock(i + 1, j + 0, k + 4, 0);
		world.setBlock(i + 1, j + 0, k + 5, 0);
		world.setBlock(i + 1, j + 0, k + 6, 0);
		world.setBlock(i + 1, j + 0, k + 7, 0);
		world.setBlock(i + 1, j + 0, k + 8, 0);
		world.setBlock(i + 1, j + 0, k + 9, 0);
		world.setBlock(i + 1, j + 0, k + 10, getDarkWallId());
		world.setBlock(i + 1, j + 0, k + 11, getDarkWallId());
		world.setBlock(i + 1, j + 0, k + 12, getDarkWallId());
		world.setBlock(i + 1, j + 0, k + 13, getDarkWallId());
		world.setBlock(i + 1, j + 0, k + 14, getDarkWallId());
		world.setBlock(i + 1, j + 0, k + 15, getDarkWallId());
		world.setBlock(i + 1, j + 0, k + 16, getDarkWallId());
		world.setBlock(i + 1, j + 0, k + 17, getDarkWallId());
		world.setBlock(i + 1, j + 0, k + 18, getDarkWallId());
		world.setBlock(i + 1, j + 0, k + 19, getDarkWallId());
		world.setBlock(i + 1, j + 0, k + 20, getDarkWallId());
		world.setBlock(i + 1, j + 0, k + 21, getDarkWallId());
		world.setBlock(i + 1, j + 0, k + 22, getDarkWallId());
		world.setBlock(i + 1, j + 0, k + 23, getDarkWallId());
		world.setBlock(i + 1, j + 0, k + 24, getDarkWallId());
		world.setBlock(i + 1, j + 0, k + 25, 0);
		world.setBlock(i + 1, j + 0, k + 26, 0);
		world.setBlock(i + 1, j + 0, k + 27, 0);
		world.setBlock(i + 1, j + 1, k + 0, 0);
		world.setBlock(i + 1, j + 1, k + 1, 0);
		world.setBlock(i + 1, j + 1, k + 2, 0);
		world.setBlock(i + 1, j + 1, k + 3, 0);
		world.setBlock(i + 1, j + 1, k + 4, 0);
		world.setBlock(i + 1, j + 1, k + 5, 0);
		world.setBlock(i + 1, j + 1, k + 6, 0);
		world.setBlock(i + 1, j + 1, k + 7, 0);
		world.setBlock(i + 1, j + 1, k + 8, 0);
		world.setBlock(i + 1, j + 1, k + 9, 0);
		world.setBlock(i + 1, j + 1, k + 10, getDarkWallId());
		world.setBlock(i + 1, j + 1, k + 11, 0);
		world.setBlock(i + 1, j + 1, k + 12, 0);
		world.setBlock(i + 1, j + 1, k + 13, 0);
		world.setBlock(i + 1, j + 1, k + 14, 0);
		world.setBlock(i + 1, j + 1, k + 15, 0);
		world.setBlock(i + 1, j + 1, k + 16, 0);
		world.setBlock(i + 1, j + 1, k + 17, 0);
		world.setBlock(i + 1, j + 1, k + 18, 0);
		world.setBlock(i + 1, j + 1, k + 19, 0);
		world.setBlock(i + 1, j + 1, k + 20, 0);
		world.setBlock(i + 1, j + 1, k + 21, 0);
		world.setBlock(i + 1, j + 1, k + 22, 0);
		world.setBlock(i + 1, j + 1, k + 23, 0);
		world.setBlock(i + 1, j + 1, k + 24, getDarkWallId());
		world.setBlock(i + 1, j + 1, k + 25, 0);
		world.setBlock(i + 1, j + 1, k + 26, 0);
		world.setBlock(i + 1, j + 1, k + 27, 0);
		world.setBlock(i + 1, j + 2, k + 0, 0);
		world.setBlock(i + 1, j + 2, k + 1, 0);
		world.setBlock(i + 1, j + 2, k + 2, 0);
		world.setBlock(i + 1, j + 2, k + 3, 0);
		world.setBlock(i + 1, j + 2, k + 4, 0);
		world.setBlock(i + 1, j + 2, k + 5, 0);
		world.setBlock(i + 1, j + 2, k + 6, 0);
		world.setBlock(i + 1, j + 2, k + 7, 0);
		world.setBlock(i + 1, j + 2, k + 8, 0);
		world.setBlock(i + 1, j + 2, k + 9, 0);
		world.setBlock(i + 1, j + 2, k + 10, getDarkWallId());
		world.setBlock(i + 1, j + 2, k + 11, 0);
		world.setBlock(i + 1, j + 2, k + 12, 0);
		world.setBlock(i + 1, j + 2, k + 13, 0);
		world.setBlock(i + 1, j + 2, k + 14, 0);
		world.setBlock(i + 1, j + 2, k + 15, 0);
		world.setBlock(i + 1, j + 2, k + 16, 0);
		world.setBlock(i + 1, j + 2, k + 17, 0);
		world.setBlock(i + 1, j + 2, k + 18, 0);
		world.setBlock(i + 1, j + 2, k + 19, 0);
		world.setBlock(i + 1, j + 2, k + 20, 0);
		world.setBlock(i + 1, j + 2, k + 21, 0);
		world.setBlock(i + 1, j + 2, k + 22, 0);
		world.setBlock(i + 1, j + 2, k + 23, 0);
		world.setBlock(i + 1, j + 2, k + 24, getDarkWallId());
		world.setBlock(i + 1, j + 2, k + 25, 0);
		world.setBlock(i + 1, j + 2, k + 26, 0);
		world.setBlock(i + 1, j + 2, k + 27, 0);
		world.setBlock(i + 1, j + 3, k + 0, 0);
		world.setBlock(i + 1, j + 3, k + 1, 0);
		world.setBlock(i + 1, j + 3, k + 2, 0);
		world.setBlock(i + 1, j + 3, k + 3, 0);
		world.setBlock(i + 1, j + 3, k + 4, 0);
		world.setBlock(i + 1, j + 3, k + 5, 0);
		world.setBlock(i + 1, j + 3, k + 6, 0);
		world.setBlock(i + 1, j + 3, k + 7, 0);
		world.setBlock(i + 1, j + 3, k + 8, 0);
		world.setBlock(i + 1, j + 3, k + 9, 0);
		world.setBlock(i + 1, j + 3, k + 10, getDarkWallId());
		world.setBlock(i + 1, j + 3, k + 11, 0);
		world.setBlock(i + 1, j + 3, k + 12, VirtiousBlocks.cytoidWallLower.blockID);
		world.setBlock(i + 1, j + 3, k + 13, VirtiousBlocks.cytoidWallLower.blockID);
		world.setBlock(i + 1, j + 3, k + 14, VirtiousBlocks.cytoidWallLower.blockID);
		world.setBlock(i + 1, j + 3, k + 15, VirtiousBlocks.cytoidWallLower.blockID);
		world.setBlock(i + 1, j + 3, k + 16, 0);
		world.setBlock(i + 1, j + 3, k + 17, 0);
		world.setBlock(i + 1, j + 3, k + 18, 0);
		world.setBlock(i + 1, j + 3, k + 19, 0);
		world.setBlock(i + 1, j + 3, k + 20, 0);
		world.setBlock(i + 1, j + 3, k + 21, 0);
		world.setBlock(i + 1, j + 3, k + 22, 0);
		world.setBlock(i + 1, j + 3, k + 23, 0);
		world.setBlock(i + 1, j + 3, k + 24, getDarkWallId());
		world.setBlock(i + 1, j + 3, k + 25, 0);
		world.setBlock(i + 1, j + 3, k + 26, 0);
		world.setBlock(i + 1, j + 3, k + 27, 0);
		world.setBlock(i + 1, j + 4, k + 0, 0);
		world.setBlock(i + 1, j + 4, k + 1, 0);
		world.setBlock(i + 1, j + 4, k + 2, 0);
		world.setBlock(i + 1, j + 4, k + 3, 0);
		world.setBlock(i + 1, j + 4, k + 4, 0);
		world.setBlock(i + 1, j + 4, k + 5, 0);
		world.setBlock(i + 1, j + 4, k + 6, 0);
		world.setBlock(i + 1, j + 4, k + 7, 0);
		world.setBlock(i + 1, j + 4, k + 8, 0);
		world.setBlock(i + 1, j + 4, k + 9, 0);
		world.setBlock(i + 1, j + 4, k + 10, getDarkWallId());
		world.setBlock(i + 1, j + 4, k + 11, 0);
		world.setBlock(i + 1, j + 4, k + 12, VirtiousBlocks.cytoidWallUpper.blockID);
		world.setBlock(i + 1, j + 4, k + 13, VirtiousBlocks.cytoidWallUpper.blockID);
		world.setBlock(i + 1, j + 4, k + 14, VirtiousBlocks.cytoidWallUpper.blockID);
		world.setBlock(i + 1, j + 4, k + 15, VirtiousBlocks.cytoidWallUpper.blockID);
		world.setBlock(i + 1, j + 4, k + 16, VirtiousBlocks.cytoidWallUpper.blockID);
		world.setBlock(i + 1, j + 4, k + 17, VirtiousBlocks.cytoidWallUpper.blockID);
		world.setBlock(i + 1, j + 4, k + 18, 0);
		world.setBlock(i + 1, j + 4, k + 19, 0);
		world.setBlock(i + 1, j + 4, k + 20, 0);
		world.setBlock(i + 1, j + 4, k + 21, 0);
		world.setBlock(i + 1, j + 4, k + 22, 0);
		world.setBlock(i + 1, j + 4, k + 23, 0);
		world.setBlock(i + 1, j + 4, k + 24, getDarkWallId());
		world.setBlock(i + 1, j + 4, k + 25, 0);
		world.setBlock(i + 1, j + 4, k + 26, 0);
		world.setBlock(i + 1, j + 4, k + 27, 0);
		world.setBlock(i + 1, j + 5, k + 0, 0);
		world.setBlock(i + 1, j + 5, k + 1, 0);
		world.setBlock(i + 1, j + 5, k + 2, 0);
		world.setBlock(i + 1, j + 5, k + 3, 0);
		world.setBlock(i + 1, j + 5, k + 4, 0);
		world.setBlock(i + 1, j + 5, k + 5, 0);
		world.setBlock(i + 1, j + 5, k + 6, 0);
		world.setBlock(i + 1, j + 5, k + 7, 0);
		world.setBlock(i + 1, j + 5, k + 8, 0);
		world.setBlock(i + 1, j + 5, k + 9, 0);
		world.setBlock(i + 1, j + 5, k + 10, getDarkWallId());
		world.setBlock(i + 1, j + 5, k + 11, 0);
		world.setBlock(i + 1, j + 5, k + 12, VirtiousBlocks.cytoidLightstrip.blockID);
		world.setBlock(i + 1, j + 5, k + 13, VirtiousBlocks.cytoidLightstrip.blockID);
		world.setBlock(i + 1, j + 5, k + 14, VirtiousBlocks.cytoidLightstrip.blockID);
		world.setBlock(i + 1, j + 5, k + 15, VirtiousBlocks.cytoidLightstrip.blockID);
		world.setBlock(i + 1, j + 5, k + 16, VirtiousBlocks.cytoidLightstrip.blockID);
		world.setBlock(i + 1, j + 5, k + 17, VirtiousBlocks.cytoidLightstrip.blockID);
		world.setBlock(i + 1, j + 5, k + 18, VirtiousBlocks.cytoidLightstrip.blockID);
		world.setBlock(i + 1, j + 5, k + 19, 0);
		world.setBlock(i + 1, j + 5, k + 20, 0);
		world.setBlock(i + 1, j + 5, k + 21, 0);
		world.setBlock(i + 1, j + 5, k + 22, 0);
		world.setBlock(i + 1, j + 5, k + 23, 0);
		world.setBlock(i + 1, j + 5, k + 24, getDarkWallId());
		world.setBlock(i + 1, j + 5, k + 25, 0);
		world.setBlock(i + 1, j + 5, k + 26, 0);
		world.setBlock(i + 1, j + 5, k + 27, 0);
		world.setBlock(i + 1, j + 6, k + 0, 0);
		world.setBlock(i + 1, j + 6, k + 1, 0);
		world.setBlock(i + 1, j + 6, k + 2, 0);
		world.setBlock(i + 1, j + 6, k + 3, 0);
		world.setBlock(i + 1, j + 6, k + 4, 0);
		world.setBlock(i + 1, j + 6, k + 5, 0);
		world.setBlock(i + 1, j + 6, k + 6, 0);
		world.setBlock(i + 1, j + 6, k + 7, 0);
		world.setBlock(i + 1, j + 6, k + 8, 0);
		world.setBlock(i + 1, j + 6, k + 9, 0);
		world.setBlock(i + 1, j + 6, k + 10, getDarkWallId());
		world.setBlock(i + 1, j + 6, k + 11, 0);
		world.setBlock(i + 1, j + 6, k + 12, VirtiousBlocks.cytoidWallLower.blockID);
		world.setBlock(i + 1, j + 6, k + 13, VirtiousBlocks.cytoidWallLower.blockID);
		world.setBlock(i + 1, j + 6, k + 14, VirtiousBlocks.cytoidWallLower.blockID);
		world.setBlock(i + 1, j + 6, k + 15, VirtiousBlocks.cytoidWallLower.blockID);
		world.setBlock(i + 1, j + 6, k + 16, VirtiousBlocks.cytoidWallLower.blockID);
		world.setBlock(i + 1, j + 6, k + 17, VirtiousBlocks.cytoidWallLower.blockID);
		world.setBlock(i + 1, j + 6, k + 18, VirtiousBlocks.cytoidWallLower.blockID);
		world.setBlock(i + 1, j + 6, k + 19, VirtiousBlocks.cytoidWallLower.blockID);
		world.setBlock(i + 1, j + 6, k + 20, VirtiousBlocks.cytoidWallLower.blockID);
		world.setBlock(i + 1, j + 6, k + 21, VirtiousBlocks.cytoidWallLower.blockID);
		world.setBlock(i + 1, j + 6, k + 22, 0);
		world.setBlock(i + 1, j + 6, k + 23, 0);
		world.setBlock(i + 1, j + 6, k + 24, getDarkWallId());
		world.setBlock(i + 1, j + 6, k + 25, 0);
		world.setBlock(i + 1, j + 6, k + 26, 0);
		world.setBlock(i + 1, j + 6, k + 27, 0);
		world.setBlock(i + 1, j + 7, k + 0, 0);
		world.setBlock(i + 1, j + 7, k + 1, 0);
		world.setBlock(i + 1, j + 7, k + 2, 0);
		world.setBlock(i + 1, j + 7, k + 3, 0);
		world.setBlock(i + 1, j + 7, k + 4, 0);
		world.setBlock(i + 1, j + 7, k + 5, 0);
		world.setBlock(i + 1, j + 7, k + 6, 0);
		world.setBlock(i + 1, j + 7, k + 7, 0);
		world.setBlock(i + 1, j + 7, k + 8, 0);
		world.setBlock(i + 1, j + 7, k + 9, 0);
		world.setBlock(i + 1, j + 7, k + 10, getDarkWallId());
		world.setBlock(i + 1, j + 7, k + 11, 0);
		world.setBlock(i + 1, j + 7, k + 12, VirtiousBlocks.cytoidWallUpper.blockID);
		world.setBlock(i + 1, j + 7, k + 13, VirtiousBlocks.cytoidWallUpper.blockID);
		world.setBlock(i + 1, j + 7, k + 14, VirtiousBlocks.cytoidWallUpper.blockID);
		world.setBlock(i + 1, j + 7, k + 15, VirtiousBlocks.cytoidWallUpper.blockID);
		world.setBlock(i + 1, j + 7, k + 16, VirtiousBlocks.cytoidWallUpper.blockID);
		world.setBlock(i + 1, j + 7, k + 17, VirtiousBlocks.cytoidWallUpper.blockID);
		world.setBlock(i + 1, j + 7, k + 18, VirtiousBlocks.cytoidWallUpper.blockID);
		world.setBlock(i + 1, j + 7, k + 19, VirtiousBlocks.cytoidWallUpper.blockID);
		world.setBlock(i + 1, j + 7, k + 20, VirtiousBlocks.cytoidWallUpper.blockID);
		world.setBlock(i + 1, j + 7, k + 21, VirtiousBlocks.cytoidWallUpper.blockID);
		world.setBlock(i + 1, j + 7, k + 22, 0);
		world.setBlock(i + 1, j + 7, k + 23, 0);
		world.setBlock(i + 1, j + 7, k + 24, getDarkWallId());
		world.setBlock(i + 1, j + 7, k + 25, 0);
		world.setBlock(i + 1, j + 7, k + 26, 0);
		world.setBlock(i + 1, j + 7, k + 27, 0);
		world.setBlock(i + 1, j + 8, k + 0, 0);
		world.setBlock(i + 1, j + 8, k + 1, 0);
		world.setBlock(i + 1, j + 8, k + 2, 0);
		world.setBlock(i + 1, j + 8, k + 3, 0);
		world.setBlock(i + 1, j + 8, k + 4, 0);
		world.setBlock(i + 1, j + 8, k + 5, 0);
		world.setBlock(i + 1, j + 8, k + 6, 0);
		world.setBlock(i + 1, j + 8, k + 7, 0);
		world.setBlock(i + 1, j + 8, k + 8, 0);
		world.setBlock(i + 1, j + 8, k + 9, 0);
		world.setBlock(i + 1, j + 8, k + 10, getDarkWallId());
		world.setBlock(i + 1, j + 8, k + 11, 0);
		world.setBlock(i + 1, j + 8, k + 12, 0);
		world.setBlock(i + 1, j + 8, k + 13, 0);
		world.setBlock(i + 1, j + 8, k + 14, 0);
		world.setBlock(i + 1, j + 8, k + 15, 0);
		world.setBlock(i + 1, j + 8, k + 16, 0);
		world.setBlock(i + 1, j + 8, k + 17, 0);
		world.setBlock(i + 1, j + 8, k + 18, 0);
		world.setBlock(i + 1, j + 8, k + 19, 0);
		world.setBlock(i + 1, j + 8, k + 20, 0);
		world.setBlock(i + 1, j + 8, k + 21, 0);
		world.setBlock(i + 1, j + 8, k + 22, 0);
		world.setBlock(i + 1, j + 8, k + 23, 0);
		world.setBlock(i + 1, j + 8, k + 24, getDarkWallId());
		world.setBlock(i + 1, j + 8, k + 25, 0);
		world.setBlock(i + 1, j + 8, k + 26, 0);
		world.setBlock(i + 1, j + 8, k + 27, 0);
		world.setBlock(i + 1, j + 9, k + 0, 0);
		world.setBlock(i + 1, j + 9, k + 1, 0);
		world.setBlock(i + 1, j + 9, k + 2, 0);
		world.setBlock(i + 1, j + 9, k + 3, 0);
		world.setBlock(i + 1, j + 9, k + 4, 0);
		world.setBlock(i + 1, j + 9, k + 5, 0);
		world.setBlock(i + 1, j + 9, k + 6, 0);
		world.setBlock(i + 1, j + 9, k + 7, 0);
		world.setBlock(i + 1, j + 9, k + 8, 0);
		world.setBlock(i + 1, j + 9, k + 9, 0);
		world.setBlock(i + 1, j + 9, k + 10, getDarkWallId());
		world.setBlock(i + 1, j + 9, k + 11, 0);
		world.setBlock(i + 1, j + 9, k + 12, 0);
		world.setBlock(i + 1, j + 9, k + 13, 0);
		world.setBlock(i + 1, j + 9, k + 14, 0);
		world.setBlock(i + 1, j + 9, k + 15, 0);
		world.setBlock(i + 1, j + 9, k + 16, 0);
		world.setBlock(i + 1, j + 9, k + 17, 0);
		world.setBlock(i + 1, j + 9, k + 18, 0);
		world.setBlock(i + 1, j + 9, k + 19, 0);
		world.setBlock(i + 1, j + 9, k + 20, 0);
		world.setBlock(i + 1, j + 9, k + 21, 0);
		world.setBlock(i + 1, j + 9, k + 22, 0);
		world.setBlock(i + 1, j + 9, k + 23, 0);
		world.setBlock(i + 1, j + 9, k + 24, getDarkWallId());
		world.setBlock(i + 1, j + 9, k + 25, 0);
		world.setBlock(i + 1, j + 9, k + 26, 0);
		world.setBlock(i + 1, j + 9, k + 27, 0);
		world.setBlock(i + 1, j + 10, k + 0, 0);
		world.setBlock(i + 1, j + 10, k + 1, 0);
		world.setBlock(i + 1, j + 10, k + 2, 0);
		world.setBlock(i + 1, j + 10, k + 3, 0);
		world.setBlock(i + 1, j + 10, k + 4, 0);
		world.setBlock(i + 1, j + 10, k + 5, 0);
		world.setBlock(i + 1, j + 10, k + 6, 0);
		world.setBlock(i + 1, j + 10, k + 7, 0);
		world.setBlock(i + 1, j + 10, k + 8, 0);
		world.setBlock(i + 1, j + 10, k + 9, 0);
		world.setBlock(i + 1, j + 10, k + 10, getDarkWallId());
		world.setBlock(i + 1, j + 10, k + 11, getDarkWallId());
		world.setBlock(i + 1, j + 10, k + 12, getDarkWallId());
		world.setBlock(i + 1, j + 10, k + 13, getDarkWallId());
		world.setBlock(i + 1, j + 10, k + 14, getDarkWallId());
		world.setBlock(i + 1, j + 10, k + 15, getDarkWallId());
		world.setBlock(i + 1, j + 10, k + 16, getDarkWallId());
		world.setBlock(i + 1, j + 10, k + 17, getDarkWallId());
		world.setBlock(i + 1, j + 10, k + 18, getDarkWallId());
		world.setBlock(i + 1, j + 10, k + 19, getDarkWallId());
		world.setBlock(i + 1, j + 10, k + 20, getDarkWallId());
		world.setBlock(i + 1, j + 10, k + 21, getDarkWallId());
		world.setBlock(i + 1, j + 10, k + 22, getDarkWallId());
		world.setBlock(i + 1, j + 10, k + 23, getDarkWallId());
		world.setBlock(i + 1, j + 10, k + 24, getDarkWallId());
		world.setBlock(i + 1, j + 10, k + 25, 0);
		world.setBlock(i + 1, j + 10, k + 26, 0);
		world.setBlock(i + 1, j + 10, k + 27, 0);
		world.setBlock(i + 2, j + 0, k + 0, 0);
		world.setBlock(i + 2, j + 0, k + 1, 0);
		world.setBlock(i + 2, j + 0, k + 2, 0);
		world.setBlock(i + 2, j + 0, k + 3, 0);
		world.setBlock(i + 2, j + 0, k + 4, 0);
		world.setBlock(i + 2, j + 0, k + 5, 0);
		world.setBlock(i + 2, j + 0, k + 6, 0);
		world.setBlock(i + 2, j + 0, k + 7, 0);
		world.setBlock(i + 2, j + 0, k + 8, 0);
		world.setBlock(i + 2, j + 0, k + 9, 0);
		world.setBlock(i + 2, j + 0, k + 10, getDarkWallId());
		world.setBlock(i + 2, j + 0, k + 11, getDarkWallId());
		world.setBlock(i + 2, j + 0, k + 12, getDarkWallId());
		world.setBlock(i + 2, j + 0, k + 13, getDarkWallId());
		world.setBlock(i + 2, j + 0, k + 14, getDarkWallId());
		world.setBlock(i + 2, j + 0, k + 15, getDarkWallId());
		world.setBlock(i + 2, j + 0, k + 16, getDarkWallId());
		world.setBlock(i + 2, j + 0, k + 17, getDarkWallId());
		world.setBlock(i + 2, j + 0, k + 18, getDarkWallId());
		world.setBlock(i + 2, j + 0, k + 19, getDarkWallId());
		world.setBlock(i + 2, j + 0, k + 20, getDarkWallId());
		world.setBlock(i + 2, j + 0, k + 21, getDarkWallId());
		world.setBlock(i + 2, j + 0, k + 22, getDarkWallId());
		world.setBlock(i + 2, j + 0, k + 23, getDarkWallId());
		world.setBlock(i + 2, j + 0, k + 24, getDarkWallId());
		world.setBlock(i + 2, j + 0, k + 25, 0);
		world.setBlock(i + 2, j + 0, k + 26, 0);
		world.setBlock(i + 2, j + 0, k + 27, 0);
		world.setBlock(i + 2, j + 1, k + 0, 0);
		world.setBlock(i + 2, j + 1, k + 1, 0);
		world.setBlock(i + 2, j + 1, k + 2, 0);
		world.setBlock(i + 2, j + 1, k + 3, 0);
		world.setBlock(i + 2, j + 1, k + 4, 0);
		world.setBlock(i + 2, j + 1, k + 5, 0);
		world.setBlock(i + 2, j + 1, k + 6, 0);
		world.setBlock(i + 2, j + 1, k + 7, 0);
		world.setBlock(i + 2, j + 1, k + 8, 0);
		world.setBlock(i + 2, j + 1, k + 9, 0);
		world.setBlock(i + 2, j + 1, k + 10, getDarkWallId());
		world.setBlock(i + 2, j + 1, k + 11, 0);
		world.setBlock(i + 2, j + 1, k + 12, 0);
		world.setBlock(i + 2, j + 1, k + 13, 0);
		world.setBlock(i + 2, j + 1, k + 14, 0);
		world.setBlock(i + 2, j + 1, k + 15, 0);
		world.setBlock(i + 2, j + 1, k + 16, 0);
		world.setBlock(i + 2, j + 1, k + 17, 0);
		world.setBlock(i + 2, j + 1, k + 18, 0);
		world.setBlock(i + 2, j + 1, k + 19, 0);
		world.setBlock(i + 2, j + 1, k + 20, 0);
		world.setBlock(i + 2, j + 1, k + 21, 0);
		world.setBlock(i + 2, j + 1, k + 22, 0);
		world.setBlock(i + 2, j + 1, k + 23, 0);
		world.setBlock(i + 2, j + 1, k + 24, getDarkWallId());
		world.setBlock(i + 2, j + 1, k + 25, 0);
		world.setBlock(i + 2, j + 1, k + 26, 0);
		world.setBlock(i + 2, j + 1, k + 27, 0);
		world.setBlock(i + 2, j + 2, k + 0, 0);
		world.setBlock(i + 2, j + 2, k + 1, 0);
		world.setBlock(i + 2, j + 2, k + 2, 0);
		world.setBlock(i + 2, j + 2, k + 3, 0);
		world.setBlock(i + 2, j + 2, k + 4, 0);
		world.setBlock(i + 2, j + 2, k + 5, 0);
		world.setBlock(i + 2, j + 2, k + 6, 0);
		world.setBlock(i + 2, j + 2, k + 7, 0);
		world.setBlock(i + 2, j + 2, k + 8, 0);
		world.setBlock(i + 2, j + 2, k + 9, 0);
		world.setBlock(i + 2, j + 2, k + 10, getDarkWallId());
		world.setBlock(i + 2, j + 2, k + 11, 0);
		world.setBlock(i + 2, j + 2, k + 12, VirtiousBlocks.cytoidFloorDouble.blockID, 0, 2);
		world.setBlock(i + 2, j + 2, k + 13, VirtiousBlocks.cytoidFloorDouble.blockID, 0, 2);
		world.setBlock(i + 2, j + 2, k + 14, 0);
		world.setBlock(i + 2, j + 2, k + 15, 0);
		world.setBlock(i + 2, j + 2, k + 16, 0);
		world.setBlock(i + 2, j + 2, k + 17, 0);
		world.setBlock(i + 2, j + 2, k + 18, 0);
		world.setBlock(i + 2, j + 2, k + 19, 0);
		world.setBlock(i + 2, j + 2, k + 20, 0);
		world.setBlock(i + 2, j + 2, k + 21, 0);
		world.setBlock(i + 2, j + 2, k + 22, 0);
		world.setBlock(i + 2, j + 2, k + 23, 0);
		world.setBlock(i + 2, j + 2, k + 24, getDarkWallId());
		world.setBlock(i + 2, j + 2, k + 25, 0);
		world.setBlock(i + 2, j + 2, k + 26, 0);
		world.setBlock(i + 2, j + 2, k + 27, 0);
		world.setBlock(i + 2, j + 3, k + 0, 0);
		world.setBlock(i + 2, j + 3, k + 1, 0);
		world.setBlock(i + 2, j + 3, k + 2, 0);
		world.setBlock(i + 2, j + 3, k + 3, 0);
		world.setBlock(i + 2, j + 3, k + 4, 0);
		world.setBlock(i + 2, j + 3, k + 5, 0);
		world.setBlock(i + 2, j + 3, k + 6, 0);
		world.setBlock(i + 2, j + 3, k + 7, 0);
		world.setBlock(i + 2, j + 3, k + 8, 0);
		world.setBlock(i + 2, j + 3, k + 9, 0);
		world.setBlock(i + 2, j + 3, k + 10, getDarkWallId());
		world.setBlock(i + 2, j + 3, k + 11, VirtiousBlocks.cytoidWallLower.blockID);
		world.setBlock(i + 2, j + 3, k + 12, 0);
		world.setBlock(i + 2, j + 3, k + 13, 0);
		world.setBlock(i + 2, j + 3, k + 14, VirtiousBlocks.cytoidFloor.blockID, 0, 2);
		world.setBlock(i + 2, j + 3, k + 15, VirtiousBlocks.cytoidFloorDouble.blockID, 0, 2);
		world.setBlock(i + 2, j + 3, k + 16, 0);
		world.setBlock(i + 2, j + 3, k + 17, 0);
		world.setBlock(i + 2, j + 3, k + 18, 0);
		world.setBlock(i + 2, j + 3, k + 19, 0);
		world.setBlock(i + 2, j + 3, k + 20, 0);
		world.setBlock(i + 2, j + 3, k + 21, 0);
		world.setBlock(i + 2, j + 3, k + 22, 0);
		world.setBlock(i + 2, j + 3, k + 23, 0);
		world.setBlock(i + 2, j + 3, k + 24, getDarkWallId());
		world.setBlock(i + 2, j + 3, k + 25, 0);
		world.setBlock(i + 2, j + 3, k + 26, 0);
		world.setBlock(i + 2, j + 3, k + 27, 0);
		world.setBlock(i + 2, j + 4, k + 0, 0);
		world.setBlock(i + 2, j + 4, k + 1, 0);
		world.setBlock(i + 2, j + 4, k + 2, 0);
		world.setBlock(i + 2, j + 4, k + 3, 0);
		world.setBlock(i + 2, j + 4, k + 4, 0);
		world.setBlock(i + 2, j + 4, k + 5, 0);
		world.setBlock(i + 2, j + 4, k + 6, 0);
		world.setBlock(i + 2, j + 4, k + 7, 0);
		world.setBlock(i + 2, j + 4, k + 8, 0);
		world.setBlock(i + 2, j + 4, k + 9, 0);
		world.setBlock(i + 2, j + 4, k + 10, getDarkWallId());
		world.setBlock(i + 2, j + 4, k + 11, VirtiousBlocks.cytoidWallUpper.blockID);
		world.setBlock(i + 2, j + 4, k + 12, 0);
		world.setBlock(i + 2, j + 4, k + 13, 0);
		world.setBlock(i + 2, j + 4, k + 14, 0);
		world.setBlock(i + 2, j + 4, k + 15, 0);
		world.setBlock(i + 2, j + 4, k + 16, VirtiousBlocks.cytoidFloor.blockID, 0, 2);
		world.setBlock(i + 2, j + 4, k + 17, VirtiousBlocks.cytoidFloorDouble.blockID, 0, 2);
		world.setBlock(i + 2, j + 4, k + 18, 0);
		world.setBlock(i + 2, j + 4, k + 19, 0);
		world.setBlock(i + 2, j + 4, k + 20, 0);
		world.setBlock(i + 2, j + 4, k + 21, 0);
		world.setBlock(i + 2, j + 4, k + 22, 0);
		world.setBlock(i + 2, j + 4, k + 23, 0);
		world.setBlock(i + 2, j + 4, k + 24, getDarkWallId());
		world.setBlock(i + 2, j + 4, k + 25, 0);
		world.setBlock(i + 2, j + 4, k + 26, 0);
		world.setBlock(i + 2, j + 4, k + 27, 0);
		world.setBlock(i + 2, j + 5, k + 0, 0);
		world.setBlock(i + 2, j + 5, k + 1, 0);
		world.setBlock(i + 2, j + 5, k + 2, 0);
		world.setBlock(i + 2, j + 5, k + 3, 0);
		world.setBlock(i + 2, j + 5, k + 4, 0);
		world.setBlock(i + 2, j + 5, k + 5, 0);
		world.setBlock(i + 2, j + 5, k + 6, 0);
		world.setBlock(i + 2, j + 5, k + 7, 0);
		world.setBlock(i + 2, j + 5, k + 8, 0);
		world.setBlock(i + 2, j + 5, k + 9, 0);
		world.setBlock(i + 2, j + 5, k + 10, getDarkWallId());
		world.setBlock(i + 2, j + 5, k + 11, VirtiousBlocks.cytoidLightstrip.blockID);
		world.setBlock(i + 2, j + 5, k + 12, 0);
		world.setBlock(i + 2, j + 5, k + 13, 0);
		world.setBlock(i + 2, j + 5, k + 14, 0);
		world.setBlock(i + 2, j + 5, k + 15, 0);
		world.setBlock(i + 2, j + 5, k + 16, 0);
		world.setBlock(i + 2, j + 5, k + 17, 0);
		world.setBlock(i + 2, j + 5, k + 18, VirtiousBlocks.cytoidFloor.blockID, 0, 2);
		world.setBlock(i + 2, j + 5, k + 19, VirtiousBlocks.cytoidFloorDouble.blockID, 0, 2);
		world.setBlock(i + 2, j + 5, k + 20, VirtiousBlocks.cytoidFloorDouble.blockID, 0, 2);
		world.setBlock(i + 2, j + 5, k + 21, VirtiousBlocks.cytoidFloorDouble.blockID, 0, 2);
		world.setBlock(i + 2, j + 5, k + 22, 0);
		world.setBlock(i + 2, j + 5, k + 23, 0);
		world.setBlock(i + 2, j + 5, k + 24, getDarkWallId());
		world.setBlock(i + 2, j + 5, k + 25, 0);
		world.setBlock(i + 2, j + 5, k + 26, 0);
		world.setBlock(i + 2, j + 5, k + 27, 0);
		world.setBlock(i + 2, j + 6, k + 0, 0);
		world.setBlock(i + 2, j + 6, k + 1, 0);
		world.setBlock(i + 2, j + 6, k + 2, 0);
		world.setBlock(i + 2, j + 6, k + 3, 0);
		world.setBlock(i + 2, j + 6, k + 4, 0);
		world.setBlock(i + 2, j + 6, k + 5, 0);
		world.setBlock(i + 2, j + 6, k + 6, 0);
		world.setBlock(i + 2, j + 6, k + 7, 0);
		world.setBlock(i + 2, j + 6, k + 8, 0);
		world.setBlock(i + 2, j + 6, k + 9, 0);
		world.setBlock(i + 2, j + 6, k + 10, getDarkWallId());
		world.setBlock(i + 2, j + 6, k + 11, VirtiousBlocks.cytoidWallLower.blockID);
		world.setBlock(i + 2, j + 6, k + 12, 0);
		world.setBlock(i + 2, j + 6, k + 13, 0);
		world.setBlock(i + 2, j + 6, k + 14, 0);
		world.setBlock(i + 2, j + 6, k + 15, 0);
		world.setBlock(i + 2, j + 6, k + 16, 0);
		world.setBlock(i + 2, j + 6, k + 17, 0);
		world.setBlock(i + 2, j + 6, k + 18, 0);
		world.setBlock(i + 2, j + 6, k + 19, 0);
		world.setBlock(i + 2, j + 6, k + 20, 0);
		world.setBlock(i + 2, j + 6, k + 21, 0);
		world.setBlock(i + 2, j + 6, k + 22, VirtiousBlocks.cytoidWallLower.blockID);
		world.setBlock(i + 2, j + 6, k + 23, 0);
		world.setBlock(i + 2, j + 6, k + 24, getDarkWallId());
		world.setBlock(i + 2, j + 6, k + 25, 0);
		world.setBlock(i + 2, j + 6, k + 26, 0);
		world.setBlock(i + 2, j + 6, k + 27, 0);
		world.setBlock(i + 2, j + 7, k + 0, 0);
		world.setBlock(i + 2, j + 7, k + 1, 0);
		world.setBlock(i + 2, j + 7, k + 2, 0);
		world.setBlock(i + 2, j + 7, k + 3, 0);
		world.setBlock(i + 2, j + 7, k + 4, 0);
		world.setBlock(i + 2, j + 7, k + 5, 0);
		world.setBlock(i + 2, j + 7, k + 6, 0);
		world.setBlock(i + 2, j + 7, k + 7, 0);
		world.setBlock(i + 2, j + 7, k + 8, 0);
		world.setBlock(i + 2, j + 7, k + 9, 0);
		world.setBlock(i + 2, j + 7, k + 10, getDarkWallId());
		world.setBlock(i + 2, j + 7, k + 11, VirtiousBlocks.cytoidWallUpper.blockID);
		world.setBlock(i + 2, j + 7, k + 12, 0);
		world.setBlock(i + 2, j + 7, k + 13, 0);
		world.setBlock(i + 2, j + 7, k + 14, 0);
		world.setBlock(i + 2, j + 7, k + 15, 0);
		world.setBlock(i + 2, j + 7, k + 16, 0);
		world.setBlock(i + 2, j + 7, k + 17, 0);
		world.setBlock(i + 2, j + 7, k + 18, 0);
		world.setBlock(i + 2, j + 7, k + 19, 0);
		world.setBlock(i + 2, j + 7, k + 20, 0);
		world.setBlock(i + 2, j + 7, k + 21, 0);
		world.setBlock(i + 2, j + 7, k + 22, VirtiousBlocks.cytoidWallUpper.blockID);
		world.setBlock(i + 2, j + 7, k + 23, 0);
		world.setBlock(i + 2, j + 7, k + 24, getDarkWallId());
		world.setBlock(i + 2, j + 7, k + 25, 0);
		world.setBlock(i + 2, j + 7, k + 26, 0);
		world.setBlock(i + 2, j + 7, k + 27, 0);
		world.setBlock(i + 2, j + 8, k + 0, 0);
		world.setBlock(i + 2, j + 8, k + 1, 0);
		world.setBlock(i + 2, j + 8, k + 2, 0);
		world.setBlock(i + 2, j + 8, k + 3, 0);
		world.setBlock(i + 2, j + 8, k + 4, 0);
		world.setBlock(i + 2, j + 8, k + 5, 0);
		world.setBlock(i + 2, j + 8, k + 6, 0);
		world.setBlock(i + 2, j + 8, k + 7, 0);
		world.setBlock(i + 2, j + 8, k + 8, 0);
		world.setBlock(i + 2, j + 8, k + 9, 0);
		world.setBlock(i + 2, j + 8, k + 10, getDarkWallId());
		world.setBlock(i + 2, j + 8, k + 11, 0);
		world.setBlock(i + 2, j + 8, k + 12, VirtiousBlocks.cytoidFloorDouble.blockID, 0, 2);
		world.setBlock(i + 2, j + 8, k + 13, VirtiousBlocks.cytoidFloorDouble.blockID, 0, 2);
		world.setBlock(i + 2, j + 8, k + 14, VirtiousBlocks.cytoidFloorDouble.blockID, 0, 2);
		world.setBlock(i + 2, j + 8, k + 15, VirtiousBlocks.cytoidFloorDouble.blockID, 0, 2);
		world.setBlock(i + 2, j + 8, k + 16, VirtiousBlocks.cytoidFloorDouble.blockID, 0, 2);
		world.setBlock(i + 2, j + 8, k + 17, VirtiousBlocks.cytoidFloorDouble.blockID, 0, 2);
		world.setBlock(i + 2, j + 8, k + 18, VirtiousBlocks.cytoidFloorDouble.blockID, 0, 2);
		world.setBlock(i + 2, j + 8, k + 19, VirtiousBlocks.cytoidFloorDouble.blockID, 0, 2);
		world.setBlock(i + 2, j + 8, k + 20, VirtiousBlocks.cytoidFloorDouble.blockID, 0, 2);
		world.setBlock(i + 2, j + 8, k + 21, VirtiousBlocks.cytoidFloorDouble.blockID, 0, 2);
		world.setBlock(i + 2, j + 8, k + 22, 0);
		world.setBlock(i + 2, j + 8, k + 23, 0);
		world.setBlock(i + 2, j + 8, k + 24, getDarkWallId());
		world.setBlock(i + 2, j + 8, k + 25, 0);
		world.setBlock(i + 2, j + 8, k + 26, 0);
		world.setBlock(i + 2, j + 8, k + 27, 0);
		world.setBlock(i + 2, j + 9, k + 0, 0);
		world.setBlock(i + 2, j + 9, k + 1, 0);
		world.setBlock(i + 2, j + 9, k + 2, 0);
		world.setBlock(i + 2, j + 9, k + 3, 0);
		world.setBlock(i + 2, j + 9, k + 4, 0);
		world.setBlock(i + 2, j + 9, k + 5, 0);
		world.setBlock(i + 2, j + 9, k + 6, 0);
		world.setBlock(i + 2, j + 9, k + 7, 0);
		world.setBlock(i + 2, j + 9, k + 8, 0);
		world.setBlock(i + 2, j + 9, k + 9, 0);
		world.setBlock(i + 2, j + 9, k + 10, getDarkWallId());
		world.setBlock(i + 2, j + 9, k + 11, 0);
		world.setBlock(i + 2, j + 9, k + 12, 0);
		world.setBlock(i + 2, j + 9, k + 13, 0);
		world.setBlock(i + 2, j + 9, k + 14, 0);
		world.setBlock(i + 2, j + 9, k + 15, 0);
		world.setBlock(i + 2, j + 9, k + 16, 0);
		world.setBlock(i + 2, j + 9, k + 17, 0);
		world.setBlock(i + 2, j + 9, k + 18, 0);
		world.setBlock(i + 2, j + 9, k + 19, 0);
		world.setBlock(i + 2, j + 9, k + 20, 0);
		world.setBlock(i + 2, j + 9, k + 21, 0);
		world.setBlock(i + 2, j + 9, k + 22, 0);
		world.setBlock(i + 2, j + 9, k + 23, 0);
		world.setBlock(i + 2, j + 9, k + 24, getDarkWallId());
		world.setBlock(i + 2, j + 9, k + 25, 0);
		world.setBlock(i + 2, j + 9, k + 26, 0);
		world.setBlock(i + 2, j + 9, k + 27, 0);
		world.setBlock(i + 2, j + 10, k + 0, 0);
		world.setBlock(i + 2, j + 10, k + 1, 0);
		world.setBlock(i + 2, j + 10, k + 2, 0);
		world.setBlock(i + 2, j + 10, k + 3, 0);
		world.setBlock(i + 2, j + 10, k + 4, 0);
		world.setBlock(i + 2, j + 10, k + 5, 0);
		world.setBlock(i + 2, j + 10, k + 6, 0);
		world.setBlock(i + 2, j + 10, k + 7, 0);
		world.setBlock(i + 2, j + 10, k + 8, 0);
		world.setBlock(i + 2, j + 10, k + 9, 0);
		world.setBlock(i + 2, j + 10, k + 10, getDarkWallId());
		world.setBlock(i + 2, j + 10, k + 11, getDarkWallId());
		world.setBlock(i + 2, j + 10, k + 12, getDarkWallId());
		world.setBlock(i + 2, j + 10, k + 13, getDarkWallId());
		world.setBlock(i + 2, j + 10, k + 14, getDarkWallId());
		world.setBlock(i + 2, j + 10, k + 15, getDarkWallId());
		world.setBlock(i + 2, j + 10, k + 16, getDarkWallId());
		world.setBlock(i + 2, j + 10, k + 17, getDarkWallId());
		world.setBlock(i + 2, j + 10, k + 18, getDarkWallId());
		world.setBlock(i + 2, j + 10, k + 19, getDarkWallId());
		world.setBlock(i + 2, j + 10, k + 20, getDarkWallId());
		world.setBlock(i + 2, j + 10, k + 21, getDarkWallId());
		world.setBlock(i + 2, j + 10, k + 22, getDarkWallId());
		world.setBlock(i + 2, j + 10, k + 23, getDarkWallId());
		world.setBlock(i + 2, j + 10, k + 24, getDarkWallId());
		world.setBlock(i + 2, j + 10, k + 25, 0);
		world.setBlock(i + 2, j + 10, k + 26, 0);
		world.setBlock(i + 2, j + 10, k + 27, 0);
		world.setBlock(i + 3, j + 0, k + 0, 0);
		world.setBlock(i + 3, j + 0, k + 1, 0);
		world.setBlock(i + 3, j + 0, k + 2, 0);
		world.setBlock(i + 3, j + 0, k + 3, 0);
		world.setBlock(i + 3, j + 0, k + 4, 0);
		world.setBlock(i + 3, j + 0, k + 5, 0);
		world.setBlock(i + 3, j + 0, k + 6, 0);
		world.setBlock(i + 3, j + 0, k + 7, 0);
		world.setBlock(i + 3, j + 0, k + 8, 0);
		world.setBlock(i + 3, j + 0, k + 9, 0);
		world.setBlock(i + 3, j + 0, k + 10, getDarkWallId());
		world.setBlock(i + 3, j + 0, k + 11, getDarkWallId());
		world.setBlock(i + 3, j + 0, k + 12, getDarkWallId());
		world.setBlock(i + 3, j + 0, k + 13, getDarkWallId());
		world.setBlock(i + 3, j + 0, k + 14, getDarkWallId());
		world.setBlock(i + 3, j + 0, k + 15, getDarkWallId());
		world.setBlock(i + 3, j + 0, k + 16, getDarkWallId());
		world.setBlock(i + 3, j + 0, k + 17, getDarkWallId());
		world.setBlock(i + 3, j + 0, k + 18, getDarkWallId());
		world.setBlock(i + 3, j + 0, k + 19, getDarkWallId());
		world.setBlock(i + 3, j + 0, k + 20, getDarkWallId());
		world.setBlock(i + 3, j + 0, k + 21, getDarkWallId());
		world.setBlock(i + 3, j + 0, k + 22, getDarkWallId());
		world.setBlock(i + 3, j + 0, k + 23, getDarkWallId());
		world.setBlock(i + 3, j + 0, k + 24, getDarkWallId());
		world.setBlock(i + 3, j + 0, k + 25, 0);
		world.setBlock(i + 3, j + 0, k + 26, 0);
		world.setBlock(i + 3, j + 0, k + 27, 0);
		world.setBlock(i + 3, j + 1, k + 0, 0);
		world.setBlock(i + 3, j + 1, k + 1, 0);
		world.setBlock(i + 3, j + 1, k + 2, 0);
		world.setBlock(i + 3, j + 1, k + 3, 0);
		world.setBlock(i + 3, j + 1, k + 4, 0);
		world.setBlock(i + 3, j + 1, k + 5, 0);
		world.setBlock(i + 3, j + 1, k + 6, 0);
		world.setBlock(i + 3, j + 1, k + 7, 0);
		world.setBlock(i + 3, j + 1, k + 8, 0);
		world.setBlock(i + 3, j + 1, k + 9, 0);
		world.setBlock(i + 3, j + 1, k + 10, getDarkWallId());
		world.setBlock(i + 3, j + 1, k + 11, 0);
		world.setBlock(i + 3, j + 1, k + 12, 0);
		world.setBlock(i + 3, j + 1, k + 13, 0);
		world.setBlock(i + 3, j + 1, k + 14, 0);
		world.setBlock(i + 3, j + 1, k + 15, 0);
		world.setBlock(i + 3, j + 1, k + 16, 0);
		world.setBlock(i + 3, j + 1, k + 17, 0);
		world.setBlock(i + 3, j + 1, k + 18, 0);
		world.setBlock(i + 3, j + 1, k + 19, 0);
		world.setBlock(i + 3, j + 1, k + 20, 0);
		world.setBlock(i + 3, j + 1, k + 21, 0);
		world.setBlock(i + 3, j + 1, k + 22, 0);
		world.setBlock(i + 3, j + 1, k + 23, 0);
		world.setBlock(i + 3, j + 1, k + 24, getDarkWallId());
		world.setBlock(i + 3, j + 1, k + 25, 0);
		world.setBlock(i + 3, j + 1, k + 26, 0);
		world.setBlock(i + 3, j + 1, k + 27, 0);
		world.setBlock(i + 3, j + 2, k + 0, 0);
		world.setBlock(i + 3, j + 2, k + 1, 0);
		world.setBlock(i + 3, j + 2, k + 2, 0);
		world.setBlock(i + 3, j + 2, k + 3, 0);
		world.setBlock(i + 3, j + 2, k + 4, 0);
		world.setBlock(i + 3, j + 2, k + 5, 0);
		world.setBlock(i + 3, j + 2, k + 6, 0);
		world.setBlock(i + 3, j + 2, k + 7, 0);
		world.setBlock(i + 3, j + 2, k + 8, 0);
		world.setBlock(i + 3, j + 2, k + 9, 0);
		world.setBlock(i + 3, j + 2, k + 10, getDarkWallId());
		world.setBlock(i + 3, j + 2, k + 11, 0);
		world.setBlock(i + 3, j + 2, k + 12, VirtiousBlocks.cytoidFloorDouble.blockID, 0, 2);
		world.setBlock(i + 3, j + 2, k + 13, VirtiousBlocks.cytoidFloorDouble.blockID, 0, 2);
		world.setBlock(i + 3, j + 2, k + 14, 0);
		world.setBlock(i + 3, j + 2, k + 15, 0);
		world.setBlock(i + 3, j + 2, k + 16, 0);
		world.setBlock(i + 3, j + 2, k + 17, 0);
		world.setBlock(i + 3, j + 2, k + 18, 0);
		world.setBlock(i + 3, j + 2, k + 19, 0);
		world.setBlock(i + 3, j + 2, k + 20, 0);
		world.setBlock(i + 3, j + 2, k + 21, 0);
		world.setBlock(i + 3, j + 2, k + 22, 0);
		world.setBlock(i + 3, j + 2, k + 23, 0);
		world.setBlock(i + 3, j + 2, k + 24, getDarkWallId());
		world.setBlock(i + 3, j + 2, k + 25, 0);
		world.setBlock(i + 3, j + 2, k + 26, 0);
		world.setBlock(i + 3, j + 2, k + 27, 0);
		world.setBlock(i + 3, j + 3, k + 0, 0);
		world.setBlock(i + 3, j + 3, k + 1, 0);
		world.setBlock(i + 3, j + 3, k + 2, 0);
		world.setBlock(i + 3, j + 3, k + 3, 0);
		world.setBlock(i + 3, j + 3, k + 4, 0);
		world.setBlock(i + 3, j + 3, k + 5, 0);
		world.setBlock(i + 3, j + 3, k + 6, 0);
		world.setBlock(i + 3, j + 3, k + 7, 0);
		world.setBlock(i + 3, j + 3, k + 8, 0);
		world.setBlock(i + 3, j + 3, k + 9, 0);
		world.setBlock(i + 3, j + 3, k + 10, getDarkWallId());
		world.setBlock(i + 3, j + 3, k + 11, VirtiousBlocks.cytoidWallLower.blockID);
		world.setBlock(i + 3, j + 3, k + 12, 0);
		world.setBlock(i + 3, j + 3, k + 13, 0);
		world.setBlock(i + 3, j + 3, k + 14, VirtiousBlocks.cytoidFloor.blockID, 0, 2);
		world.setBlock(i + 3, j + 3, k + 15, VirtiousBlocks.cytoidFloorDouble.blockID, 0, 2);
		world.setBlock(i + 3, j + 3, k + 16, 0);
		world.setBlock(i + 3, j + 3, k + 17, 0);
		world.setBlock(i + 3, j + 3, k + 18, 0);
		world.setBlock(i + 3, j + 3, k + 19, 0);
		world.setBlock(i + 3, j + 3, k + 20, 0);
		world.setBlock(i + 3, j + 3, k + 21, 0);
		world.setBlock(i + 3, j + 3, k + 22, 0);
		world.setBlock(i + 3, j + 3, k + 23, 0);
		world.setBlock(i + 3, j + 3, k + 24, getDarkWallId());
		world.setBlock(i + 3, j + 3, k + 25, 0);
		world.setBlock(i + 3, j + 3, k + 26, 0);
		world.setBlock(i + 3, j + 3, k + 27, 0);
		world.setBlock(i + 3, j + 4, k + 0, 0);
		world.setBlock(i + 3, j + 4, k + 1, 0);
		world.setBlock(i + 3, j + 4, k + 2, 0);
		world.setBlock(i + 3, j + 4, k + 3, 0);
		world.setBlock(i + 3, j + 4, k + 4, 0);
		world.setBlock(i + 3, j + 4, k + 5, 0);
		world.setBlock(i + 3, j + 4, k + 6, 0);
		world.setBlock(i + 3, j + 4, k + 7, 0);
		world.setBlock(i + 3, j + 4, k + 8, 0);
		world.setBlock(i + 3, j + 4, k + 9, 0);
		world.setBlock(i + 3, j + 4, k + 10, getDarkWallId());
		world.setBlock(i + 3, j + 4, k + 11, VirtiousBlocks.cytoidWallUpper.blockID);
		world.setBlock(i + 3, j + 4, k + 12, 0);
		world.setBlock(i + 3, j + 4, k + 13, 0);
		world.setBlock(i + 3, j + 4, k + 14, 0);
		world.setBlock(i + 3, j + 4, k + 15, 0);
		world.setBlock(i + 3, j + 4, k + 16, VirtiousBlocks.cytoidFloor.blockID, 0, 2);
		world.setBlock(i + 3, j + 4, k + 17, VirtiousBlocks.cytoidFloorDouble.blockID, 0, 2);
		world.setBlock(i + 3, j + 4, k + 18, 0);
		world.setBlock(i + 3, j + 4, k + 19, 0);
		world.setBlock(i + 3, j + 4, k + 20, 0);
		world.setBlock(i + 3, j + 4, k + 21, 0);
		world.setBlock(i + 3, j + 4, k + 22, 0);
		world.setBlock(i + 3, j + 4, k + 23, 0);
		world.setBlock(i + 3, j + 4, k + 24, getDarkWallId());
		world.setBlock(i + 3, j + 4, k + 25, 0);
		world.setBlock(i + 3, j + 4, k + 26, 0);
		world.setBlock(i + 3, j + 4, k + 27, 0);
		world.setBlock(i + 3, j + 5, k + 0, 0);
		world.setBlock(i + 3, j + 5, k + 1, 0);
		world.setBlock(i + 3, j + 5, k + 2, 0);
		world.setBlock(i + 3, j + 5, k + 3, 0);
		world.setBlock(i + 3, j + 5, k + 4, 0);
		world.setBlock(i + 3, j + 5, k + 5, 0);
		world.setBlock(i + 3, j + 5, k + 6, 0);
		world.setBlock(i + 3, j + 5, k + 7, 0);
		world.setBlock(i + 3, j + 5, k + 8, 0);
		world.setBlock(i + 3, j + 5, k + 9, 0);
		world.setBlock(i + 3, j + 5, k + 10, getDarkWallId());
		world.setBlock(i + 3, j + 5, k + 11, VirtiousBlocks.cytoidLightstrip.blockID);
		world.setBlock(i + 3, j + 5, k + 12, 0);
		world.setBlock(i + 3, j + 5, k + 13, 0);
		world.setBlock(i + 3, j + 5, k + 14, 0);
		world.setBlock(i + 3, j + 5, k + 15, 0);
		world.setBlock(i + 3, j + 5, k + 16, 0);
		world.setBlock(i + 3, j + 5, k + 17, 0);
		world.setBlock(i + 3, j + 5, k + 18, VirtiousBlocks.cytoidFloor.blockID, 0, 2);
		world.setBlock(i + 3, j + 5, k + 19, VirtiousBlocks.cytoidFloorDouble.blockID, 0, 2);
		world.setBlock(i + 3, j + 5, k + 20, VirtiousBlocks.cytoidFloorDouble.blockID, 0, 2);
		world.setBlock(i + 3, j + 5, k + 21, VirtiousBlocks.cytoidFloorDouble.blockID, 0, 2);
		world.setBlock(i + 3, j + 5, k + 22, 0);
		world.setBlock(i + 3, j + 5, k + 23, 0);
		world.setBlock(i + 3, j + 5, k + 24, getDarkWallId());
		world.setBlock(i + 3, j + 5, k + 25, 0);
		world.setBlock(i + 3, j + 5, k + 26, 0);
		world.setBlock(i + 3, j + 5, k + 27, 0);
		world.setBlock(i + 3, j + 6, k + 0, 0);
		world.setBlock(i + 3, j + 6, k + 1, 0);
		world.setBlock(i + 3, j + 6, k + 2, 0);
		world.setBlock(i + 3, j + 6, k + 3, 0);
		world.setBlock(i + 3, j + 6, k + 4, 0);
		world.setBlock(i + 3, j + 6, k + 5, 0);
		world.setBlock(i + 3, j + 6, k + 6, 0);
		world.setBlock(i + 3, j + 6, k + 7, 0);
		world.setBlock(i + 3, j + 6, k + 8, 0);
		world.setBlock(i + 3, j + 6, k + 9, 0);
		world.setBlock(i + 3, j + 6, k + 10, getDarkWallId());
		world.setBlock(i + 3, j + 6, k + 11, VirtiousBlocks.cytoidWallLower.blockID);
		world.setBlock(i + 3, j + 6, k + 12, 0);
		world.setBlock(i + 3, j + 6, k + 13, 0);
		world.setBlock(i + 3, j + 6, k + 14, 0);
		world.setBlock(i + 3, j + 6, k + 15, 0);
		world.setBlock(i + 3, j + 6, k + 16, 0);
		world.setBlock(i + 3, j + 6, k + 17, 0);
		world.setBlock(i + 3, j + 6, k + 18, 0);
		world.setBlock(i + 3, j + 6, k + 19, 0);
		world.setBlock(i + 3, j + 6, k + 20, Block.mobSpawner.blockID, 0, 2);
		 tileentitymobspawner = (TileEntityMobSpawner)world.getBlockTileEntity(i + 3, j + 6, k + 20);

	        if (tileentitymobspawner != null)
	        {
	            tileentitymobspawner.getSpawnerLogic().setMobID("NativeSkeleton");
	        }
		world.setBlock(i + 3, j + 6, k + 21, 0);
		world.setBlock(i + 3, j + 6, k + 22, VirtiousBlocks.cytoidWallLower.blockID);
		world.setBlock(i + 3, j + 6, k + 23, 0);
		world.setBlock(i + 3, j + 6, k + 24, getDarkWallId());
		world.setBlock(i + 3, j + 6, k + 25, 0);
		world.setBlock(i + 3, j + 6, k + 26, 0);
		world.setBlock(i + 3, j + 6, k + 27, 0);
		world.setBlock(i + 3, j + 7, k + 0, 0);
		world.setBlock(i + 3, j + 7, k + 1, 0);
		world.setBlock(i + 3, j + 7, k + 2, 0);
		world.setBlock(i + 3, j + 7, k + 3, 0);
		world.setBlock(i + 3, j + 7, k + 4, 0);
		world.setBlock(i + 3, j + 7, k + 5, 0);
		world.setBlock(i + 3, j + 7, k + 6, 0);
		world.setBlock(i + 3, j + 7, k + 7, 0);
		world.setBlock(i + 3, j + 7, k + 8, 0);
		world.setBlock(i + 3, j + 7, k + 9, 0);
		world.setBlock(i + 3, j + 7, k + 10, getDarkWallId());
		world.setBlock(i + 3, j + 7, k + 11, VirtiousBlocks.cytoidWallUpper.blockID);
		world.setBlock(i + 3, j + 7, k + 12, 0);
		world.setBlock(i + 3, j + 7, k + 13, 0);
		world.setBlock(i + 3, j + 7, k + 14, 0);
		world.setBlock(i + 3, j + 7, k + 15, 0);
		world.setBlock(i + 3, j + 7, k + 16, 0);
		world.setBlock(i + 3, j + 7, k + 17, 0);
		world.setBlock(i + 3, j + 7, k + 18, 0);
		world.setBlock(i + 3, j + 7, k + 19, 0);
		world.setBlock(i + 3, j + 7, k + 20, Block.chest.blockID, 0, 2);
		world.setBlock(i + 3, j + 7, k + 21, 0);
		world.setBlock(i + 3, j + 7, k + 22, VirtiousBlocks.cytoidWallUpper.blockID);
		world.setBlock(i + 3, j + 7, k + 23, 0);
		world.setBlock(i + 3, j + 7, k + 24, getDarkWallId());
		world.setBlock(i + 3, j + 7, k + 25, 0);
		world.setBlock(i + 3, j + 7, k + 26, 0);
		world.setBlock(i + 3, j + 7, k + 27, 0);
		world.setBlock(i + 3, j + 8, k + 0, 0);
		world.setBlock(i + 3, j + 8, k + 1, 0);
		world.setBlock(i + 3, j + 8, k + 2, 0);
		world.setBlock(i + 3, j + 8, k + 3, 0);
		world.setBlock(i + 3, j + 8, k + 4, 0);
		world.setBlock(i + 3, j + 8, k + 5, 0);
		world.setBlock(i + 3, j + 8, k + 6, 0);
		world.setBlock(i + 3, j + 8, k + 7, 0);
		world.setBlock(i + 3, j + 8, k + 8, 0);
		world.setBlock(i + 3, j + 8, k + 9, 0);
		world.setBlock(i + 3, j + 8, k + 10, getDarkWallId());
		world.setBlock(i + 3, j + 8, k + 11, 0);
		world.setBlock(i + 3, j + 8, k + 12, VirtiousBlocks.cytoidFloorDouble.blockID, 0, 2);
		world.setBlock(i + 3, j + 8, k + 13, VirtiousBlocks.cytoidFloorDouble.blockID, 0, 2);
		world.setBlock(i + 3, j + 8, k + 14, VirtiousBlocks.cytoidFloorDouble.blockID, 0, 2);
		world.setBlock(i + 3, j + 8, k + 15, VirtiousBlocks.cytoidFloorDouble.blockID, 0, 2);
		world.setBlock(i + 3, j + 8, k + 16, VirtiousBlocks.cytoidFloorDouble.blockID, 0, 2);
		world.setBlock(i + 3, j + 8, k + 17, VirtiousBlocks.cytoidFloorDouble.blockID, 0, 2);
		world.setBlock(i + 3, j + 8, k + 18, VirtiousBlocks.cytoidFloorDouble.blockID, 0, 2);
		world.setBlock(i + 3, j + 8, k + 19, VirtiousBlocks.cytoidFloorDouble.blockID, 0, 2);
		world.setBlock(i + 3, j + 8, k + 20, VirtiousBlocks.cytoidFloorDouble.blockID, 0, 2);
		world.setBlock(i + 3, j + 8, k + 21, VirtiousBlocks.cytoidFloorDouble.blockID, 0, 2);
		world.setBlock(i + 3, j + 8, k + 22, 0);
		world.setBlock(i + 3, j + 8, k + 23, 0);
		world.setBlock(i + 3, j + 8, k + 24, getDarkWallId());
		world.setBlock(i + 3, j + 8, k + 25, 0);
		world.setBlock(i + 3, j + 8, k + 26, 0);
		world.setBlock(i + 3, j + 8, k + 27, 0);
		world.setBlock(i + 3, j + 9, k + 0, 0);
		world.setBlock(i + 3, j + 9, k + 1, 0);
		world.setBlock(i + 3, j + 9, k + 2, 0);
		world.setBlock(i + 3, j + 9, k + 3, 0);
		world.setBlock(i + 3, j + 9, k + 4, 0);
		world.setBlock(i + 3, j + 9, k + 5, 0);
		world.setBlock(i + 3, j + 9, k + 6, 0);
		world.setBlock(i + 3, j + 9, k + 7, 0);
		world.setBlock(i + 3, j + 9, k + 8, 0);
		world.setBlock(i + 3, j + 9, k + 9, 0);
		world.setBlock(i + 3, j + 9, k + 10, getDarkWallId());
		world.setBlock(i + 3, j + 9, k + 11, 0);
		world.setBlock(i + 3, j + 9, k + 12, 0);
		world.setBlock(i + 3, j + 9, k + 13, 0);
		world.setBlock(i + 3, j + 9, k + 14, 0);
		world.setBlock(i + 3, j + 9, k + 15, 0);
		world.setBlock(i + 3, j + 9, k + 16, 0);
		world.setBlock(i + 3, j + 9, k + 17, 0);
		world.setBlock(i + 3, j + 9, k + 18, 0);
		world.setBlock(i + 3, j + 9, k + 19, 0);
		world.setBlock(i + 3, j + 9, k + 20, 0);
		world.setBlock(i + 3, j + 9, k + 21, 0);
		world.setBlock(i + 3, j + 9, k + 22, 0);
		world.setBlock(i + 3, j + 9, k + 23, 0);
		world.setBlock(i + 3, j + 9, k + 24, getDarkWallId());
		world.setBlock(i + 3, j + 9, k + 25, 0);
		world.setBlock(i + 3, j + 9, k + 26, 0);
		world.setBlock(i + 3, j + 9, k + 27, 0);
		world.setBlock(i + 3, j + 10, k + 0, 0);
		world.setBlock(i + 3, j + 10, k + 1, 0);
		world.setBlock(i + 3, j + 10, k + 2, 0);
		world.setBlock(i + 3, j + 10, k + 3, 0);
		world.setBlock(i + 3, j + 10, k + 4, 0);
		world.setBlock(i + 3, j + 10, k + 5, 0);
		world.setBlock(i + 3, j + 10, k + 6, 0);
		world.setBlock(i + 3, j + 10, k + 7, 0);
		world.setBlock(i + 3, j + 10, k + 8, 0);
		world.setBlock(i + 3, j + 10, k + 9, 0);
		world.setBlock(i + 3, j + 10, k + 10, getDarkWallId());
		world.setBlock(i + 3, j + 10, k + 11, getDarkWallId());
		world.setBlock(i + 3, j + 10, k + 12, getDarkWallId());
		world.setBlock(i + 3, j + 10, k + 13, getDarkWallId());
		world.setBlock(i + 3, j + 10, k + 14, getDarkWallId());
		world.setBlock(i + 3, j + 10, k + 15, getDarkWallId());
		world.setBlock(i + 3, j + 10, k + 16, getDarkWallId());
		world.setBlock(i + 3, j + 10, k + 17, getDarkWallId());
		world.setBlock(i + 3, j + 10, k + 18, getDarkWallId());
		world.setBlock(i + 3, j + 10, k + 19, getDarkWallId());
		world.setBlock(i + 3, j + 10, k + 20, getDarkWallId());
		world.setBlock(i + 3, j + 10, k + 21, getDarkWallId());
		world.setBlock(i + 3, j + 10, k + 22, getDarkWallId());
		world.setBlock(i + 3, j + 10, k + 23, getDarkWallId());
		world.setBlock(i + 3, j + 10, k + 24, getDarkWallId());
		world.setBlock(i + 3, j + 10, k + 25, 0);
		world.setBlock(i + 3, j + 10, k + 26, 0);
		world.setBlock(i + 3, j + 10, k + 27, 0);
		world.setBlock(i + 4, j + 0, k + 0, getDarkWallId());
		world.setBlock(i + 4, j + 0, k + 1, getDarkWallId());
		world.setBlock(i + 4, j + 0, k + 2, getDarkWallId());
		world.setBlock(i + 4, j + 0, k + 3, getDarkWallId());
		world.setBlock(i + 4, j + 0, k + 4, getDarkWallId());
		world.setBlock(i + 4, j + 0, k + 5, getDarkWallId());
		world.setBlock(i + 4, j + 0, k + 6, getDarkWallId());
		world.setBlock(i + 4, j + 0, k + 7, getDarkWallId());
		world.setBlock(i + 4, j + 0, k + 8, getDarkWallId());
		world.setBlock(i + 4, j + 0, k + 9, getDarkWallId());
		world.setBlock(i + 4, j + 0, k + 10, getDarkWallId());
		world.setBlock(i + 4, j + 0, k + 11, getDarkWallId());
		world.setBlock(i + 4, j + 0, k + 12, getDarkWallId());
		world.setBlock(i + 4, j + 0, k + 13, getDarkWallId());
		world.setBlock(i + 4, j + 0, k + 14, getDarkWallId());
		world.setBlock(i + 4, j + 0, k + 15, getDarkWallId());
		world.setBlock(i + 4, j + 0, k + 16, getDarkWallId());
		world.setBlock(i + 4, j + 0, k + 17, getDarkWallId());
		world.setBlock(i + 4, j + 0, k + 18, getDarkWallId());
		world.setBlock(i + 4, j + 0, k + 19, getDarkWallId());
		world.setBlock(i + 4, j + 0, k + 20, getDarkWallId());
		world.setBlock(i + 4, j + 0, k + 21, getDarkWallId());
		world.setBlock(i + 4, j + 0, k + 22, getDarkWallId());
		world.setBlock(i + 4, j + 0, k + 23, getDarkWallId());
		world.setBlock(i + 4, j + 0, k + 24, getDarkWallId());
		world.setBlock(i + 4, j + 0, k + 25, 0);
		world.setBlock(i + 4, j + 0, k + 26, 0);
		world.setBlock(i + 4, j + 0, k + 27, 0);
		world.setBlock(i + 4, j + 1, k + 0, getDarkWallId());
		world.setBlock(i + 4, j + 1, k + 1, getDarkWallId());
		world.setBlock(i + 4, j + 1, k + 2, getDarkWallId());
		world.setBlock(i + 4, j + 1, k + 3, getDarkWallId());
		world.setBlock(i + 4, j + 1, k + 4, getDarkWallId());
		world.setBlock(i + 4, j + 1, k + 5, getDarkWallId());
		world.setBlock(i + 4, j + 1, k + 6, getDarkWallId());
		world.setBlock(i + 4, j + 1, k + 7, getDarkWallId());
		world.setBlock(i + 4, j + 1, k + 8, getDarkWallId());
		world.setBlock(i + 4, j + 1, k + 9, getDarkWallId());
		world.setBlock(i + 4, j + 1, k + 10, 0);
		world.setBlock(i + 4, j + 1, k + 11, 0);
		world.setBlock(i + 4, j + 1, k + 12, 0);
		world.setBlock(i + 4, j + 1, k + 13, 0);
		world.setBlock(i + 4, j + 1, k + 14, 0);
		world.setBlock(i + 4, j + 1, k + 15, 0);
		world.setBlock(i + 4, j + 1, k + 16, 0);
		world.setBlock(i + 4, j + 1, k + 17, 0);
		world.setBlock(i + 4, j + 1, k + 18, 0);
		world.setBlock(i + 4, j + 1, k + 19, 0);
		world.setBlock(i + 4, j + 1, k + 20, 0);
		world.setBlock(i + 4, j + 1, k + 21, 0);
		world.setBlock(i + 4, j + 1, k + 22, 0);
		world.setBlock(i + 4, j + 1, k + 23, 0);
		world.setBlock(i + 4, j + 1, k + 24, getDarkWallId());
		world.setBlock(i + 4, j + 1, k + 25, 0);
		world.setBlock(i + 4, j + 1, k + 26, 0);
		world.setBlock(i + 4, j + 1, k + 27, 0);
		world.setBlock(i + 4, j + 2, k + 0, getDarkWallId());
		world.setBlock(i + 4, j + 2, k + 1, getDarkWallId());
		world.setBlock(i + 4, j + 2, k + 2, getDarkWallId());
		world.setBlock(i + 4, j + 2, k + 3, getDarkWallId());
		world.setBlock(i + 4, j + 2, k + 4, getDarkWallId());
		world.setBlock(i + 4, j + 2, k + 5, getDarkWallId());
		world.setBlock(i + 4, j + 2, k + 6, getDarkWallId());
		world.setBlock(i + 4, j + 2, k + 7, getDarkWallId());
		world.setBlock(i + 4, j + 2, k + 8, getDarkWallId());
		world.setBlock(i + 4, j + 2, k + 9, getDarkWallId());
		world.setBlock(i + 4, j + 2, k + 10, 0);
		world.setBlock(i + 4, j + 2, k + 11, 0);
		world.setBlock(i + 4, j + 2, k + 12, VirtiousBlocks.cytoidFloorDouble.blockID, 0, 2);
		world.setBlock(i + 4, j + 2, k + 13, VirtiousBlocks.cytoidFloorDouble.blockID, 0, 2);
		world.setBlock(i + 4, j + 2, k + 14, 0);
		world.setBlock(i + 4, j + 2, k + 15, 0);
		world.setBlock(i + 4, j + 2, k + 16, 0);
		world.setBlock(i + 4, j + 2, k + 17, 0);
		world.setBlock(i + 4, j + 2, k + 18, 0);
		world.setBlock(i + 4, j + 2, k + 19, 0);
		world.setBlock(i + 4, j + 2, k + 20, 0);
		world.setBlock(i + 4, j + 2, k + 21, 0);
		world.setBlock(i + 4, j + 2, k + 22, 0);
		world.setBlock(i + 4, j + 2, k + 23, 0);
		world.setBlock(i + 4, j + 2, k + 24, getDarkWallId());
		world.setBlock(i + 4, j + 2, k + 25, 0);
		world.setBlock(i + 4, j + 2, k + 26, 0);
		world.setBlock(i + 4, j + 2, k + 27, 0);
		world.setBlock(i + 4, j + 3, k + 0, getDarkWallId());
		world.setBlock(i + 4, j + 3, k + 1, getDarkWallId());
		world.setBlock(i + 4, j + 3, k + 2, getDarkWallId());
		world.setBlock(i + 4, j + 3, k + 3, getDarkWallId());
		world.setBlock(i + 4, j + 3, k + 4, getDarkWallId());
		world.setBlock(i + 4, j + 3, k + 5, getDarkWallId());
		world.setBlock(i + 4, j + 3, k + 6, getDarkWallId());
		world.setBlock(i + 4, j + 3, k + 7, getDarkWallId());
		world.setBlock(i + 4, j + 3, k + 8, getDarkWallId());
		world.setBlock(i + 4, j + 3, k + 9, getDarkWallId());
		world.setBlock(i + 4, j + 3, k + 10, 0);
		world.setBlock(i + 4, j + 3, k + 11, VirtiousBlocks.cytoidWallLower.blockID);
		world.setBlock(i + 4, j + 3, k + 12, 0);
		world.setBlock(i + 4, j + 3, k + 13, 0);
		world.setBlock(i + 4, j + 3, k + 14, VirtiousBlocks.cytoidFloor.blockID, 0, 2);
		world.setBlock(i + 4, j + 3, k + 15, VirtiousBlocks.cytoidFloorDouble.blockID, 0, 2);
		world.setBlock(i + 4, j + 3, k + 16, 0);
		world.setBlock(i + 4, j + 3, k + 17, 0);
		world.setBlock(i + 4, j + 3, k + 18, 0);
		world.setBlock(i + 4, j + 3, k + 19, 0);
		world.setBlock(i + 4, j + 3, k + 20, 0);
		world.setBlock(i + 4, j + 3, k + 21, 0);
		world.setBlock(i + 4, j + 3, k + 22, 0);
		world.setBlock(i + 4, j + 3, k + 23, 0);
		world.setBlock(i + 4, j + 3, k + 24, getDarkWallId());
		world.setBlock(i + 4, j + 3, k + 25, 0);
		world.setBlock(i + 4, j + 3, k + 26, 0);
		world.setBlock(i + 4, j + 3, k + 27, 0);
		world.setBlock(i + 4, j + 4, k + 0, getDarkWallId());
		world.setBlock(i + 4, j + 4, k + 1, getDarkWallId());
		world.setBlock(i + 4, j + 4, k + 2, getDarkWallId());
		world.setBlock(i + 4, j + 4, k + 3, 0);
		world.setBlock(i + 4, j + 4, k + 4, getDarkWallId());
		world.setBlock(i + 4, j + 4, k + 5, 0);
		world.setBlock(i + 4, j + 4, k + 6, getDarkWallId());
		world.setBlock(i + 4, j + 4, k + 7, 0);
		world.setBlock(i + 4, j + 4, k + 8, getDarkWallId());
		world.setBlock(i + 4, j + 4, k + 9, 0);
		world.setBlock(i + 4, j + 4, k + 10, getDarkWallId());
		world.setBlock(i + 4, j + 4, k + 11, VirtiousBlocks.cytoidWallUpper.blockID);
		world.setBlock(i + 4, j + 4, k + 12, 0);
		world.setBlock(i + 4, j + 4, k + 13, 0);
		world.setBlock(i + 4, j + 4, k + 14, 0);
		world.setBlock(i + 4, j + 4, k + 15, 0);
		world.setBlock(i + 4, j + 4, k + 16, VirtiousBlocks.cytoidFloor.blockID, 0, 2);
		world.setBlock(i + 4, j + 4, k + 17, VirtiousBlocks.cytoidFloorDouble.blockID, 0, 2);
		world.setBlock(i + 4, j + 4, k + 18, 0);
		world.setBlock(i + 4, j + 4, k + 19, 0);
		world.setBlock(i + 4, j + 4, k + 20, 0);
		world.setBlock(i + 4, j + 4, k + 21, 0);
		world.setBlock(i + 4, j + 4, k + 22, 0);
		world.setBlock(i + 4, j + 4, k + 23, 0);
		world.setBlock(i + 4, j + 4, k + 24, getDarkWallId());
		world.setBlock(i + 4, j + 4, k + 25, 0);
		world.setBlock(i + 4, j + 4, k + 26, 0);
		world.setBlock(i + 4, j + 4, k + 27, 0);
		world.setBlock(i + 4, j + 5, k + 0, getDarkWallId());
		world.setBlock(i + 4, j + 5, k + 1, getDarkWallId());
		world.setBlock(i + 4, j + 5, k + 2, getDarkWallId());
		world.setBlock(i + 4, j + 5, k + 3, getDarkWallId());
		world.setBlock(i + 4, j + 5, k + 4, getDarkWallId());
		world.setBlock(i + 4, j + 5, k + 5, getDarkWallId());
		world.setBlock(i + 4, j + 5, k + 6, getDarkWallId());
		world.setBlock(i + 4, j + 5, k + 7, getDarkWallId());
		world.setBlock(i + 4, j + 5, k + 8, getDarkWallId());
		world.setBlock(i + 4, j + 5, k + 9, getDarkWallId());
		world.setBlock(i + 4, j + 5, k + 10, 0);
		world.setBlock(i + 4, j + 5, k + 11, VirtiousBlocks.cytoidLightstrip.blockID);
		world.setBlock(i + 4, j + 5, k + 12, 0);
		world.setBlock(i + 4, j + 5, k + 13, 0);
		world.setBlock(i + 4, j + 5, k + 14, 0);
		world.setBlock(i + 4, j + 5, k + 15, 0);
		world.setBlock(i + 4, j + 5, k + 16, 0);
		world.setBlock(i + 4, j + 5, k + 17, 0);
		world.setBlock(i + 4, j + 5, k + 18, VirtiousBlocks.cytoidFloor.blockID, 0, 2);
		world.setBlock(i + 4, j + 5, k + 19, VirtiousBlocks.cytoidFloorDouble.blockID, 0, 2);
		world.setBlock(i + 4, j + 5, k + 20, VirtiousBlocks.cytoidFloorDouble.blockID, 0, 2);
		world.setBlock(i + 4, j + 5, k + 21, VirtiousBlocks.cytoidFloorDouble.blockID, 0, 2);
		world.setBlock(i + 4, j + 5, k + 22, 0);
		world.setBlock(i + 4, j + 5, k + 23, 0);
		world.setBlock(i + 4, j + 5, k + 24, getDarkWallId());
		world.setBlock(i + 4, j + 5, k + 25, 0);
		world.setBlock(i + 4, j + 5, k + 26, 0);
		world.setBlock(i + 4, j + 5, k + 27, 0);
		world.setBlock(i + 4, j + 6, k + 0, getDarkWallId());
		world.setBlock(i + 4, j + 6, k + 1, getDarkWallId());
		world.setBlock(i + 4, j + 6, k + 2, getDarkWallId());
		world.setBlock(i + 4, j + 6, k + 3, getDarkWallId());
		world.setBlock(i + 4, j + 6, k + 4, getDarkWallId());
		world.setBlock(i + 4, j + 6, k + 5, getDarkWallId());
		world.setBlock(i + 4, j + 6, k + 6, getDarkWallId());
		world.setBlock(i + 4, j + 6, k + 7, getDarkWallId());
		world.setBlock(i + 4, j + 6, k + 8, getDarkWallId());
		world.setBlock(i + 4, j + 6, k + 9, getDarkWallId());
		world.setBlock(i + 4, j + 6, k + 10, 0);
		world.setBlock(i + 4, j + 6, k + 11, VirtiousBlocks.cytoidWallLower.blockID);
		world.setBlock(i + 4, j + 6, k + 12, 0);
		world.setBlock(i + 4, j + 6, k + 13, 0);
		world.setBlock(i + 4, j + 6, k + 14, 0);
		world.setBlock(i + 4, j + 6, k + 15, 0);
		world.setBlock(i + 4, j + 6, k + 16, 0);
		world.setBlock(i + 4, j + 6, k + 17, 0);
		world.setBlock(i + 4, j + 6, k + 18, 0);
		world.setBlock(i + 4, j + 6, k + 19, 0);
		world.setBlock(i + 4, j + 6, k + 20, 0);
		world.setBlock(i + 4, j + 6, k + 21, 0);
		world.setBlock(i + 4, j + 6, k + 22, VirtiousBlocks.cytoidWallLower.blockID);
		world.setBlock(i + 4, j + 6, k + 23, 0);
		world.setBlock(i + 4, j + 6, k + 24, getDarkWallId());
		world.setBlock(i + 4, j + 6, k + 25, 0);
		world.setBlock(i + 4, j + 6, k + 26, 0);
		world.setBlock(i + 4, j + 6, k + 27, 0);
		world.setBlock(i + 4, j + 7, k + 0, 0);
		world.setBlock(i + 4, j + 7, k + 1, 0);
		world.setBlock(i + 4, j + 7, k + 2, 0);
		world.setBlock(i + 4, j + 7, k + 3, 0);
		world.setBlock(i + 4, j + 7, k + 4, 0);
		world.setBlock(i + 4, j + 7, k + 5, 0);
		world.setBlock(i + 4, j + 7, k + 6, 0);
		world.setBlock(i + 4, j + 7, k + 7, 0);
		world.setBlock(i + 4, j + 7, k + 8, 0);
		world.setBlock(i + 4, j + 7, k + 9, 0);
		world.setBlock(i + 4, j + 7, k + 10, getDarkWallId());
		world.setBlock(i + 4, j + 7, k + 11, VirtiousBlocks.cytoidWallUpper.blockID);
		world.setBlock(i + 4, j + 7, k + 12, 0);
		world.setBlock(i + 4, j + 7, k + 13, 0);
		world.setBlock(i + 4, j + 7, k + 14, 0);
		world.setBlock(i + 4, j + 7, k + 15, 0);
		world.setBlock(i + 4, j + 7, k + 16, 0);
		world.setBlock(i + 4, j + 7, k + 17, 0);
		world.setBlock(i + 4, j + 7, k + 18, 0);
		world.setBlock(i + 4, j + 7, k + 19, 0);
		world.setBlock(i + 4, j + 7, k + 20, 0);
		world.setBlock(i + 4, j + 7, k + 21, 0);
		world.setBlock(i + 4, j + 7, k + 22, VirtiousBlocks.cytoidWallUpper.blockID);
		world.setBlock(i + 4, j + 7, k + 23, 0);
		world.setBlock(i + 4, j + 7, k + 24, getDarkWallId());
		world.setBlock(i + 4, j + 7, k + 25, 0);
		world.setBlock(i + 4, j + 7, k + 26, 0);
		world.setBlock(i + 4, j + 7, k + 27, 0);
		world.setBlock(i + 4, j + 8, k + 0, 0);
		world.setBlock(i + 4, j + 8, k + 1, 0);
		world.setBlock(i + 4, j + 8, k + 2, 0);
		world.setBlock(i + 4, j + 8, k + 3, 0);
		world.setBlock(i + 4, j + 8, k + 4, 0);
		world.setBlock(i + 4, j + 8, k + 5, 0);
		world.setBlock(i + 4, j + 8, k + 6, 0);
		world.setBlock(i + 4, j + 8, k + 7, 0);
		world.setBlock(i + 4, j + 8, k + 8, 0);
		world.setBlock(i + 4, j + 8, k + 9, 0);
		world.setBlock(i + 4, j + 8, k + 10, getDarkWallId());
		world.setBlock(i + 4, j + 8, k + 11, 0);
		world.setBlock(i + 4, j + 8, k + 12, VirtiousBlocks.cytoidFloorDouble.blockID, 0, 2);
		world.setBlock(i + 4, j + 8, k + 13, VirtiousBlocks.cytoidFloorDouble.blockID, 0, 2);
		world.setBlock(i + 4, j + 8, k + 14, VirtiousBlocks.cytoidFloorDouble.blockID, 0, 2);
		world.setBlock(i + 4, j + 8, k + 15, VirtiousBlocks.cytoidFloorDouble.blockID, 0, 2);
		world.setBlock(i + 4, j + 8, k + 16, VirtiousBlocks.cytoidFloorDouble.blockID, 0, 2);
		world.setBlock(i + 4, j + 8, k + 17, VirtiousBlocks.cytoidFloorDouble.blockID, 0, 2);
		world.setBlock(i + 4, j + 8, k + 18, VirtiousBlocks.cytoidFloorDouble.blockID, 0, 2);
		world.setBlock(i + 4, j + 8, k + 19, VirtiousBlocks.cytoidFloorDouble.blockID, 0, 2);
		world.setBlock(i + 4, j + 8, k + 20, VirtiousBlocks.cytoidFloorDouble.blockID, 0, 2);
		world.setBlock(i + 4, j + 8, k + 21, VirtiousBlocks.cytoidFloorDouble.blockID, 0, 2);
		world.setBlock(i + 4, j + 8, k + 22, 0);
		world.setBlock(i + 4, j + 8, k + 23, 0);
		world.setBlock(i + 4, j + 8, k + 24, getDarkWallId());
		world.setBlock(i + 4, j + 8, k + 25, 0);
		world.setBlock(i + 4, j + 8, k + 26, 0);
		world.setBlock(i + 4, j + 8, k + 27, 0);
		world.setBlock(i + 4, j + 9, k + 0, 0);
		world.setBlock(i + 4, j + 9, k + 1, 0);
		world.setBlock(i + 4, j + 9, k + 2, 0);
		world.setBlock(i + 4, j + 9, k + 3, 0);
		world.setBlock(i + 4, j + 9, k + 4, 0);
		world.setBlock(i + 4, j + 9, k + 5, 0);
		world.setBlock(i + 4, j + 9, k + 6, 0);
		world.setBlock(i + 4, j + 9, k + 7, 0);
		world.setBlock(i + 4, j + 9, k + 8, 0);
		world.setBlock(i + 4, j + 9, k + 9, 0);
		world.setBlock(i + 4, j + 9, k + 10, getDarkWallId());
		world.setBlock(i + 4, j + 9, k + 11, 0);
		world.setBlock(i + 4, j + 9, k + 12, 0);
		world.setBlock(i + 4, j + 9, k + 13, 0);
		world.setBlock(i + 4, j + 9, k + 14, 0);
		world.setBlock(i + 4, j + 9, k + 15, 0);

		generate2(world, rand, i, j, k);
		return true;
	}

	private int getDarkWallId() {
		Random random = new Random();
		int rand = random.nextInt(4);
		if (rand == 0)
			return VirtiousBlocks.cytoidWallDark2.blockID;
		
		if (rand == 1)
			return VirtiousBlocks.cytoidWallDark3.blockID;

		if (rand == 2)
			return VirtiousBlocks.cytoidWallDark4.blockID;

		return VirtiousBlocks.cytoidWallDark.blockID;
	}

	public boolean generate2(World world, Random rand, int i, int j, int k) {
		world.setBlock(i + 4, j + 9, k + 16, 0);
		world.setBlock(i + 4, j + 9, k + 17, 0);
		world.setBlock(i + 4, j + 9, k + 18, 0);
		world.setBlock(i + 4, j + 9, k + 19, 0);
		world.setBlock(i + 4, j + 9, k + 20, 0);
		world.setBlock(i + 4, j + 9, k + 21, 0);
		world.setBlock(i + 4, j + 9, k + 22, 0);
		world.setBlock(i + 4, j + 9, k + 23, 0);
		world.setBlock(i + 4, j + 9, k + 24, getDarkWallId());
		world.setBlock(i + 4, j + 9, k + 25, 0);
		world.setBlock(i + 4, j + 9, k + 26, 0);
		world.setBlock(i + 4, j + 9, k + 27, 0);
		world.setBlock(i + 4, j + 10, k + 0, 0);
		world.setBlock(i + 4, j + 10, k + 1, 0);
		world.setBlock(i + 4, j + 10, k + 2, 0);
		world.setBlock(i + 4, j + 10, k + 3, 0);
		world.setBlock(i + 4, j + 10, k + 4, 0);
		world.setBlock(i + 4, j + 10, k + 5, 0);
		world.setBlock(i + 4, j + 10, k + 6, 0);
		world.setBlock(i + 4, j + 10, k + 7, 0);
		world.setBlock(i + 4, j + 10, k + 8, 0);
		world.setBlock(i + 4, j + 10, k + 9, 0);
		world.setBlock(i + 4, j + 10, k + 10, getDarkWallId());
		world.setBlock(i + 4, j + 10, k + 11, getDarkWallId());
		world.setBlock(i + 4, j + 10, k + 12, getDarkWallId());
		world.setBlock(i + 4, j + 10, k + 13, getDarkWallId());
		world.setBlock(i + 4, j + 10, k + 14, getDarkWallId());
		world.setBlock(i + 4, j + 10, k + 15, getDarkWallId());
		world.setBlock(i + 4, j + 10, k + 16, getDarkWallId());
		world.setBlock(i + 4, j + 10, k + 17, getDarkWallId());
		world.setBlock(i + 4, j + 10, k + 18, getDarkWallId());
		world.setBlock(i + 4, j + 10, k + 19, getDarkWallId());
		world.setBlock(i + 4, j + 10, k + 20, getDarkWallId());
		world.setBlock(i + 4, j + 10, k + 21, getDarkWallId());
		world.setBlock(i + 4, j + 10, k + 22, getDarkWallId());
		world.setBlock(i + 4, j + 10, k + 23, getDarkWallId());
		world.setBlock(i + 4, j + 10, k + 24, getDarkWallId());
		world.setBlock(i + 4, j + 10, k + 25, 0);
		world.setBlock(i + 4, j + 10, k + 26, 0);
		world.setBlock(i + 4, j + 10, k + 27, 0);
		world.setBlock(i + 5, j + 0, k + 0, getDarkWallId());
		world.setBlock(i + 5, j + 0, k + 1, getDarkWallId());
		world.setBlock(i + 5, j + 0, k + 2, getDarkWallId());
		world.setBlock(i + 5, j + 0, k + 3, getDarkWallId());
		world.setBlock(i + 5, j + 0, k + 4, getDarkWallId());
		world.setBlock(i + 5, j + 0, k + 5, getDarkWallId());
		world.setBlock(i + 5, j + 0, k + 6, getDarkWallId());
		world.setBlock(i + 5, j + 0, k + 7, getDarkWallId());
		world.setBlock(i + 5, j + 0, k + 8, getDarkWallId());
		world.setBlock(i + 5, j + 0, k + 9, getDarkWallId());
		world.setBlock(i + 5, j + 0, k + 10, getDarkWallId());
		world.setBlock(i + 5, j + 0, k + 11, getDarkWallId());
		world.setBlock(i + 5, j + 0, k + 12, getDarkWallId());
		world.setBlock(i + 5, j + 0, k + 13, getDarkWallId());
		world.setBlock(i + 5, j + 0, k + 14, getDarkWallId());
		world.setBlock(i + 5, j + 0, k + 15, getDarkWallId());
		world.setBlock(i + 5, j + 0, k + 16, getDarkWallId());
		world.setBlock(i + 5, j + 0, k + 17, getDarkWallId());
		world.setBlock(i + 5, j + 0, k + 18, getDarkWallId());
		world.setBlock(i + 5, j + 0, k + 19, getDarkWallId());
		world.setBlock(i + 5, j + 0, k + 20, getDarkWallId());
		world.setBlock(i + 5, j + 0, k + 21, getDarkWallId());
		world.setBlock(i + 5, j + 0, k + 22, getDarkWallId());
		world.setBlock(i + 5, j + 0, k + 23, getDarkWallId());
		world.setBlock(i + 5, j + 0, k + 24, getDarkWallId());
		world.setBlock(i + 5, j + 0, k + 25, 0);
		world.setBlock(i + 5, j + 0, k + 26, 0);
		world.setBlock(i + 5, j + 0, k + 27, 0);
		world.setBlock(i + 5, j + 1, k + 0, getDarkWallId());
		world.setBlock(i + 5, j + 1, k + 1, 0);
		world.setBlock(i + 5, j + 1, k + 2, 0);
		world.setBlock(i + 5, j + 1, k + 3, 0);
		world.setBlock(i + 5, j + 1, k + 4, 0);
		world.setBlock(i + 5, j + 1, k + 5, 0);
		world.setBlock(i + 5, j + 1, k + 6, 0);
		world.setBlock(i + 5, j + 1, k + 7, 0);
		world.setBlock(i + 5, j + 1, k + 8, 0);
		world.setBlock(i + 5, j + 1, k + 9, 0);
		world.setBlock(i + 5, j + 1, k + 10, 0);
		world.setBlock(i + 5, j + 1, k + 11, 0);
		world.setBlock(i + 5, j + 1, k + 12, 0);
		world.setBlock(i + 5, j + 1, k + 13, 0);
		world.setBlock(i + 5, j + 1, k + 14, 0);
		world.setBlock(i + 5, j + 1, k + 15, 0);
		world.setBlock(i + 5, j + 1, k + 16, 0);
		world.setBlock(i + 5, j + 1, k + 17, 0);
		world.setBlock(i + 5, j + 1, k + 18, 0);
		world.setBlock(i + 5, j + 1, k + 19, 0);
		world.setBlock(i + 5, j + 1, k + 20, 0);
		world.setBlock(i + 5, j + 1, k + 21, 0);
		world.setBlock(i + 5, j + 1, k + 22, 0);
		world.setBlock(i + 5, j + 1, k + 23, 0);
		world.setBlock(i + 5, j + 1, k + 24, getDarkWallId());
		world.setBlock(i + 5, j + 1, k + 25, 0);
		world.setBlock(i + 5, j + 1, k + 26, 0);
		world.setBlock(i + 5, j + 1, k + 27, 0);
		world.setBlock(i + 5, j + 2, k + 0, getDarkWallId());
		world.setBlock(i + 5, j + 2, k + 1, 0);
		world.setBlock(i + 5, j + 2, k + 2, 0);
		world.setBlock(i + 5, j + 2, k + 3, 0);
		world.setBlock(i + 5, j + 2, k + 4, 0);
		world.setBlock(i + 5, j + 2, k + 5, 0);
		world.setBlock(i + 5, j + 2, k + 6, 0);
		world.setBlock(i + 5, j + 2, k + 7, 0);
		world.setBlock(i + 5, j + 2, k + 8, 0);
		world.setBlock(i + 5, j + 2, k + 9, 0);
		world.setBlock(i + 5, j + 2, k + 10, 0);
		world.setBlock(i + 5, j + 2, k + 11, 0);
		world.setBlock(i + 5, j + 2, k + 12, VirtiousBlocks.cytoidFloorDouble.blockID, 0, 2);
		world.setBlock(i + 5, j + 2, k + 13, VirtiousBlocks.cytoidFloorDouble.blockID, 0, 2);
		world.setBlock(i + 5, j + 2, k + 14, 0);
		world.setBlock(i + 5, j + 2, k + 15, 0);
		world.setBlock(i + 5, j + 2, k + 16, 0);
		world.setBlock(i + 5, j + 2, k + 17, 0);
		world.setBlock(i + 5, j + 2, k + 18, 0);
		world.setBlock(i + 5, j + 2, k + 19, 0);
		world.setBlock(i + 5, j + 2, k + 20, 0);
		world.setBlock(i + 5, j + 2, k + 21, 0);
		world.setBlock(i + 5, j + 2, k + 22, 0);
		world.setBlock(i + 5, j + 2, k + 23, 0);
		world.setBlock(i + 5, j + 2, k + 24, getDarkWallId());
		world.setBlock(i + 5, j + 2, k + 25, 0);
		world.setBlock(i + 5, j + 2, k + 26, 0);
		world.setBlock(i + 5, j + 2, k + 27, 0);
		world.setBlock(i + 5, j + 3, k + 0, getDarkWallId());
		world.setBlock(i + 5, j + 3, k + 1, 0);
		world.setBlock(i + 5, j + 3, k + 2, VirtiousBlocks.cytoidWallLower.blockID);
		world.setBlock(i + 5, j + 3, k + 3, VirtiousBlocks.virtianstone.blockID);
		world.setBlock(i + 5, j + 3, k + 4, VirtiousBlocks.cytoidWallLower.blockID);
		world.setBlock(i + 5, j + 3, k + 5, VirtiousBlocks.virtianstone.blockID);
		world.setBlock(i + 5, j + 3, k + 6, VirtiousBlocks.cytoidWallLower.blockID);
		world.setBlock(i + 5, j + 3, k + 7, VirtiousBlocks.virtianstone.blockID);
		world.setBlock(i + 5, j + 3, k + 8, VirtiousBlocks.cytoidWallLower.blockID);
		world.setBlock(i + 5, j + 3, k + 9, VirtiousBlocks.virtianstone.blockID);
		world.setBlock(i + 5, j + 3, k + 10, VirtiousBlocks.cytoidWallLower.blockID);
		world.setBlock(i + 5, j + 3, k + 11, VirtiousBlocks.cytoidWallLower.blockID);
		world.setBlock(i + 5, j + 3, k + 12, 0);
		world.setBlock(i + 5, j + 3, k + 13, 0);
		world.setBlock(i + 5, j + 3, k + 14, VirtiousBlocks.cytoidWallLower.blockID);
		world.setBlock(i + 5, j + 3, k + 15, VirtiousBlocks.cytoidWallLower.blockID);
		world.setBlock(i + 5, j + 3, k + 16, VirtiousBlocks.cytoidWallLower.blockID);
		world.setBlock(i + 5, j + 3, k + 17, VirtiousBlocks.cytoidWallLower.blockID);
		world.setBlock(i + 5, j + 3, k + 18, VirtiousBlocks.cytoidWallLower.blockID);
		world.setBlock(i + 5, j + 3, k + 19, VirtiousBlocks.cytoidWallLower.blockID);
		world.setBlock(i + 5, j + 3, k + 20, VirtiousBlocks.cytoidWallLower.blockID);
		world.setBlock(i + 5, j + 3, k + 21, VirtiousBlocks.cytoidWallLower.blockID);
		world.setBlock(i + 5, j + 3, k + 22, 0);
		world.setBlock(i + 5, j + 3, k + 23, 0);
		world.setBlock(i + 5, j + 3, k + 24, getDarkWallId());
		world.setBlock(i + 5, j + 3, k + 25, 0);
		world.setBlock(i + 5, j + 3, k + 26, 0);
		world.setBlock(i + 5, j + 3, k + 27, 0);
		world.setBlock(i + 5, j + 4, k + 0, getDarkWallId());
		world.setBlock(i + 5, j + 4, k + 1, 0);
		world.setBlock(i + 5, j + 4, k + 2, VirtiousBlocks.cytoidWallUpper.blockID);
		world.setBlock(i + 5, j + 4, k + 3, VirtiousBlocks.cytoidGlass.blockID);
		world.setBlock(i + 5, j + 4, k + 4, VirtiousBlocks.cytoidWallUpper.blockID);
		world.setBlock(i + 5, j + 4, k + 5, VirtiousBlocks.cytoidGlass.blockID);
		world.setBlock(i + 5, j + 4, k + 6, VirtiousBlocks.cytoidWallUpper.blockID);
		world.setBlock(i + 5, j + 4, k + 7, VirtiousBlocks.cytoidGlass.blockID);
		world.setBlock(i + 5, j + 4, k + 8, VirtiousBlocks.cytoidWallUpper.blockID);
		world.setBlock(i + 5, j + 4, k + 9, VirtiousBlocks.cytoidGlass.blockID);
		world.setBlock(i + 5, j + 4, k + 10, VirtiousBlocks.cytoidWallUpper.blockID);
		world.setBlock(i + 5, j + 4, k + 11, VirtiousBlocks.cytoidWallUpper.blockID);
		world.setBlock(i + 5, j + 4, k + 12, 0);
		world.setBlock(i + 5, j + 4, k + 13, 0);
		world.setBlock(i + 5, j + 4, k + 14, VirtiousBlocks.virtianstone.blockID);
		world.setBlock(i + 5, j + 4, k + 15, VirtiousBlocks.virtianstone.blockID);
		world.setBlock(i + 5, j + 4, k + 16, VirtiousBlocks.virtianstone.blockID);
		world.setBlock(i + 5, j + 4, k + 17, VirtiousBlocks.virtianstone.blockID);
		world.setBlock(i + 5, j + 4, k + 18, VirtiousBlocks.virtianstone.blockID);
		world.setBlock(i + 5, j + 4, k + 19, VirtiousBlocks.virtianstone.blockID);
		world.setBlock(i + 5, j + 4, k + 20, VirtiousBlocks.virtianstone.blockID);
		world.setBlock(i + 5, j + 4, k + 21, VirtiousBlocks.virtianstone.blockID);
		world.setBlock(i + 5, j + 4, k + 22, 0);
		world.setBlock(i + 5, j + 4, k + 23, 0);
		world.setBlock(i + 5, j + 4, k + 24, getDarkWallId());
		world.setBlock(i + 5, j + 4, k + 25, 0);
		world.setBlock(i + 5, j + 4, k + 26, 0);
		world.setBlock(i + 5, j + 4, k + 27, 0);
		world.setBlock(i + 5, j + 5, k + 0, getDarkWallId());
		world.setBlock(i + 5, j + 5, k + 1, 0);
		world.setBlock(i + 5, j + 5, k + 2, 0);
		world.setBlock(i + 5, j + 5, k + 3, VirtiousBlocks.virtianstone.blockID);
		world.setBlock(i + 5, j + 5, k + 4, 0);
		world.setBlock(i + 5, j + 5, k + 5, VirtiousBlocks.virtianstone.blockID);
		world.setBlock(i + 5, j + 5, k + 6, 0);
		world.setBlock(i + 5, j + 5, k + 7, VirtiousBlocks.virtianstone.blockID);
		world.setBlock(i + 5, j + 5, k + 8, 0);
		world.setBlock(i + 5, j + 5, k + 9, VirtiousBlocks.virtianstone.blockID);
		world.setBlock(i + 5, j + 5, k + 10, 0);
		world.setBlock(i + 5, j + 5, k + 11, VirtiousBlocks.cytoidLightstrip.blockID);
		world.setBlock(i + 5, j + 5, k + 12, 0);
		world.setBlock(i + 5, j + 5, k + 13, 0);
		world.setBlock(i + 5, j + 5, k + 14, VirtiousBlocks.cytoidLightstrip.blockID);
		world.setBlock(i + 5, j + 5, k + 15, VirtiousBlocks.cytoidLightstrip.blockID);
		world.setBlock(i + 5, j + 5, k + 16, VirtiousBlocks.cytoidLightstrip.blockID);
		world.setBlock(i + 5, j + 5, k + 17, VirtiousBlocks.cytoidLightstrip.blockID);
		world.setBlock(i + 5, j + 5, k + 18, VirtiousBlocks.cytoidLightstrip.blockID);
		world.setBlock(i + 5, j + 5, k + 19, VirtiousBlocks.cytoidLightstrip.blockID);
		world.setBlock(i + 5, j + 5, k + 20, VirtiousBlocks.cytoidLightstrip.blockID);
		world.setBlock(i + 5, j + 5, k + 21, VirtiousBlocks.cytoidLightstrip.blockID);
		world.setBlock(i + 5, j + 5, k + 22, 0);
		world.setBlock(i + 5, j + 5, k + 23, 0);
		world.setBlock(i + 5, j + 5, k + 24, getDarkWallId());
		world.setBlock(i + 5, j + 5, k + 25, 0);
		world.setBlock(i + 5, j + 5, k + 26, 0);
		world.setBlock(i + 5, j + 5, k + 27, 0);
		world.setBlock(i + 5, j + 6, k + 0, getDarkWallId());
		world.setBlock(i + 5, j + 6, k + 1, getDarkWallId());
		world.setBlock(i + 5, j + 6, k + 2, getDarkWallId());
		world.setBlock(i + 5, j + 6, k + 3, getDarkWallId());
		world.setBlock(i + 5, j + 6, k + 4, getDarkWallId());
		world.setBlock(i + 5, j + 6, k + 5, getDarkWallId());
		world.setBlock(i + 5, j + 6, k + 6, getDarkWallId());
		world.setBlock(i + 5, j + 6, k + 7, getDarkWallId());
		world.setBlock(i + 5, j + 6, k + 8, getDarkWallId());
		world.setBlock(i + 5, j + 6, k + 9, getDarkWallId());
		world.setBlock(i + 5, j + 6, k + 10, 0);
		world.setBlock(i + 5, j + 6, k + 11, VirtiousBlocks.cytoidWallLower.blockID);
		world.setBlock(i + 5, j + 6, k + 12, 0);
		world.setBlock(i + 5, j + 6, k + 13, 0);
		world.setBlock(i + 5, j + 6, k + 14, VirtiousBlocks.cytoidWallLower.blockID);
		world.setBlock(i + 5, j + 6, k + 15, VirtiousBlocks.virtianstone.blockID);
		world.setBlock(i + 5, j + 6, k + 16, VirtiousBlocks.cytoidWallLower.blockID);
		world.setBlock(i + 5, j + 6, k + 17, VirtiousBlocks.virtianstone.blockID);
		world.setBlock(i + 5, j + 6, k + 18, VirtiousBlocks.cytoidWallLower.blockID);
		world.setBlock(i + 5, j + 6, k + 19, 0);
		world.setBlock(i + 5, j + 6, k + 20, 0);
		world.setBlock(i + 5, j + 6, k + 21, 0);
		world.setBlock(i + 5, j + 6, k + 22, VirtiousBlocks.cytoidWallLower.blockID);
		world.setBlock(i + 5, j + 6, k + 23, 0);
		world.setBlock(i + 5, j + 6, k + 24, getDarkWallId());
		world.setBlock(i + 5, j + 6, k + 25, 0);
		world.setBlock(i + 5, j + 6, k + 26, 0);
		world.setBlock(i + 5, j + 6, k + 27, 0);
		world.setBlock(i + 5, j + 7, k + 0, 0);
		world.setBlock(i + 5, j + 7, k + 1, 0);
		world.setBlock(i + 5, j + 7, k + 2, 0);
		world.setBlock(i + 5, j + 7, k + 3, 0);
		world.setBlock(i + 5, j + 7, k + 4, 0);
		world.setBlock(i + 5, j + 7, k + 5, 0);
		world.setBlock(i + 5, j + 7, k + 6, 0);
		world.setBlock(i + 5, j + 7, k + 7, 0);
		world.setBlock(i + 5, j + 7, k + 8, 0);
		world.setBlock(i + 5, j + 7, k + 9, 0);
		world.setBlock(i + 5, j + 7, k + 10, getDarkWallId());
		world.setBlock(i + 5, j + 7, k + 11, VirtiousBlocks.cytoidWallUpper.blockID);
		world.setBlock(i + 5, j + 7, k + 12, 0);
		world.setBlock(i + 5, j + 7, k + 13, 0);
		world.setBlock(i + 5, j + 7, k + 14, VirtiousBlocks.cytoidWallUpper.blockID);
		world.setBlock(i + 5, j + 7, k + 15, VirtiousBlocks.cytoidGlass.blockID);
		world.setBlock(i + 5, j + 7, k + 16, VirtiousBlocks.cytoidWallUpper.blockID);
		world.setBlock(i + 5, j + 7, k + 17, VirtiousBlocks.cytoidGlass.blockID);
		world.setBlock(i + 5, j + 7, k + 18, VirtiousBlocks.cytoidWallUpper.blockID);
		world.setBlock(i + 5, j + 7, k + 19, 0);
		world.setBlock(i + 5, j + 7, k + 20, 0);
		world.setBlock(i + 5, j + 7, k + 21, 0);
		world.setBlock(i + 5, j + 7, k + 22, VirtiousBlocks.cytoidWallUpper.blockID);
		world.setBlock(i + 5, j + 7, k + 23, 0);
		world.setBlock(i + 5, j + 7, k + 24, getDarkWallId());
		world.setBlock(i + 5, j + 7, k + 25, 0);
		world.setBlock(i + 5, j + 7, k + 26, 0);
		world.setBlock(i + 5, j + 7, k + 27, 0);
		world.setBlock(i + 5, j + 8, k + 0, 0);
		world.setBlock(i + 5, j + 8, k + 1, 0);
		world.setBlock(i + 5, j + 8, k + 2, 0);
		world.setBlock(i + 5, j + 8, k + 3, 0);
		world.setBlock(i + 5, j + 8, k + 4, 0);
		world.setBlock(i + 5, j + 8, k + 5, 0);
		world.setBlock(i + 5, j + 8, k + 6, 0);
		world.setBlock(i + 5, j + 8, k + 7, 0);
		world.setBlock(i + 5, j + 8, k + 8, 0);
		world.setBlock(i + 5, j + 8, k + 9, 0);
		world.setBlock(i + 5, j + 8, k + 10, getDarkWallId());
		world.setBlock(i + 5, j + 8, k + 11, 0);
		world.setBlock(i + 5, j + 8, k + 12, VirtiousBlocks.cytoidFloorDouble.blockID, 0, 2);
		world.setBlock(i + 5, j + 8, k + 13, VirtiousBlocks.cytoidFloorDouble.blockID, 0, 2);
		world.setBlock(i + 5, j + 8, k + 14, 0);
		world.setBlock(i + 5, j + 8, k + 15, VirtiousBlocks.virtianstone.blockID);
		world.setBlock(i + 5, j + 8, k + 16, 0);
		world.setBlock(i + 5, j + 8, k + 17, VirtiousBlocks.virtianstone.blockID);
		world.setBlock(i + 5, j + 8, k + 18, 0);
		world.setBlock(i + 5, j + 8, k + 19, VirtiousBlocks.cytoidFloorDouble.blockID, 0, 2);
		world.setBlock(i + 5, j + 8, k + 20, VirtiousBlocks.cytoidFloorDouble.blockID, 0, 2);
		world.setBlock(i + 5, j + 8, k + 21, VirtiousBlocks.cytoidFloorDouble.blockID, 0, 2);
		world.setBlock(i + 5, j + 8, k + 22, 0);
		world.setBlock(i + 5, j + 8, k + 23, 0);
		world.setBlock(i + 5, j + 8, k + 24, getDarkWallId());
		world.setBlock(i + 5, j + 8, k + 25, 0);
		world.setBlock(i + 5, j + 8, k + 26, 0);
		world.setBlock(i + 5, j + 8, k + 27, 0);
		world.setBlock(i + 5, j + 9, k + 0, 0);
		world.setBlock(i + 5, j + 9, k + 1, 0);
		world.setBlock(i + 5, j + 9, k + 2, 0);
		world.setBlock(i + 5, j + 9, k + 3, 0);
		world.setBlock(i + 5, j + 9, k + 4, 0);
		world.setBlock(i + 5, j + 9, k + 5, 0);
		world.setBlock(i + 5, j + 9, k + 6, 0);
		world.setBlock(i + 5, j + 9, k + 7, 0);
		world.setBlock(i + 5, j + 9, k + 8, 0);
		world.setBlock(i + 5, j + 9, k + 9, 0);
		world.setBlock(i + 5, j + 9, k + 10, getDarkWallId());
		world.setBlock(i + 5, j + 9, k + 11, 0);
		world.setBlock(i + 5, j + 9, k + 12, 0);
		world.setBlock(i + 5, j + 9, k + 13, 0);
		world.setBlock(i + 5, j + 9, k + 14, 0);
		world.setBlock(i + 5, j + 9, k + 15, 0);
		world.setBlock(i + 5, j + 9, k + 16, 0);
		world.setBlock(i + 5, j + 9, k + 17, 0);
		world.setBlock(i + 5, j + 9, k + 18, 0);
		world.setBlock(i + 5, j + 9, k + 19, 0);
		world.setBlock(i + 5, j + 9, k + 20, 0);
		world.setBlock(i + 5, j + 9, k + 21, 0);
		world.setBlock(i + 5, j + 9, k + 22, 0);
		world.setBlock(i + 5, j + 9, k + 23, 0);
		world.setBlock(i + 5, j + 9, k + 24, getDarkWallId());
		world.setBlock(i + 5, j + 9, k + 25, 0);
		world.setBlock(i + 5, j + 9, k + 26, 0);
		world.setBlock(i + 5, j + 9, k + 27, 0);
		world.setBlock(i + 5, j + 10, k + 0, 0);
		world.setBlock(i + 5, j + 10, k + 1, 0);
		world.setBlock(i + 5, j + 10, k + 2, 0);
		world.setBlock(i + 5, j + 10, k + 3, 0);
		world.setBlock(i + 5, j + 10, k + 4, 0);
		world.setBlock(i + 5, j + 10, k + 5, 0);
		world.setBlock(i + 5, j + 10, k + 6, 0);
		world.setBlock(i + 5, j + 10, k + 7, 0);
		world.setBlock(i + 5, j + 10, k + 8, 0);
		world.setBlock(i + 5, j + 10, k + 9, 0);
		world.setBlock(i + 5, j + 10, k + 10, getDarkWallId());
		world.setBlock(i + 5, j + 10, k + 11, getDarkWallId());
		world.setBlock(i + 5, j + 10, k + 12, getDarkWallId());
		world.setBlock(i + 5, j + 10, k + 13, getDarkWallId());
		world.setBlock(i + 5, j + 10, k + 14, getDarkWallId());
		world.setBlock(i + 5, j + 10, k + 15, getDarkWallId());
		world.setBlock(i + 5, j + 10, k + 16, getDarkWallId());
		world.setBlock(i + 5, j + 10, k + 17, getDarkWallId());
		world.setBlock(i + 5, j + 10, k + 18, getDarkWallId());
		world.setBlock(i + 5, j + 10, k + 19, getDarkWallId());
		world.setBlock(i + 5, j + 10, k + 20, getDarkWallId());
		world.setBlock(i + 5, j + 10, k + 21, getDarkWallId());
		world.setBlock(i + 5, j + 10, k + 22, getDarkWallId());
		world.setBlock(i + 5, j + 10, k + 23, getDarkWallId());
		world.setBlock(i + 5, j + 10, k + 24, getDarkWallId());
		world.setBlock(i + 5, j + 10, k + 25, 0);
		world.setBlock(i + 5, j + 10, k + 26, 0);
		world.setBlock(i + 5, j + 10, k + 27, 0);
		world.setBlock(i + 6, j + 0, k + 0, getDarkWallId());
		world.setBlock(i + 6, j + 0, k + 1, getDarkWallId());
		world.setBlock(i + 6, j + 0, k + 2, getDarkWallId());
		world.setBlock(i + 6, j + 0, k + 3, getDarkWallId());
		world.setBlock(i + 6, j + 0, k + 4, getDarkWallId());
		world.setBlock(i + 6, j + 0, k + 5, getDarkWallId());
		world.setBlock(i + 6, j + 0, k + 6, getDarkWallId());
		world.setBlock(i + 6, j + 0, k + 7, getDarkWallId());
		world.setBlock(i + 6, j + 0, k + 8, getDarkWallId());
		world.setBlock(i + 6, j + 0, k + 9, getDarkWallId());
		world.setBlock(i + 6, j + 0, k + 10, getDarkWallId());
		world.setBlock(i + 6, j + 0, k + 11, getDarkWallId());
		world.setBlock(i + 6, j + 0, k + 12, getDarkWallId());
		world.setBlock(i + 6, j + 0, k + 13, getDarkWallId());
		world.setBlock(i + 6, j + 0, k + 14, getDarkWallId());
		world.setBlock(i + 6, j + 0, k + 15, getDarkWallId());
		world.setBlock(i + 6, j + 0, k + 16, getDarkWallId());
		world.setBlock(i + 6, j + 0, k + 17, getDarkWallId());
		world.setBlock(i + 6, j + 0, k + 18, getDarkWallId());
		world.setBlock(i + 6, j + 0, k + 19, getDarkWallId());
		world.setBlock(i + 6, j + 0, k + 20, getDarkWallId());
		world.setBlock(i + 6, j + 0, k + 21, getDarkWallId());
		world.setBlock(i + 6, j + 0, k + 22, getDarkWallId());
		world.setBlock(i + 6, j + 0, k + 23, getDarkWallId());
		world.setBlock(i + 6, j + 0, k + 24, getDarkWallId());
		world.setBlock(i + 6, j + 0, k + 25, 0);
		world.setBlock(i + 6, j + 0, k + 26, 0);
		world.setBlock(i + 6, j + 0, k + 27, 0);
		world.setBlock(i + 6, j + 1, k + 0, getDarkWallId());
		world.setBlock(i + 6, j + 1, k + 1, 0);
		world.setBlock(i + 6, j + 1, k + 2, 0);
		world.setBlock(i + 6, j + 1, k + 3, 0);
		world.setBlock(i + 6, j + 1, k + 4, 0);
		world.setBlock(i + 6, j + 1, k + 5, 0);
		world.setBlock(i + 6, j + 1, k + 6, 0);
		world.setBlock(i + 6, j + 1, k + 7, 0);
		world.setBlock(i + 6, j + 1, k + 8, 0);
		world.setBlock(i + 6, j + 1, k + 9, 0);
		world.setBlock(i + 6, j + 1, k + 10, 0);
		world.setBlock(i + 6, j + 1, k + 11, 0);
		world.setBlock(i + 6, j + 1, k + 12, 0);
		world.setBlock(i + 6, j + 1, k + 13, 0);
		world.setBlock(i + 6, j + 1, k + 14, 0);
		world.setBlock(i + 6, j + 1, k + 15, 0);
		world.setBlock(i + 6, j + 1, k + 16, 0);
		world.setBlock(i + 6, j + 1, k + 17, 0);
		world.setBlock(i + 6, j + 1, k + 18, 0);
		world.setBlock(i + 6, j + 1, k + 19, 0);
		world.setBlock(i + 6, j + 1, k + 20, 0);
		world.setBlock(i + 6, j + 1, k + 21, 0);
		world.setBlock(i + 6, j + 1, k + 22, 0);
		world.setBlock(i + 6, j + 1, k + 23, 0);
		world.setBlock(i + 6, j + 1, k + 24, getDarkWallId());
		world.setBlock(i + 6, j + 1, k + 25, 0);
		world.setBlock(i + 6, j + 1, k + 26, 0);
		world.setBlock(i + 6, j + 1, k + 27, 0);
		world.setBlock(i + 6, j + 2, k + 0, getDarkWallId());
		world.setBlock(i + 6, j + 2, k + 1, 0);
		world.setBlock(i + 6, j + 2, k + 2, VirtiousBlocks.cytoidFloorDouble.blockID, 0, 2);
		world.setBlock(i + 6, j + 2, k + 3, VirtiousBlocks.cytoidFloorDouble.blockID, 0, 2);
		world.setBlock(i + 6, j + 2, k + 4, VirtiousBlocks.cytoidFloorDouble.blockID, 0, 2);
		world.setBlock(i + 6, j + 2, k + 5, VirtiousBlocks.cytoidFloorDouble.blockID, 0, 2);
		world.setBlock(i + 6, j + 2, k + 6, VirtiousBlocks.cytoidFloorDouble.blockID, 0, 2);
		world.setBlock(i + 6, j + 2, k + 7, VirtiousBlocks.cytoidFloorDouble.blockID, 0, 2);
		world.setBlock(i + 6, j + 2, k + 8, VirtiousBlocks.cytoidFloorDouble.blockID, 0, 2);
		world.setBlock(i + 6, j + 2, k + 9, VirtiousBlocks.cytoidFloorDouble.blockID, 0, 2);
		world.setBlock(i + 6, j + 2, k + 10, VirtiousBlocks.cytoidFloorDouble.blockID, 0, 2);
		world.setBlock(i + 6, j + 2, k + 11, VirtiousBlocks.cytoidFloorDouble.blockID, 0, 2);
